<?xml version="1.0"?><robot name="pepe">
	<link name="0">
		<visual>
			<geometry>
				<cylinder length="0.02055004831631324" radius="0.8893368137097987"/>
			</geometry>
		</visual>
		<collision>
			<geometry>
				<cylinder length="0.02055004831631324" radius="0.8893368137097987"/>
			</geometry>
		</collision>
		<inertial>
			<mass value="0.051061698887551785"/>
			<inertia ixx="0.03" ixy="0" ixz="0" iyx="0" iyy="0.03" izz="0.03"/>
		</inertial>
	</link>
	<link name="11">
		<visual>
			<geometry>
				<cylinder length="1.60513991533209" radius="0.8634613215792118"/>
			</geometry>
		</visual>
		<collision>
			<geometry>
				<cylinder length="1.60513991533209" radius="0.8634613215792118"/>
			</geometry>
		</collision>
		<inertial>
			<mass value="3.7596597574657444"/>
			<inertia ixx="0.03" ixy="0" ixz="0" iyx="0" iyy="0.03" izz="0.03"/>
		</inertial>
	</link>
	<link name="22">
		<visual>
			<geometry>
				<cylinder length="0.918337099951559" radius="0.695715506343085"/>
			</geometry>
		</visual>
		<collision>
			<geometry>
				<cylinder length="0.918337099951559" radius="0.695715506343085"/>
			</geometry>
		</collision>
		<inertial>
			<mass value="1.3964177765357255"/>
			<inertia ixx="0.03" ixy="0" ixz="0" iyx="0" iyy="0.03" izz="0.03"/>
		</inertial>
	</link>
	<link name="33">
		<visual>
			<geometry>
				<cylinder length="1.0451484976951648" radius="0.7835822465096126"/>
			</geometry>
		</visual>
		<collision>
			<geometry>
				<cylinder length="1.0451484976951648" radius="0.7835822465096126"/>
			</geometry>
		</collision>
		<inertial>
			<mass value="2.0160302705622875"/>
			<inertia ixx="0.03" ixy="0" ixz="0" iyx="0" iyy="0.03" izz="0.03"/>
		</inertial>
	</link>
	<link name="34">
		<visual>
			<geometry>
				<cylinder length="1.0451484976951648" radius="0.7835822465096126"/>
			</geometry>
		</visual>
		<collision>
			<geometry>
				<cylinder length="1.0451484976951648" radius="0.7835822465096126"/>
			</geometry>
		</collision>
		<inertial>
			<mass value="2.0160302705622875"/>
			<inertia ixx="0.03" ixy="0" ixz="0" iyx="0" iyy="0.03" izz="0.03"/>
		</inertial>
	</link>
	<link name="35">
		<visual>
			<geometry>
				<cylinder length="1.0451484976951648" radius="0.7835822465096126"/>
			</geometry>
		</visual>
		<collision>
			<geometry>
				<cylinder length="1.0451484976951648" radius="0.7835822465096126"/>
			</geometry>
		</collision>
		<inertial>
			<mass value="2.0160302705622875"/>
			<inertia ixx="0.03" ixy="0" ixz="0" iyx="0" iyy="0.03" izz="0.03"/>
		</inertial>
	</link>
	<link name="46">
		<visual>
			<geometry>
				<cylinder length="1.8450523789944118" radius="0.6492368691014052"/>
			</geometry>
		</visual>
		<collision>
			<geometry>
				<cylinder length="1.8450523789944118" radius="0.6492368691014052"/>
			</geometry>
		</collision>
		<inertial>
			<mass value="2.4432332043656966"/>
			<inertia ixx="0.03" ixy="0" ixz="0" iyx="0" iyy="0.03" izz="0.03"/>
		</inertial>
	</link>
	<link name="47">
		<visual>
			<geometry>
				<cylinder length="1.8450523789944118" radius="0.6492368691014052"/>
			</geometry>
		</visual>
		<collision>
			<geometry>
				<cylinder length="1.8450523789944118" radius="0.6492368691014052"/>
			</geometry>
		</collision>
		<inertial>
			<mass value="2.4432332043656966"/>
			<inertia ixx="0.03" ixy="0" ixz="0" iyx="0" iyy="0.03" izz="0.03"/>
		</inertial>
	</link>
	<link name="78">
		<visual>
			<geometry>
				<cylinder length="1.6076123025584668" radius="0.5316572381935852"/>
			</geometry>
		</visual>
		<collision>
			<geometry>
				<cylinder length="1.6076123025584668" radius="0.5316572381935852"/>
			</geometry>
		</collision>
		<inertial>
			<mass value="1.4275609367447786"/>
			<inertia ixx="0.03" ixy="0" ixz="0" iyx="0" iyy="0.03" izz="0.03"/>
		</inertial>
	</link>
	<link name="109">
		<visual>
			<geometry>
				<cylinder length="1.3070330000811032" radius="0.13366270972617045"/>
			</geometry>
		</visual>
		<collision>
			<geometry>
				<cylinder length="1.3070330000811032" radius="0.13366270972617045"/>
			</geometry>
		</collision>
		<inertial>
			<mass value="0.0733595988887064"/>
			<inertia ixx="0.03" ixy="0" ixz="0" iyx="0" iyy="0.03" izz="0.03"/>
		</inertial>
	</link>
	<link name="1010">
		<visual>
			<geometry>
				<cylinder length="1.3070330000811032" radius="0.13366270972617045"/>
			</geometry>
		</visual>
		<collision>
			<geometry>
				<cylinder length="1.3070330000811032" radius="0.13366270972617045"/>
			</geometry>
		</collision>
		<inertial>
			<mass value="0.0733595988887064"/>
			<inertia ixx="0.03" ixy="0" ixz="0" iyx="0" iyy="0.03" izz="0.03"/>
		</inertial>
	</link>
	<link name="1011">
		<visual>
			<geometry>
				<cylinder length="1.3070330000811032" radius="0.13366270972617045"/>
			</geometry>
		</visual>
		<collision>
			<geometry>
				<cylinder length="1.3070330000811032" radius="0.13366270972617045"/>
			</geometry>
		</collision>
		<inertial>
			<mass value="0.0733595988887064"/>
			<inertia ixx="0.03" ixy="0" ixz="0" iyx="0" iyy="0.03" izz="0.03"/>
		</inertial>
	</link>
	<link name="212">
		<visual>
			<geometry>
				<cylinder length="0.918337099951559" radius="0.695715506343085"/>
			</geometry>
		</visual>
		<collision>
			<geometry>
				<cylinder length="0.918337099951559" radius="0.695715506343085"/>
			</geometry>
		</collision>
		<inertial>
			<mass value="1.3964177765357255"/>
			<inertia ixx="0.03" ixy="0" ixz="0" iyx="0" iyy="0.03" izz="0.03"/>
		</inertial>
	</link>
	<link name="313">
		<visual>
			<geometry>
				<cylinder length="1.0451484976951648" radius="0.7835822465096126"/>
			</geometry>
		</visual>
		<collision>
			<geometry>
				<cylinder length="1.0451484976951648" radius="0.7835822465096126"/>
			</geometry>
		</collision>
		<inertial>
			<mass value="2.0160302705622875"/>
			<inertia ixx="0.03" ixy="0" ixz="0" iyx="0" iyy="0.03" izz="0.03"/>
		</inertial>
	</link>
	<link name="314">
		<visual>
			<geometry>
				<cylinder length="1.0451484976951648" radius="0.7835822465096126"/>
			</geometry>
		</visual>
		<collision>
			<geometry>
				<cylinder length="1.0451484976951648" radius="0.7835822465096126"/>
			</geometry>
		</collision>
		<inertial>
			<mass value="2.0160302705622875"/>
			<inertia ixx="0.03" ixy="0" ixz="0" iyx="0" iyy="0.03" izz="0.03"/>
		</inertial>
	</link>
	<link name="315">
		<visual>
			<geometry>
				<cylinder length="1.0451484976951648" radius="0.7835822465096126"/>
			</geometry>
		</visual>
		<collision>
			<geometry>
				<cylinder length="1.0451484976951648" radius="0.7835822465096126"/>
			</geometry>
		</collision>
		<inertial>
			<mass value="2.0160302705622875"/>
			<inertia ixx="0.03" ixy="0" ixz="0" iyx="0" iyy="0.03" izz="0.03"/>
		</inertial>
	</link>
	<link name="416">
		<visual>
			<geometry>
				<cylinder length="1.8450523789944118" radius="0.6492368691014052"/>
			</geometry>
		</visual>
		<collision>
			<geometry>
				<cylinder length="1.8450523789944118" radius="0.6492368691014052"/>
			</geometry>
		</collision>
		<inertial>
			<mass value="2.4432332043656966"/>
			<inertia ixx="0.03" ixy="0" ixz="0" iyx="0" iyy="0.03" izz="0.03"/>
		</inertial>
	</link>
	<link name="417">
		<visual>
			<geometry>
				<cylinder length="1.8450523789944118" radius="0.6492368691014052"/>
			</geometry>
		</visual>
		<collision>
			<geometry>
				<cylinder length="1.8450523789944118" radius="0.6492368691014052"/>
			</geometry>
		</collision>
		<inertial>
			<mass value="2.4432332043656966"/>
			<inertia ixx="0.03" ixy="0" ixz="0" iyx="0" iyy="0.03" izz="0.03"/>
		</inertial>
	</link>
	<link name="718">
		<visual>
			<geometry>
				<cylinder length="1.6076123025584668" radius="0.5316572381935852"/>
			</geometry>
		</visual>
		<collision>
			<geometry>
				<cylinder length="1.6076123025584668" radius="0.5316572381935852"/>
			</geometry>
		</collision>
		<inertial>
			<mass value="1.4275609367447786"/>
			<inertia ixx="0.03" ixy="0" ixz="0" iyx="0" iyy="0.03" izz="0.03"/>
		</inertial>
	</link>
	<link name="1019">
		<visual>
			<geometry>
				<cylinder length="1.3070330000811032" radius="0.13366270972617045"/>
			</geometry>
		</visual>
		<collision>
			<geometry>
				<cylinder length="1.3070330000811032" radius="0.13366270972617045"/>
			</geometry>
		</collision>
		<inertial>
			<mass value="0.0733595988887064"/>
			<inertia ixx="0.03" ixy="0" ixz="0" iyx="0" iyy="0.03" izz="0.03"/>
		</inertial>
	</link>
	<link name="1020">
		<visual>
			<geometry>
				<cylinder length="1.3070330000811032" radius="0.13366270972617045"/>
			</geometry>
		</visual>
		<collision>
			<geometry>
				<cylinder length="1.3070330000811032" radius="0.13366270972617045"/>
			</geometry>
		</collision>
		<inertial>
			<mass value="0.0733595988887064"/>
			<inertia ixx="0.03" ixy="0" ixz="0" iyx="0" iyy="0.03" izz="0.03"/>
		</inertial>
	</link>
	<link name="1021">
		<visual>
			<geometry>
				<cylinder length="1.3070330000811032" radius="0.13366270972617045"/>
			</geometry>
		</visual>
		<collision>
			<geometry>
				<cylinder length="1.3070330000811032" radius="0.13366270972617045"/>
			</geometry>
		</collision>
		<inertial>
			<mass value="0.0733595988887064"/>
			<inertia ixx="0.03" ixy="0" ixz="0" iyx="0" iyy="0.03" izz="0.03"/>
		</inertial>
	</link>
	<link name="522">
		<visual>
			<geometry>
				<cylinder length="0.683556296618276" radius="0.12311561935334447"/>
			</geometry>
		</visual>
		<collision>
			<geometry>
				<cylinder length="0.683556296618276" radius="0.12311561935334447"/>
			</geometry>
		</collision>
		<inertial>
			<mass value="0.03254996075780896"/>
			<inertia ixx="0.03" ixy="0" ixz="0" iyx="0" iyy="0.03" izz="0.03"/>
		</inertial>
	</link>
	<link name="623">
		<visual>
			<geometry>
				<cylinder length="1.0616564631497882" radius="0.47452326718540105"/>
			</geometry>
		</visual>
		<collision>
			<geometry>
				<cylinder length="1.0616564631497882" radius="0.47452326718540105"/>
			</geometry>
		</collision>
		<inertial>
			<mass value="0.7510155072504279"/>
			<inertia ixx="0.03" ixy="0" ixz="0" iyx="0" iyy="0.03" izz="0.03"/>
		</inertial>
	</link>
	<link name="824">
		<visual>
			<geometry>
				<cylinder length="1.0983020388851625" radius="0.9404783616452294"/>
			</geometry>
		</visual>
		<collision>
			<geometry>
				<cylinder length="1.0983020388851625" radius="0.9404783616452294"/>
			</geometry>
		</collision>
		<inertial>
			<mass value="3.0518928249512554"/>
			<inertia ixx="0.03" ixy="0" ixz="0" iyx="0" iyy="0.03" izz="0.03"/>
		</inertial>
	</link>
	<link name="925">
		<visual>
			<geometry>
				<cylinder length="0.009633436752836788" radius="0.6125198031128518"/>
			</geometry>
		</visual>
		<collision>
			<geometry>
				<cylinder length="0.009633436752836788" radius="0.6125198031128518"/>
			</geometry>
		</collision>
		<inertial>
			<mass value="0.011354588290231483"/>
			<inertia ixx="0.03" ixy="0" ixz="0" iyx="0" iyy="0.03" izz="0.03"/>
		</inertial>
	</link>
	<link name="1126">
		<visual>
			<geometry>
				<cylinder length="0.9211349450593251" radius="0.5255249725899309"/>
			</geometry>
		</visual>
		<collision>
			<geometry>
				<cylinder length="0.9211349450593251" radius="0.5255249725899309"/>
			</geometry>
		</collision>
		<inertial>
			<mass value="0.7992080461932983"/>
			<inertia ixx="0.03" ixy="0" ixz="0" iyx="0" iyy="0.03" izz="0.03"/>
		</inertial>
	</link>
	<link name="1127">
		<visual>
			<geometry>
				<cylinder length="0.9211349450593251" radius="0.5255249725899309"/>
			</geometry>
		</visual>
		<collision>
			<geometry>
				<cylinder length="0.9211349450593251" radius="0.5255249725899309"/>
			</geometry>
		</collision>
		<inertial>
			<mass value="0.7992080461932983"/>
			<inertia ixx="0.03" ixy="0" ixz="0" iyx="0" iyy="0.03" izz="0.03"/>
		</inertial>
	</link>
	<link name="1128">
		<visual>
			<geometry>
				<cylinder length="0.9211349450593251" radius="0.5255249725899309"/>
			</geometry>
		</visual>
		<collision>
			<geometry>
				<cylinder length="0.9211349450593251" radius="0.5255249725899309"/>
			</geometry>
		</collision>
		<inertial>
			<mass value="0.7992080461932983"/>
			<inertia ixx="0.03" ixy="0" ixz="0" iyx="0" iyy="0.03" izz="0.03"/>
		</inertial>
	</link>
	<link name="929">
		<visual>
			<geometry>
				<cylinder length="0.009633436752836788" radius="0.6125198031128518"/>
			</geometry>
		</visual>
		<collision>
			<geometry>
				<cylinder length="0.009633436752836788" radius="0.6125198031128518"/>
			</geometry>
		</collision>
		<inertial>
			<mass value="0.011354588290231483"/>
			<inertia ixx="0.03" ixy="0" ixz="0" iyx="0" iyy="0.03" izz="0.03"/>
		</inertial>
	</link>
	<link name="1130">
		<visual>
			<geometry>
				<cylinder length="0.9211349450593251" radius="0.5255249725899309"/>
			</geometry>
		</visual>
		<collision>
			<geometry>
				<cylinder length="0.9211349450593251" radius="0.5255249725899309"/>
			</geometry>
		</collision>
		<inertial>
			<mass value="0.7992080461932983"/>
			<inertia ixx="0.03" ixy="0" ixz="0" iyx="0" iyy="0.03" izz="0.03"/>
		</inertial>
	</link>
	<link name="1131">
		<visual>
			<geometry>
				<cylinder length="0.9211349450593251" radius="0.5255249725899309"/>
			</geometry>
		</visual>
		<collision>
			<geometry>
				<cylinder length="0.9211349450593251" radius="0.5255249725899309"/>
			</geometry>
		</collision>
		<inertial>
			<mass value="0.7992080461932983"/>
			<inertia ixx="0.03" ixy="0" ixz="0" iyx="0" iyy="0.03" izz="0.03"/>
		</inertial>
	</link>
	<link name="1132">
		<visual>
			<geometry>
				<cylinder length="0.9211349450593251" radius="0.5255249725899309"/>
			</geometry>
		</visual>
		<collision>
			<geometry>
				<cylinder length="0.9211349450593251" radius="0.5255249725899309"/>
			</geometry>
		</collision>
		<inertial>
			<mass value="0.7992080461932983"/>
			<inertia ixx="0.03" ixy="0" ixz="0" iyx="0" iyy="0.03" izz="0.03"/>
		</inertial>
	</link>
	<link name="933">
		<visual>
			<geometry>
				<cylinder length="0.009633436752836788" radius="0.6125198031128518"/>
			</geometry>
		</visual>
		<collision>
			<geometry>
				<cylinder length="0.009633436752836788" radius="0.6125198031128518"/>
			</geometry>
		</collision>
		<inertial>
			<mass value="0.011354588290231483"/>
			<inertia ixx="0.03" ixy="0" ixz="0" iyx="0" iyy="0.03" izz="0.03"/>
		</inertial>
	</link>
	<link name="1134">
		<visual>
			<geometry>
				<cylinder length="0.9211349450593251" radius="0.5255249725899309"/>
			</geometry>
		</visual>
		<collision>
			<geometry>
				<cylinder length="0.9211349450593251" radius="0.5255249725899309"/>
			</geometry>
		</collision>
		<inertial>
			<mass value="0.7992080461932983"/>
			<inertia ixx="0.03" ixy="0" ixz="0" iyx="0" iyy="0.03" izz="0.03"/>
		</inertial>
	</link>
	<link name="1135">
		<visual>
			<geometry>
				<cylinder length="0.9211349450593251" radius="0.5255249725899309"/>
			</geometry>
		</visual>
		<collision>
			<geometry>
				<cylinder length="0.9211349450593251" radius="0.5255249725899309"/>
			</geometry>
		</collision>
		<inertial>
			<mass value="0.7992080461932983"/>
			<inertia ixx="0.03" ixy="0" ixz="0" iyx="0" iyy="0.03" izz="0.03"/>
		</inertial>
	</link>
	<link name="1136">
		<visual>
			<geometry>
				<cylinder length="0.9211349450593251" radius="0.5255249725899309"/>
			</geometry>
		</visual>
		<collision>
			<geometry>
				<cylinder length="0.9211349450593251" radius="0.5255249725899309"/>
			</geometry>
		</collision>
		<inertial>
			<mass value="0.7992080461932983"/>
			<inertia ixx="0.03" ixy="0" ixz="0" iyx="0" iyy="0.03" izz="0.03"/>
		</inertial>
	</link>
	<link name="837">
		<visual>
			<geometry>
				<cylinder length="1.0983020388851625" radius="0.9404783616452294"/>
			</geometry>
		</visual>
		<collision>
			<geometry>
				<cylinder length="1.0983020388851625" radius="0.9404783616452294"/>
			</geometry>
		</collision>
		<inertial>
			<mass value="3.0518928249512554"/>
			<inertia ixx="0.03" ixy="0" ixz="0" iyx="0" iyy="0.03" izz="0.03"/>
		</inertial>
	</link>
	<link name="938">
		<visual>
			<geometry>
				<cylinder length="0.009633436752836788" radius="0.6125198031128518"/>
			</geometry>
		</visual>
		<collision>
			<geometry>
				<cylinder length="0.009633436752836788" radius="0.6125198031128518"/>
			</geometry>
		</collision>
		<inertial>
			<mass value="0.011354588290231483"/>
			<inertia ixx="0.03" ixy="0" ixz="0" iyx="0" iyy="0.03" izz="0.03"/>
		</inertial>
	</link>
	<link name="1139">
		<visual>
			<geometry>
				<cylinder length="0.9211349450593251" radius="0.5255249725899309"/>
			</geometry>
		</visual>
		<collision>
			<geometry>
				<cylinder length="0.9211349450593251" radius="0.5255249725899309"/>
			</geometry>
		</collision>
		<inertial>
			<mass value="0.7992080461932983"/>
			<inertia ixx="0.03" ixy="0" ixz="0" iyx="0" iyy="0.03" izz="0.03"/>
		</inertial>
	</link>
	<link name="1140">
		<visual>
			<geometry>
				<cylinder length="0.9211349450593251" radius="0.5255249725899309"/>
			</geometry>
		</visual>
		<collision>
			<geometry>
				<cylinder length="0.9211349450593251" radius="0.5255249725899309"/>
			</geometry>
		</collision>
		<inertial>
			<mass value="0.7992080461932983"/>
			<inertia ixx="0.03" ixy="0" ixz="0" iyx="0" iyy="0.03" izz="0.03"/>
		</inertial>
	</link>
	<link name="1141">
		<visual>
			<geometry>
				<cylinder length="0.9211349450593251" radius="0.5255249725899309"/>
			</geometry>
		</visual>
		<collision>
			<geometry>
				<cylinder length="0.9211349450593251" radius="0.5255249725899309"/>
			</geometry>
		</collision>
		<inertial>
			<mass value="0.7992080461932983"/>
			<inertia ixx="0.03" ixy="0" ixz="0" iyx="0" iyy="0.03" izz="0.03"/>
		</inertial>
	</link>
	<link name="942">
		<visual>
			<geometry>
				<cylinder length="0.009633436752836788" radius="0.6125198031128518"/>
			</geometry>
		</visual>
		<collision>
			<geometry>
				<cylinder length="0.009633436752836788" radius="0.6125198031128518"/>
			</geometry>
		</collision>
		<inertial>
			<mass value="0.011354588290231483"/>
			<inertia ixx="0.03" ixy="0" ixz="0" iyx="0" iyy="0.03" izz="0.03"/>
		</inertial>
	</link>
	<link name="1143">
		<visual>
			<geometry>
				<cylinder length="0.9211349450593251" radius="0.5255249725899309"/>
			</geometry>
		</visual>
		<collision>
			<geometry>
				<cylinder length="0.9211349450593251" radius="0.5255249725899309"/>
			</geometry>
		</collision>
		<inertial>
			<mass value="0.7992080461932983"/>
			<inertia ixx="0.03" ixy="0" ixz="0" iyx="0" iyy="0.03" izz="0.03"/>
		</inertial>
	</link>
	<link name="1144">
		<visual>
			<geometry>
				<cylinder length="0.9211349450593251" radius="0.5255249725899309"/>
			</geometry>
		</visual>
		<collision>
			<geometry>
				<cylinder length="0.9211349450593251" radius="0.5255249725899309"/>
			</geometry>
		</collision>
		<inertial>
			<mass value="0.7992080461932983"/>
			<inertia ixx="0.03" ixy="0" ixz="0" iyx="0" iyy="0.03" izz="0.03"/>
		</inertial>
	</link>
	<link name="1145">
		<visual>
			<geometry>
				<cylinder length="0.9211349450593251" radius="0.5255249725899309"/>
			</geometry>
		</visual>
		<collision>
			<geometry>
				<cylinder length="0.9211349450593251" radius="0.5255249725899309"/>
			</geometry>
		</collision>
		<inertial>
			<mass value="0.7992080461932983"/>
			<inertia ixx="0.03" ixy="0" ixz="0" iyx="0" iyy="0.03" izz="0.03"/>
		</inertial>
	</link>
	<link name="946">
		<visual>
			<geometry>
				<cylinder length="0.009633436752836788" radius="0.6125198031128518"/>
			</geometry>
		</visual>
		<collision>
			<geometry>
				<cylinder length="0.009633436752836788" radius="0.6125198031128518"/>
			</geometry>
		</collision>
		<inertial>
			<mass value="0.011354588290231483"/>
			<inertia ixx="0.03" ixy="0" ixz="0" iyx="0" iyy="0.03" izz="0.03"/>
		</inertial>
	</link>
	<link name="1147">
		<visual>
			<geometry>
				<cylinder length="0.9211349450593251" radius="0.5255249725899309"/>
			</geometry>
		</visual>
		<collision>
			<geometry>
				<cylinder length="0.9211349450593251" radius="0.5255249725899309"/>
			</geometry>
		</collision>
		<inertial>
			<mass value="0.7992080461932983"/>
			<inertia ixx="0.03" ixy="0" ixz="0" iyx="0" iyy="0.03" izz="0.03"/>
		</inertial>
	</link>
	<link name="1148">
		<visual>
			<geometry>
				<cylinder length="0.9211349450593251" radius="0.5255249725899309"/>
			</geometry>
		</visual>
		<collision>
			<geometry>
				<cylinder length="0.9211349450593251" radius="0.5255249725899309"/>
			</geometry>
		</collision>
		<inertial>
			<mass value="0.7992080461932983"/>
			<inertia ixx="0.03" ixy="0" ixz="0" iyx="0" iyy="0.03" izz="0.03"/>
		</inertial>
	</link>
	<link name="1149">
		<visual>
			<geometry>
				<cylinder length="0.9211349450593251" radius="0.5255249725899309"/>
			</geometry>
		</visual>
		<collision>
			<geometry>
				<cylinder length="0.9211349450593251" radius="0.5255249725899309"/>
			</geometry>
		</collision>
		<inertial>
			<mass value="0.7992080461932983"/>
			<inertia ixx="0.03" ixy="0" ixz="0" iyx="0" iyy="0.03" izz="0.03"/>
		</inertial>
	</link>
	<link name="850">
		<visual>
			<geometry>
				<cylinder length="1.0983020388851625" radius="0.9404783616452294"/>
			</geometry>
		</visual>
		<collision>
			<geometry>
				<cylinder length="1.0983020388851625" radius="0.9404783616452294"/>
			</geometry>
		</collision>
		<inertial>
			<mass value="3.0518928249512554"/>
			<inertia ixx="0.03" ixy="0" ixz="0" iyx="0" iyy="0.03" izz="0.03"/>
		</inertial>
	</link>
	<link name="951">
		<visual>
			<geometry>
				<cylinder length="0.009633436752836788" radius="0.6125198031128518"/>
			</geometry>
		</visual>
		<collision>
			<geometry>
				<cylinder length="0.009633436752836788" radius="0.6125198031128518"/>
			</geometry>
		</collision>
		<inertial>
			<mass value="0.011354588290231483"/>
			<inertia ixx="0.03" ixy="0" ixz="0" iyx="0" iyy="0.03" izz="0.03"/>
		</inertial>
	</link>
	<link name="1152">
		<visual>
			<geometry>
				<cylinder length="0.9211349450593251" radius="0.5255249725899309"/>
			</geometry>
		</visual>
		<collision>
			<geometry>
				<cylinder length="0.9211349450593251" radius="0.5255249725899309"/>
			</geometry>
		</collision>
		<inertial>
			<mass value="0.7992080461932983"/>
			<inertia ixx="0.03" ixy="0" ixz="0" iyx="0" iyy="0.03" izz="0.03"/>
		</inertial>
	</link>
	<link name="1153">
		<visual>
			<geometry>
				<cylinder length="0.9211349450593251" radius="0.5255249725899309"/>
			</geometry>
		</visual>
		<collision>
			<geometry>
				<cylinder length="0.9211349450593251" radius="0.5255249725899309"/>
			</geometry>
		</collision>
		<inertial>
			<mass value="0.7992080461932983"/>
			<inertia ixx="0.03" ixy="0" ixz="0" iyx="0" iyy="0.03" izz="0.03"/>
		</inertial>
	</link>
	<link name="1154">
		<visual>
			<geometry>
				<cylinder length="0.9211349450593251" radius="0.5255249725899309"/>
			</geometry>
		</visual>
		<collision>
			<geometry>
				<cylinder length="0.9211349450593251" radius="0.5255249725899309"/>
			</geometry>
		</collision>
		<inertial>
			<mass value="0.7992080461932983"/>
			<inertia ixx="0.03" ixy="0" ixz="0" iyx="0" iyy="0.03" izz="0.03"/>
		</inertial>
	</link>
	<link name="955">
		<visual>
			<geometry>
				<cylinder length="0.009633436752836788" radius="0.6125198031128518"/>
			</geometry>
		</visual>
		<collision>
			<geometry>
				<cylinder length="0.009633436752836788" radius="0.6125198031128518"/>
			</geometry>
		</collision>
		<inertial>
			<mass value="0.011354588290231483"/>
			<inertia ixx="0.03" ixy="0" ixz="0" iyx="0" iyy="0.03" izz="0.03"/>
		</inertial>
	</link>
	<link name="1156">
		<visual>
			<geometry>
				<cylinder length="0.9211349450593251" radius="0.5255249725899309"/>
			</geometry>
		</visual>
		<collision>
			<geometry>
				<cylinder length="0.9211349450593251" radius="0.5255249725899309"/>
			</geometry>
		</collision>
		<inertial>
			<mass value="0.7992080461932983"/>
			<inertia ixx="0.03" ixy="0" ixz="0" iyx="0" iyy="0.03" izz="0.03"/>
		</inertial>
	</link>
	<link name="1157">
		<visual>
			<geometry>
				<cylinder length="0.9211349450593251" radius="0.5255249725899309"/>
			</geometry>
		</visual>
		<collision>
			<geometry>
				<cylinder length="0.9211349450593251" radius="0.5255249725899309"/>
			</geometry>
		</collision>
		<inertial>
			<mass value="0.7992080461932983"/>
			<inertia ixx="0.03" ixy="0" ixz="0" iyx="0" iyy="0.03" izz="0.03"/>
		</inertial>
	</link>
	<link name="1158">
		<visual>
			<geometry>
				<cylinder length="0.9211349450593251" radius="0.5255249725899309"/>
			</geometry>
		</visual>
		<collision>
			<geometry>
				<cylinder length="0.9211349450593251" radius="0.5255249725899309"/>
			</geometry>
		</collision>
		<inertial>
			<mass value="0.7992080461932983"/>
			<inertia ixx="0.03" ixy="0" ixz="0" iyx="0" iyy="0.03" izz="0.03"/>
		</inertial>
	</link>
	<link name="959">
		<visual>
			<geometry>
				<cylinder length="0.009633436752836788" radius="0.6125198031128518"/>
			</geometry>
		</visual>
		<collision>
			<geometry>
				<cylinder length="0.009633436752836788" radius="0.6125198031128518"/>
			</geometry>
		</collision>
		<inertial>
			<mass value="0.011354588290231483"/>
			<inertia ixx="0.03" ixy="0" ixz="0" iyx="0" iyy="0.03" izz="0.03"/>
		</inertial>
	</link>
	<link name="1160">
		<visual>
			<geometry>
				<cylinder length="0.9211349450593251" radius="0.5255249725899309"/>
			</geometry>
		</visual>
		<collision>
			<geometry>
				<cylinder length="0.9211349450593251" radius="0.5255249725899309"/>
			</geometry>
		</collision>
		<inertial>
			<mass value="0.7992080461932983"/>
			<inertia ixx="0.03" ixy="0" ixz="0" iyx="0" iyy="0.03" izz="0.03"/>
		</inertial>
	</link>
	<link name="1161">
		<visual>
			<geometry>
				<cylinder length="0.9211349450593251" radius="0.5255249725899309"/>
			</geometry>
		</visual>
		<collision>
			<geometry>
				<cylinder length="0.9211349450593251" radius="0.5255249725899309"/>
			</geometry>
		</collision>
		<inertial>
			<mass value="0.7992080461932983"/>
			<inertia ixx="0.03" ixy="0" ixz="0" iyx="0" iyy="0.03" izz="0.03"/>
		</inertial>
	</link>
	<link name="1162">
		<visual>
			<geometry>
				<cylinder length="0.9211349450593251" radius="0.5255249725899309"/>
			</geometry>
		</visual>
		<collision>
			<geometry>
				<cylinder length="0.9211349450593251" radius="0.5255249725899309"/>
			</geometry>
		</collision>
		<inertial>
			<mass value="0.7992080461932983"/>
			<inertia ixx="0.03" ixy="0" ixz="0" iyx="0" iyy="0.03" izz="0.03"/>
		</inertial>
	</link>
	<link name="663">
		<visual>
			<geometry>
				<cylinder length="1.0616564631497882" radius="0.47452326718540105"/>
			</geometry>
		</visual>
		<collision>
			<geometry>
				<cylinder length="1.0616564631497882" radius="0.47452326718540105"/>
			</geometry>
		</collision>
		<inertial>
			<mass value="0.7510155072504279"/>
			<inertia ixx="0.03" ixy="0" ixz="0" iyx="0" iyy="0.03" izz="0.03"/>
		</inertial>
	</link>
	<link name="864">
		<visual>
			<geometry>
				<cylinder length="1.0983020388851625" radius="0.9404783616452294"/>
			</geometry>
		</visual>
		<collision>
			<geometry>
				<cylinder length="1.0983020388851625" radius="0.9404783616452294"/>
			</geometry>
		</collision>
		<inertial>
			<mass value="3.0518928249512554"/>
			<inertia ixx="0.03" ixy="0" ixz="0" iyx="0" iyy="0.03" izz="0.03"/>
		</inertial>
	</link>
	<link name="965">
		<visual>
			<geometry>
				<cylinder length="0.009633436752836788" radius="0.6125198031128518"/>
			</geometry>
		</visual>
		<collision>
			<geometry>
				<cylinder length="0.009633436752836788" radius="0.6125198031128518"/>
			</geometry>
		</collision>
		<inertial>
			<mass value="0.011354588290231483"/>
			<inertia ixx="0.03" ixy="0" ixz="0" iyx="0" iyy="0.03" izz="0.03"/>
		</inertial>
	</link>
	<link name="1166">
		<visual>
			<geometry>
				<cylinder length="0.9211349450593251" radius="0.5255249725899309"/>
			</geometry>
		</visual>
		<collision>
			<geometry>
				<cylinder length="0.9211349450593251" radius="0.5255249725899309"/>
			</geometry>
		</collision>
		<inertial>
			<mass value="0.7992080461932983"/>
			<inertia ixx="0.03" ixy="0" ixz="0" iyx="0" iyy="0.03" izz="0.03"/>
		</inertial>
	</link>
	<link name="1167">
		<visual>
			<geometry>
				<cylinder length="0.9211349450593251" radius="0.5255249725899309"/>
			</geometry>
		</visual>
		<collision>
			<geometry>
				<cylinder length="0.9211349450593251" radius="0.5255249725899309"/>
			</geometry>
		</collision>
		<inertial>
			<mass value="0.7992080461932983"/>
			<inertia ixx="0.03" ixy="0" ixz="0" iyx="0" iyy="0.03" izz="0.03"/>
		</inertial>
	</link>
	<link name="1168">
		<visual>
			<geometry>
				<cylinder length="0.9211349450593251" radius="0.5255249725899309"/>
			</geometry>
		</visual>
		<collision>
			<geometry>
				<cylinder length="0.9211349450593251" radius="0.5255249725899309"/>
			</geometry>
		</collision>
		<inertial>
			<mass value="0.7992080461932983"/>
			<inertia ixx="0.03" ixy="0" ixz="0" iyx="0" iyy="0.03" izz="0.03"/>
		</inertial>
	</link>
	<link name="969">
		<visual>
			<geometry>
				<cylinder length="0.009633436752836788" radius="0.6125198031128518"/>
			</geometry>
		</visual>
		<collision>
			<geometry>
				<cylinder length="0.009633436752836788" radius="0.6125198031128518"/>
			</geometry>
		</collision>
		<inertial>
			<mass value="0.011354588290231483"/>
			<inertia ixx="0.03" ixy="0" ixz="0" iyx="0" iyy="0.03" izz="0.03"/>
		</inertial>
	</link>
	<link name="1170">
		<visual>
			<geometry>
				<cylinder length="0.9211349450593251" radius="0.5255249725899309"/>
			</geometry>
		</visual>
		<collision>
			<geometry>
				<cylinder length="0.9211349450593251" radius="0.5255249725899309"/>
			</geometry>
		</collision>
		<inertial>
			<mass value="0.7992080461932983"/>
			<inertia ixx="0.03" ixy="0" ixz="0" iyx="0" iyy="0.03" izz="0.03"/>
		</inertial>
	</link>
	<link name="1171">
		<visual>
			<geometry>
				<cylinder length="0.9211349450593251" radius="0.5255249725899309"/>
			</geometry>
		</visual>
		<collision>
			<geometry>
				<cylinder length="0.9211349450593251" radius="0.5255249725899309"/>
			</geometry>
		</collision>
		<inertial>
			<mass value="0.7992080461932983"/>
			<inertia ixx="0.03" ixy="0" ixz="0" iyx="0" iyy="0.03" izz="0.03"/>
		</inertial>
	</link>
	<link name="1172">
		<visual>
			<geometry>
				<cylinder length="0.9211349450593251" radius="0.5255249725899309"/>
			</geometry>
		</visual>
		<collision>
			<geometry>
				<cylinder length="0.9211349450593251" radius="0.5255249725899309"/>
			</geometry>
		</collision>
		<inertial>
			<mass value="0.7992080461932983"/>
			<inertia ixx="0.03" ixy="0" ixz="0" iyx="0" iyy="0.03" izz="0.03"/>
		</inertial>
	</link>
	<link name="973">
		<visual>
			<geometry>
				<cylinder length="0.009633436752836788" radius="0.6125198031128518"/>
			</geometry>
		</visual>
		<collision>
			<geometry>
				<cylinder length="0.009633436752836788" radius="0.6125198031128518"/>
			</geometry>
		</collision>
		<inertial>
			<mass value="0.011354588290231483"/>
			<inertia ixx="0.03" ixy="0" ixz="0" iyx="0" iyy="0.03" izz="0.03"/>
		</inertial>
	</link>
	<link name="1174">
		<visual>
			<geometry>
				<cylinder length="0.9211349450593251" radius="0.5255249725899309"/>
			</geometry>
		</visual>
		<collision>
			<geometry>
				<cylinder length="0.9211349450593251" radius="0.5255249725899309"/>
			</geometry>
		</collision>
		<inertial>
			<mass value="0.7992080461932983"/>
			<inertia ixx="0.03" ixy="0" ixz="0" iyx="0" iyy="0.03" izz="0.03"/>
		</inertial>
	</link>
	<link name="1175">
		<visual>
			<geometry>
				<cylinder length="0.9211349450593251" radius="0.5255249725899309"/>
			</geometry>
		</visual>
		<collision>
			<geometry>
				<cylinder length="0.9211349450593251" radius="0.5255249725899309"/>
			</geometry>
		</collision>
		<inertial>
			<mass value="0.7992080461932983"/>
			<inertia ixx="0.03" ixy="0" ixz="0" iyx="0" iyy="0.03" izz="0.03"/>
		</inertial>
	</link>
	<link name="1176">
		<visual>
			<geometry>
				<cylinder length="0.9211349450593251" radius="0.5255249725899309"/>
			</geometry>
		</visual>
		<collision>
			<geometry>
				<cylinder length="0.9211349450593251" radius="0.5255249725899309"/>
			</geometry>
		</collision>
		<inertial>
			<mass value="0.7992080461932983"/>
			<inertia ixx="0.03" ixy="0" ixz="0" iyx="0" iyy="0.03" izz="0.03"/>
		</inertial>
	</link>
	<link name="877">
		<visual>
			<geometry>
				<cylinder length="1.0983020388851625" radius="0.9404783616452294"/>
			</geometry>
		</visual>
		<collision>
			<geometry>
				<cylinder length="1.0983020388851625" radius="0.9404783616452294"/>
			</geometry>
		</collision>
		<inertial>
			<mass value="3.0518928249512554"/>
			<inertia ixx="0.03" ixy="0" ixz="0" iyx="0" iyy="0.03" izz="0.03"/>
		</inertial>
	</link>
	<link name="978">
		<visual>
			<geometry>
				<cylinder length="0.009633436752836788" radius="0.6125198031128518"/>
			</geometry>
		</visual>
		<collision>
			<geometry>
				<cylinder length="0.009633436752836788" radius="0.6125198031128518"/>
			</geometry>
		</collision>
		<inertial>
			<mass value="0.011354588290231483"/>
			<inertia ixx="0.03" ixy="0" ixz="0" iyx="0" iyy="0.03" izz="0.03"/>
		</inertial>
	</link>
	<link name="1179">
		<visual>
			<geometry>
				<cylinder length="0.9211349450593251" radius="0.5255249725899309"/>
			</geometry>
		</visual>
		<collision>
			<geometry>
				<cylinder length="0.9211349450593251" radius="0.5255249725899309"/>
			</geometry>
		</collision>
		<inertial>
			<mass value="0.7992080461932983"/>
			<inertia ixx="0.03" ixy="0" ixz="0" iyx="0" iyy="0.03" izz="0.03"/>
		</inertial>
	</link>
	<link name="1180">
		<visual>
			<geometry>
				<cylinder length="0.9211349450593251" radius="0.5255249725899309"/>
			</geometry>
		</visual>
		<collision>
			<geometry>
				<cylinder length="0.9211349450593251" radius="0.5255249725899309"/>
			</geometry>
		</collision>
		<inertial>
			<mass value="0.7992080461932983"/>
			<inertia ixx="0.03" ixy="0" ixz="0" iyx="0" iyy="0.03" izz="0.03"/>
		</inertial>
	</link>
	<link name="1181">
		<visual>
			<geometry>
				<cylinder length="0.9211349450593251" radius="0.5255249725899309"/>
			</geometry>
		</visual>
		<collision>
			<geometry>
				<cylinder length="0.9211349450593251" radius="0.5255249725899309"/>
			</geometry>
		</collision>
		<inertial>
			<mass value="0.7992080461932983"/>
			<inertia ixx="0.03" ixy="0" ixz="0" iyx="0" iyy="0.03" izz="0.03"/>
		</inertial>
	</link>
	<link name="982">
		<visual>
			<geometry>
				<cylinder length="0.009633436752836788" radius="0.6125198031128518"/>
			</geometry>
		</visual>
		<collision>
			<geometry>
				<cylinder length="0.009633436752836788" radius="0.6125198031128518"/>
			</geometry>
		</collision>
		<inertial>
			<mass value="0.011354588290231483"/>
			<inertia ixx="0.03" ixy="0" ixz="0" iyx="0" iyy="0.03" izz="0.03"/>
		</inertial>
	</link>
	<link name="1183">
		<visual>
			<geometry>
				<cylinder length="0.9211349450593251" radius="0.5255249725899309"/>
			</geometry>
		</visual>
		<collision>
			<geometry>
				<cylinder length="0.9211349450593251" radius="0.5255249725899309"/>
			</geometry>
		</collision>
		<inertial>
			<mass value="0.7992080461932983"/>
			<inertia ixx="0.03" ixy="0" ixz="0" iyx="0" iyy="0.03" izz="0.03"/>
		</inertial>
	</link>
	<link name="1184">
		<visual>
			<geometry>
				<cylinder length="0.9211349450593251" radius="0.5255249725899309"/>
			</geometry>
		</visual>
		<collision>
			<geometry>
				<cylinder length="0.9211349450593251" radius="0.5255249725899309"/>
			</geometry>
		</collision>
		<inertial>
			<mass value="0.7992080461932983"/>
			<inertia ixx="0.03" ixy="0" ixz="0" iyx="0" iyy="0.03" izz="0.03"/>
		</inertial>
	</link>
	<link name="1185">
		<visual>
			<geometry>
				<cylinder length="0.9211349450593251" radius="0.5255249725899309"/>
			</geometry>
		</visual>
		<collision>
			<geometry>
				<cylinder length="0.9211349450593251" radius="0.5255249725899309"/>
			</geometry>
		</collision>
		<inertial>
			<mass value="0.7992080461932983"/>
			<inertia ixx="0.03" ixy="0" ixz="0" iyx="0" iyy="0.03" izz="0.03"/>
		</inertial>
	</link>
	<link name="986">
		<visual>
			<geometry>
				<cylinder length="0.009633436752836788" radius="0.6125198031128518"/>
			</geometry>
		</visual>
		<collision>
			<geometry>
				<cylinder length="0.009633436752836788" radius="0.6125198031128518"/>
			</geometry>
		</collision>
		<inertial>
			<mass value="0.011354588290231483"/>
			<inertia ixx="0.03" ixy="0" ixz="0" iyx="0" iyy="0.03" izz="0.03"/>
		</inertial>
	</link>
	<link name="1187">
		<visual>
			<geometry>
				<cylinder length="0.9211349450593251" radius="0.5255249725899309"/>
			</geometry>
		</visual>
		<collision>
			<geometry>
				<cylinder length="0.9211349450593251" radius="0.5255249725899309"/>
			</geometry>
		</collision>
		<inertial>
			<mass value="0.7992080461932983"/>
			<inertia ixx="0.03" ixy="0" ixz="0" iyx="0" iyy="0.03" izz="0.03"/>
		</inertial>
	</link>
	<link name="1188">
		<visual>
			<geometry>
				<cylinder length="0.9211349450593251" radius="0.5255249725899309"/>
			</geometry>
		</visual>
		<collision>
			<geometry>
				<cylinder length="0.9211349450593251" radius="0.5255249725899309"/>
			</geometry>
		</collision>
		<inertial>
			<mass value="0.7992080461932983"/>
			<inertia ixx="0.03" ixy="0" ixz="0" iyx="0" iyy="0.03" izz="0.03"/>
		</inertial>
	</link>
	<link name="1189">
		<visual>
			<geometry>
				<cylinder length="0.9211349450593251" radius="0.5255249725899309"/>
			</geometry>
		</visual>
		<collision>
			<geometry>
				<cylinder length="0.9211349450593251" radius="0.5255249725899309"/>
			</geometry>
		</collision>
		<inertial>
			<mass value="0.7992080461932983"/>
			<inertia ixx="0.03" ixy="0" ixz="0" iyx="0" iyy="0.03" izz="0.03"/>
		</inertial>
	</link>
	<link name="890">
		<visual>
			<geometry>
				<cylinder length="1.0983020388851625" radius="0.9404783616452294"/>
			</geometry>
		</visual>
		<collision>
			<geometry>
				<cylinder length="1.0983020388851625" radius="0.9404783616452294"/>
			</geometry>
		</collision>
		<inertial>
			<mass value="3.0518928249512554"/>
			<inertia ixx="0.03" ixy="0" ixz="0" iyx="0" iyy="0.03" izz="0.03"/>
		</inertial>
	</link>
	<link name="991">
		<visual>
			<geometry>
				<cylinder length="0.009633436752836788" radius="0.6125198031128518"/>
			</geometry>
		</visual>
		<collision>
			<geometry>
				<cylinder length="0.009633436752836788" radius="0.6125198031128518"/>
			</geometry>
		</collision>
		<inertial>
			<mass value="0.011354588290231483"/>
			<inertia ixx="0.03" ixy="0" ixz="0" iyx="0" iyy="0.03" izz="0.03"/>
		</inertial>
	</link>
	<link name="1192">
		<visual>
			<geometry>
				<cylinder length="0.9211349450593251" radius="0.5255249725899309"/>
			</geometry>
		</visual>
		<collision>
			<geometry>
				<cylinder length="0.9211349450593251" radius="0.5255249725899309"/>
			</geometry>
		</collision>
		<inertial>
			<mass value="0.7992080461932983"/>
			<inertia ixx="0.03" ixy="0" ixz="0" iyx="0" iyy="0.03" izz="0.03"/>
		</inertial>
	</link>
	<link name="1193">
		<visual>
			<geometry>
				<cylinder length="0.9211349450593251" radius="0.5255249725899309"/>
			</geometry>
		</visual>
		<collision>
			<geometry>
				<cylinder length="0.9211349450593251" radius="0.5255249725899309"/>
			</geometry>
		</collision>
		<inertial>
			<mass value="0.7992080461932983"/>
			<inertia ixx="0.03" ixy="0" ixz="0" iyx="0" iyy="0.03" izz="0.03"/>
		</inertial>
	</link>
	<link name="1194">
		<visual>
			<geometry>
				<cylinder length="0.9211349450593251" radius="0.5255249725899309"/>
			</geometry>
		</visual>
		<collision>
			<geometry>
				<cylinder length="0.9211349450593251" radius="0.5255249725899309"/>
			</geometry>
		</collision>
		<inertial>
			<mass value="0.7992080461932983"/>
			<inertia ixx="0.03" ixy="0" ixz="0" iyx="0" iyy="0.03" izz="0.03"/>
		</inertial>
	</link>
	<link name="995">
		<visual>
			<geometry>
				<cylinder length="0.009633436752836788" radius="0.6125198031128518"/>
			</geometry>
		</visual>
		<collision>
			<geometry>
				<cylinder length="0.009633436752836788" radius="0.6125198031128518"/>
			</geometry>
		</collision>
		<inertial>
			<mass value="0.011354588290231483"/>
			<inertia ixx="0.03" ixy="0" ixz="0" iyx="0" iyy="0.03" izz="0.03"/>
		</inertial>
	</link>
	<link name="1196">
		<visual>
			<geometry>
				<cylinder length="0.9211349450593251" radius="0.5255249725899309"/>
			</geometry>
		</visual>
		<collision>
			<geometry>
				<cylinder length="0.9211349450593251" radius="0.5255249725899309"/>
			</geometry>
		</collision>
		<inertial>
			<mass value="0.7992080461932983"/>
			<inertia ixx="0.03" ixy="0" ixz="0" iyx="0" iyy="0.03" izz="0.03"/>
		</inertial>
	</link>
	<link name="1197">
		<visual>
			<geometry>
				<cylinder length="0.9211349450593251" radius="0.5255249725899309"/>
			</geometry>
		</visual>
		<collision>
			<geometry>
				<cylinder length="0.9211349450593251" radius="0.5255249725899309"/>
			</geometry>
		</collision>
		<inertial>
			<mass value="0.7992080461932983"/>
			<inertia ixx="0.03" ixy="0" ixz="0" iyx="0" iyy="0.03" izz="0.03"/>
		</inertial>
	</link>
	<link name="1198">
		<visual>
			<geometry>
				<cylinder length="0.9211349450593251" radius="0.5255249725899309"/>
			</geometry>
		</visual>
		<collision>
			<geometry>
				<cylinder length="0.9211349450593251" radius="0.5255249725899309"/>
			</geometry>
		</collision>
		<inertial>
			<mass value="0.7992080461932983"/>
			<inertia ixx="0.03" ixy="0" ixz="0" iyx="0" iyy="0.03" izz="0.03"/>
		</inertial>
	</link>
	<link name="999">
		<visual>
			<geometry>
				<cylinder length="0.009633436752836788" radius="0.6125198031128518"/>
			</geometry>
		</visual>
		<collision>
			<geometry>
				<cylinder length="0.009633436752836788" radius="0.6125198031128518"/>
			</geometry>
		</collision>
		<inertial>
			<mass value="0.011354588290231483"/>
			<inertia ixx="0.03" ixy="0" ixz="0" iyx="0" iyy="0.03" izz="0.03"/>
		</inertial>
	</link>
	<link name="11100">
		<visual>
			<geometry>
				<cylinder length="0.9211349450593251" radius="0.5255249725899309"/>
			</geometry>
		</visual>
		<collision>
			<geometry>
				<cylinder length="0.9211349450593251" radius="0.5255249725899309"/>
			</geometry>
		</collision>
		<inertial>
			<mass value="0.7992080461932983"/>
			<inertia ixx="0.03" ixy="0" ixz="0" iyx="0" iyy="0.03" izz="0.03"/>
		</inertial>
	</link>
	<link name="11101">
		<visual>
			<geometry>
				<cylinder length="0.9211349450593251" radius="0.5255249725899309"/>
			</geometry>
		</visual>
		<collision>
			<geometry>
				<cylinder length="0.9211349450593251" radius="0.5255249725899309"/>
			</geometry>
		</collision>
		<inertial>
			<mass value="0.7992080461932983"/>
			<inertia ixx="0.03" ixy="0" ixz="0" iyx="0" iyy="0.03" izz="0.03"/>
		</inertial>
	</link>
	<link name="11102">
		<visual>
			<geometry>
				<cylinder length="0.9211349450593251" radius="0.5255249725899309"/>
			</geometry>
		</visual>
		<collision>
			<geometry>
				<cylinder length="0.9211349450593251" radius="0.5255249725899309"/>
			</geometry>
		</collision>
		<inertial>
			<mass value="0.7992080461932983"/>
			<inertia ixx="0.03" ixy="0" ixz="0" iyx="0" iyy="0.03" izz="0.03"/>
		</inertial>
	</link>
	<link name="6103">
		<visual>
			<geometry>
				<cylinder length="1.0616564631497882" radius="0.47452326718540105"/>
			</geometry>
		</visual>
		<collision>
			<geometry>
				<cylinder length="1.0616564631497882" radius="0.47452326718540105"/>
			</geometry>
		</collision>
		<inertial>
			<mass value="0.7510155072504279"/>
			<inertia ixx="0.03" ixy="0" ixz="0" iyx="0" iyy="0.03" izz="0.03"/>
		</inertial>
	</link>
	<link name="8104">
		<visual>
			<geometry>
				<cylinder length="1.0983020388851625" radius="0.9404783616452294"/>
			</geometry>
		</visual>
		<collision>
			<geometry>
				<cylinder length="1.0983020388851625" radius="0.9404783616452294"/>
			</geometry>
		</collision>
		<inertial>
			<mass value="3.0518928249512554"/>
			<inertia ixx="0.03" ixy="0" ixz="0" iyx="0" iyy="0.03" izz="0.03"/>
		</inertial>
	</link>
	<link name="9105">
		<visual>
			<geometry>
				<cylinder length="0.009633436752836788" radius="0.6125198031128518"/>
			</geometry>
		</visual>
		<collision>
			<geometry>
				<cylinder length="0.009633436752836788" radius="0.6125198031128518"/>
			</geometry>
		</collision>
		<inertial>
			<mass value="0.011354588290231483"/>
			<inertia ixx="0.03" ixy="0" ixz="0" iyx="0" iyy="0.03" izz="0.03"/>
		</inertial>
	</link>
	<link name="11106">
		<visual>
			<geometry>
				<cylinder length="0.9211349450593251" radius="0.5255249725899309"/>
			</geometry>
		</visual>
		<collision>
			<geometry>
				<cylinder length="0.9211349450593251" radius="0.5255249725899309"/>
			</geometry>
		</collision>
		<inertial>
			<mass value="0.7992080461932983"/>
			<inertia ixx="0.03" ixy="0" ixz="0" iyx="0" iyy="0.03" izz="0.03"/>
		</inertial>
	</link>
	<link name="11107">
		<visual>
			<geometry>
				<cylinder length="0.9211349450593251" radius="0.5255249725899309"/>
			</geometry>
		</visual>
		<collision>
			<geometry>
				<cylinder length="0.9211349450593251" radius="0.5255249725899309"/>
			</geometry>
		</collision>
		<inertial>
			<mass value="0.7992080461932983"/>
			<inertia ixx="0.03" ixy="0" ixz="0" iyx="0" iyy="0.03" izz="0.03"/>
		</inertial>
	</link>
	<link name="11108">
		<visual>
			<geometry>
				<cylinder length="0.9211349450593251" radius="0.5255249725899309"/>
			</geometry>
		</visual>
		<collision>
			<geometry>
				<cylinder length="0.9211349450593251" radius="0.5255249725899309"/>
			</geometry>
		</collision>
		<inertial>
			<mass value="0.7992080461932983"/>
			<inertia ixx="0.03" ixy="0" ixz="0" iyx="0" iyy="0.03" izz="0.03"/>
		</inertial>
	</link>
	<link name="9109">
		<visual>
			<geometry>
				<cylinder length="0.009633436752836788" radius="0.6125198031128518"/>
			</geometry>
		</visual>
		<collision>
			<geometry>
				<cylinder length="0.009633436752836788" radius="0.6125198031128518"/>
			</geometry>
		</collision>
		<inertial>
			<mass value="0.011354588290231483"/>
			<inertia ixx="0.03" ixy="0" ixz="0" iyx="0" iyy="0.03" izz="0.03"/>
		</inertial>
	</link>
	<link name="11110">
		<visual>
			<geometry>
				<cylinder length="0.9211349450593251" radius="0.5255249725899309"/>
			</geometry>
		</visual>
		<collision>
			<geometry>
				<cylinder length="0.9211349450593251" radius="0.5255249725899309"/>
			</geometry>
		</collision>
		<inertial>
			<mass value="0.7992080461932983"/>
			<inertia ixx="0.03" ixy="0" ixz="0" iyx="0" iyy="0.03" izz="0.03"/>
		</inertial>
	</link>
	<link name="11111">
		<visual>
			<geometry>
				<cylinder length="0.9211349450593251" radius="0.5255249725899309"/>
			</geometry>
		</visual>
		<collision>
			<geometry>
				<cylinder length="0.9211349450593251" radius="0.5255249725899309"/>
			</geometry>
		</collision>
		<inertial>
			<mass value="0.7992080461932983"/>
			<inertia ixx="0.03" ixy="0" ixz="0" iyx="0" iyy="0.03" izz="0.03"/>
		</inertial>
	</link>
	<link name="11112">
		<visual>
			<geometry>
				<cylinder length="0.9211349450593251" radius="0.5255249725899309"/>
			</geometry>
		</visual>
		<collision>
			<geometry>
				<cylinder length="0.9211349450593251" radius="0.5255249725899309"/>
			</geometry>
		</collision>
		<inertial>
			<mass value="0.7992080461932983"/>
			<inertia ixx="0.03" ixy="0" ixz="0" iyx="0" iyy="0.03" izz="0.03"/>
		</inertial>
	</link>
	<link name="9113">
		<visual>
			<geometry>
				<cylinder length="0.009633436752836788" radius="0.6125198031128518"/>
			</geometry>
		</visual>
		<collision>
			<geometry>
				<cylinder length="0.009633436752836788" radius="0.6125198031128518"/>
			</geometry>
		</collision>
		<inertial>
			<mass value="0.011354588290231483"/>
			<inertia ixx="0.03" ixy="0" ixz="0" iyx="0" iyy="0.03" izz="0.03"/>
		</inertial>
	</link>
	<link name="11114">
		<visual>
			<geometry>
				<cylinder length="0.9211349450593251" radius="0.5255249725899309"/>
			</geometry>
		</visual>
		<collision>
			<geometry>
				<cylinder length="0.9211349450593251" radius="0.5255249725899309"/>
			</geometry>
		</collision>
		<inertial>
			<mass value="0.7992080461932983"/>
			<inertia ixx="0.03" ixy="0" ixz="0" iyx="0" iyy="0.03" izz="0.03"/>
		</inertial>
	</link>
	<link name="11115">
		<visual>
			<geometry>
				<cylinder length="0.9211349450593251" radius="0.5255249725899309"/>
			</geometry>
		</visual>
		<collision>
			<geometry>
				<cylinder length="0.9211349450593251" radius="0.5255249725899309"/>
			</geometry>
		</collision>
		<inertial>
			<mass value="0.7992080461932983"/>
			<inertia ixx="0.03" ixy="0" ixz="0" iyx="0" iyy="0.03" izz="0.03"/>
		</inertial>
	</link>
	<link name="11116">
		<visual>
			<geometry>
				<cylinder length="0.9211349450593251" radius="0.5255249725899309"/>
			</geometry>
		</visual>
		<collision>
			<geometry>
				<cylinder length="0.9211349450593251" radius="0.5255249725899309"/>
			</geometry>
		</collision>
		<inertial>
			<mass value="0.7992080461932983"/>
			<inertia ixx="0.03" ixy="0" ixz="0" iyx="0" iyy="0.03" izz="0.03"/>
		</inertial>
	</link>
	<link name="8117">
		<visual>
			<geometry>
				<cylinder length="1.0983020388851625" radius="0.9404783616452294"/>
			</geometry>
		</visual>
		<collision>
			<geometry>
				<cylinder length="1.0983020388851625" radius="0.9404783616452294"/>
			</geometry>
		</collision>
		<inertial>
			<mass value="3.0518928249512554"/>
			<inertia ixx="0.03" ixy="0" ixz="0" iyx="0" iyy="0.03" izz="0.03"/>
		</inertial>
	</link>
	<link name="9118">
		<visual>
			<geometry>
				<cylinder length="0.009633436752836788" radius="0.6125198031128518"/>
			</geometry>
		</visual>
		<collision>
			<geometry>
				<cylinder length="0.009633436752836788" radius="0.6125198031128518"/>
			</geometry>
		</collision>
		<inertial>
			<mass value="0.011354588290231483"/>
			<inertia ixx="0.03" ixy="0" ixz="0" iyx="0" iyy="0.03" izz="0.03"/>
		</inertial>
	</link>
	<link name="11119">
		<visual>
			<geometry>
				<cylinder length="0.9211349450593251" radius="0.5255249725899309"/>
			</geometry>
		</visual>
		<collision>
			<geometry>
				<cylinder length="0.9211349450593251" radius="0.5255249725899309"/>
			</geometry>
		</collision>
		<inertial>
			<mass value="0.7992080461932983"/>
			<inertia ixx="0.03" ixy="0" ixz="0" iyx="0" iyy="0.03" izz="0.03"/>
		</inertial>
	</link>
	<link name="11120">
		<visual>
			<geometry>
				<cylinder length="0.9211349450593251" radius="0.5255249725899309"/>
			</geometry>
		</visual>
		<collision>
			<geometry>
				<cylinder length="0.9211349450593251" radius="0.5255249725899309"/>
			</geometry>
		</collision>
		<inertial>
			<mass value="0.7992080461932983"/>
			<inertia ixx="0.03" ixy="0" ixz="0" iyx="0" iyy="0.03" izz="0.03"/>
		</inertial>
	</link>
	<link name="11121">
		<visual>
			<geometry>
				<cylinder length="0.9211349450593251" radius="0.5255249725899309"/>
			</geometry>
		</visual>
		<collision>
			<geometry>
				<cylinder length="0.9211349450593251" radius="0.5255249725899309"/>
			</geometry>
		</collision>
		<inertial>
			<mass value="0.7992080461932983"/>
			<inertia ixx="0.03" ixy="0" ixz="0" iyx="0" iyy="0.03" izz="0.03"/>
		</inertial>
	</link>
	<link name="9122">
		<visual>
			<geometry>
				<cylinder length="0.009633436752836788" radius="0.6125198031128518"/>
			</geometry>
		</visual>
		<collision>
			<geometry>
				<cylinder length="0.009633436752836788" radius="0.6125198031128518"/>
			</geometry>
		</collision>
		<inertial>
			<mass value="0.011354588290231483"/>
			<inertia ixx="0.03" ixy="0" ixz="0" iyx="0" iyy="0.03" izz="0.03"/>
		</inertial>
	</link>
	<link name="11123">
		<visual>
			<geometry>
				<cylinder length="0.9211349450593251" radius="0.5255249725899309"/>
			</geometry>
		</visual>
		<collision>
			<geometry>
				<cylinder length="0.9211349450593251" radius="0.5255249725899309"/>
			</geometry>
		</collision>
		<inertial>
			<mass value="0.7992080461932983"/>
			<inertia ixx="0.03" ixy="0" ixz="0" iyx="0" iyy="0.03" izz="0.03"/>
		</inertial>
	</link>
	<link name="11124">
		<visual>
			<geometry>
				<cylinder length="0.9211349450593251" radius="0.5255249725899309"/>
			</geometry>
		</visual>
		<collision>
			<geometry>
				<cylinder length="0.9211349450593251" radius="0.5255249725899309"/>
			</geometry>
		</collision>
		<inertial>
			<mass value="0.7992080461932983"/>
			<inertia ixx="0.03" ixy="0" ixz="0" iyx="0" iyy="0.03" izz="0.03"/>
		</inertial>
	</link>
	<link name="11125">
		<visual>
			<geometry>
				<cylinder length="0.9211349450593251" radius="0.5255249725899309"/>
			</geometry>
		</visual>
		<collision>
			<geometry>
				<cylinder length="0.9211349450593251" radius="0.5255249725899309"/>
			</geometry>
		</collision>
		<inertial>
			<mass value="0.7992080461932983"/>
			<inertia ixx="0.03" ixy="0" ixz="0" iyx="0" iyy="0.03" izz="0.03"/>
		</inertial>
	</link>
	<link name="9126">
		<visual>
			<geometry>
				<cylinder length="0.009633436752836788" radius="0.6125198031128518"/>
			</geometry>
		</visual>
		<collision>
			<geometry>
				<cylinder length="0.009633436752836788" radius="0.6125198031128518"/>
			</geometry>
		</collision>
		<inertial>
			<mass value="0.011354588290231483"/>
			<inertia ixx="0.03" ixy="0" ixz="0" iyx="0" iyy="0.03" izz="0.03"/>
		</inertial>
	</link>
	<link name="11127">
		<visual>
			<geometry>
				<cylinder length="0.9211349450593251" radius="0.5255249725899309"/>
			</geometry>
		</visual>
		<collision>
			<geometry>
				<cylinder length="0.9211349450593251" radius="0.5255249725899309"/>
			</geometry>
		</collision>
		<inertial>
			<mass value="0.7992080461932983"/>
			<inertia ixx="0.03" ixy="0" ixz="0" iyx="0" iyy="0.03" izz="0.03"/>
		</inertial>
	</link>
	<link name="11128">
		<visual>
			<geometry>
				<cylinder length="0.9211349450593251" radius="0.5255249725899309"/>
			</geometry>
		</visual>
		<collision>
			<geometry>
				<cylinder length="0.9211349450593251" radius="0.5255249725899309"/>
			</geometry>
		</collision>
		<inertial>
			<mass value="0.7992080461932983"/>
			<inertia ixx="0.03" ixy="0" ixz="0" iyx="0" iyy="0.03" izz="0.03"/>
		</inertial>
	</link>
	<link name="11129">
		<visual>
			<geometry>
				<cylinder length="0.9211349450593251" radius="0.5255249725899309"/>
			</geometry>
		</visual>
		<collision>
			<geometry>
				<cylinder length="0.9211349450593251" radius="0.5255249725899309"/>
			</geometry>
		</collision>
		<inertial>
			<mass value="0.7992080461932983"/>
			<inertia ixx="0.03" ixy="0" ixz="0" iyx="0" iyy="0.03" izz="0.03"/>
		</inertial>
	</link>
	<link name="8130">
		<visual>
			<geometry>
				<cylinder length="1.0983020388851625" radius="0.9404783616452294"/>
			</geometry>
		</visual>
		<collision>
			<geometry>
				<cylinder length="1.0983020388851625" radius="0.9404783616452294"/>
			</geometry>
		</collision>
		<inertial>
			<mass value="3.0518928249512554"/>
			<inertia ixx="0.03" ixy="0" ixz="0" iyx="0" iyy="0.03" izz="0.03"/>
		</inertial>
	</link>
	<link name="9131">
		<visual>
			<geometry>
				<cylinder length="0.009633436752836788" radius="0.6125198031128518"/>
			</geometry>
		</visual>
		<collision>
			<geometry>
				<cylinder length="0.009633436752836788" radius="0.6125198031128518"/>
			</geometry>
		</collision>
		<inertial>
			<mass value="0.011354588290231483"/>
			<inertia ixx="0.03" ixy="0" ixz="0" iyx="0" iyy="0.03" izz="0.03"/>
		</inertial>
	</link>
	<link name="11132">
		<visual>
			<geometry>
				<cylinder length="0.9211349450593251" radius="0.5255249725899309"/>
			</geometry>
		</visual>
		<collision>
			<geometry>
				<cylinder length="0.9211349450593251" radius="0.5255249725899309"/>
			</geometry>
		</collision>
		<inertial>
			<mass value="0.7992080461932983"/>
			<inertia ixx="0.03" ixy="0" ixz="0" iyx="0" iyy="0.03" izz="0.03"/>
		</inertial>
	</link>
	<link name="11133">
		<visual>
			<geometry>
				<cylinder length="0.9211349450593251" radius="0.5255249725899309"/>
			</geometry>
		</visual>
		<collision>
			<geometry>
				<cylinder length="0.9211349450593251" radius="0.5255249725899309"/>
			</geometry>
		</collision>
		<inertial>
			<mass value="0.7992080461932983"/>
			<inertia ixx="0.03" ixy="0" ixz="0" iyx="0" iyy="0.03" izz="0.03"/>
		</inertial>
	</link>
	<link name="11134">
		<visual>
			<geometry>
				<cylinder length="0.9211349450593251" radius="0.5255249725899309"/>
			</geometry>
		</visual>
		<collision>
			<geometry>
				<cylinder length="0.9211349450593251" radius="0.5255249725899309"/>
			</geometry>
		</collision>
		<inertial>
			<mass value="0.7992080461932983"/>
			<inertia ixx="0.03" ixy="0" ixz="0" iyx="0" iyy="0.03" izz="0.03"/>
		</inertial>
	</link>
	<link name="9135">
		<visual>
			<geometry>
				<cylinder length="0.009633436752836788" radius="0.6125198031128518"/>
			</geometry>
		</visual>
		<collision>
			<geometry>
				<cylinder length="0.009633436752836788" radius="0.6125198031128518"/>
			</geometry>
		</collision>
		<inertial>
			<mass value="0.011354588290231483"/>
			<inertia ixx="0.03" ixy="0" ixz="0" iyx="0" iyy="0.03" izz="0.03"/>
		</inertial>
	</link>
	<link name="11136">
		<visual>
			<geometry>
				<cylinder length="0.9211349450593251" radius="0.5255249725899309"/>
			</geometry>
		</visual>
		<collision>
			<geometry>
				<cylinder length="0.9211349450593251" radius="0.5255249725899309"/>
			</geometry>
		</collision>
		<inertial>
			<mass value="0.7992080461932983"/>
			<inertia ixx="0.03" ixy="0" ixz="0" iyx="0" iyy="0.03" izz="0.03"/>
		</inertial>
	</link>
	<link name="11137">
		<visual>
			<geometry>
				<cylinder length="0.9211349450593251" radius="0.5255249725899309"/>
			</geometry>
		</visual>
		<collision>
			<geometry>
				<cylinder length="0.9211349450593251" radius="0.5255249725899309"/>
			</geometry>
		</collision>
		<inertial>
			<mass value="0.7992080461932983"/>
			<inertia ixx="0.03" ixy="0" ixz="0" iyx="0" iyy="0.03" izz="0.03"/>
		</inertial>
	</link>
	<link name="11138">
		<visual>
			<geometry>
				<cylinder length="0.9211349450593251" radius="0.5255249725899309"/>
			</geometry>
		</visual>
		<collision>
			<geometry>
				<cylinder length="0.9211349450593251" radius="0.5255249725899309"/>
			</geometry>
		</collision>
		<inertial>
			<mass value="0.7992080461932983"/>
			<inertia ixx="0.03" ixy="0" ixz="0" iyx="0" iyy="0.03" izz="0.03"/>
		</inertial>
	</link>
	<link name="9139">
		<visual>
			<geometry>
				<cylinder length="0.009633436752836788" radius="0.6125198031128518"/>
			</geometry>
		</visual>
		<collision>
			<geometry>
				<cylinder length="0.009633436752836788" radius="0.6125198031128518"/>
			</geometry>
		</collision>
		<inertial>
			<mass value="0.011354588290231483"/>
			<inertia ixx="0.03" ixy="0" ixz="0" iyx="0" iyy="0.03" izz="0.03"/>
		</inertial>
	</link>
	<link name="11140">
		<visual>
			<geometry>
				<cylinder length="0.9211349450593251" radius="0.5255249725899309"/>
			</geometry>
		</visual>
		<collision>
			<geometry>
				<cylinder length="0.9211349450593251" radius="0.5255249725899309"/>
			</geometry>
		</collision>
		<inertial>
			<mass value="0.7992080461932983"/>
			<inertia ixx="0.03" ixy="0" ixz="0" iyx="0" iyy="0.03" izz="0.03"/>
		</inertial>
	</link>
	<link name="11141">
		<visual>
			<geometry>
				<cylinder length="0.9211349450593251" radius="0.5255249725899309"/>
			</geometry>
		</visual>
		<collision>
			<geometry>
				<cylinder length="0.9211349450593251" radius="0.5255249725899309"/>
			</geometry>
		</collision>
		<inertial>
			<mass value="0.7992080461932983"/>
			<inertia ixx="0.03" ixy="0" ixz="0" iyx="0" iyy="0.03" izz="0.03"/>
		</inertial>
	</link>
	<link name="11142">
		<visual>
			<geometry>
				<cylinder length="0.9211349450593251" radius="0.5255249725899309"/>
			</geometry>
		</visual>
		<collision>
			<geometry>
				<cylinder length="0.9211349450593251" radius="0.5255249725899309"/>
			</geometry>
		</collision>
		<inertial>
			<mass value="0.7992080461932983"/>
			<inertia ixx="0.03" ixy="0" ixz="0" iyx="0" iyy="0.03" izz="0.03"/>
		</inertial>
	</link>
	<joint name="11_to_0" type="revolute">
		<parent link="0"/>
		<child link="11"/>
		<axis xyz="0 0 1"/>
		<limit effort="1" lower="3.1415" upper="-3.1415" velocity="1"/>
		<origin rpy="12.080855928694664 3.038505011429899 4.873889122079934" xyz="0.5711742634975288 0.24459650295839697 0.6477589435733465"/>
	</joint>
	<joint name="22_to_0" type="revolute">
		<parent link="0"/>
		<child link="22"/>
		<axis xyz="1 0 0"/>
		<limit effort="1" lower="3.1415" upper="-3.1415" velocity="1"/>
		<origin rpy="16.15799518231517 1.682935932394174 3.083880262279056" xyz="0.848233530894951 0.8239102365252825 0.30744022330781695"/>
	</joint>
	<joint name="33_to_22" type="revolute">
		<parent link="22"/>
		<child link="33"/>
		<axis xyz="1 0 0"/>
		<limit effort="1" lower="3.1415" upper="-3.1415" velocity="1"/>
		<origin rpy="5.8053765018299615 4.047973428897371 3.824485242423209" xyz="0.3448776833672901 0.08172212122848799 0.38830129011958936"/>
	</joint>
	<joint name="34_to_22" type="revolute">
		<parent link="22"/>
		<child link="34"/>
		<axis xyz="1 0 0"/>
		<limit effort="1" lower="3.1415" upper="-3.1415" velocity="1"/>
		<origin rpy="8.708064752744942 4.047973428897371 3.824485242423209" xyz="0.3448776833672901 0.08172212122848799 0.38830129011958936"/>
	</joint>
	<joint name="35_to_22" type="revolute">
		<parent link="22"/>
		<child link="35"/>
		<axis xyz="1 0 0"/>
		<limit effort="1" lower="3.1415" upper="-3.1415" velocity="1"/>
		<origin rpy="11.610753003659923 4.047973428897371 3.824485242423209" xyz="0.3448776833672901 0.08172212122848799 0.38830129011958936"/>
	</joint>
	<joint name="46_to_22" type="revolute">
		<parent link="22"/>
		<child link="46"/>
		<axis xyz="0 0 1"/>
		<limit effort="1" lower="3.1415" upper="-3.1415" velocity="1"/>
		<origin rpy="28.793012260135463 1.7172825442967552 5.8753720835787915" xyz="0.6068082788758926 0.286738056203273 0.06453492810330763"/>
	</joint>
	<joint name="47_to_22" type="revolute">
		<parent link="22"/>
		<child link="47"/>
		<axis xyz="0 0 1"/>
		<limit effort="1" lower="3.1415" upper="-3.1415" velocity="1"/>
		<origin rpy="34.55161471216256 1.7172825442967552 5.8753720835787915" xyz="0.6068082788758926 0.286738056203273 0.06453492810330763"/>
	</joint>
	<joint name="78_to_22" type="revolute">
		<parent link="22"/>
		<child link="78"/>
		<axis xyz="0 1 0"/>
		<limit effort="1" lower="3.1415" upper="-3.1415" velocity="1"/>
		<origin rpy="12.452046111532743 4.230714013689577 3.960533590628372" xyz="0.45526733524353813 0.9978622786664605 0.545674060686307"/>
	</joint>
	<joint name="109_to_78" type="revolute">
		<parent link="78"/>
		<child link="109"/>
		<axis xyz="0 0 1"/>
		<limit effort="1" lower="3.1415" upper="-3.1415" velocity="1"/>
		<origin rpy="4.234705768388898 0.43081851455142905 2.0903863611473943" xyz="0.8613789754890344 0.12956203241729192 0.6104915496217067"/>
	</joint>
	<joint name="1010_to_78" type="revolute">
		<parent link="78"/>
		<child link="1010"/>
		<axis xyz="0 0 1"/>
		<limit effort="1" lower="3.1415" upper="-3.1415" velocity="1"/>
		<origin rpy="6.352058652583347 0.43081851455142905 2.0903863611473943" xyz="0.8613789754890344 0.12956203241729192 0.6104915496217067"/>
	</joint>
	<joint name="1011_to_78" type="revolute">
		<parent link="78"/>
		<child link="1011"/>
		<axis xyz="0 0 1"/>
		<limit effort="1" lower="3.1415" upper="-3.1415" velocity="1"/>
		<origin rpy="8.469411536777796 0.43081851455142905 2.0903863611473943" xyz="0.8613789754890344 0.12956203241729192 0.6104915496217067"/>
	</joint>
	<joint name="212_to_0" type="revolute">
		<parent link="0"/>
		<child link="212"/>
		<axis xyz="1 0 0"/>
		<limit effort="1" lower="3.1415" upper="-3.1415" velocity="1"/>
		<origin rpy="21.543993576420227 1.682935932394174 3.083880262279056" xyz="0.848233530894951 0.8239102365252825 0.30744022330781695"/>
	</joint>
	<joint name="313_to_212" type="revolute">
		<parent link="212"/>
		<child link="313"/>
		<axis xyz="1 0 0"/>
		<limit effort="1" lower="3.1415" upper="-3.1415" velocity="1"/>
		<origin rpy="5.8053765018299615 4.047973428897371 3.824485242423209" xyz="0.3448776833672901 0.08172212122848799 0.38830129011958936"/>
	</joint>
	<joint name="314_to_212" type="revolute">
		<parent link="212"/>
		<child link="314"/>
		<axis xyz="1 0 0"/>
		<limit effort="1" lower="3.1415" upper="-3.1415" velocity="1"/>
		<origin rpy="8.708064752744942 4.047973428897371 3.824485242423209" xyz="0.3448776833672901 0.08172212122848799 0.38830129011958936"/>
	</joint>
	<joint name="315_to_212" type="revolute">
		<parent link="212"/>
		<child link="315"/>
		<axis xyz="1 0 0"/>
		<limit effort="1" lower="3.1415" upper="-3.1415" velocity="1"/>
		<origin rpy="11.610753003659923 4.047973428897371 3.824485242423209" xyz="0.3448776833672901 0.08172212122848799 0.38830129011958936"/>
	</joint>
	<joint name="416_to_212" type="revolute">
		<parent link="212"/>
		<child link="416"/>
		<axis xyz="0 0 1"/>
		<limit effort="1" lower="3.1415" upper="-3.1415" velocity="1"/>
		<origin rpy="28.793012260135463 1.7172825442967552 5.8753720835787915" xyz="0.6068082788758926 0.286738056203273 0.06453492810330763"/>
	</joint>
	<joint name="417_to_212" type="revolute">
		<parent link="212"/>
		<child link="417"/>
		<axis xyz="0 0 1"/>
		<limit effort="1" lower="3.1415" upper="-3.1415" velocity="1"/>
		<origin rpy="34.55161471216256 1.7172825442967552 5.8753720835787915" xyz="0.6068082788758926 0.286738056203273 0.06453492810330763"/>
	</joint>
	<joint name="718_to_212" type="revolute">
		<parent link="212"/>
		<child link="718"/>
		<axis xyz="0 1 0"/>
		<limit effort="1" lower="3.1415" upper="-3.1415" velocity="1"/>
		<origin rpy="12.452046111532743 4.230714013689577 3.960533590628372" xyz="0.45526733524353813 0.9978622786664605 0.545674060686307"/>
	</joint>
	<joint name="1019_to_718" type="revolute">
		<parent link="718"/>
		<child link="1019"/>
		<axis xyz="0 0 1"/>
		<limit effort="1" lower="3.1415" upper="-3.1415" velocity="1"/>
		<origin rpy="4.234705768388898 0.43081851455142905 2.0903863611473943" xyz="0.8613789754890344 0.12956203241729192 0.6104915496217067"/>
	</joint>
	<joint name="1020_to_718" type="revolute">
		<parent link="718"/>
		<child link="1020"/>
		<axis xyz="0 0 1"/>
		<limit effort="1" lower="3.1415" upper="-3.1415" velocity="1"/>
		<origin rpy="6.352058652583347 0.43081851455142905 2.0903863611473943" xyz="0.8613789754890344 0.12956203241729192 0.6104915496217067"/>
	</joint>
	<joint name="1021_to_718" type="revolute">
		<parent link="718"/>
		<child link="1021"/>
		<axis xyz="0 0 1"/>
		<limit effort="1" lower="3.1415" upper="-3.1415" velocity="1"/>
		<origin rpy="8.469411536777796 0.43081851455142905 2.0903863611473943" xyz="0.8613789754890344 0.12956203241729192 0.6104915496217067"/>
	</joint>
	<joint name="522_to_0" type="revolute">
		<parent link="0"/>
		<child link="522"/>
		<axis xyz="0 0 1"/>
		<limit effort="1" lower="3.1415" upper="-3.1415" velocity="1"/>
		<origin rpy="27.920725942655217 5.14885574486338 3.5861621301833733" xyz="0.4234197883577201 0.613811939214859 0.8448036919003655"/>
	</joint>
	<joint name="623_to_522" type="revolute">
		<parent link="522"/>
		<child link="623"/>
		<axis xyz="1 0 0"/>
		<limit effort="1" lower="3.1415" upper="-3.1415" velocity="1"/>
		<origin rpy="11.956622391267562 5.8408927158036406 1.757202600326469" xyz="0.3991203093009007 0.7404582271390947 0.25824358693969596"/>
	</joint>
	<joint name="824_to_623" type="revolute">
		<parent link="623"/>
		<child link="824"/>
		<axis xyz="0 0 1"/>
		<limit effort="1" lower="3.1415" upper="-3.1415" velocity="1"/>
		<origin rpy="0.8555613612440921 1.6469028794380574 4.886933099365235" xyz="0.13309883395318223 0.18982122129549728 0.31799876382890835"/>
	</joint>
	<joint name="925_to_824" type="revolute">
		<parent link="824"/>
		<child link="925"/>
		<axis xyz="0 0 1"/>
		<limit effort="1" lower="3.1415" upper="-3.1415" velocity="1"/>
		<origin rpy="10.147014135352803 3.0438750815767115 6.074433198983962" xyz="0.4063874542205713 0.921388344359273 0.1479935141037736"/>
	</joint>
	<joint name="1126_to_925" type="revolute">
		<parent link="925"/>
		<child link="1126"/>
		<axis xyz="0 0 1"/>
		<limit effort="1" lower="3.1415" upper="-3.1415" velocity="1"/>
		<origin rpy="9.681940991770094 2.5000270535281763 1.886959186340941" xyz="0.1105894167925342 0.2887719606417388 0.03276481018708366"/>
	</joint>
	<joint name="1127_to_925" type="revolute">
		<parent link="925"/>
		<child link="1127"/>
		<axis xyz="0 0 1"/>
		<limit effort="1" lower="3.1415" upper="-3.1415" velocity="1"/>
		<origin rpy="14.522911487655142 2.5000270535281763 1.886959186340941" xyz="0.1105894167925342 0.2887719606417388 0.03276481018708366"/>
	</joint>
	<joint name="1128_to_925" type="revolute">
		<parent link="925"/>
		<child link="1128"/>
		<axis xyz="0 0 1"/>
		<limit effort="1" lower="3.1415" upper="-3.1415" velocity="1"/>
		<origin rpy="19.36388198354019 2.5000270535281763 1.886959186340941" xyz="0.1105894167925342 0.2887719606417388 0.03276481018708366"/>
	</joint>
	<joint name="929_to_824" type="revolute">
		<parent link="824"/>
		<child link="929"/>
		<axis xyz="0 0 1"/>
		<limit effort="1" lower="3.1415" upper="-3.1415" velocity="1"/>
		<origin rpy="15.220521203029204 3.0438750815767115 6.074433198983962" xyz="0.4063874542205713 0.921388344359273 0.1479935141037736"/>
	</joint>
	<joint name="1130_to_929" type="revolute">
		<parent link="929"/>
		<child link="1130"/>
		<axis xyz="0 0 1"/>
		<limit effort="1" lower="3.1415" upper="-3.1415" velocity="1"/>
		<origin rpy="9.681940991770094 2.5000270535281763 1.886959186340941" xyz="0.1105894167925342 0.2887719606417388 0.03276481018708366"/>
	</joint>
	<joint name="1131_to_929" type="revolute">
		<parent link="929"/>
		<child link="1131"/>
		<axis xyz="0 0 1"/>
		<limit effort="1" lower="3.1415" upper="-3.1415" velocity="1"/>
		<origin rpy="14.522911487655142 2.5000270535281763 1.886959186340941" xyz="0.1105894167925342 0.2887719606417388 0.03276481018708366"/>
	</joint>
	<joint name="1132_to_929" type="revolute">
		<parent link="929"/>
		<child link="1132"/>
		<axis xyz="0 0 1"/>
		<limit effort="1" lower="3.1415" upper="-3.1415" velocity="1"/>
		<origin rpy="19.36388198354019 2.5000270535281763 1.886959186340941" xyz="0.1105894167925342 0.2887719606417388 0.03276481018708366"/>
	</joint>
	<joint name="933_to_824" type="revolute">
		<parent link="824"/>
		<child link="933"/>
		<axis xyz="0 0 1"/>
		<limit effort="1" lower="3.1415" upper="-3.1415" velocity="1"/>
		<origin rpy="20.294028270705606 3.0438750815767115 6.074433198983962" xyz="0.4063874542205713 0.921388344359273 0.1479935141037736"/>
	</joint>
	<joint name="1134_to_933" type="revolute">
		<parent link="933"/>
		<child link="1134"/>
		<axis xyz="0 0 1"/>
		<limit effort="1" lower="3.1415" upper="-3.1415" velocity="1"/>
		<origin rpy="9.681940991770094 2.5000270535281763 1.886959186340941" xyz="0.1105894167925342 0.2887719606417388 0.03276481018708366"/>
	</joint>
	<joint name="1135_to_933" type="revolute">
		<parent link="933"/>
		<child link="1135"/>
		<axis xyz="0 0 1"/>
		<limit effort="1" lower="3.1415" upper="-3.1415" velocity="1"/>
		<origin rpy="14.522911487655142 2.5000270535281763 1.886959186340941" xyz="0.1105894167925342 0.2887719606417388 0.03276481018708366"/>
	</joint>
	<joint name="1136_to_933" type="revolute">
		<parent link="933"/>
		<child link="1136"/>
		<axis xyz="0 0 1"/>
		<limit effort="1" lower="3.1415" upper="-3.1415" velocity="1"/>
		<origin rpy="19.36388198354019 2.5000270535281763 1.886959186340941" xyz="0.1105894167925342 0.2887719606417388 0.03276481018708366"/>
	</joint>
	<joint name="837_to_623" type="revolute">
		<parent link="623"/>
		<child link="837"/>
		<axis xyz="0 0 1"/>
		<limit effort="1" lower="3.1415" upper="-3.1415" velocity="1"/>
		<origin rpy="1.283342041866138 1.6469028794380574 4.886933099365235" xyz="0.13309883395318223 0.18982122129549728 0.31799876382890835"/>
	</joint>
	<joint name="938_to_837" type="revolute">
		<parent link="837"/>
		<child link="938"/>
		<axis xyz="0 0 1"/>
		<limit effort="1" lower="3.1415" upper="-3.1415" velocity="1"/>
		<origin rpy="10.147014135352803 3.0438750815767115 6.074433198983962" xyz="0.4063874542205713 0.921388344359273 0.1479935141037736"/>
	</joint>
	<joint name="1139_to_938" type="revolute">
		<parent link="938"/>
		<child link="1139"/>
		<axis xyz="0 0 1"/>
		<limit effort="1" lower="3.1415" upper="-3.1415" velocity="1"/>
		<origin rpy="9.681940991770094 2.5000270535281763 1.886959186340941" xyz="0.1105894167925342 0.2887719606417388 0.03276481018708366"/>
	</joint>
	<joint name="1140_to_938" type="revolute">
		<parent link="938"/>
		<child link="1140"/>
		<axis xyz="0 0 1"/>
		<limit effort="1" lower="3.1415" upper="-3.1415" velocity="1"/>
		<origin rpy="14.522911487655142 2.5000270535281763 1.886959186340941" xyz="0.1105894167925342 0.2887719606417388 0.03276481018708366"/>
	</joint>
	<joint name="1141_to_938" type="revolute">
		<parent link="938"/>
		<child link="1141"/>
		<axis xyz="0 0 1"/>
		<limit effort="1" lower="3.1415" upper="-3.1415" velocity="1"/>
		<origin rpy="19.36388198354019 2.5000270535281763 1.886959186340941" xyz="0.1105894167925342 0.2887719606417388 0.03276481018708366"/>
	</joint>
	<joint name="942_to_837" type="revolute">
		<parent link="837"/>
		<child link="942"/>
		<axis xyz="0 0 1"/>
		<limit effort="1" lower="3.1415" upper="-3.1415" velocity="1"/>
		<origin rpy="15.220521203029204 3.0438750815767115 6.074433198983962" xyz="0.4063874542205713 0.921388344359273 0.1479935141037736"/>
	</joint>
	<joint name="1143_to_942" type="revolute">
		<parent link="942"/>
		<child link="1143"/>
		<axis xyz="0 0 1"/>
		<limit effort="1" lower="3.1415" upper="-3.1415" velocity="1"/>
		<origin rpy="9.681940991770094 2.5000270535281763 1.886959186340941" xyz="0.1105894167925342 0.2887719606417388 0.03276481018708366"/>
	</joint>
	<joint name="1144_to_942" type="revolute">
		<parent link="942"/>
		<child link="1144"/>
		<axis xyz="0 0 1"/>
		<limit effort="1" lower="3.1415" upper="-3.1415" velocity="1"/>
		<origin rpy="14.522911487655142 2.5000270535281763 1.886959186340941" xyz="0.1105894167925342 0.2887719606417388 0.03276481018708366"/>
	</joint>
	<joint name="1145_to_942" type="revolute">
		<parent link="942"/>
		<child link="1145"/>
		<axis xyz="0 0 1"/>
		<limit effort="1" lower="3.1415" upper="-3.1415" velocity="1"/>
		<origin rpy="19.36388198354019 2.5000270535281763 1.886959186340941" xyz="0.1105894167925342 0.2887719606417388 0.03276481018708366"/>
	</joint>
	<joint name="946_to_837" type="revolute">
		<parent link="837"/>
		<child link="946"/>
		<axis xyz="0 0 1"/>
		<limit effort="1" lower="3.1415" upper="-3.1415" velocity="1"/>
		<origin rpy="20.294028270705606 3.0438750815767115 6.074433198983962" xyz="0.4063874542205713 0.921388344359273 0.1479935141037736"/>
	</joint>
	<joint name="1147_to_946" type="revolute">
		<parent link="946"/>
		<child link="1147"/>
		<axis xyz="0 0 1"/>
		<limit effort="1" lower="3.1415" upper="-3.1415" velocity="1"/>
		<origin rpy="9.681940991770094 2.5000270535281763 1.886959186340941" xyz="0.1105894167925342 0.2887719606417388 0.03276481018708366"/>
	</joint>
	<joint name="1148_to_946" type="revolute">
		<parent link="946"/>
		<child link="1148"/>
		<axis xyz="0 0 1"/>
		<limit effort="1" lower="3.1415" upper="-3.1415" velocity="1"/>
		<origin rpy="14.522911487655142 2.5000270535281763 1.886959186340941" xyz="0.1105894167925342 0.2887719606417388 0.03276481018708366"/>
	</joint>
	<joint name="1149_to_946" type="revolute">
		<parent link="946"/>
		<child link="1149"/>
		<axis xyz="0 0 1"/>
		<limit effort="1" lower="3.1415" upper="-3.1415" velocity="1"/>
		<origin rpy="19.36388198354019 2.5000270535281763 1.886959186340941" xyz="0.1105894167925342 0.2887719606417388 0.03276481018708366"/>
	</joint>
	<joint name="850_to_623" type="revolute">
		<parent link="623"/>
		<child link="850"/>
		<axis xyz="0 0 1"/>
		<limit effort="1" lower="3.1415" upper="-3.1415" velocity="1"/>
		<origin rpy="1.7111227224881842 1.6469028794380574 4.886933099365235" xyz="0.13309883395318223 0.18982122129549728 0.31799876382890835"/>
	</joint>
	<joint name="951_to_850" type="revolute">
		<parent link="850"/>
		<child link="951"/>
		<axis xyz="0 0 1"/>
		<limit effort="1" lower="3.1415" upper="-3.1415" velocity="1"/>
		<origin rpy="10.147014135352803 3.0438750815767115 6.074433198983962" xyz="0.4063874542205713 0.921388344359273 0.1479935141037736"/>
	</joint>
	<joint name="1152_to_951" type="revolute">
		<parent link="951"/>
		<child link="1152"/>
		<axis xyz="0 0 1"/>
		<limit effort="1" lower="3.1415" upper="-3.1415" velocity="1"/>
		<origin rpy="9.681940991770094 2.5000270535281763 1.886959186340941" xyz="0.1105894167925342 0.2887719606417388 0.03276481018708366"/>
	</joint>
	<joint name="1153_to_951" type="revolute">
		<parent link="951"/>
		<child link="1153"/>
		<axis xyz="0 0 1"/>
		<limit effort="1" lower="3.1415" upper="-3.1415" velocity="1"/>
		<origin rpy="14.522911487655142 2.5000270535281763 1.886959186340941" xyz="0.1105894167925342 0.2887719606417388 0.03276481018708366"/>
	</joint>
	<joint name="1154_to_951" type="revolute">
		<parent link="951"/>
		<child link="1154"/>
		<axis xyz="0 0 1"/>
		<limit effort="1" lower="3.1415" upper="-3.1415" velocity="1"/>
		<origin rpy="19.36388198354019 2.5000270535281763 1.886959186340941" xyz="0.1105894167925342 0.2887719606417388 0.03276481018708366"/>
	</joint>
	<joint name="955_to_850" type="revolute">
		<parent link="850"/>
		<child link="955"/>
		<axis xyz="0 0 1"/>
		<limit effort="1" lower="3.1415" upper="-3.1415" velocity="1"/>
		<origin rpy="15.220521203029204 3.0438750815767115 6.074433198983962" xyz="0.4063874542205713 0.921388344359273 0.1479935141037736"/>
	</joint>
	<joint name="1156_to_955" type="revolute">
		<parent link="955"/>
		<child link="1156"/>
		<axis xyz="0 0 1"/>
		<limit effort="1" lower="3.1415" upper="-3.1415" velocity="1"/>
		<origin rpy="9.681940991770094 2.5000270535281763 1.886959186340941" xyz="0.1105894167925342 0.2887719606417388 0.03276481018708366"/>
	</joint>
	<joint name="1157_to_955" type="revolute">
		<parent link="955"/>
		<child link="1157"/>
		<axis xyz="0 0 1"/>
		<limit effort="1" lower="3.1415" upper="-3.1415" velocity="1"/>
		<origin rpy="14.522911487655142 2.5000270535281763 1.886959186340941" xyz="0.1105894167925342 0.2887719606417388 0.03276481018708366"/>
	</joint>
	<joint name="1158_to_955" type="revolute">
		<parent link="955"/>
		<child link="1158"/>
		<axis xyz="0 0 1"/>
		<limit effort="1" lower="3.1415" upper="-3.1415" velocity="1"/>
		<origin rpy="19.36388198354019 2.5000270535281763 1.886959186340941" xyz="0.1105894167925342 0.2887719606417388 0.03276481018708366"/>
	</joint>
	<joint name="959_to_850" type="revolute">
		<parent link="850"/>
		<child link="959"/>
		<axis xyz="0 0 1"/>
		<limit effort="1" lower="3.1415" upper="-3.1415" velocity="1"/>
		<origin rpy="20.294028270705606 3.0438750815767115 6.074433198983962" xyz="0.4063874542205713 0.921388344359273 0.1479935141037736"/>
	</joint>
	<joint name="1160_to_959" type="revolute">
		<parent link="959"/>
		<child link="1160"/>
		<axis xyz="0 0 1"/>
		<limit effort="1" lower="3.1415" upper="-3.1415" velocity="1"/>
		<origin rpy="9.681940991770094 2.5000270535281763 1.886959186340941" xyz="0.1105894167925342 0.2887719606417388 0.03276481018708366"/>
	</joint>
	<joint name="1161_to_959" type="revolute">
		<parent link="959"/>
		<child link="1161"/>
		<axis xyz="0 0 1"/>
		<limit effort="1" lower="3.1415" upper="-3.1415" velocity="1"/>
		<origin rpy="14.522911487655142 2.5000270535281763 1.886959186340941" xyz="0.1105894167925342 0.2887719606417388 0.03276481018708366"/>
	</joint>
	<joint name="1162_to_959" type="revolute">
		<parent link="959"/>
		<child link="1162"/>
		<axis xyz="0 0 1"/>
		<limit effort="1" lower="3.1415" upper="-3.1415" velocity="1"/>
		<origin rpy="19.36388198354019 2.5000270535281763 1.886959186340941" xyz="0.1105894167925342 0.2887719606417388 0.03276481018708366"/>
	</joint>
	<joint name="663_to_522" type="revolute">
		<parent link="522"/>
		<child link="663"/>
		<axis xyz="1 0 0"/>
		<limit effort="1" lower="3.1415" upper="-3.1415" velocity="1"/>
		<origin rpy="17.934933586901344 5.8408927158036406 1.757202600326469" xyz="0.3991203093009007 0.7404582271390947 0.25824358693969596"/>
	</joint>
	<joint name="864_to_663" type="revolute">
		<parent link="663"/>
		<child link="864"/>
		<axis xyz="0 0 1"/>
		<limit effort="1" lower="3.1415" upper="-3.1415" velocity="1"/>
		<origin rpy="0.8555613612440921 1.6469028794380574 4.886933099365235" xyz="0.13309883395318223 0.18982122129549728 0.31799876382890835"/>
	</joint>
	<joint name="965_to_864" type="revolute">
		<parent link="864"/>
		<child link="965"/>
		<axis xyz="0 0 1"/>
		<limit effort="1" lower="3.1415" upper="-3.1415" velocity="1"/>
		<origin rpy="10.147014135352803 3.0438750815767115 6.074433198983962" xyz="0.4063874542205713 0.921388344359273 0.1479935141037736"/>
	</joint>
	<joint name="1166_to_965" type="revolute">
		<parent link="965"/>
		<child link="1166"/>
		<axis xyz="0 0 1"/>
		<limit effort="1" lower="3.1415" upper="-3.1415" velocity="1"/>
		<origin rpy="9.681940991770094 2.5000270535281763 1.886959186340941" xyz="0.1105894167925342 0.2887719606417388 0.03276481018708366"/>
	</joint>
	<joint name="1167_to_965" type="revolute">
		<parent link="965"/>
		<child link="1167"/>
		<axis xyz="0 0 1"/>
		<limit effort="1" lower="3.1415" upper="-3.1415" velocity="1"/>
		<origin rpy="14.522911487655142 2.5000270535281763 1.886959186340941" xyz="0.1105894167925342 0.2887719606417388 0.03276481018708366"/>
	</joint>
	<joint name="1168_to_965" type="revolute">
		<parent link="965"/>
		<child link="1168"/>
		<axis xyz="0 0 1"/>
		<limit effort="1" lower="3.1415" upper="-3.1415" velocity="1"/>
		<origin rpy="19.36388198354019 2.5000270535281763 1.886959186340941" xyz="0.1105894167925342 0.2887719606417388 0.03276481018708366"/>
	</joint>
	<joint name="969_to_864" type="revolute">
		<parent link="864"/>
		<child link="969"/>
		<axis xyz="0 0 1"/>
		<limit effort="1" lower="3.1415" upper="-3.1415" velocity="1"/>
		<origin rpy="15.220521203029204 3.0438750815767115 6.074433198983962" xyz="0.4063874542205713 0.921388344359273 0.1479935141037736"/>
	</joint>
	<joint name="1170_to_969" type="revolute">
		<parent link="969"/>
		<child link="1170"/>
		<axis xyz="0 0 1"/>
		<limit effort="1" lower="3.1415" upper="-3.1415" velocity="1"/>
		<origin rpy="9.681940991770094 2.5000270535281763 1.886959186340941" xyz="0.1105894167925342 0.2887719606417388 0.03276481018708366"/>
	</joint>
	<joint name="1171_to_969" type="revolute">
		<parent link="969"/>
		<child link="1171"/>
		<axis xyz="0 0 1"/>
		<limit effort="1" lower="3.1415" upper="-3.1415" velocity="1"/>
		<origin rpy="14.522911487655142 2.5000270535281763 1.886959186340941" xyz="0.1105894167925342 0.2887719606417388 0.03276481018708366"/>
	</joint>
	<joint name="1172_to_969" type="revolute">
		<parent link="969"/>
		<child link="1172"/>
		<axis xyz="0 0 1"/>
		<limit effort="1" lower="3.1415" upper="-3.1415" velocity="1"/>
		<origin rpy="19.36388198354019 2.5000270535281763 1.886959186340941" xyz="0.1105894167925342 0.2887719606417388 0.03276481018708366"/>
	</joint>
	<joint name="973_to_864" type="revolute">
		<parent link="864"/>
		<child link="973"/>
		<axis xyz="0 0 1"/>
		<limit effort="1" lower="3.1415" upper="-3.1415" velocity="1"/>
		<origin rpy="20.294028270705606 3.0438750815767115 6.074433198983962" xyz="0.4063874542205713 0.921388344359273 0.1479935141037736"/>
	</joint>
	<joint name="1174_to_973" type="revolute">
		<parent link="973"/>
		<child link="1174"/>
		<axis xyz="0 0 1"/>
		<limit effort="1" lower="3.1415" upper="-3.1415" velocity="1"/>
		<origin rpy="9.681940991770094 2.5000270535281763 1.886959186340941" xyz="0.1105894167925342 0.2887719606417388 0.03276481018708366"/>
	</joint>
	<joint name="1175_to_973" type="revolute">
		<parent link="973"/>
		<child link="1175"/>
		<axis xyz="0 0 1"/>
		<limit effort="1" lower="3.1415" upper="-3.1415" velocity="1"/>
		<origin rpy="14.522911487655142 2.5000270535281763 1.886959186340941" xyz="0.1105894167925342 0.2887719606417388 0.03276481018708366"/>
	</joint>
	<joint name="1176_to_973" type="revolute">
		<parent link="973"/>
		<child link="1176"/>
		<axis xyz="0 0 1"/>
		<limit effort="1" lower="3.1415" upper="-3.1415" velocity="1"/>
		<origin rpy="19.36388198354019 2.5000270535281763 1.886959186340941" xyz="0.1105894167925342 0.2887719606417388 0.03276481018708366"/>
	</joint>
	<joint name="877_to_663" type="revolute">
		<parent link="663"/>
		<child link="877"/>
		<axis xyz="0 0 1"/>
		<limit effort="1" lower="3.1415" upper="-3.1415" velocity="1"/>
		<origin rpy="1.283342041866138 1.6469028794380574 4.886933099365235" xyz="0.13309883395318223 0.18982122129549728 0.31799876382890835"/>
	</joint>
	<joint name="978_to_877" type="revolute">
		<parent link="877"/>
		<child link="978"/>
		<axis xyz="0 0 1"/>
		<limit effort="1" lower="3.1415" upper="-3.1415" velocity="1"/>
		<origin rpy="10.147014135352803 3.0438750815767115 6.074433198983962" xyz="0.4063874542205713 0.921388344359273 0.1479935141037736"/>
	</joint>
	<joint name="1179_to_978" type="revolute">
		<parent link="978"/>
		<child link="1179"/>
		<axis xyz="0 0 1"/>
		<limit effort="1" lower="3.1415" upper="-3.1415" velocity="1"/>
		<origin rpy="9.681940991770094 2.5000270535281763 1.886959186340941" xyz="0.1105894167925342 0.2887719606417388 0.03276481018708366"/>
	</joint>
	<joint name="1180_to_978" type="revolute">
		<parent link="978"/>
		<child link="1180"/>
		<axis xyz="0 0 1"/>
		<limit effort="1" lower="3.1415" upper="-3.1415" velocity="1"/>
		<origin rpy="14.522911487655142 2.5000270535281763 1.886959186340941" xyz="0.1105894167925342 0.2887719606417388 0.03276481018708366"/>
	</joint>
	<joint name="1181_to_978" type="revolute">
		<parent link="978"/>
		<child link="1181"/>
		<axis xyz="0 0 1"/>
		<limit effort="1" lower="3.1415" upper="-3.1415" velocity="1"/>
		<origin rpy="19.36388198354019 2.5000270535281763 1.886959186340941" xyz="0.1105894167925342 0.2887719606417388 0.03276481018708366"/>
	</joint>
	<joint name="982_to_877" type="revolute">
		<parent link="877"/>
		<child link="982"/>
		<axis xyz="0 0 1"/>
		<limit effort="1" lower="3.1415" upper="-3.1415" velocity="1"/>
		<origin rpy="15.220521203029204 3.0438750815767115 6.074433198983962" xyz="0.4063874542205713 0.921388344359273 0.1479935141037736"/>
	</joint>
	<joint name="1183_to_982" type="revolute">
		<parent link="982"/>
		<child link="1183"/>
		<axis xyz="0 0 1"/>
		<limit effort="1" lower="3.1415" upper="-3.1415" velocity="1"/>
		<origin rpy="9.681940991770094 2.5000270535281763 1.886959186340941" xyz="0.1105894167925342 0.2887719606417388 0.03276481018708366"/>
	</joint>
	<joint name="1184_to_982" type="revolute">
		<parent link="982"/>
		<child link="1184"/>
		<axis xyz="0 0 1"/>
		<limit effort="1" lower="3.1415" upper="-3.1415" velocity="1"/>
		<origin rpy="14.522911487655142 2.5000270535281763 1.886959186340941" xyz="0.1105894167925342 0.2887719606417388 0.03276481018708366"/>
	</joint>
	<joint name="1185_to_982" type="revolute">
		<parent link="982"/>
		<child link="1185"/>
		<axis xyz="0 0 1"/>
		<limit effort="1" lower="3.1415" upper="-3.1415" velocity="1"/>
		<origin rpy="19.36388198354019 2.5000270535281763 1.886959186340941" xyz="0.1105894167925342 0.2887719606417388 0.03276481018708366"/>
	</joint>
	<joint name="986_to_877" type="revolute">
		<parent link="877"/>
		<child link="986"/>
		<axis xyz="0 0 1"/>
		<limit effort="1" lower="3.1415" upper="-3.1415" velocity="1"/>
		<origin rpy="20.294028270705606 3.0438750815767115 6.074433198983962" xyz="0.4063874542205713 0.921388344359273 0.1479935141037736"/>
	</joint>
	<joint name="1187_to_986" type="revolute">
		<parent link="986"/>
		<child link="1187"/>
		<axis xyz="0 0 1"/>
		<limit effort="1" lower="3.1415" upper="-3.1415" velocity="1"/>
		<origin rpy="9.681940991770094 2.5000270535281763 1.886959186340941" xyz="0.1105894167925342 0.2887719606417388 0.03276481018708366"/>
	</joint>
	<joint name="1188_to_986" type="revolute">
		<parent link="986"/>
		<child link="1188"/>
		<axis xyz="0 0 1"/>
		<limit effort="1" lower="3.1415" upper="-3.1415" velocity="1"/>
		<origin rpy="14.522911487655142 2.5000270535281763 1.886959186340941" xyz="0.1105894167925342 0.2887719606417388 0.03276481018708366"/>
	</joint>
	<joint name="1189_to_986" type="revolute">
		<parent link="986"/>
		<child link="1189"/>
		<axis xyz="0 0 1"/>
		<limit effort="1" lower="3.1415" upper="-3.1415" velocity="1"/>
		<origin rpy="19.36388198354019 2.5000270535281763 1.886959186340941" xyz="0.1105894167925342 0.2887719606417388 0.03276481018708366"/>
	</joint>
	<joint name="890_to_663" type="revolute">
		<parent link="663"/>
		<child link="890"/>
		<axis xyz="0 0 1"/>
		<limit effort="1" lower="3.1415" upper="-3.1415" velocity="1"/>
		<origin rpy="1.7111227224881842 1.6469028794380574 4.886933099365235" xyz="0.13309883395318223 0.18982122129549728 0.31799876382890835"/>
	</joint>
	<joint name="991_to_890" type="revolute">
		<parent link="890"/>
		<child link="991"/>
		<axis xyz="0 0 1"/>
		<limit effort="1" lower="3.1415" upper="-3.1415" velocity="1"/>
		<origin rpy="10.147014135352803 3.0438750815767115 6.074433198983962" xyz="0.4063874542205713 0.921388344359273 0.1479935141037736"/>
	</joint>
	<joint name="1192_to_991" type="revolute">
		<parent link="991"/>
		<child link="1192"/>
		<axis xyz="0 0 1"/>
		<limit effort="1" lower="3.1415" upper="-3.1415" velocity="1"/>
		<origin rpy="9.681940991770094 2.5000270535281763 1.886959186340941" xyz="0.1105894167925342 0.2887719606417388 0.03276481018708366"/>
	</joint>
	<joint name="1193_to_991" type="revolute">
		<parent link="991"/>
		<child link="1193"/>
		<axis xyz="0 0 1"/>
		<limit effort="1" lower="3.1415" upper="-3.1415" velocity="1"/>
		<origin rpy="14.522911487655142 2.5000270535281763 1.886959186340941" xyz="0.1105894167925342 0.2887719606417388 0.03276481018708366"/>
	</joint>
	<joint name="1194_to_991" type="revolute">
		<parent link="991"/>
		<child link="1194"/>
		<axis xyz="0 0 1"/>
		<limit effort="1" lower="3.1415" upper="-3.1415" velocity="1"/>
		<origin rpy="19.36388198354019 2.5000270535281763 1.886959186340941" xyz="0.1105894167925342 0.2887719606417388 0.03276481018708366"/>
	</joint>
	<joint name="995_to_890" type="revolute">
		<parent link="890"/>
		<child link="995"/>
		<axis xyz="0 0 1"/>
		<limit effort="1" lower="3.1415" upper="-3.1415" velocity="1"/>
		<origin rpy="15.220521203029204 3.0438750815767115 6.074433198983962" xyz="0.4063874542205713 0.921388344359273 0.1479935141037736"/>
	</joint>
	<joint name="1196_to_995" type="revolute">
		<parent link="995"/>
		<child link="1196"/>
		<axis xyz="0 0 1"/>
		<limit effort="1" lower="3.1415" upper="-3.1415" velocity="1"/>
		<origin rpy="9.681940991770094 2.5000270535281763 1.886959186340941" xyz="0.1105894167925342 0.2887719606417388 0.03276481018708366"/>
	</joint>
	<joint name="1197_to_995" type="revolute">
		<parent link="995"/>
		<child link="1197"/>
		<axis xyz="0 0 1"/>
		<limit effort="1" lower="3.1415" upper="-3.1415" velocity="1"/>
		<origin rpy="14.522911487655142 2.5000270535281763 1.886959186340941" xyz="0.1105894167925342 0.2887719606417388 0.03276481018708366"/>
	</joint>
	<joint name="1198_to_995" type="revolute">
		<parent link="995"/>
		<child link="1198"/>
		<axis xyz="0 0 1"/>
		<limit effort="1" lower="3.1415" upper="-3.1415" velocity="1"/>
		<origin rpy="19.36388198354019 2.5000270535281763 1.886959186340941" xyz="0.1105894167925342 0.2887719606417388 0.03276481018708366"/>
	</joint>
	<joint name="999_to_890" type="revolute">
		<parent link="890"/>
		<child link="999"/>
		<axis xyz="0 0 1"/>
		<limit effort="1" lower="3.1415" upper="-3.1415" velocity="1"/>
		<origin rpy="20.294028270705606 3.0438750815767115 6.074433198983962" xyz="0.4063874542205713 0.921388344359273 0.1479935141037736"/>
	</joint>
	<joint name="11100_to_999" type="revolute">
		<parent link="999"/>
		<child link="11100"/>
		<axis xyz="0 0 1"/>
		<limit effort="1" lower="3.1415" upper="-3.1415" velocity="1"/>
		<origin rpy="9.681940991770094 2.5000270535281763 1.886959186340941" xyz="0.1105894167925342 0.2887719606417388 0.03276481018708366"/>
	</joint>
	<joint name="11101_to_999" type="revolute">
		<parent link="999"/>
		<child link="11101"/>
		<axis xyz="0 0 1"/>
		<limit effort="1" lower="3.1415" upper="-3.1415" velocity="1"/>
		<origin rpy="14.522911487655142 2.5000270535281763 1.886959186340941" xyz="0.1105894167925342 0.2887719606417388 0.03276481018708366"/>
	</joint>
	<joint name="11102_to_999" type="revolute">
		<parent link="999"/>
		<child link="11102"/>
		<axis xyz="0 0 1"/>
		<limit effort="1" lower="3.1415" upper="-3.1415" velocity="1"/>
		<origin rpy="19.36388198354019 2.5000270535281763 1.886959186340941" xyz="0.1105894167925342 0.2887719606417388 0.03276481018708366"/>
	</joint>
	<joint name="6103_to_522" type="revolute">
		<parent link="522"/>
		<child link="6103"/>
		<axis xyz="1 0 0"/>
		<limit effort="1" lower="3.1415" upper="-3.1415" velocity="1"/>
		<origin rpy="23.913244782535124 5.8408927158036406 1.757202600326469" xyz="0.3991203093009007 0.7404582271390947 0.25824358693969596"/>
	</joint>
	<joint name="8104_to_6103" type="revolute">
		<parent link="6103"/>
		<child link="8104"/>
		<axis xyz="0 0 1"/>
		<limit effort="1" lower="3.1415" upper="-3.1415" velocity="1"/>
		<origin rpy="0.8555613612440921 1.6469028794380574 4.886933099365235" xyz="0.13309883395318223 0.18982122129549728 0.31799876382890835"/>
	</joint>
	<joint name="9105_to_8104" type="revolute">
		<parent link="8104"/>
		<child link="9105"/>
		<axis xyz="0 0 1"/>
		<limit effort="1" lower="3.1415" upper="-3.1415" velocity="1"/>
		<origin rpy="10.147014135352803 3.0438750815767115 6.074433198983962" xyz="0.4063874542205713 0.921388344359273 0.1479935141037736"/>
	</joint>
	<joint name="11106_to_9105" type="revolute">
		<parent link="9105"/>
		<child link="11106"/>
		<axis xyz="0 0 1"/>
		<limit effort="1" lower="3.1415" upper="-3.1415" velocity="1"/>
		<origin rpy="9.681940991770094 2.5000270535281763 1.886959186340941" xyz="0.1105894167925342 0.2887719606417388 0.03276481018708366"/>
	</joint>
	<joint name="11107_to_9105" type="revolute">
		<parent link="9105"/>
		<child link="11107"/>
		<axis xyz="0 0 1"/>
		<limit effort="1" lower="3.1415" upper="-3.1415" velocity="1"/>
		<origin rpy="14.522911487655142 2.5000270535281763 1.886959186340941" xyz="0.1105894167925342 0.2887719606417388 0.03276481018708366"/>
	</joint>
	<joint name="11108_to_9105" type="revolute">
		<parent link="9105"/>
		<child link="11108"/>
		<axis xyz="0 0 1"/>
		<limit effort="1" lower="3.1415" upper="-3.1415" velocity="1"/>
		<origin rpy="19.36388198354019 2.5000270535281763 1.886959186340941" xyz="0.1105894167925342 0.2887719606417388 0.03276481018708366"/>
	</joint>
	<joint name="9109_to_8104" type="revolute">
		<parent link="8104"/>
		<child link="9109"/>
		<axis xyz="0 0 1"/>
		<limit effort="1" lower="3.1415" upper="-3.1415" velocity="1"/>
		<origin rpy="15.220521203029204 3.0438750815767115 6.074433198983962" xyz="0.4063874542205713 0.921388344359273 0.1479935141037736"/>
	</joint>
	<joint name="11110_to_9109" type="revolute">
		<parent link="9109"/>
		<child link="11110"/>
		<axis xyz="0 0 1"/>
		<limit effort="1" lower="3.1415" upper="-3.1415" velocity="1"/>
		<origin rpy="9.681940991770094 2.5000270535281763 1.886959186340941" xyz="0.1105894167925342 0.2887719606417388 0.03276481018708366"/>
	</joint>
	<joint name="11111_to_9109" type="revolute">
		<parent link="9109"/>
		<child link="11111"/>
		<axis xyz="0 0 1"/>
		<limit effort="1" lower="3.1415" upper="-3.1415" velocity="1"/>
		<origin rpy="14.522911487655142 2.5000270535281763 1.886959186340941" xyz="0.1105894167925342 0.2887719606417388 0.03276481018708366"/>
	</joint>
	<joint name="11112_to_9109" type="revolute">
		<parent link="9109"/>
		<child link="11112"/>
		<axis xyz="0 0 1"/>
		<limit effort="1" lower="3.1415" upper="-3.1415" velocity="1"/>
		<origin rpy="19.36388198354019 2.5000270535281763 1.886959186340941" xyz="0.1105894167925342 0.2887719606417388 0.03276481018708366"/>
	</joint>
	<joint name="9113_to_8104" type="revolute">
		<parent link="8104"/>
		<child link="9113"/>
		<axis xyz="0 0 1"/>
		<limit effort="1" lower="3.1415" upper="-3.1415" velocity="1"/>
		<origin rpy="20.294028270705606 3.0438750815767115 6.074433198983962" xyz="0.4063874542205713 0.921388344359273 0.1479935141037736"/>
	</joint>
	<joint name="11114_to_9113" type="revolute">
		<parent link="9113"/>
		<child link="11114"/>
		<axis xyz="0 0 1"/>
		<limit effort="1" lower="3.1415" upper="-3.1415" velocity="1"/>
		<origin rpy="9.681940991770094 2.5000270535281763 1.886959186340941" xyz="0.1105894167925342 0.2887719606417388 0.03276481018708366"/>
	</joint>
	<joint name="11115_to_9113" type="revolute">
		<parent link="9113"/>
		<child link="11115"/>
		<axis xyz="0 0 1"/>
		<limit effort="1" lower="3.1415" upper="-3.1415" velocity="1"/>
		<origin rpy="14.522911487655142 2.5000270535281763 1.886959186340941" xyz="0.1105894167925342 0.2887719606417388 0.03276481018708366"/>
	</joint>
	<joint name="11116_to_9113" type="revolute">
		<parent link="9113"/>
		<child link="11116"/>
		<axis xyz="0 0 1"/>
		<limit effort="1" lower="3.1415" upper="-3.1415" velocity="1"/>
		<origin rpy="19.36388198354019 2.5000270535281763 1.886959186340941" xyz="0.1105894167925342 0.2887719606417388 0.03276481018708366"/>
	</joint>
	<joint name="8117_to_6103" type="revolute">
		<parent link="6103"/>
		<child link="8117"/>
		<axis xyz="0 0 1"/>
		<limit effort="1" lower="3.1415" upper="-3.1415" velocity="1"/>
		<origin rpy="1.283342041866138 1.6469028794380574 4.886933099365235" xyz="0.13309883395318223 0.18982122129549728 0.31799876382890835"/>
	</joint>
	<joint name="9118_to_8117" type="revolute">
		<parent link="8117"/>
		<child link="9118"/>
		<axis xyz="0 0 1"/>
		<limit effort="1" lower="3.1415" upper="-3.1415" velocity="1"/>
		<origin rpy="10.147014135352803 3.0438750815767115 6.074433198983962" xyz="0.4063874542205713 0.921388344359273 0.1479935141037736"/>
	</joint>
	<joint name="11119_to_9118" type="revolute">
		<parent link="9118"/>
		<child link="11119"/>
		<axis xyz="0 0 1"/>
		<limit effort="1" lower="3.1415" upper="-3.1415" velocity="1"/>
		<origin rpy="9.681940991770094 2.5000270535281763 1.886959186340941" xyz="0.1105894167925342 0.2887719606417388 0.03276481018708366"/>
	</joint>
	<joint name="11120_to_9118" type="revolute">
		<parent link="9118"/>
		<child link="11120"/>
		<axis xyz="0 0 1"/>
		<limit effort="1" lower="3.1415" upper="-3.1415" velocity="1"/>
		<origin rpy="14.522911487655142 2.5000270535281763 1.886959186340941" xyz="0.1105894167925342 0.2887719606417388 0.03276481018708366"/>
	</joint>
	<joint name="11121_to_9118" type="revolute">
		<parent link="9118"/>
		<child link="11121"/>
		<axis xyz="0 0 1"/>
		<limit effort="1" lower="3.1415" upper="-3.1415" velocity="1"/>
		<origin rpy="19.36388198354019 2.5000270535281763 1.886959186340941" xyz="0.1105894167925342 0.2887719606417388 0.03276481018708366"/>
	</joint>
	<joint name="9122_to_8117" type="revolute">
		<parent link="8117"/>
		<child link="9122"/>
		<axis xyz="0 0 1"/>
		<limit effort="1" lower="3.1415" upper="-3.1415" velocity="1"/>
		<origin rpy="15.220521203029204 3.0438750815767115 6.074433198983962" xyz="0.4063874542205713 0.921388344359273 0.1479935141037736"/>
	</joint>
	<joint name="11123_to_9122" type="revolute">
		<parent link="9122"/>
		<child link="11123"/>
		<axis xyz="0 0 1"/>
		<limit effort="1" lower="3.1415" upper="-3.1415" velocity="1"/>
		<origin rpy="9.681940991770094 2.5000270535281763 1.886959186340941" xyz="0.1105894167925342 0.2887719606417388 0.03276481018708366"/>
	</joint>
	<joint name="11124_to_9122" type="revolute">
		<parent link="9122"/>
		<child link="11124"/>
		<axis xyz="0 0 1"/>
		<limit effort="1" lower="3.1415" upper="-3.1415" velocity="1"/>
		<origin rpy="14.522911487655142 2.5000270535281763 1.886959186340941" xyz="0.1105894167925342 0.2887719606417388 0.03276481018708366"/>
	</joint>
	<joint name="11125_to_9122" type="revolute">
		<parent link="9122"/>
		<child link="11125"/>
		<axis xyz="0 0 1"/>
		<limit effort="1" lower="3.1415" upper="-3.1415" velocity="1"/>
		<origin rpy="19.36388198354019 2.5000270535281763 1.886959186340941" xyz="0.1105894167925342 0.2887719606417388 0.03276481018708366"/>
	</joint>
	<joint name="9126_to_8117" type="revolute">
		<parent link="8117"/>
		<child link="9126"/>
		<axis xyz="0 0 1"/>
		<limit effort="1" lower="3.1415" upper="-3.1415" velocity="1"/>
		<origin rpy="20.294028270705606 3.0438750815767115 6.074433198983962" xyz="0.4063874542205713 0.921388344359273 0.1479935141037736"/>
	</joint>
	<joint name="11127_to_9126" type="revolute">
		<parent link="9126"/>
		<child link="11127"/>
		<axis xyz="0 0 1"/>
		<limit effort="1" lower="3.1415" upper="-3.1415" velocity="1"/>
		<origin rpy="9.681940991770094 2.5000270535281763 1.886959186340941" xyz="0.1105894167925342 0.2887719606417388 0.03276481018708366"/>
	</joint>
	<joint name="11128_to_9126" type="revolute">
		<parent link="9126"/>
		<child link="11128"/>
		<axis xyz="0 0 1"/>
		<limit effort="1" lower="3.1415" upper="-3.1415" velocity="1"/>
		<origin rpy="14.522911487655142 2.5000270535281763 1.886959186340941" xyz="0.1105894167925342 0.2887719606417388 0.03276481018708366"/>
	</joint>
	<joint name="11129_to_9126" type="revolute">
		<parent link="9126"/>
		<child link="11129"/>
		<axis xyz="0 0 1"/>
		<limit effort="1" lower="3.1415" upper="-3.1415" velocity="1"/>
		<origin rpy="19.36388198354019 2.5000270535281763 1.886959186340941" xyz="0.1105894167925342 0.2887719606417388 0.03276481018708366"/>
	</joint>
	<joint name="8130_to_6103" type="revolute">
		<parent link="6103"/>
		<child link="8130"/>
		<axis xyz="0 0 1"/>
		<limit effort="1" lower="3.1415" upper="-3.1415" velocity="1"/>
		<origin rpy="1.7111227224881842 1.6469028794380574 4.886933099365235" xyz="0.13309883395318223 0.18982122129549728 0.31799876382890835"/>
	</joint>
	<joint name="9131_to_8130" type="revolute">
		<parent link="8130"/>
		<child link="9131"/>
		<axis xyz="0 0 1"/>
		<limit effort="1" lower="3.1415" upper="-3.1415" velocity="1"/>
		<origin rpy="10.147014135352803 3.0438750815767115 6.074433198983962" xyz="0.4063874542205713 0.921388344359273 0.1479935141037736"/>
	</joint>
	<joint name="11132_to_9131" type="revolute">
		<parent link="9131"/>
		<child link="11132"/>
		<axis xyz="0 0 1"/>
		<limit effort="1" lower="3.1415" upper="-3.1415" velocity="1"/>
		<origin rpy="9.681940991770094 2.5000270535281763 1.886959186340941" xyz="0.1105894167925342 0.2887719606417388 0.03276481018708366"/>
	</joint>
	<joint name="11133_to_9131" type="revolute">
		<parent link="9131"/>
		<child link="11133"/>
		<axis xyz="0 0 1"/>
		<limit effort="1" lower="3.1415" upper="-3.1415" velocity="1"/>
		<origin rpy="14.522911487655142 2.5000270535281763 1.886959186340941" xyz="0.1105894167925342 0.2887719606417388 0.03276481018708366"/>
	</joint>
	<joint name="11134_to_9131" type="revolute">
		<parent link="9131"/>
		<child link="11134"/>
		<axis xyz="0 0 1"/>
		<limit effort="1" lower="3.1415" upper="-3.1415" velocity="1"/>
		<origin rpy="19.36388198354019 2.5000270535281763 1.886959186340941" xyz="0.1105894167925342 0.2887719606417388 0.03276481018708366"/>
	</joint>
	<joint name="9135_to_8130" type="revolute">
		<parent link="8130"/>
		<child link="9135"/>
		<axis xyz="0 0 1"/>
		<limit effort="1" lower="3.1415" upper="-3.1415" velocity="1"/>
		<origin rpy="15.220521203029204 3.0438750815767115 6.074433198983962" xyz="0.4063874542205713 0.921388344359273 0.1479935141037736"/>
	</joint>
	<joint name="11136_to_9135" type="revolute">
		<parent link="9135"/>
		<child link="11136"/>
		<axis xyz="0 0 1"/>
		<limit effort="1" lower="3.1415" upper="-3.1415" velocity="1"/>
		<origin rpy="9.681940991770094 2.5000270535281763 1.886959186340941" xyz="0.1105894167925342 0.2887719606417388 0.03276481018708366"/>
	</joint>
	<joint name="11137_to_9135" type="revolute">
		<parent link="9135"/>
		<child link="11137"/>
		<axis xyz="0 0 1"/>
		<limit effort="1" lower="3.1415" upper="-3.1415" velocity="1"/>
		<origin rpy="14.522911487655142 2.5000270535281763 1.886959186340941" xyz="0.1105894167925342 0.2887719606417388 0.03276481018708366"/>
	</joint>
	<joint name="11138_to_9135" type="revolute">
		<parent link="9135"/>
		<child link="11138"/>
		<axis xyz="0 0 1"/>
		<limit effort="1" lower="3.1415" upper="-3.1415" velocity="1"/>
		<origin rpy="19.36388198354019 2.5000270535281763 1.886959186340941" xyz="0.1105894167925342 0.2887719606417388 0.03276481018708366"/>
	</joint>
	<joint name="9139_to_8130" type="revolute">
		<parent link="8130"/>
		<child link="9139"/>
		<axis xyz="0 0 1"/>
		<limit effort="1" lower="3.1415" upper="-3.1415" velocity="1"/>
		<origin rpy="20.294028270705606 3.0438750815767115 6.074433198983962" xyz="0.4063874542205713 0.921388344359273 0.1479935141037736"/>
	</joint>
	<joint name="11140_to_9139" type="revolute">
		<parent link="9139"/>
		<child link="11140"/>
		<axis xyz="0 0 1"/>
		<limit effort="1" lower="3.1415" upper="-3.1415" velocity="1"/>
		<origin rpy="9.681940991770094 2.5000270535281763 1.886959186340941" xyz="0.1105894167925342 0.2887719606417388 0.03276481018708366"/>
	</joint>
	<joint name="11141_to_9139" type="revolute">
		<parent link="9139"/>
		<child link="11141"/>
		<axis xyz="0 0 1"/>
		<limit effort="1" lower="3.1415" upper="-3.1415" velocity="1"/>
		<origin rpy="14.522911487655142 2.5000270535281763 1.886959186340941" xyz="0.1105894167925342 0.2887719606417388 0.03276481018708366"/>
	</joint>
	<joint name="11142_to_9139" type="revolute">
		<parent link="9139"/>
		<child link="11142"/>
		<axis xyz="0 0 1"/>
		<limit effort="1" lower="3.1415" upper="-3.1415" velocity="1"/>
		<origin rpy="19.36388198354019 2.5000270535281763 1.886959186340941" xyz="0.1105894167925342 0.2887719606417388 0.03276481018708366"/>
	</joint>
</robot>
