<?xml version="1.0"?><robot name="pepe">
	<link name="0">
		<visual>
			<geometry>
				<cylinder length="1.9998" radius="0.010269367177534572"/>
			</geometry>
		</visual>
		<collision>
			<geometry>
				<cylinder length="1.9998" radius="0.010269367177534572"/>
			</geometry>
		</collision>
		<inertial>
			<mass value="0.0006625578457586183"/>
			<inertia ixx="0.03" ixy="0" ixz="0" iyx="0" iyy="0.03" izz="0.03"/>
		</inertial>
	</link>
	<link name="11">
		<visual>
			<geometry>
				<cylinder length="1.9998" radius="0.9999"/>
			</geometry>
		</visual>
		<collision>
			<geometry>
				<cylinder length="1.9998" radius="0.9999"/>
			</geometry>
		</collision>
		<inertial>
			<mass value="6.281300540076709"/>
			<inertia ixx="0.03" ixy="0" ixz="0" iyx="0" iyy="0.03" izz="0.03"/>
		</inertial>
	</link>
	<link name="22">
		<visual>
			<geometry>
				<cylinder length="1.9005037910659992" radius="0.7058882183069434"/>
			</geometry>
		</visual>
		<collision>
			<geometry>
				<cylinder length="1.9005037910659992" radius="0.7058882183069434"/>
			</geometry>
		</collision>
		<inertial>
			<mass value="2.9750240410745246"/>
			<inertia ixx="0.03" ixy="0" ixz="0" iyx="0" iyy="0.03" izz="0.03"/>
		</inertial>
	</link>
	<link name="23">
		<visual>
			<geometry>
				<cylinder length="1.9005037910659992" radius="0.7058882183069434"/>
			</geometry>
		</visual>
		<collision>
			<geometry>
				<cylinder length="1.9005037910659992" radius="0.7058882183069434"/>
			</geometry>
		</collision>
		<inertial>
			<mass value="2.9750240410745246"/>
			<inertia ixx="0.03" ixy="0" ixz="0" iyx="0" iyy="0.03" izz="0.03"/>
		</inertial>
	</link>
	<link name="24">
		<visual>
			<geometry>
				<cylinder length="1.9005037910659992" radius="0.7058882183069434"/>
			</geometry>
		</visual>
		<collision>
			<geometry>
				<cylinder length="1.9005037910659992" radius="0.7058882183069434"/>
			</geometry>
		</collision>
		<inertial>
			<mass value="2.9750240410745246"/>
			<inertia ixx="0.03" ixy="0" ixz="0" iyx="0" iyy="0.03" izz="0.03"/>
		</inertial>
	</link>
	<link name="15">
		<visual>
			<geometry>
				<cylinder length="1.9998" radius="0.9999"/>
			</geometry>
		</visual>
		<collision>
			<geometry>
				<cylinder length="1.9998" radius="0.9999"/>
			</geometry>
		</collision>
		<inertial>
			<mass value="6.281300540076709"/>
			<inertia ixx="0.03" ixy="0" ixz="0" iyx="0" iyy="0.03" izz="0.03"/>
		</inertial>
	</link>
	<link name="26">
		<visual>
			<geometry>
				<cylinder length="1.9005037910659992" radius="0.7058882183069434"/>
			</geometry>
		</visual>
		<collision>
			<geometry>
				<cylinder length="1.9005037910659992" radius="0.7058882183069434"/>
			</geometry>
		</collision>
		<inertial>
			<mass value="2.9750240410745246"/>
			<inertia ixx="0.03" ixy="0" ixz="0" iyx="0" iyy="0.03" izz="0.03"/>
		</inertial>
	</link>
	<link name="27">
		<visual>
			<geometry>
				<cylinder length="1.9005037910659992" radius="0.7058882183069434"/>
			</geometry>
		</visual>
		<collision>
			<geometry>
				<cylinder length="1.9005037910659992" radius="0.7058882183069434"/>
			</geometry>
		</collision>
		<inertial>
			<mass value="2.9750240410745246"/>
			<inertia ixx="0.03" ixy="0" ixz="0" iyx="0" iyy="0.03" izz="0.03"/>
		</inertial>
	</link>
	<link name="28">
		<visual>
			<geometry>
				<cylinder length="1.9005037910659992" radius="0.7058882183069434"/>
			</geometry>
		</visual>
		<collision>
			<geometry>
				<cylinder length="1.9005037910659992" radius="0.7058882183069434"/>
			</geometry>
		</collision>
		<inertial>
			<mass value="2.9750240410745246"/>
			<inertia ixx="0.03" ixy="0" ixz="0" iyx="0" iyy="0.03" izz="0.03"/>
		</inertial>
	</link>
	<link name="19">
		<visual>
			<geometry>
				<cylinder length="1.9998" radius="0.9999"/>
			</geometry>
		</visual>
		<collision>
			<geometry>
				<cylinder length="1.9998" radius="0.9999"/>
			</geometry>
		</collision>
		<inertial>
			<mass value="6.281300540076709"/>
			<inertia ixx="0.03" ixy="0" ixz="0" iyx="0" iyy="0.03" izz="0.03"/>
		</inertial>
	</link>
	<link name="210">
		<visual>
			<geometry>
				<cylinder length="1.9005037910659992" radius="0.7058882183069434"/>
			</geometry>
		</visual>
		<collision>
			<geometry>
				<cylinder length="1.9005037910659992" radius="0.7058882183069434"/>
			</geometry>
		</collision>
		<inertial>
			<mass value="2.9750240410745246"/>
			<inertia ixx="0.03" ixy="0" ixz="0" iyx="0" iyy="0.03" izz="0.03"/>
		</inertial>
	</link>
	<link name="211">
		<visual>
			<geometry>
				<cylinder length="1.9005037910659992" radius="0.7058882183069434"/>
			</geometry>
		</visual>
		<collision>
			<geometry>
				<cylinder length="1.9005037910659992" radius="0.7058882183069434"/>
			</geometry>
		</collision>
		<inertial>
			<mass value="2.9750240410745246"/>
			<inertia ixx="0.03" ixy="0" ixz="0" iyx="0" iyy="0.03" izz="0.03"/>
		</inertial>
	</link>
	<link name="212">
		<visual>
			<geometry>
				<cylinder length="1.9005037910659992" radius="0.7058882183069434"/>
			</geometry>
		</visual>
		<collision>
			<geometry>
				<cylinder length="1.9005037910659992" radius="0.7058882183069434"/>
			</geometry>
		</collision>
		<inertial>
			<mass value="2.9750240410745246"/>
			<inertia ixx="0.03" ixy="0" ixz="0" iyx="0" iyy="0.03" izz="0.03"/>
		</inertial>
	</link>
	<joint name="11_to_0" type="revolute">
		<parent link="0"/>
		<child link="11"/>
		<axis xyz="1 0 0"/>
		<limit effort="1" lower="3.1415" upper="-3.1415" velocity="1"/>
		<origin rpy="10.00547663531266 4.364559318388451 3.6585971237677777" xyz="0.7849810317268884 0.4262293513728075 0.9999"/>
	</joint>
	<joint name="22_to_11" type="revolute">
		<parent link="11"/>
		<child link="22"/>
		<axis xyz="1 0 0"/>
		<limit effort="1" lower="3.1415" upper="-3.1415" velocity="1"/>
		<origin rpy="3.0036540205902273 4.495996032334981 5.787035230481515" xyz="0.2506740408016117 0.09067578195260384 0.9286167875098919"/>
	</joint>
	<joint name="23_to_11" type="revolute">
		<parent link="11"/>
		<child link="23"/>
		<axis xyz="1 0 0"/>
		<limit effort="1" lower="3.1415" upper="-3.1415" velocity="1"/>
		<origin rpy="4.505481030885341 4.495996032334981 5.787035230481515" xyz="0.2506740408016117 0.09067578195260384 0.9286167875098919"/>
	</joint>
	<joint name="24_to_11" type="revolute">
		<parent link="11"/>
		<child link="24"/>
		<axis xyz="1 0 0"/>
		<limit effort="1" lower="3.1415" upper="-3.1415" velocity="1"/>
		<origin rpy="6.007308041180455 4.495996032334981 5.787035230481515" xyz="0.2506740408016117 0.09067578195260384 0.9286167875098919"/>
	</joint>
	<joint name="15_to_0" type="revolute">
		<parent link="0"/>
		<child link="15"/>
		<axis xyz="1 0 0"/>
		<limit effort="1" lower="3.1415" upper="-3.1415" velocity="1"/>
		<origin rpy="15.008214952968988 4.364559318388451 3.6585971237677777" xyz="0.7849810317268884 0.4262293513728075 0.9999"/>
	</joint>
	<joint name="26_to_15" type="revolute">
		<parent link="15"/>
		<child link="26"/>
		<axis xyz="1 0 0"/>
		<limit effort="1" lower="3.1415" upper="-3.1415" velocity="1"/>
		<origin rpy="3.0036540205902273 4.495996032334981 5.787035230481515" xyz="0.2506740408016117 0.09067578195260384 0.9286167875098919"/>
	</joint>
	<joint name="27_to_15" type="revolute">
		<parent link="15"/>
		<child link="27"/>
		<axis xyz="1 0 0"/>
		<limit effort="1" lower="3.1415" upper="-3.1415" velocity="1"/>
		<origin rpy="4.505481030885341 4.495996032334981 5.787035230481515" xyz="0.2506740408016117 0.09067578195260384 0.9286167875098919"/>
	</joint>
	<joint name="28_to_15" type="revolute">
		<parent link="15"/>
		<child link="28"/>
		<axis xyz="1 0 0"/>
		<limit effort="1" lower="3.1415" upper="-3.1415" velocity="1"/>
		<origin rpy="6.007308041180455 4.495996032334981 5.787035230481515" xyz="0.2506740408016117 0.09067578195260384 0.9286167875098919"/>
	</joint>
	<joint name="19_to_0" type="revolute">
		<parent link="0"/>
		<child link="19"/>
		<axis xyz="1 0 0"/>
		<limit effort="1" lower="3.1415" upper="-3.1415" velocity="1"/>
		<origin rpy="20.01095327062532 4.364559318388451 3.6585971237677777" xyz="0.7849810317268884 0.4262293513728075 0.9999"/>
	</joint>
	<joint name="210_to_19" type="revolute">
		<parent link="19"/>
		<child link="210"/>
		<axis xyz="1 0 0"/>
		<limit effort="1" lower="3.1415" upper="-3.1415" velocity="1"/>
		<origin rpy="3.0036540205902273 4.495996032334981 5.787035230481515" xyz="0.2506740408016117 0.09067578195260384 0.9286167875098919"/>
	</joint>
	<joint name="211_to_19" type="revolute">
		<parent link="19"/>
		<child link="211"/>
		<axis xyz="1 0 0"/>
		<limit effort="1" lower="3.1415" upper="-3.1415" velocity="1"/>
		<origin rpy="4.505481030885341 4.495996032334981 5.787035230481515" xyz="0.2506740408016117 0.09067578195260384 0.9286167875098919"/>
	</joint>
	<joint name="212_to_19" type="revolute">
		<parent link="19"/>
		<child link="212"/>
		<axis xyz="1 0 0"/>
		<limit effort="1" lower="3.1415" upper="-3.1415" velocity="1"/>
		<origin rpy="6.007308041180455 4.495996032334981 5.787035230481515" xyz="0.2506740408016117 0.09067578195260384 0.9286167875098919"/>
	</joint>
</robot>
