<?xml version="1.0"?><robot name="pepe">
	<link name="0">
		<visual>
			<geometry>
				<cylinder length="1.8856710176840368" radius="0.9999"/>
			</geometry>
		</visual>
		<collision>
			<geometry>
				<cylinder length="1.8856710176840368" radius="0.9999"/>
			</geometry>
		</collision>
		<inertial>
			<mass value="5.922825473440213"/>
			<inertia ixx="0.03" ixy="0" ixz="0" iyx="0" iyy="0.03" izz="0.03"/>
		</inertial>
	</link>
	<link name="11">
		<visual>
			<geometry>
				<cylinder length="1.1274469940070369" radius="0.344506793690461"/>
			</geometry>
		</visual>
		<collision>
			<geometry>
				<cylinder length="1.1274469940070369" radius="0.344506793690461"/>
			</geometry>
		</collision>
		<inertial>
			<mass value="0.4203795558477106"/>
			<inertia ixx="0.03" ixy="0" ixz="0" iyx="0" iyy="0.03" izz="0.03"/>
		</inertial>
	</link>
	<link name="12">
		<visual>
			<geometry>
				<cylinder length="1.1274469940070369" radius="0.344506793690461"/>
			</geometry>
		</visual>
		<collision>
			<geometry>
				<cylinder length="1.1274469940070369" radius="0.344506793690461"/>
			</geometry>
		</collision>
		<inertial>
			<mass value="0.4203795558477106"/>
			<inertia ixx="0.03" ixy="0" ixz="0" iyx="0" iyy="0.03" izz="0.03"/>
		</inertial>
	</link>
	<link name="13">
		<visual>
			<geometry>
				<cylinder length="1.1274469940070369" radius="0.344506793690461"/>
			</geometry>
		</visual>
		<collision>
			<geometry>
				<cylinder length="1.1274469940070369" radius="0.344506793690461"/>
			</geometry>
		</collision>
		<inertial>
			<mass value="0.4203795558477106"/>
			<inertia ixx="0.03" ixy="0" ixz="0" iyx="0" iyy="0.03" izz="0.03"/>
		</inertial>
	</link>
	<joint name="11_to_0" type="revolute">
		<parent link="0"/>
		<child link="11"/>
		<axis xyz="0 0 1"/>
		<limit effort="1" lower="3.1415" upper="-3.1415" velocity="1"/>
		<origin rpy="12.565113977297736 6.282556988648868 5.352476816319871" xyz="0.5507040907358064 0.5018865040146698 0.48089488158635463"/>
	</joint>
	<joint name="12_to_0" type="revolute">
		<parent link="0"/>
		<child link="12"/>
		<axis xyz="0 0 1"/>
		<limit effort="1" lower="3.1415" upper="-3.1415" velocity="1"/>
		<origin rpy="18.847670965946605 6.282556988648868 5.352476816319871" xyz="0.5507040907358064 0.5018865040146698 0.48089488158635463"/>
	</joint>
	<joint name="13_to_0" type="revolute">
		<parent link="0"/>
		<child link="13"/>
		<axis xyz="0 0 1"/>
		<limit effort="1" lower="3.1415" upper="-3.1415" velocity="1"/>
		<origin rpy="25.130227954595473 6.282556988648868 5.352476816319871" xyz="0.5507040907358064 0.5018865040146698 0.48089488158635463"/>
	</joint>
</robot>
