<?xml version="1.0"?><robot name="pepe">
	<link name="0">
		<visual>
			<geometry>
				<cylinder length="0.31230003506431925" radius="0.01692394088196847"/>
			</geometry>
		</visual>
		<collision>
			<geometry>
				<cylinder length="0.31230003506431925" radius="0.01692394088196847"/>
			</geometry>
		</collision>
		<inertial>
			<mass value="0.0002810120252331259"/>
			<inertia ixx="0.03" ixy="0" ixz="0" iyx="0" iyy="0.03" izz="0.03"/>
		</inertial>
	</link>
	<link name="11">
		<visual>
			<geometry>
				<cylinder length="1.7888891298554797" radius="0.4160768401091772"/>
			</geometry>
		</visual>
		<collision>
			<geometry>
				<cylinder length="1.7888891298554797" radius="0.4160768401091772"/>
			</geometry>
		</collision>
		<inertial>
			<mass value="0.9729272846353406"/>
			<inertia ixx="0.03" ixy="0" ixz="0" iyx="0" iyy="0.03" izz="0.03"/>
		</inertial>
	</link>
	<link name="22">
		<visual>
			<geometry>
				<cylinder length="0.8087551493112171" radius="0.6853008201344472"/>
			</geometry>
		</visual>
		<collision>
			<geometry>
				<cylinder length="0.8087551493112171" radius="0.6853008201344472"/>
			</geometry>
		</collision>
		<inertial>
			<mass value="1.1932444818053722"/>
			<inertia ixx="0.03" ixy="0" ixz="0" iyx="0" iyy="0.03" izz="0.03"/>
		</inertial>
	</link>
	<link name="33">
		<visual>
			<geometry>
				<cylinder length="0.10556557423188928" radius="0.7402568284366033"/>
			</geometry>
		</visual>
		<collision>
			<geometry>
				<cylinder length="0.10556557423188928" radius="0.7402568284366033"/>
			</geometry>
		</collision>
		<inertial>
			<mass value="0.18173435397614995"/>
			<inertia ixx="0.03" ixy="0" ixz="0" iyx="0" iyy="0.03" izz="0.03"/>
		</inertial>
	</link>
	<link name="54">
		<visual>
			<geometry>
				<cylinder length="0.8423657099853261" radius="0.1347932314003546"/>
			</geometry>
		</visual>
		<collision>
			<geometry>
				<cylinder length="0.8423657099853261" radius="0.1347932314003546"/>
			</geometry>
		</collision>
		<inertial>
			<mass value="0.048082464769551164"/>
			<inertia ixx="0.03" ixy="0" ixz="0" iyx="0" iyy="0.03" izz="0.03"/>
		</inertial>
	</link>
	<link name="55">
		<visual>
			<geometry>
				<cylinder length="0.8423657099853261" radius="0.1347932314003546"/>
			</geometry>
		</visual>
		<collision>
			<geometry>
				<cylinder length="0.8423657099853261" radius="0.1347932314003546"/>
			</geometry>
		</collision>
		<inertial>
			<mass value="0.048082464769551164"/>
			<inertia ixx="0.03" ixy="0" ixz="0" iyx="0" iyy="0.03" izz="0.03"/>
		</inertial>
	</link>
	<link name="56">
		<visual>
			<geometry>
				<cylinder length="0.8423657099853261" radius="0.1347932314003546"/>
			</geometry>
		</visual>
		<collision>
			<geometry>
				<cylinder length="0.8423657099853261" radius="0.1347932314003546"/>
			</geometry>
		</collision>
		<inertial>
			<mass value="0.048082464769551164"/>
			<inertia ixx="0.03" ixy="0" ixz="0" iyx="0" iyy="0.03" izz="0.03"/>
		</inertial>
	</link>
	<link name="97">
		<visual>
			<geometry>
				<cylinder length="1.8153111004403502" radius="0.7784801617663459"/>
			</geometry>
		</visual>
		<collision>
			<geometry>
				<cylinder length="1.8153111004403502" radius="0.7784801617663459"/>
			</geometry>
		</collision>
		<inertial>
			<mass value="3.4561774763639304"/>
			<inertia ixx="0.03" ixy="0" ixz="0" iyx="0" iyy="0.03" izz="0.03"/>
		</inertial>
	</link>
	<link name="98">
		<visual>
			<geometry>
				<cylinder length="1.8153111004403502" radius="0.7784801617663459"/>
			</geometry>
		</visual>
		<collision>
			<geometry>
				<cylinder length="1.8153111004403502" radius="0.7784801617663459"/>
			</geometry>
		</collision>
		<inertial>
			<mass value="3.4561774763639304"/>
			<inertia ixx="0.03" ixy="0" ixz="0" iyx="0" iyy="0.03" izz="0.03"/>
		</inertial>
	</link>
	<link name="99">
		<visual>
			<geometry>
				<cylinder length="1.8153111004403502" radius="0.7784801617663459"/>
			</geometry>
		</visual>
		<collision>
			<geometry>
				<cylinder length="1.8153111004403502" radius="0.7784801617663459"/>
			</geometry>
		</collision>
		<inertial>
			<mass value="3.4561774763639304"/>
			<inertia ixx="0.03" ixy="0" ixz="0" iyx="0" iyy="0.03" izz="0.03"/>
		</inertial>
	</link>
	<link name="310">
		<visual>
			<geometry>
				<cylinder length="0.10556557423188928" radius="0.7402568284366033"/>
			</geometry>
		</visual>
		<collision>
			<geometry>
				<cylinder length="0.10556557423188928" radius="0.7402568284366033"/>
			</geometry>
		</collision>
		<inertial>
			<mass value="0.18173435397614995"/>
			<inertia ixx="0.03" ixy="0" ixz="0" iyx="0" iyy="0.03" izz="0.03"/>
		</inertial>
	</link>
	<link name="511">
		<visual>
			<geometry>
				<cylinder length="0.8423657099853261" radius="0.1347932314003546"/>
			</geometry>
		</visual>
		<collision>
			<geometry>
				<cylinder length="0.8423657099853261" radius="0.1347932314003546"/>
			</geometry>
		</collision>
		<inertial>
			<mass value="0.048082464769551164"/>
			<inertia ixx="0.03" ixy="0" ixz="0" iyx="0" iyy="0.03" izz="0.03"/>
		</inertial>
	</link>
	<link name="512">
		<visual>
			<geometry>
				<cylinder length="0.8423657099853261" radius="0.1347932314003546"/>
			</geometry>
		</visual>
		<collision>
			<geometry>
				<cylinder length="0.8423657099853261" radius="0.1347932314003546"/>
			</geometry>
		</collision>
		<inertial>
			<mass value="0.048082464769551164"/>
			<inertia ixx="0.03" ixy="0" ixz="0" iyx="0" iyy="0.03" izz="0.03"/>
		</inertial>
	</link>
	<link name="513">
		<visual>
			<geometry>
				<cylinder length="0.8423657099853261" radius="0.1347932314003546"/>
			</geometry>
		</visual>
		<collision>
			<geometry>
				<cylinder length="0.8423657099853261" radius="0.1347932314003546"/>
			</geometry>
		</collision>
		<inertial>
			<mass value="0.048082464769551164"/>
			<inertia ixx="0.03" ixy="0" ixz="0" iyx="0" iyy="0.03" izz="0.03"/>
		</inertial>
	</link>
	<link name="914">
		<visual>
			<geometry>
				<cylinder length="1.8153111004403502" radius="0.7784801617663459"/>
			</geometry>
		</visual>
		<collision>
			<geometry>
				<cylinder length="1.8153111004403502" radius="0.7784801617663459"/>
			</geometry>
		</collision>
		<inertial>
			<mass value="3.4561774763639304"/>
			<inertia ixx="0.03" ixy="0" ixz="0" iyx="0" iyy="0.03" izz="0.03"/>
		</inertial>
	</link>
	<link name="915">
		<visual>
			<geometry>
				<cylinder length="1.8153111004403502" radius="0.7784801617663459"/>
			</geometry>
		</visual>
		<collision>
			<geometry>
				<cylinder length="1.8153111004403502" radius="0.7784801617663459"/>
			</geometry>
		</collision>
		<inertial>
			<mass value="3.4561774763639304"/>
			<inertia ixx="0.03" ixy="0" ixz="0" iyx="0" iyy="0.03" izz="0.03"/>
		</inertial>
	</link>
	<link name="916">
		<visual>
			<geometry>
				<cylinder length="1.8153111004403502" radius="0.7784801617663459"/>
			</geometry>
		</visual>
		<collision>
			<geometry>
				<cylinder length="1.8153111004403502" radius="0.7784801617663459"/>
			</geometry>
		</collision>
		<inertial>
			<mass value="3.4561774763639304"/>
			<inertia ixx="0.03" ixy="0" ixz="0" iyx="0" iyy="0.03" izz="0.03"/>
		</inertial>
	</link>
	<link name="317">
		<visual>
			<geometry>
				<cylinder length="0.10556557423188928" radius="0.7402568284366033"/>
			</geometry>
		</visual>
		<collision>
			<geometry>
				<cylinder length="0.10556557423188928" radius="0.7402568284366033"/>
			</geometry>
		</collision>
		<inertial>
			<mass value="0.18173435397614995"/>
			<inertia ixx="0.03" ixy="0" ixz="0" iyx="0" iyy="0.03" izz="0.03"/>
		</inertial>
	</link>
	<link name="518">
		<visual>
			<geometry>
				<cylinder length="0.8423657099853261" radius="0.1347932314003546"/>
			</geometry>
		</visual>
		<collision>
			<geometry>
				<cylinder length="0.8423657099853261" radius="0.1347932314003546"/>
			</geometry>
		</collision>
		<inertial>
			<mass value="0.048082464769551164"/>
			<inertia ixx="0.03" ixy="0" ixz="0" iyx="0" iyy="0.03" izz="0.03"/>
		</inertial>
	</link>
	<link name="519">
		<visual>
			<geometry>
				<cylinder length="0.8423657099853261" radius="0.1347932314003546"/>
			</geometry>
		</visual>
		<collision>
			<geometry>
				<cylinder length="0.8423657099853261" radius="0.1347932314003546"/>
			</geometry>
		</collision>
		<inertial>
			<mass value="0.048082464769551164"/>
			<inertia ixx="0.03" ixy="0" ixz="0" iyx="0" iyy="0.03" izz="0.03"/>
		</inertial>
	</link>
	<link name="520">
		<visual>
			<geometry>
				<cylinder length="0.8423657099853261" radius="0.1347932314003546"/>
			</geometry>
		</visual>
		<collision>
			<geometry>
				<cylinder length="0.8423657099853261" radius="0.1347932314003546"/>
			</geometry>
		</collision>
		<inertial>
			<mass value="0.048082464769551164"/>
			<inertia ixx="0.03" ixy="0" ixz="0" iyx="0" iyy="0.03" izz="0.03"/>
		</inertial>
	</link>
	<link name="921">
		<visual>
			<geometry>
				<cylinder length="1.8153111004403502" radius="0.7784801617663459"/>
			</geometry>
		</visual>
		<collision>
			<geometry>
				<cylinder length="1.8153111004403502" radius="0.7784801617663459"/>
			</geometry>
		</collision>
		<inertial>
			<mass value="3.4561774763639304"/>
			<inertia ixx="0.03" ixy="0" ixz="0" iyx="0" iyy="0.03" izz="0.03"/>
		</inertial>
	</link>
	<link name="922">
		<visual>
			<geometry>
				<cylinder length="1.8153111004403502" radius="0.7784801617663459"/>
			</geometry>
		</visual>
		<collision>
			<geometry>
				<cylinder length="1.8153111004403502" radius="0.7784801617663459"/>
			</geometry>
		</collision>
		<inertial>
			<mass value="3.4561774763639304"/>
			<inertia ixx="0.03" ixy="0" ixz="0" iyx="0" iyy="0.03" izz="0.03"/>
		</inertial>
	</link>
	<link name="923">
		<visual>
			<geometry>
				<cylinder length="1.8153111004403502" radius="0.7784801617663459"/>
			</geometry>
		</visual>
		<collision>
			<geometry>
				<cylinder length="1.8153111004403502" radius="0.7784801617663459"/>
			</geometry>
		</collision>
		<inertial>
			<mass value="3.4561774763639304"/>
			<inertia ixx="0.03" ixy="0" ixz="0" iyx="0" iyy="0.03" izz="0.03"/>
		</inertial>
	</link>
	<link name="424">
		<visual>
			<geometry>
				<cylinder length="1.6751421822334385" radius="0.4346209040991994"/>
			</geometry>
		</visual>
		<collision>
			<geometry>
				<cylinder length="1.6751421822334385" radius="0.4346209040991994"/>
			</geometry>
		</collision>
		<inertial>
			<mass value="0.9940832802040312"/>
			<inertia ixx="0.03" ixy="0" ixz="0" iyx="0" iyy="0.03" izz="0.03"/>
		</inertial>
	</link>
	<link name="625">
		<visual>
			<geometry>
				<cylinder length="1.7794247443546032" radius="0.8716464380780272"/>
			</geometry>
		</visual>
		<collision>
			<geometry>
				<cylinder length="1.7794247443546032" radius="0.8716464380780272"/>
			</geometry>
		</collision>
		<inertial>
			<mass value="4.247273400215599"/>
			<inertia ixx="0.03" ixy="0" ixz="0" iyx="0" iyy="0.03" izz="0.03"/>
		</inertial>
	</link>
	<link name="826">
		<visual>
			<geometry>
				<cylinder length="0.30780985055894794" radius="0.17994911704766692"/>
			</geometry>
		</visual>
		<collision>
			<geometry>
				<cylinder length="0.30780985055894794" radius="0.17994911704766692"/>
			</geometry>
		</collision>
		<inertial>
			<mass value="0.031313515442226034"/>
			<inertia ixx="0.03" ixy="0" ixz="0" iyx="0" iyy="0.03" izz="0.03"/>
		</inertial>
	</link>
	<link name="1027">
		<visual>
			<geometry>
				<cylinder length="0.6187978465166291" radius="0.8972173738882653"/>
			</geometry>
		</visual>
		<collision>
			<geometry>
				<cylinder length="0.6187978465166291" radius="0.8972173738882653"/>
			</geometry>
		</collision>
		<inertial>
			<mass value="1.5649267558893547"/>
			<inertia ixx="0.03" ixy="0" ixz="0" iyx="0" iyy="0.03" izz="0.03"/>
		</inertial>
	</link>
	<link name="1028">
		<visual>
			<geometry>
				<cylinder length="0.6187978465166291" radius="0.8972173738882653"/>
			</geometry>
		</visual>
		<collision>
			<geometry>
				<cylinder length="0.6187978465166291" radius="0.8972173738882653"/>
			</geometry>
		</collision>
		<inertial>
			<mass value="1.5649267558893547"/>
			<inertia ixx="0.03" ixy="0" ixz="0" iyx="0" iyy="0.03" izz="0.03"/>
		</inertial>
	</link>
	<link name="429">
		<visual>
			<geometry>
				<cylinder length="1.6751421822334385" radius="0.4346209040991994"/>
			</geometry>
		</visual>
		<collision>
			<geometry>
				<cylinder length="1.6751421822334385" radius="0.4346209040991994"/>
			</geometry>
		</collision>
		<inertial>
			<mass value="0.9940832802040312"/>
			<inertia ixx="0.03" ixy="0" ixz="0" iyx="0" iyy="0.03" izz="0.03"/>
		</inertial>
	</link>
	<link name="630">
		<visual>
			<geometry>
				<cylinder length="1.7794247443546032" radius="0.8716464380780272"/>
			</geometry>
		</visual>
		<collision>
			<geometry>
				<cylinder length="1.7794247443546032" radius="0.8716464380780272"/>
			</geometry>
		</collision>
		<inertial>
			<mass value="4.247273400215599"/>
			<inertia ixx="0.03" ixy="0" ixz="0" iyx="0" iyy="0.03" izz="0.03"/>
		</inertial>
	</link>
	<link name="831">
		<visual>
			<geometry>
				<cylinder length="0.30780985055894794" radius="0.17994911704766692"/>
			</geometry>
		</visual>
		<collision>
			<geometry>
				<cylinder length="0.30780985055894794" radius="0.17994911704766692"/>
			</geometry>
		</collision>
		<inertial>
			<mass value="0.031313515442226034"/>
			<inertia ixx="0.03" ixy="0" ixz="0" iyx="0" iyy="0.03" izz="0.03"/>
		</inertial>
	</link>
	<link name="1032">
		<visual>
			<geometry>
				<cylinder length="0.6187978465166291" radius="0.8972173738882653"/>
			</geometry>
		</visual>
		<collision>
			<geometry>
				<cylinder length="0.6187978465166291" radius="0.8972173738882653"/>
			</geometry>
		</collision>
		<inertial>
			<mass value="1.5649267558893547"/>
			<inertia ixx="0.03" ixy="0" ixz="0" iyx="0" iyy="0.03" izz="0.03"/>
		</inertial>
	</link>
	<link name="1033">
		<visual>
			<geometry>
				<cylinder length="0.6187978465166291" radius="0.8972173738882653"/>
			</geometry>
		</visual>
		<collision>
			<geometry>
				<cylinder length="0.6187978465166291" radius="0.8972173738882653"/>
			</geometry>
		</collision>
		<inertial>
			<mass value="1.5649267558893547"/>
			<inertia ixx="0.03" ixy="0" ixz="0" iyx="0" iyy="0.03" izz="0.03"/>
		</inertial>
	</link>
	<link name="434">
		<visual>
			<geometry>
				<cylinder length="1.6751421822334385" radius="0.4346209040991994"/>
			</geometry>
		</visual>
		<collision>
			<geometry>
				<cylinder length="1.6751421822334385" radius="0.4346209040991994"/>
			</geometry>
		</collision>
		<inertial>
			<mass value="0.9940832802040312"/>
			<inertia ixx="0.03" ixy="0" ixz="0" iyx="0" iyy="0.03" izz="0.03"/>
		</inertial>
	</link>
	<link name="635">
		<visual>
			<geometry>
				<cylinder length="1.7794247443546032" radius="0.8716464380780272"/>
			</geometry>
		</visual>
		<collision>
			<geometry>
				<cylinder length="1.7794247443546032" radius="0.8716464380780272"/>
			</geometry>
		</collision>
		<inertial>
			<mass value="4.247273400215599"/>
			<inertia ixx="0.03" ixy="0" ixz="0" iyx="0" iyy="0.03" izz="0.03"/>
		</inertial>
	</link>
	<link name="836">
		<visual>
			<geometry>
				<cylinder length="0.30780985055894794" radius="0.17994911704766692"/>
			</geometry>
		</visual>
		<collision>
			<geometry>
				<cylinder length="0.30780985055894794" radius="0.17994911704766692"/>
			</geometry>
		</collision>
		<inertial>
			<mass value="0.031313515442226034"/>
			<inertia ixx="0.03" ixy="0" ixz="0" iyx="0" iyy="0.03" izz="0.03"/>
		</inertial>
	</link>
	<link name="1037">
		<visual>
			<geometry>
				<cylinder length="0.6187978465166291" radius="0.8972173738882653"/>
			</geometry>
		</visual>
		<collision>
			<geometry>
				<cylinder length="0.6187978465166291" radius="0.8972173738882653"/>
			</geometry>
		</collision>
		<inertial>
			<mass value="1.5649267558893547"/>
			<inertia ixx="0.03" ixy="0" ixz="0" iyx="0" iyy="0.03" izz="0.03"/>
		</inertial>
	</link>
	<link name="1038">
		<visual>
			<geometry>
				<cylinder length="0.6187978465166291" radius="0.8972173738882653"/>
			</geometry>
		</visual>
		<collision>
			<geometry>
				<cylinder length="0.6187978465166291" radius="0.8972173738882653"/>
			</geometry>
		</collision>
		<inertial>
			<mass value="1.5649267558893547"/>
			<inertia ixx="0.03" ixy="0" ixz="0" iyx="0" iyy="0.03" izz="0.03"/>
		</inertial>
	</link>
	<link name="739">
		<visual>
			<geometry>
				<cylinder length="1.109350724187484" radius="0.5610200019038187"/>
			</geometry>
		</visual>
		<collision>
			<geometry>
				<cylinder length="1.109350724187484" radius="0.5610200019038187"/>
			</geometry>
		</collision>
		<inertial>
			<mass value="1.0969212112662685"/>
			<inertia ixx="0.03" ixy="0" ixz="0" iyx="0" iyy="0.03" izz="0.03"/>
		</inertial>
	</link>
	<link name="740">
		<visual>
			<geometry>
				<cylinder length="1.109350724187484" radius="0.5610200019038187"/>
			</geometry>
		</visual>
		<collision>
			<geometry>
				<cylinder length="1.109350724187484" radius="0.5610200019038187"/>
			</geometry>
		</collision>
		<inertial>
			<mass value="1.0969212112662685"/>
			<inertia ixx="0.03" ixy="0" ixz="0" iyx="0" iyy="0.03" izz="0.03"/>
		</inertial>
	</link>
	<link name="741">
		<visual>
			<geometry>
				<cylinder length="1.109350724187484" radius="0.5610200019038187"/>
			</geometry>
		</visual>
		<collision>
			<geometry>
				<cylinder length="1.109350724187484" radius="0.5610200019038187"/>
			</geometry>
		</collision>
		<inertial>
			<mass value="1.0969212112662685"/>
			<inertia ixx="0.03" ixy="0" ixz="0" iyx="0" iyy="0.03" izz="0.03"/>
		</inertial>
	</link>
	<link name="242">
		<visual>
			<geometry>
				<cylinder length="0.8087551493112171" radius="0.6853008201344472"/>
			</geometry>
		</visual>
		<collision>
			<geometry>
				<cylinder length="0.8087551493112171" radius="0.6853008201344472"/>
			</geometry>
		</collision>
		<inertial>
			<mass value="1.1932444818053722"/>
			<inertia ixx="0.03" ixy="0" ixz="0" iyx="0" iyy="0.03" izz="0.03"/>
		</inertial>
	</link>
	<link name="343">
		<visual>
			<geometry>
				<cylinder length="0.10556557423188928" radius="0.7402568284366033"/>
			</geometry>
		</visual>
		<collision>
			<geometry>
				<cylinder length="0.10556557423188928" radius="0.7402568284366033"/>
			</geometry>
		</collision>
		<inertial>
			<mass value="0.18173435397614995"/>
			<inertia ixx="0.03" ixy="0" ixz="0" iyx="0" iyy="0.03" izz="0.03"/>
		</inertial>
	</link>
	<link name="544">
		<visual>
			<geometry>
				<cylinder length="0.8423657099853261" radius="0.1347932314003546"/>
			</geometry>
		</visual>
		<collision>
			<geometry>
				<cylinder length="0.8423657099853261" radius="0.1347932314003546"/>
			</geometry>
		</collision>
		<inertial>
			<mass value="0.048082464769551164"/>
			<inertia ixx="0.03" ixy="0" ixz="0" iyx="0" iyy="0.03" izz="0.03"/>
		</inertial>
	</link>
	<link name="545">
		<visual>
			<geometry>
				<cylinder length="0.8423657099853261" radius="0.1347932314003546"/>
			</geometry>
		</visual>
		<collision>
			<geometry>
				<cylinder length="0.8423657099853261" radius="0.1347932314003546"/>
			</geometry>
		</collision>
		<inertial>
			<mass value="0.048082464769551164"/>
			<inertia ixx="0.03" ixy="0" ixz="0" iyx="0" iyy="0.03" izz="0.03"/>
		</inertial>
	</link>
	<link name="546">
		<visual>
			<geometry>
				<cylinder length="0.8423657099853261" radius="0.1347932314003546"/>
			</geometry>
		</visual>
		<collision>
			<geometry>
				<cylinder length="0.8423657099853261" radius="0.1347932314003546"/>
			</geometry>
		</collision>
		<inertial>
			<mass value="0.048082464769551164"/>
			<inertia ixx="0.03" ixy="0" ixz="0" iyx="0" iyy="0.03" izz="0.03"/>
		</inertial>
	</link>
	<link name="947">
		<visual>
			<geometry>
				<cylinder length="1.8153111004403502" radius="0.7784801617663459"/>
			</geometry>
		</visual>
		<collision>
			<geometry>
				<cylinder length="1.8153111004403502" radius="0.7784801617663459"/>
			</geometry>
		</collision>
		<inertial>
			<mass value="3.4561774763639304"/>
			<inertia ixx="0.03" ixy="0" ixz="0" iyx="0" iyy="0.03" izz="0.03"/>
		</inertial>
	</link>
	<link name="948">
		<visual>
			<geometry>
				<cylinder length="1.8153111004403502" radius="0.7784801617663459"/>
			</geometry>
		</visual>
		<collision>
			<geometry>
				<cylinder length="1.8153111004403502" radius="0.7784801617663459"/>
			</geometry>
		</collision>
		<inertial>
			<mass value="3.4561774763639304"/>
			<inertia ixx="0.03" ixy="0" ixz="0" iyx="0" iyy="0.03" izz="0.03"/>
		</inertial>
	</link>
	<link name="949">
		<visual>
			<geometry>
				<cylinder length="1.8153111004403502" radius="0.7784801617663459"/>
			</geometry>
		</visual>
		<collision>
			<geometry>
				<cylinder length="1.8153111004403502" radius="0.7784801617663459"/>
			</geometry>
		</collision>
		<inertial>
			<mass value="3.4561774763639304"/>
			<inertia ixx="0.03" ixy="0" ixz="0" iyx="0" iyy="0.03" izz="0.03"/>
		</inertial>
	</link>
	<link name="350">
		<visual>
			<geometry>
				<cylinder length="0.10556557423188928" radius="0.7402568284366033"/>
			</geometry>
		</visual>
		<collision>
			<geometry>
				<cylinder length="0.10556557423188928" radius="0.7402568284366033"/>
			</geometry>
		</collision>
		<inertial>
			<mass value="0.18173435397614995"/>
			<inertia ixx="0.03" ixy="0" ixz="0" iyx="0" iyy="0.03" izz="0.03"/>
		</inertial>
	</link>
	<link name="551">
		<visual>
			<geometry>
				<cylinder length="0.8423657099853261" radius="0.1347932314003546"/>
			</geometry>
		</visual>
		<collision>
			<geometry>
				<cylinder length="0.8423657099853261" radius="0.1347932314003546"/>
			</geometry>
		</collision>
		<inertial>
			<mass value="0.048082464769551164"/>
			<inertia ixx="0.03" ixy="0" ixz="0" iyx="0" iyy="0.03" izz="0.03"/>
		</inertial>
	</link>
	<link name="552">
		<visual>
			<geometry>
				<cylinder length="0.8423657099853261" radius="0.1347932314003546"/>
			</geometry>
		</visual>
		<collision>
			<geometry>
				<cylinder length="0.8423657099853261" radius="0.1347932314003546"/>
			</geometry>
		</collision>
		<inertial>
			<mass value="0.048082464769551164"/>
			<inertia ixx="0.03" ixy="0" ixz="0" iyx="0" iyy="0.03" izz="0.03"/>
		</inertial>
	</link>
	<link name="553">
		<visual>
			<geometry>
				<cylinder length="0.8423657099853261" radius="0.1347932314003546"/>
			</geometry>
		</visual>
		<collision>
			<geometry>
				<cylinder length="0.8423657099853261" radius="0.1347932314003546"/>
			</geometry>
		</collision>
		<inertial>
			<mass value="0.048082464769551164"/>
			<inertia ixx="0.03" ixy="0" ixz="0" iyx="0" iyy="0.03" izz="0.03"/>
		</inertial>
	</link>
	<link name="954">
		<visual>
			<geometry>
				<cylinder length="1.8153111004403502" radius="0.7784801617663459"/>
			</geometry>
		</visual>
		<collision>
			<geometry>
				<cylinder length="1.8153111004403502" radius="0.7784801617663459"/>
			</geometry>
		</collision>
		<inertial>
			<mass value="3.4561774763639304"/>
			<inertia ixx="0.03" ixy="0" ixz="0" iyx="0" iyy="0.03" izz="0.03"/>
		</inertial>
	</link>
	<link name="955">
		<visual>
			<geometry>
				<cylinder length="1.8153111004403502" radius="0.7784801617663459"/>
			</geometry>
		</visual>
		<collision>
			<geometry>
				<cylinder length="1.8153111004403502" radius="0.7784801617663459"/>
			</geometry>
		</collision>
		<inertial>
			<mass value="3.4561774763639304"/>
			<inertia ixx="0.03" ixy="0" ixz="0" iyx="0" iyy="0.03" izz="0.03"/>
		</inertial>
	</link>
	<link name="956">
		<visual>
			<geometry>
				<cylinder length="1.8153111004403502" radius="0.7784801617663459"/>
			</geometry>
		</visual>
		<collision>
			<geometry>
				<cylinder length="1.8153111004403502" radius="0.7784801617663459"/>
			</geometry>
		</collision>
		<inertial>
			<mass value="3.4561774763639304"/>
			<inertia ixx="0.03" ixy="0" ixz="0" iyx="0" iyy="0.03" izz="0.03"/>
		</inertial>
	</link>
	<link name="357">
		<visual>
			<geometry>
				<cylinder length="0.10556557423188928" radius="0.7402568284366033"/>
			</geometry>
		</visual>
		<collision>
			<geometry>
				<cylinder length="0.10556557423188928" radius="0.7402568284366033"/>
			</geometry>
		</collision>
		<inertial>
			<mass value="0.18173435397614995"/>
			<inertia ixx="0.03" ixy="0" ixz="0" iyx="0" iyy="0.03" izz="0.03"/>
		</inertial>
	</link>
	<link name="558">
		<visual>
			<geometry>
				<cylinder length="0.8423657099853261" radius="0.1347932314003546"/>
			</geometry>
		</visual>
		<collision>
			<geometry>
				<cylinder length="0.8423657099853261" radius="0.1347932314003546"/>
			</geometry>
		</collision>
		<inertial>
			<mass value="0.048082464769551164"/>
			<inertia ixx="0.03" ixy="0" ixz="0" iyx="0" iyy="0.03" izz="0.03"/>
		</inertial>
	</link>
	<link name="559">
		<visual>
			<geometry>
				<cylinder length="0.8423657099853261" radius="0.1347932314003546"/>
			</geometry>
		</visual>
		<collision>
			<geometry>
				<cylinder length="0.8423657099853261" radius="0.1347932314003546"/>
			</geometry>
		</collision>
		<inertial>
			<mass value="0.048082464769551164"/>
			<inertia ixx="0.03" ixy="0" ixz="0" iyx="0" iyy="0.03" izz="0.03"/>
		</inertial>
	</link>
	<link name="560">
		<visual>
			<geometry>
				<cylinder length="0.8423657099853261" radius="0.1347932314003546"/>
			</geometry>
		</visual>
		<collision>
			<geometry>
				<cylinder length="0.8423657099853261" radius="0.1347932314003546"/>
			</geometry>
		</collision>
		<inertial>
			<mass value="0.048082464769551164"/>
			<inertia ixx="0.03" ixy="0" ixz="0" iyx="0" iyy="0.03" izz="0.03"/>
		</inertial>
	</link>
	<link name="961">
		<visual>
			<geometry>
				<cylinder length="1.8153111004403502" radius="0.7784801617663459"/>
			</geometry>
		</visual>
		<collision>
			<geometry>
				<cylinder length="1.8153111004403502" radius="0.7784801617663459"/>
			</geometry>
		</collision>
		<inertial>
			<mass value="3.4561774763639304"/>
			<inertia ixx="0.03" ixy="0" ixz="0" iyx="0" iyy="0.03" izz="0.03"/>
		</inertial>
	</link>
	<link name="962">
		<visual>
			<geometry>
				<cylinder length="1.8153111004403502" radius="0.7784801617663459"/>
			</geometry>
		</visual>
		<collision>
			<geometry>
				<cylinder length="1.8153111004403502" radius="0.7784801617663459"/>
			</geometry>
		</collision>
		<inertial>
			<mass value="3.4561774763639304"/>
			<inertia ixx="0.03" ixy="0" ixz="0" iyx="0" iyy="0.03" izz="0.03"/>
		</inertial>
	</link>
	<link name="963">
		<visual>
			<geometry>
				<cylinder length="1.8153111004403502" radius="0.7784801617663459"/>
			</geometry>
		</visual>
		<collision>
			<geometry>
				<cylinder length="1.8153111004403502" radius="0.7784801617663459"/>
			</geometry>
		</collision>
		<inertial>
			<mass value="3.4561774763639304"/>
			<inertia ixx="0.03" ixy="0" ixz="0" iyx="0" iyy="0.03" izz="0.03"/>
		</inertial>
	</link>
	<link name="464">
		<visual>
			<geometry>
				<cylinder length="1.6751421822334385" radius="0.4346209040991994"/>
			</geometry>
		</visual>
		<collision>
			<geometry>
				<cylinder length="1.6751421822334385" radius="0.4346209040991994"/>
			</geometry>
		</collision>
		<inertial>
			<mass value="0.9940832802040312"/>
			<inertia ixx="0.03" ixy="0" ixz="0" iyx="0" iyy="0.03" izz="0.03"/>
		</inertial>
	</link>
	<link name="665">
		<visual>
			<geometry>
				<cylinder length="1.7794247443546032" radius="0.8716464380780272"/>
			</geometry>
		</visual>
		<collision>
			<geometry>
				<cylinder length="1.7794247443546032" radius="0.8716464380780272"/>
			</geometry>
		</collision>
		<inertial>
			<mass value="4.247273400215599"/>
			<inertia ixx="0.03" ixy="0" ixz="0" iyx="0" iyy="0.03" izz="0.03"/>
		</inertial>
	</link>
	<link name="866">
		<visual>
			<geometry>
				<cylinder length="0.30780985055894794" radius="0.17994911704766692"/>
			</geometry>
		</visual>
		<collision>
			<geometry>
				<cylinder length="0.30780985055894794" radius="0.17994911704766692"/>
			</geometry>
		</collision>
		<inertial>
			<mass value="0.031313515442226034"/>
			<inertia ixx="0.03" ixy="0" ixz="0" iyx="0" iyy="0.03" izz="0.03"/>
		</inertial>
	</link>
	<link name="1067">
		<visual>
			<geometry>
				<cylinder length="0.6187978465166291" radius="0.8972173738882653"/>
			</geometry>
		</visual>
		<collision>
			<geometry>
				<cylinder length="0.6187978465166291" radius="0.8972173738882653"/>
			</geometry>
		</collision>
		<inertial>
			<mass value="1.5649267558893547"/>
			<inertia ixx="0.03" ixy="0" ixz="0" iyx="0" iyy="0.03" izz="0.03"/>
		</inertial>
	</link>
	<link name="1068">
		<visual>
			<geometry>
				<cylinder length="0.6187978465166291" radius="0.8972173738882653"/>
			</geometry>
		</visual>
		<collision>
			<geometry>
				<cylinder length="0.6187978465166291" radius="0.8972173738882653"/>
			</geometry>
		</collision>
		<inertial>
			<mass value="1.5649267558893547"/>
			<inertia ixx="0.03" ixy="0" ixz="0" iyx="0" iyy="0.03" izz="0.03"/>
		</inertial>
	</link>
	<link name="469">
		<visual>
			<geometry>
				<cylinder length="1.6751421822334385" radius="0.4346209040991994"/>
			</geometry>
		</visual>
		<collision>
			<geometry>
				<cylinder length="1.6751421822334385" radius="0.4346209040991994"/>
			</geometry>
		</collision>
		<inertial>
			<mass value="0.9940832802040312"/>
			<inertia ixx="0.03" ixy="0" ixz="0" iyx="0" iyy="0.03" izz="0.03"/>
		</inertial>
	</link>
	<link name="670">
		<visual>
			<geometry>
				<cylinder length="1.7794247443546032" radius="0.8716464380780272"/>
			</geometry>
		</visual>
		<collision>
			<geometry>
				<cylinder length="1.7794247443546032" radius="0.8716464380780272"/>
			</geometry>
		</collision>
		<inertial>
			<mass value="4.247273400215599"/>
			<inertia ixx="0.03" ixy="0" ixz="0" iyx="0" iyy="0.03" izz="0.03"/>
		</inertial>
	</link>
	<link name="871">
		<visual>
			<geometry>
				<cylinder length="0.30780985055894794" radius="0.17994911704766692"/>
			</geometry>
		</visual>
		<collision>
			<geometry>
				<cylinder length="0.30780985055894794" radius="0.17994911704766692"/>
			</geometry>
		</collision>
		<inertial>
			<mass value="0.031313515442226034"/>
			<inertia ixx="0.03" ixy="0" ixz="0" iyx="0" iyy="0.03" izz="0.03"/>
		</inertial>
	</link>
	<link name="1072">
		<visual>
			<geometry>
				<cylinder length="0.6187978465166291" radius="0.8972173738882653"/>
			</geometry>
		</visual>
		<collision>
			<geometry>
				<cylinder length="0.6187978465166291" radius="0.8972173738882653"/>
			</geometry>
		</collision>
		<inertial>
			<mass value="1.5649267558893547"/>
			<inertia ixx="0.03" ixy="0" ixz="0" iyx="0" iyy="0.03" izz="0.03"/>
		</inertial>
	</link>
	<link name="1073">
		<visual>
			<geometry>
				<cylinder length="0.6187978465166291" radius="0.8972173738882653"/>
			</geometry>
		</visual>
		<collision>
			<geometry>
				<cylinder length="0.6187978465166291" radius="0.8972173738882653"/>
			</geometry>
		</collision>
		<inertial>
			<mass value="1.5649267558893547"/>
			<inertia ixx="0.03" ixy="0" ixz="0" iyx="0" iyy="0.03" izz="0.03"/>
		</inertial>
	</link>
	<link name="474">
		<visual>
			<geometry>
				<cylinder length="1.6751421822334385" radius="0.4346209040991994"/>
			</geometry>
		</visual>
		<collision>
			<geometry>
				<cylinder length="1.6751421822334385" radius="0.4346209040991994"/>
			</geometry>
		</collision>
		<inertial>
			<mass value="0.9940832802040312"/>
			<inertia ixx="0.03" ixy="0" ixz="0" iyx="0" iyy="0.03" izz="0.03"/>
		</inertial>
	</link>
	<link name="675">
		<visual>
			<geometry>
				<cylinder length="1.7794247443546032" radius="0.8716464380780272"/>
			</geometry>
		</visual>
		<collision>
			<geometry>
				<cylinder length="1.7794247443546032" radius="0.8716464380780272"/>
			</geometry>
		</collision>
		<inertial>
			<mass value="4.247273400215599"/>
			<inertia ixx="0.03" ixy="0" ixz="0" iyx="0" iyy="0.03" izz="0.03"/>
		</inertial>
	</link>
	<link name="876">
		<visual>
			<geometry>
				<cylinder length="0.30780985055894794" radius="0.17994911704766692"/>
			</geometry>
		</visual>
		<collision>
			<geometry>
				<cylinder length="0.30780985055894794" radius="0.17994911704766692"/>
			</geometry>
		</collision>
		<inertial>
			<mass value="0.031313515442226034"/>
			<inertia ixx="0.03" ixy="0" ixz="0" iyx="0" iyy="0.03" izz="0.03"/>
		</inertial>
	</link>
	<link name="1077">
		<visual>
			<geometry>
				<cylinder length="0.6187978465166291" radius="0.8972173738882653"/>
			</geometry>
		</visual>
		<collision>
			<geometry>
				<cylinder length="0.6187978465166291" radius="0.8972173738882653"/>
			</geometry>
		</collision>
		<inertial>
			<mass value="1.5649267558893547"/>
			<inertia ixx="0.03" ixy="0" ixz="0" iyx="0" iyy="0.03" izz="0.03"/>
		</inertial>
	</link>
	<link name="1078">
		<visual>
			<geometry>
				<cylinder length="0.6187978465166291" radius="0.8972173738882653"/>
			</geometry>
		</visual>
		<collision>
			<geometry>
				<cylinder length="0.6187978465166291" radius="0.8972173738882653"/>
			</geometry>
		</collision>
		<inertial>
			<mass value="1.5649267558893547"/>
			<inertia ixx="0.03" ixy="0" ixz="0" iyx="0" iyy="0.03" izz="0.03"/>
		</inertial>
	</link>
	<link name="779">
		<visual>
			<geometry>
				<cylinder length="1.109350724187484" radius="0.5610200019038187"/>
			</geometry>
		</visual>
		<collision>
			<geometry>
				<cylinder length="1.109350724187484" radius="0.5610200019038187"/>
			</geometry>
		</collision>
		<inertial>
			<mass value="1.0969212112662685"/>
			<inertia ixx="0.03" ixy="0" ixz="0" iyx="0" iyy="0.03" izz="0.03"/>
		</inertial>
	</link>
	<link name="780">
		<visual>
			<geometry>
				<cylinder length="1.109350724187484" radius="0.5610200019038187"/>
			</geometry>
		</visual>
		<collision>
			<geometry>
				<cylinder length="1.109350724187484" radius="0.5610200019038187"/>
			</geometry>
		</collision>
		<inertial>
			<mass value="1.0969212112662685"/>
			<inertia ixx="0.03" ixy="0" ixz="0" iyx="0" iyy="0.03" izz="0.03"/>
		</inertial>
	</link>
	<link name="781">
		<visual>
			<geometry>
				<cylinder length="1.109350724187484" radius="0.5610200019038187"/>
			</geometry>
		</visual>
		<collision>
			<geometry>
				<cylinder length="1.109350724187484" radius="0.5610200019038187"/>
			</geometry>
		</collision>
		<inertial>
			<mass value="1.0969212112662685"/>
			<inertia ixx="0.03" ixy="0" ixz="0" iyx="0" iyy="0.03" izz="0.03"/>
		</inertial>
	</link>
	<link name="1182">
		<visual>
			<geometry>
				<cylinder length="0.7759044348561761" radius="0.4958700042037112"/>
			</geometry>
		</visual>
		<collision>
			<geometry>
				<cylinder length="0.7759044348561761" radius="0.4958700042037112"/>
			</geometry>
		</collision>
		<inertial>
			<mass value="0.5993683182275441"/>
			<inertia ixx="0.03" ixy="0" ixz="0" iyx="0" iyy="0.03" izz="0.03"/>
		</inertial>
	</link>
	<link name="1183">
		<visual>
			<geometry>
				<cylinder length="0.7759044348561761" radius="0.4958700042037112"/>
			</geometry>
		</visual>
		<collision>
			<geometry>
				<cylinder length="0.7759044348561761" radius="0.4958700042037112"/>
			</geometry>
		</collision>
		<inertial>
			<mass value="0.5993683182275441"/>
			<inertia ixx="0.03" ixy="0" ixz="0" iyx="0" iyy="0.03" izz="0.03"/>
		</inertial>
	</link>
	<link name="1184">
		<visual>
			<geometry>
				<cylinder length="0.7759044348561761" radius="0.4958700042037112"/>
			</geometry>
		</visual>
		<collision>
			<geometry>
				<cylinder length="0.7759044348561761" radius="0.4958700042037112"/>
			</geometry>
		</collision>
		<inertial>
			<mass value="0.5993683182275441"/>
			<inertia ixx="0.03" ixy="0" ixz="0" iyx="0" iyy="0.03" izz="0.03"/>
		</inertial>
	</link>
	<joint name="11_to_0" type="revolute">
		<parent link="0"/>
		<child link="11"/>
		<axis xyz="0 1 0"/>
		<limit effort="1" lower="3.1415" upper="-3.1415" velocity="1"/>
		<origin rpy="8.547940858668197 1.0149326589339163 2.9253246612287014" xyz="0.7552850851251348 0.5012198787045238 0.928150598676136"/>
	</joint>
	<joint name="22_to_11" type="revolute">
		<parent link="11"/>
		<child link="22"/>
		<axis xyz="0 1 0"/>
		<limit effort="1" lower="3.1415" upper="-3.1415" velocity="1"/>
		<origin rpy="6.521487448430773 5.997133906161363 0.716612822377441" xyz="0.9971978769505032 0.8492120586245268 0.8001964532037776"/>
	</joint>
	<joint name="33_to_22" type="revolute">
		<parent link="22"/>
		<child link="33"/>
		<axis xyz="1 0 0"/>
		<limit effort="1" lower="3.1415" upper="-3.1415" velocity="1"/>
		<origin rpy="5.102211312179498 6.0345459325986885 6.026024206404531" xyz="0.8870273714349025 0.17216772015845994 0.38723735971412654"/>
	</joint>
	<joint name="54_to_33" type="revolute">
		<parent link="33"/>
		<child link="54"/>
		<axis xyz="1 0 0"/>
		<limit effort="1" lower="3.1415" upper="-3.1415" velocity="1"/>
		<origin rpy="11.172533644537083 2.7514247752982386 4.562718481281774" xyz="0.33780177789617394 0.5704144672280524 0.7694467761941833"/>
	</joint>
	<joint name="55_to_33" type="revolute">
		<parent link="33"/>
		<child link="55"/>
		<axis xyz="1 0 0"/>
		<limit effort="1" lower="3.1415" upper="-3.1415" velocity="1"/>
		<origin rpy="16.758800466805624 2.7514247752982386 4.562718481281774" xyz="0.33780177789617394 0.5704144672280524 0.7694467761941833"/>
	</joint>
	<joint name="56_to_33" type="revolute">
		<parent link="33"/>
		<child link="56"/>
		<axis xyz="1 0 0"/>
		<limit effort="1" lower="3.1415" upper="-3.1415" velocity="1"/>
		<origin rpy="22.345067289074166 2.7514247752982386 4.562718481281774" xyz="0.33780177789617394 0.5704144672280524 0.7694467761941833"/>
	</joint>
	<joint name="97_to_33" type="revolute">
		<parent link="33"/>
		<child link="97"/>
		<axis xyz="0 1 0"/>
		<limit effort="1" lower="3.1415" upper="-3.1415" velocity="1"/>
		<origin rpy="15.043745226020524 1.1555211417897493 5.499434911688023" xyz="0.3525444036651104 0.34919317475362766 0.6813593264712398"/>
	</joint>
	<joint name="98_to_33" type="revolute">
		<parent link="33"/>
		<child link="98"/>
		<axis xyz="0 1 0"/>
		<limit effort="1" lower="3.1415" upper="-3.1415" velocity="1"/>
		<origin rpy="18.052494271224628 1.1555211417897493 5.499434911688023" xyz="0.3525444036651104 0.34919317475362766 0.6813593264712398"/>
	</joint>
	<joint name="99_to_33" type="revolute">
		<parent link="33"/>
		<child link="99"/>
		<axis xyz="0 1 0"/>
		<limit effort="1" lower="3.1415" upper="-3.1415" velocity="1"/>
		<origin rpy="21.061243316428733 1.1555211417897493 5.499434911688023" xyz="0.3525444036651104 0.34919317475362766 0.6813593264712398"/>
	</joint>
	<joint name="310_to_22" type="revolute">
		<parent link="22"/>
		<child link="310"/>
		<axis xyz="1 0 0"/>
		<limit effort="1" lower="3.1415" upper="-3.1415" velocity="1"/>
		<origin rpy="7.653316968269246 6.0345459325986885 6.026024206404531" xyz="0.8870273714349025 0.17216772015845994 0.38723735971412654"/>
	</joint>
	<joint name="511_to_310" type="revolute">
		<parent link="310"/>
		<child link="511"/>
		<axis xyz="1 0 0"/>
		<limit effort="1" lower="3.1415" upper="-3.1415" velocity="1"/>
		<origin rpy="11.172533644537083 2.7514247752982386 4.562718481281774" xyz="0.33780177789617394 0.5704144672280524 0.7694467761941833"/>
	</joint>
	<joint name="512_to_310" type="revolute">
		<parent link="310"/>
		<child link="512"/>
		<axis xyz="1 0 0"/>
		<limit effort="1" lower="3.1415" upper="-3.1415" velocity="1"/>
		<origin rpy="16.758800466805624 2.7514247752982386 4.562718481281774" xyz="0.33780177789617394 0.5704144672280524 0.7694467761941833"/>
	</joint>
	<joint name="513_to_310" type="revolute">
		<parent link="310"/>
		<child link="513"/>
		<axis xyz="1 0 0"/>
		<limit effort="1" lower="3.1415" upper="-3.1415" velocity="1"/>
		<origin rpy="22.345067289074166 2.7514247752982386 4.562718481281774" xyz="0.33780177789617394 0.5704144672280524 0.7694467761941833"/>
	</joint>
	<joint name="914_to_310" type="revolute">
		<parent link="310"/>
		<child link="914"/>
		<axis xyz="0 1 0"/>
		<limit effort="1" lower="3.1415" upper="-3.1415" velocity="1"/>
		<origin rpy="15.043745226020524 1.1555211417897493 5.499434911688023" xyz="0.3525444036651104 0.34919317475362766 0.6813593264712398"/>
	</joint>
	<joint name="915_to_310" type="revolute">
		<parent link="310"/>
		<child link="915"/>
		<axis xyz="0 1 0"/>
		<limit effort="1" lower="3.1415" upper="-3.1415" velocity="1"/>
		<origin rpy="18.052494271224628 1.1555211417897493 5.499434911688023" xyz="0.3525444036651104 0.34919317475362766 0.6813593264712398"/>
	</joint>
	<joint name="916_to_310" type="revolute">
		<parent link="310"/>
		<child link="916"/>
		<axis xyz="0 1 0"/>
		<limit effort="1" lower="3.1415" upper="-3.1415" velocity="1"/>
		<origin rpy="21.061243316428733 1.1555211417897493 5.499434911688023" xyz="0.3525444036651104 0.34919317475362766 0.6813593264712398"/>
	</joint>
	<joint name="317_to_22" type="revolute">
		<parent link="22"/>
		<child link="317"/>
		<axis xyz="1 0 0"/>
		<limit effort="1" lower="3.1415" upper="-3.1415" velocity="1"/>
		<origin rpy="10.204422624358996 6.0345459325986885 6.026024206404531" xyz="0.8870273714349025 0.17216772015845994 0.38723735971412654"/>
	</joint>
	<joint name="518_to_317" type="revolute">
		<parent link="317"/>
		<child link="518"/>
		<axis xyz="1 0 0"/>
		<limit effort="1" lower="3.1415" upper="-3.1415" velocity="1"/>
		<origin rpy="11.172533644537083 2.7514247752982386 4.562718481281774" xyz="0.33780177789617394 0.5704144672280524 0.7694467761941833"/>
	</joint>
	<joint name="519_to_317" type="revolute">
		<parent link="317"/>
		<child link="519"/>
		<axis xyz="1 0 0"/>
		<limit effort="1" lower="3.1415" upper="-3.1415" velocity="1"/>
		<origin rpy="16.758800466805624 2.7514247752982386 4.562718481281774" xyz="0.33780177789617394 0.5704144672280524 0.7694467761941833"/>
	</joint>
	<joint name="520_to_317" type="revolute">
		<parent link="317"/>
		<child link="520"/>
		<axis xyz="1 0 0"/>
		<limit effort="1" lower="3.1415" upper="-3.1415" velocity="1"/>
		<origin rpy="22.345067289074166 2.7514247752982386 4.562718481281774" xyz="0.33780177789617394 0.5704144672280524 0.7694467761941833"/>
	</joint>
	<joint name="921_to_317" type="revolute">
		<parent link="317"/>
		<child link="921"/>
		<axis xyz="0 1 0"/>
		<limit effort="1" lower="3.1415" upper="-3.1415" velocity="1"/>
		<origin rpy="15.043745226020524 1.1555211417897493 5.499434911688023" xyz="0.3525444036651104 0.34919317475362766 0.6813593264712398"/>
	</joint>
	<joint name="922_to_317" type="revolute">
		<parent link="317"/>
		<child link="922"/>
		<axis xyz="0 1 0"/>
		<limit effort="1" lower="3.1415" upper="-3.1415" velocity="1"/>
		<origin rpy="18.052494271224628 1.1555211417897493 5.499434911688023" xyz="0.3525444036651104 0.34919317475362766 0.6813593264712398"/>
	</joint>
	<joint name="923_to_317" type="revolute">
		<parent link="317"/>
		<child link="923"/>
		<axis xyz="0 1 0"/>
		<limit effort="1" lower="3.1415" upper="-3.1415" velocity="1"/>
		<origin rpy="21.061243316428733 1.1555211417897493 5.499434911688023" xyz="0.3525444036651104 0.34919317475362766 0.6813593264712398"/>
	</joint>
	<joint name="424_to_22" type="revolute">
		<parent link="22"/>
		<child link="424"/>
		<axis xyz="1 0 0"/>
		<limit effort="1" lower="3.1415" upper="-3.1415" velocity="1"/>
		<origin rpy="21.867749812897014 2.085849278768821 4.851000886523474" xyz="0.760092322278548 0.7843169416872703 0.7085483075455614"/>
	</joint>
	<joint name="625_to_424" type="revolute">
		<parent link="424"/>
		<child link="625"/>
		<axis xyz="1 0 0"/>
		<limit effort="1" lower="3.1415" upper="-3.1415" velocity="1"/>
		<origin rpy="4.327363526521489 1.676692086458292 2.8516786786967874" xyz="0.37927848649735696 0.722877595318166 0.1516858157512171"/>
	</joint>
	<joint name="826_to_424" type="revolute">
		<parent link="424"/>
		<child link="826"/>
		<axis xyz="0 0 1"/>
		<limit effort="1" lower="3.1415" upper="-3.1415" velocity="1"/>
		<origin rpy="2.557328583965563 1.1552157584870997 0.485125210236082" xyz="0.1610097667265198 0.8530449472195707 0.5349706193074901"/>
	</joint>
	<joint name="1027_to_424" type="revolute">
		<parent link="424"/>
		<child link="1027"/>
		<axis xyz="1 0 0"/>
		<limit effort="1" lower="3.1415" upper="-3.1415" velocity="1"/>
		<origin rpy="3.0642269209158326 1.7369670225369154 4.394038209488055" xyz="0.4046093564015002 0.7180039230235388 0.5483722462440448"/>
	</joint>
	<joint name="1028_to_424" type="revolute">
		<parent link="424"/>
		<child link="1028"/>
		<axis xyz="1 0 0"/>
		<limit effort="1" lower="3.1415" upper="-3.1415" velocity="1"/>
		<origin rpy="3.8302836511447906 1.7369670225369154 4.394038209488055" xyz="0.4046093564015002 0.7180039230235388 0.5483722462440448"/>
	</joint>
	<joint name="429_to_22" type="revolute">
		<parent link="22"/>
		<child link="429"/>
		<axis xyz="1 0 0"/>
		<limit effort="1" lower="3.1415" upper="-3.1415" velocity="1"/>
		<origin rpy="26.241299775476413 2.085849278768821 4.851000886523474" xyz="0.760092322278548 0.7843169416872703 0.7085483075455614"/>
	</joint>
	<joint name="630_to_429" type="revolute">
		<parent link="429"/>
		<child link="630"/>
		<axis xyz="1 0 0"/>
		<limit effort="1" lower="3.1415" upper="-3.1415" velocity="1"/>
		<origin rpy="4.327363526521489 1.676692086458292 2.8516786786967874" xyz="0.37927848649735696 0.722877595318166 0.1516858157512171"/>
	</joint>
	<joint name="831_to_429" type="revolute">
		<parent link="429"/>
		<child link="831"/>
		<axis xyz="0 0 1"/>
		<limit effort="1" lower="3.1415" upper="-3.1415" velocity="1"/>
		<origin rpy="2.557328583965563 1.1552157584870997 0.485125210236082" xyz="0.1610097667265198 0.8530449472195707 0.5349706193074901"/>
	</joint>
	<joint name="1032_to_429" type="revolute">
		<parent link="429"/>
		<child link="1032"/>
		<axis xyz="1 0 0"/>
		<limit effort="1" lower="3.1415" upper="-3.1415" velocity="1"/>
		<origin rpy="3.0642269209158326 1.7369670225369154 4.394038209488055" xyz="0.4046093564015002 0.7180039230235388 0.5483722462440448"/>
	</joint>
	<joint name="1033_to_429" type="revolute">
		<parent link="429"/>
		<child link="1033"/>
		<axis xyz="1 0 0"/>
		<limit effort="1" lower="3.1415" upper="-3.1415" velocity="1"/>
		<origin rpy="3.8302836511447906 1.7369670225369154 4.394038209488055" xyz="0.4046093564015002 0.7180039230235388 0.5483722462440448"/>
	</joint>
	<joint name="434_to_22" type="revolute">
		<parent link="22"/>
		<child link="434"/>
		<axis xyz="1 0 0"/>
		<limit effort="1" lower="3.1415" upper="-3.1415" velocity="1"/>
		<origin rpy="30.614849738055817 2.085849278768821 4.851000886523474" xyz="0.760092322278548 0.7843169416872703 0.7085483075455614"/>
	</joint>
	<joint name="635_to_434" type="revolute">
		<parent link="434"/>
		<child link="635"/>
		<axis xyz="1 0 0"/>
		<limit effort="1" lower="3.1415" upper="-3.1415" velocity="1"/>
		<origin rpy="4.327363526521489 1.676692086458292 2.8516786786967874" xyz="0.37927848649735696 0.722877595318166 0.1516858157512171"/>
	</joint>
	<joint name="836_to_434" type="revolute">
		<parent link="434"/>
		<child link="836"/>
		<axis xyz="0 0 1"/>
		<limit effort="1" lower="3.1415" upper="-3.1415" velocity="1"/>
		<origin rpy="2.557328583965563 1.1552157584870997 0.485125210236082" xyz="0.1610097667265198 0.8530449472195707 0.5349706193074901"/>
	</joint>
	<joint name="1037_to_434" type="revolute">
		<parent link="434"/>
		<child link="1037"/>
		<axis xyz="1 0 0"/>
		<limit effort="1" lower="3.1415" upper="-3.1415" velocity="1"/>
		<origin rpy="3.0642269209158326 1.7369670225369154 4.394038209488055" xyz="0.4046093564015002 0.7180039230235388 0.5483722462440448"/>
	</joint>
	<joint name="1038_to_434" type="revolute">
		<parent link="434"/>
		<child link="1038"/>
		<axis xyz="1 0 0"/>
		<limit effort="1" lower="3.1415" upper="-3.1415" velocity="1"/>
		<origin rpy="3.8302836511447906 1.7369670225369154 4.394038209488055" xyz="0.4046093564015002 0.7180039230235388 0.5483722462440448"/>
	</joint>
	<joint name="739_to_22" type="revolute">
		<parent link="22"/>
		<child link="739"/>
		<axis xyz="0 1 0"/>
		<limit effort="1" lower="3.1415" upper="-3.1415" velocity="1"/>
		<origin rpy="3.660516838142487 3.624952322726604 2.5393922749987925" xyz="0.647824095487416 0.4591485242089549 0.9171824412792904"/>
	</joint>
	<joint name="740_to_22" type="revolute">
		<parent link="22"/>
		<child link="740"/>
		<axis xyz="0 1 0"/>
		<limit effort="1" lower="3.1415" upper="-3.1415" velocity="1"/>
		<origin rpy="4.118081442910298 3.624952322726604 2.5393922749987925" xyz="0.647824095487416 0.4591485242089549 0.9171824412792904"/>
	</joint>
	<joint name="741_to_22" type="revolute">
		<parent link="22"/>
		<child link="741"/>
		<axis xyz="0 1 0"/>
		<limit effort="1" lower="3.1415" upper="-3.1415" velocity="1"/>
		<origin rpy="4.5756460476781085 3.624952322726604 2.5393922749987925" xyz="0.647824095487416 0.4591485242089549 0.9171824412792904"/>
	</joint>
	<joint name="242_to_11" type="revolute">
		<parent link="11"/>
		<child link="242"/>
		<axis xyz="0 1 0"/>
		<limit effort="1" lower="3.1415" upper="-3.1415" velocity="1"/>
		<origin rpy="9.78223117264616 5.997133906161363 0.716612822377441" xyz="0.9971978769505032 0.8492120586245268 0.8001964532037776"/>
	</joint>
	<joint name="343_to_242" type="revolute">
		<parent link="242"/>
		<child link="343"/>
		<axis xyz="1 0 0"/>
		<limit effort="1" lower="3.1415" upper="-3.1415" velocity="1"/>
		<origin rpy="5.102211312179498 6.0345459325986885 6.026024206404531" xyz="0.8870273714349025 0.17216772015845994 0.38723735971412654"/>
	</joint>
	<joint name="544_to_343" type="revolute">
		<parent link="343"/>
		<child link="544"/>
		<axis xyz="1 0 0"/>
		<limit effort="1" lower="3.1415" upper="-3.1415" velocity="1"/>
		<origin rpy="11.172533644537083 2.7514247752982386 4.562718481281774" xyz="0.33780177789617394 0.5704144672280524 0.7694467761941833"/>
	</joint>
	<joint name="545_to_343" type="revolute">
		<parent link="343"/>
		<child link="545"/>
		<axis xyz="1 0 0"/>
		<limit effort="1" lower="3.1415" upper="-3.1415" velocity="1"/>
		<origin rpy="16.758800466805624 2.7514247752982386 4.562718481281774" xyz="0.33780177789617394 0.5704144672280524 0.7694467761941833"/>
	</joint>
	<joint name="546_to_343" type="revolute">
		<parent link="343"/>
		<child link="546"/>
		<axis xyz="1 0 0"/>
		<limit effort="1" lower="3.1415" upper="-3.1415" velocity="1"/>
		<origin rpy="22.345067289074166 2.7514247752982386 4.562718481281774" xyz="0.33780177789617394 0.5704144672280524 0.7694467761941833"/>
	</joint>
	<joint name="947_to_343" type="revolute">
		<parent link="343"/>
		<child link="947"/>
		<axis xyz="0 1 0"/>
		<limit effort="1" lower="3.1415" upper="-3.1415" velocity="1"/>
		<origin rpy="15.043745226020524 1.1555211417897493 5.499434911688023" xyz="0.3525444036651104 0.34919317475362766 0.6813593264712398"/>
	</joint>
	<joint name="948_to_343" type="revolute">
		<parent link="343"/>
		<child link="948"/>
		<axis xyz="0 1 0"/>
		<limit effort="1" lower="3.1415" upper="-3.1415" velocity="1"/>
		<origin rpy="18.052494271224628 1.1555211417897493 5.499434911688023" xyz="0.3525444036651104 0.34919317475362766 0.6813593264712398"/>
	</joint>
	<joint name="949_to_343" type="revolute">
		<parent link="343"/>
		<child link="949"/>
		<axis xyz="0 1 0"/>
		<limit effort="1" lower="3.1415" upper="-3.1415" velocity="1"/>
		<origin rpy="21.061243316428733 1.1555211417897493 5.499434911688023" xyz="0.3525444036651104 0.34919317475362766 0.6813593264712398"/>
	</joint>
	<joint name="350_to_242" type="revolute">
		<parent link="242"/>
		<child link="350"/>
		<axis xyz="1 0 0"/>
		<limit effort="1" lower="3.1415" upper="-3.1415" velocity="1"/>
		<origin rpy="7.653316968269246 6.0345459325986885 6.026024206404531" xyz="0.8870273714349025 0.17216772015845994 0.38723735971412654"/>
	</joint>
	<joint name="551_to_350" type="revolute">
		<parent link="350"/>
		<child link="551"/>
		<axis xyz="1 0 0"/>
		<limit effort="1" lower="3.1415" upper="-3.1415" velocity="1"/>
		<origin rpy="11.172533644537083 2.7514247752982386 4.562718481281774" xyz="0.33780177789617394 0.5704144672280524 0.7694467761941833"/>
	</joint>
	<joint name="552_to_350" type="revolute">
		<parent link="350"/>
		<child link="552"/>
		<axis xyz="1 0 0"/>
		<limit effort="1" lower="3.1415" upper="-3.1415" velocity="1"/>
		<origin rpy="16.758800466805624 2.7514247752982386 4.562718481281774" xyz="0.33780177789617394 0.5704144672280524 0.7694467761941833"/>
	</joint>
	<joint name="553_to_350" type="revolute">
		<parent link="350"/>
		<child link="553"/>
		<axis xyz="1 0 0"/>
		<limit effort="1" lower="3.1415" upper="-3.1415" velocity="1"/>
		<origin rpy="22.345067289074166 2.7514247752982386 4.562718481281774" xyz="0.33780177789617394 0.5704144672280524 0.7694467761941833"/>
	</joint>
	<joint name="954_to_350" type="revolute">
		<parent link="350"/>
		<child link="954"/>
		<axis xyz="0 1 0"/>
		<limit effort="1" lower="3.1415" upper="-3.1415" velocity="1"/>
		<origin rpy="15.043745226020524 1.1555211417897493 5.499434911688023" xyz="0.3525444036651104 0.34919317475362766 0.6813593264712398"/>
	</joint>
	<joint name="955_to_350" type="revolute">
		<parent link="350"/>
		<child link="955"/>
		<axis xyz="0 1 0"/>
		<limit effort="1" lower="3.1415" upper="-3.1415" velocity="1"/>
		<origin rpy="18.052494271224628 1.1555211417897493 5.499434911688023" xyz="0.3525444036651104 0.34919317475362766 0.6813593264712398"/>
	</joint>
	<joint name="956_to_350" type="revolute">
		<parent link="350"/>
		<child link="956"/>
		<axis xyz="0 1 0"/>
		<limit effort="1" lower="3.1415" upper="-3.1415" velocity="1"/>
		<origin rpy="21.061243316428733 1.1555211417897493 5.499434911688023" xyz="0.3525444036651104 0.34919317475362766 0.6813593264712398"/>
	</joint>
	<joint name="357_to_242" type="revolute">
		<parent link="242"/>
		<child link="357"/>
		<axis xyz="1 0 0"/>
		<limit effort="1" lower="3.1415" upper="-3.1415" velocity="1"/>
		<origin rpy="10.204422624358996 6.0345459325986885 6.026024206404531" xyz="0.8870273714349025 0.17216772015845994 0.38723735971412654"/>
	</joint>
	<joint name="558_to_357" type="revolute">
		<parent link="357"/>
		<child link="558"/>
		<axis xyz="1 0 0"/>
		<limit effort="1" lower="3.1415" upper="-3.1415" velocity="1"/>
		<origin rpy="11.172533644537083 2.7514247752982386 4.562718481281774" xyz="0.33780177789617394 0.5704144672280524 0.7694467761941833"/>
	</joint>
	<joint name="559_to_357" type="revolute">
		<parent link="357"/>
		<child link="559"/>
		<axis xyz="1 0 0"/>
		<limit effort="1" lower="3.1415" upper="-3.1415" velocity="1"/>
		<origin rpy="16.758800466805624 2.7514247752982386 4.562718481281774" xyz="0.33780177789617394 0.5704144672280524 0.7694467761941833"/>
	</joint>
	<joint name="560_to_357" type="revolute">
		<parent link="357"/>
		<child link="560"/>
		<axis xyz="1 0 0"/>
		<limit effort="1" lower="3.1415" upper="-3.1415" velocity="1"/>
		<origin rpy="22.345067289074166 2.7514247752982386 4.562718481281774" xyz="0.33780177789617394 0.5704144672280524 0.7694467761941833"/>
	</joint>
	<joint name="961_to_357" type="revolute">
		<parent link="357"/>
		<child link="961"/>
		<axis xyz="0 1 0"/>
		<limit effort="1" lower="3.1415" upper="-3.1415" velocity="1"/>
		<origin rpy="15.043745226020524 1.1555211417897493 5.499434911688023" xyz="0.3525444036651104 0.34919317475362766 0.6813593264712398"/>
	</joint>
	<joint name="962_to_357" type="revolute">
		<parent link="357"/>
		<child link="962"/>
		<axis xyz="0 1 0"/>
		<limit effort="1" lower="3.1415" upper="-3.1415" velocity="1"/>
		<origin rpy="18.052494271224628 1.1555211417897493 5.499434911688023" xyz="0.3525444036651104 0.34919317475362766 0.6813593264712398"/>
	</joint>
	<joint name="963_to_357" type="revolute">
		<parent link="357"/>
		<child link="963"/>
		<axis xyz="0 1 0"/>
		<limit effort="1" lower="3.1415" upper="-3.1415" velocity="1"/>
		<origin rpy="21.061243316428733 1.1555211417897493 5.499434911688023" xyz="0.3525444036651104 0.34919317475362766 0.6813593264712398"/>
	</joint>
	<joint name="464_to_242" type="revolute">
		<parent link="242"/>
		<child link="464"/>
		<axis xyz="1 0 0"/>
		<limit effort="1" lower="3.1415" upper="-3.1415" velocity="1"/>
		<origin rpy="21.867749812897014 2.085849278768821 4.851000886523474" xyz="0.760092322278548 0.7843169416872703 0.7085483075455614"/>
	</joint>
	<joint name="665_to_464" type="revolute">
		<parent link="464"/>
		<child link="665"/>
		<axis xyz="1 0 0"/>
		<limit effort="1" lower="3.1415" upper="-3.1415" velocity="1"/>
		<origin rpy="4.327363526521489 1.676692086458292 2.8516786786967874" xyz="0.37927848649735696 0.722877595318166 0.1516858157512171"/>
	</joint>
	<joint name="866_to_464" type="revolute">
		<parent link="464"/>
		<child link="866"/>
		<axis xyz="0 0 1"/>
		<limit effort="1" lower="3.1415" upper="-3.1415" velocity="1"/>
		<origin rpy="2.557328583965563 1.1552157584870997 0.485125210236082" xyz="0.1610097667265198 0.8530449472195707 0.5349706193074901"/>
	</joint>
	<joint name="1067_to_464" type="revolute">
		<parent link="464"/>
		<child link="1067"/>
		<axis xyz="1 0 0"/>
		<limit effort="1" lower="3.1415" upper="-3.1415" velocity="1"/>
		<origin rpy="3.0642269209158326 1.7369670225369154 4.394038209488055" xyz="0.4046093564015002 0.7180039230235388 0.5483722462440448"/>
	</joint>
	<joint name="1068_to_464" type="revolute">
		<parent link="464"/>
		<child link="1068"/>
		<axis xyz="1 0 0"/>
		<limit effort="1" lower="3.1415" upper="-3.1415" velocity="1"/>
		<origin rpy="3.8302836511447906 1.7369670225369154 4.394038209488055" xyz="0.4046093564015002 0.7180039230235388 0.5483722462440448"/>
	</joint>
	<joint name="469_to_242" type="revolute">
		<parent link="242"/>
		<child link="469"/>
		<axis xyz="1 0 0"/>
		<limit effort="1" lower="3.1415" upper="-3.1415" velocity="1"/>
		<origin rpy="26.241299775476413 2.085849278768821 4.851000886523474" xyz="0.760092322278548 0.7843169416872703 0.7085483075455614"/>
	</joint>
	<joint name="670_to_469" type="revolute">
		<parent link="469"/>
		<child link="670"/>
		<axis xyz="1 0 0"/>
		<limit effort="1" lower="3.1415" upper="-3.1415" velocity="1"/>
		<origin rpy="4.327363526521489 1.676692086458292 2.8516786786967874" xyz="0.37927848649735696 0.722877595318166 0.1516858157512171"/>
	</joint>
	<joint name="871_to_469" type="revolute">
		<parent link="469"/>
		<child link="871"/>
		<axis xyz="0 0 1"/>
		<limit effort="1" lower="3.1415" upper="-3.1415" velocity="1"/>
		<origin rpy="2.557328583965563 1.1552157584870997 0.485125210236082" xyz="0.1610097667265198 0.8530449472195707 0.5349706193074901"/>
	</joint>
	<joint name="1072_to_469" type="revolute">
		<parent link="469"/>
		<child link="1072"/>
		<axis xyz="1 0 0"/>
		<limit effort="1" lower="3.1415" upper="-3.1415" velocity="1"/>
		<origin rpy="3.0642269209158326 1.7369670225369154 4.394038209488055" xyz="0.4046093564015002 0.7180039230235388 0.5483722462440448"/>
	</joint>
	<joint name="1073_to_469" type="revolute">
		<parent link="469"/>
		<child link="1073"/>
		<axis xyz="1 0 0"/>
		<limit effort="1" lower="3.1415" upper="-3.1415" velocity="1"/>
		<origin rpy="3.8302836511447906 1.7369670225369154 4.394038209488055" xyz="0.4046093564015002 0.7180039230235388 0.5483722462440448"/>
	</joint>
	<joint name="474_to_242" type="revolute">
		<parent link="242"/>
		<child link="474"/>
		<axis xyz="1 0 0"/>
		<limit effort="1" lower="3.1415" upper="-3.1415" velocity="1"/>
		<origin rpy="30.614849738055817 2.085849278768821 4.851000886523474" xyz="0.760092322278548 0.7843169416872703 0.7085483075455614"/>
	</joint>
	<joint name="675_to_474" type="revolute">
		<parent link="474"/>
		<child link="675"/>
		<axis xyz="1 0 0"/>
		<limit effort="1" lower="3.1415" upper="-3.1415" velocity="1"/>
		<origin rpy="4.327363526521489 1.676692086458292 2.8516786786967874" xyz="0.37927848649735696 0.722877595318166 0.1516858157512171"/>
	</joint>
	<joint name="876_to_474" type="revolute">
		<parent link="474"/>
		<child link="876"/>
		<axis xyz="0 0 1"/>
		<limit effort="1" lower="3.1415" upper="-3.1415" velocity="1"/>
		<origin rpy="2.557328583965563 1.1552157584870997 0.485125210236082" xyz="0.1610097667265198 0.8530449472195707 0.5349706193074901"/>
	</joint>
	<joint name="1077_to_474" type="revolute">
		<parent link="474"/>
		<child link="1077"/>
		<axis xyz="1 0 0"/>
		<limit effort="1" lower="3.1415" upper="-3.1415" velocity="1"/>
		<origin rpy="3.0642269209158326 1.7369670225369154 4.394038209488055" xyz="0.4046093564015002 0.7180039230235388 0.5483722462440448"/>
	</joint>
	<joint name="1078_to_474" type="revolute">
		<parent link="474"/>
		<child link="1078"/>
		<axis xyz="1 0 0"/>
		<limit effort="1" lower="3.1415" upper="-3.1415" velocity="1"/>
		<origin rpy="3.8302836511447906 1.7369670225369154 4.394038209488055" xyz="0.4046093564015002 0.7180039230235388 0.5483722462440448"/>
	</joint>
	<joint name="779_to_242" type="revolute">
		<parent link="242"/>
		<child link="779"/>
		<axis xyz="0 1 0"/>
		<limit effort="1" lower="3.1415" upper="-3.1415" velocity="1"/>
		<origin rpy="3.660516838142487 3.624952322726604 2.5393922749987925" xyz="0.647824095487416 0.4591485242089549 0.9171824412792904"/>
	</joint>
	<joint name="780_to_242" type="revolute">
		<parent link="242"/>
		<child link="780"/>
		<axis xyz="0 1 0"/>
		<limit effort="1" lower="3.1415" upper="-3.1415" velocity="1"/>
		<origin rpy="4.118081442910298 3.624952322726604 2.5393922749987925" xyz="0.647824095487416 0.4591485242089549 0.9171824412792904"/>
	</joint>
	<joint name="781_to_242" type="revolute">
		<parent link="242"/>
		<child link="781"/>
		<axis xyz="0 1 0"/>
		<limit effort="1" lower="3.1415" upper="-3.1415" velocity="1"/>
		<origin rpy="4.5756460476781085 3.624952322726604 2.5393922749987925" xyz="0.647824095487416 0.4591485242089549 0.9171824412792904"/>
	</joint>
	<joint name="1182_to_0" type="revolute">
		<parent link="0"/>
		<child link="1182"/>
		<axis xyz="0 1 0"/>
		<limit effort="1" lower="3.1415" upper="-3.1415" velocity="1"/>
		<origin rpy="7.034051257583179 1.9531726777120828 5.669029596208047" xyz="0.27607555712633025 0.6666497545336492 0.43782052733678434"/>
	</joint>
	<joint name="1183_to_0" type="revolute">
		<parent link="0"/>
		<child link="1183"/>
		<axis xyz="0 1 0"/>
		<limit effort="1" lower="3.1415" upper="-3.1415" velocity="1"/>
		<origin rpy="9.378735010110905 1.9531726777120828 5.669029596208047" xyz="0.27607555712633025 0.6666497545336492 0.43782052733678434"/>
	</joint>
	<joint name="1184_to_0" type="revolute">
		<parent link="0"/>
		<child link="1184"/>
		<axis xyz="0 1 0"/>
		<limit effort="1" lower="3.1415" upper="-3.1415" velocity="1"/>
		<origin rpy="11.72341876263863 1.9531726777120828 5.669029596208047" xyz="0.27607555712633025 0.6666497545336492 0.43782052733678434"/>
	</joint>
</robot>
