<?xml version="1.0"?><robot name="pepe">
	<link name="0">
		<visual>
			<geometry>
				<cylinder length="1.5943767278626475" radius="0.06807362538067108"/>
			</geometry>
		</visual>
		<collision>
			<geometry>
				<cylinder length="1.5943767278626475" radius="0.06807362538067108"/>
			</geometry>
		</collision>
		<inertial>
			<mass value="0.02321125271215263"/>
			<inertia ixx="0.03" ixy="0" ixz="0" iyx="0" iyy="0.03" izz="0.03"/>
		</inertial>
	</link>
	<link name="11">
		<visual>
			<geometry>
				<cylinder length="0.10430806287932759" radius="0.6293243395328799"/>
			</geometry>
		</visual>
		<collision>
			<geometry>
				<cylinder length="0.10430806287932759" radius="0.6293243395328799"/>
			</geometry>
		</collision>
		<inertial>
			<mass value="0.12978270156493504"/>
			<inertia ixx="0.03" ixy="0" ixz="0" iyx="0" iyy="0.03" izz="0.03"/>
		</inertial>
	</link>
	<link name="22">
		<visual>
			<geometry>
				<cylinder length="0.8233219586705103" radius="0.6519539931818936"/>
			</geometry>
		</visual>
		<collision>
			<geometry>
				<cylinder length="0.8233219586705103" radius="0.6519539931818936"/>
			</geometry>
		</collision>
		<inertial>
			<mass value="1.0993942739023423"/>
			<inertia ixx="0.03" ixy="0" ixz="0" iyx="0" iyy="0.03" izz="0.03"/>
		</inertial>
	</link>
	<link name="23">
		<visual>
			<geometry>
				<cylinder length="0.8233219586705103" radius="0.6519539931818936"/>
			</geometry>
		</visual>
		<collision>
			<geometry>
				<cylinder length="0.8233219586705103" radius="0.6519539931818936"/>
			</geometry>
		</collision>
		<inertial>
			<mass value="1.0993942739023423"/>
			<inertia ixx="0.03" ixy="0" ixz="0" iyx="0" iyy="0.03" izz="0.03"/>
		</inertial>
	</link>
	<link name="14">
		<visual>
			<geometry>
				<cylinder length="0.10430806287932759" radius="0.6293243395328799"/>
			</geometry>
		</visual>
		<collision>
			<geometry>
				<cylinder length="0.10430806287932759" radius="0.6293243395328799"/>
			</geometry>
		</collision>
		<inertial>
			<mass value="0.12978270156493504"/>
			<inertia ixx="0.03" ixy="0" ixz="0" iyx="0" iyy="0.03" izz="0.03"/>
		</inertial>
	</link>
	<link name="25">
		<visual>
			<geometry>
				<cylinder length="0.8233219586705103" radius="0.6519539931818936"/>
			</geometry>
		</visual>
		<collision>
			<geometry>
				<cylinder length="0.8233219586705103" radius="0.6519539931818936"/>
			</geometry>
		</collision>
		<inertial>
			<mass value="1.0993942739023423"/>
			<inertia ixx="0.03" ixy="0" ixz="0" iyx="0" iyy="0.03" izz="0.03"/>
		</inertial>
	</link>
	<link name="26">
		<visual>
			<geometry>
				<cylinder length="0.8233219586705103" radius="0.6519539931818936"/>
			</geometry>
		</visual>
		<collision>
			<geometry>
				<cylinder length="0.8233219586705103" radius="0.6519539931818936"/>
			</geometry>
		</collision>
		<inertial>
			<mass value="1.0993942739023423"/>
			<inertia ixx="0.03" ixy="0" ixz="0" iyx="0" iyy="0.03" izz="0.03"/>
		</inertial>
	</link>
	<link name="17">
		<visual>
			<geometry>
				<cylinder length="0.10430806287932759" radius="0.6293243395328799"/>
			</geometry>
		</visual>
		<collision>
			<geometry>
				<cylinder length="0.10430806287932759" radius="0.6293243395328799"/>
			</geometry>
		</collision>
		<inertial>
			<mass value="0.12978270156493504"/>
			<inertia ixx="0.03" ixy="0" ixz="0" iyx="0" iyy="0.03" izz="0.03"/>
		</inertial>
	</link>
	<link name="28">
		<visual>
			<geometry>
				<cylinder length="0.8233219586705103" radius="0.6519539931818936"/>
			</geometry>
		</visual>
		<collision>
			<geometry>
				<cylinder length="0.8233219586705103" radius="0.6519539931818936"/>
			</geometry>
		</collision>
		<inertial>
			<mass value="1.0993942739023423"/>
			<inertia ixx="0.03" ixy="0" ixz="0" iyx="0" iyy="0.03" izz="0.03"/>
		</inertial>
	</link>
	<link name="29">
		<visual>
			<geometry>
				<cylinder length="0.8233219586705103" radius="0.6519539931818936"/>
			</geometry>
		</visual>
		<collision>
			<geometry>
				<cylinder length="0.8233219586705103" radius="0.6519539931818936"/>
			</geometry>
		</collision>
		<inertial>
			<mass value="1.0993942739023423"/>
			<inertia ixx="0.03" ixy="0" ixz="0" iyx="0" iyy="0.03" izz="0.03"/>
		</inertial>
	</link>
	<joint name="11_to_0" type="revolute">
		<parent link="0"/>
		<child link="11"/>
		<axis xyz="1 0 0"/>
		<limit effort="1" lower="3.1415" upper="-3.1415" velocity="1"/>
		<origin rpy="6.524330174264022 4.717985807462383 2.359086977962126" xyz="0.18457565513068275 0.37313347329975777 0.7217667791091414"/>
	</joint>
	<joint name="22_to_11" type="revolute">
		<parent link="11"/>
		<child link="22"/>
		<axis xyz="0 1 0"/>
		<limit effort="1" lower="3.1415" upper="-3.1415" velocity="1"/>
		<origin rpy="9.27380649927809 4.761254996217394 2.7830122907600003" xyz="0.5765749496532885 0.18662603572218528 0.22149339297314974"/>
	</joint>
	<joint name="23_to_11" type="revolute">
		<parent link="11"/>
		<child link="23"/>
		<axis xyz="0 1 0"/>
		<limit effort="1" lower="3.1415" upper="-3.1415" velocity="1"/>
		<origin rpy="13.910709748917135 4.761254996217394 2.7830122907600003" xyz="0.5765749496532885 0.18662603572218528 0.22149339297314974"/>
	</joint>
	<joint name="14_to_0" type="revolute">
		<parent link="0"/>
		<child link="14"/>
		<axis xyz="1 0 0"/>
		<limit effort="1" lower="3.1415" upper="-3.1415" velocity="1"/>
		<origin rpy="9.786495261396032 4.717985807462383 2.359086977962126" xyz="0.18457565513068275 0.37313347329975777 0.7217667791091414"/>
	</joint>
	<joint name="25_to_14" type="revolute">
		<parent link="14"/>
		<child link="25"/>
		<axis xyz="0 1 0"/>
		<limit effort="1" lower="3.1415" upper="-3.1415" velocity="1"/>
		<origin rpy="9.27380649927809 4.761254996217394 2.7830122907600003" xyz="0.5765749496532885 0.18662603572218528 0.22149339297314974"/>
	</joint>
	<joint name="26_to_14" type="revolute">
		<parent link="14"/>
		<child link="26"/>
		<axis xyz="0 1 0"/>
		<limit effort="1" lower="3.1415" upper="-3.1415" velocity="1"/>
		<origin rpy="13.910709748917135 4.761254996217394 2.7830122907600003" xyz="0.5765749496532885 0.18662603572218528 0.22149339297314974"/>
	</joint>
	<joint name="17_to_0" type="revolute">
		<parent link="0"/>
		<child link="17"/>
		<axis xyz="1 0 0"/>
		<limit effort="1" lower="3.1415" upper="-3.1415" velocity="1"/>
		<origin rpy="13.048660348528044 4.717985807462383 2.359086977962126" xyz="0.18457565513068275 0.37313347329975777 0.7217667791091414"/>
	</joint>
	<joint name="28_to_17" type="revolute">
		<parent link="17"/>
		<child link="28"/>
		<axis xyz="0 1 0"/>
		<limit effort="1" lower="3.1415" upper="-3.1415" velocity="1"/>
		<origin rpy="9.27380649927809 4.761254996217394 2.7830122907600003" xyz="0.5765749496532885 0.18662603572218528 0.22149339297314974"/>
	</joint>
	<joint name="29_to_17" type="revolute">
		<parent link="17"/>
		<child link="29"/>
		<axis xyz="0 1 0"/>
		<limit effort="1" lower="3.1415" upper="-3.1415" velocity="1"/>
		<origin rpy="13.910709748917135 4.761254996217394 2.7830122907600003" xyz="0.5765749496532885 0.18662603572218528 0.22149339297314974"/>
	</joint>
</robot>
