<?xml version="1.0"?><robot name="pepe">
	<link name="0">
		<visual>
			<geometry>
				<cylinder length="0.8233219586705103" radius="0.6519539931818936"/>
			</geometry>
		</visual>
		<collision>
			<geometry>
				<cylinder length="0.8233219586705103" radius="0.6519539931818936"/>
			</geometry>
		</collision>
		<inertial>
			<mass value="1.0993942739023423"/>
			<inertia ixx="0.03" ixy="0" ixz="0" iyx="0" iyy="0.03" izz="0.03"/>
		</inertial>
	</link>
	<link name="11">
		<visual>
			<geometry>
				<cylinder length="0.8233219586705103" radius="0.6519539931818936"/>
			</geometry>
		</visual>
		<collision>
			<geometry>
				<cylinder length="0.8233219586705103" radius="0.6519539931818936"/>
			</geometry>
		</collision>
		<inertial>
			<mass value="1.0993942739023423"/>
			<inertia ixx="0.03" ixy="0" ixz="0" iyx="0" iyy="0.03" izz="0.03"/>
		</inertial>
	</link>
	<link name="12">
		<visual>
			<geometry>
				<cylinder length="0.8233219586705103" radius="0.6519539931818936"/>
			</geometry>
		</visual>
		<collision>
			<geometry>
				<cylinder length="0.8233219586705103" radius="0.6519539931818936"/>
			</geometry>
		</collision>
		<inertial>
			<mass value="1.0993942739023423"/>
			<inertia ixx="0.03" ixy="0" ixz="0" iyx="0" iyy="0.03" izz="0.03"/>
		</inertial>
	</link>
	<link name="23">
		<visual>
			<geometry>
				<cylinder length="1.7112919320549032" radius="0.6135074818764842"/>
			</geometry>
		</visual>
		<collision>
			<geometry>
				<cylinder length="1.7112919320549032" radius="0.6135074818764842"/>
			</geometry>
		</collision>
		<inertial>
			<mass value="2.023548893566616"/>
			<inertia ixx="0.03" ixy="0" ixz="0" iyx="0" iyy="0.03" izz="0.03"/>
		</inertial>
	</link>
	<link name="24">
		<visual>
			<geometry>
				<cylinder length="1.7112919320549032" radius="0.6135074818764842"/>
			</geometry>
		</visual>
		<collision>
			<geometry>
				<cylinder length="1.7112919320549032" radius="0.6135074818764842"/>
			</geometry>
		</collision>
		<inertial>
			<mass value="2.023548893566616"/>
			<inertia ixx="0.03" ixy="0" ixz="0" iyx="0" iyy="0.03" izz="0.03"/>
		</inertial>
	</link>
	<joint name="11_to_0" type="revolute">
		<parent link="0"/>
		<child link="11"/>
		<axis xyz="0 1 0"/>
		<limit effort="1" lower="3.1415" upper="-3.1415" velocity="1"/>
		<origin rpy="10.530443560714005 4.761254996217394 2.7830122907600003" xyz="0.5765749496532885 0.18662603572218528 0.22149339297314974"/>
	</joint>
	<joint name="12_to_0" type="revolute">
		<parent link="0"/>
		<child link="12"/>
		<axis xyz="0 1 0"/>
		<limit effort="1" lower="3.1415" upper="-3.1415" velocity="1"/>
		<origin rpy="15.795665341071008 4.761254996217394 2.7830122907600003" xyz="0.5765749496532885 0.18662603572218528 0.22149339297314974"/>
	</joint>
	<joint name="23_to_0" type="revolute">
		<parent link="0"/>
		<child link="23"/>
		<axis xyz="1 0 0"/>
		<limit effort="1" lower="3.1415" upper="-3.1415" velocity="1"/>
		<origin rpy="11.82236631451134 1.0907596646813935 6.282556988648868" xyz="0.10903610664661101 0.3415547623359111 0.310074180084253"/>
	</joint>
	<joint name="24_to_0" type="revolute">
		<parent link="0"/>
		<child link="24"/>
		<axis xyz="1 0 0"/>
		<limit effort="1" lower="3.1415" upper="-3.1415" velocity="1"/>
		<origin rpy="14.777957893139176 1.0907596646813935 6.282556988648868" xyz="0.10903610664661101 0.3415547623359111 0.310074180084253"/>
	</joint>
</robot>
