<?xml version="1.0"?><robot name="pepe">
	<link name="0">
		<visual>
			<geometry>
				<cylinder length="1.5467743005789663" radius="0.9999"/>
			</geometry>
		</visual>
		<collision>
			<geometry>
				<cylinder length="1.5467743005789663" radius="0.9999"/>
			</geometry>
		</collision>
		<inertial>
			<mass value="4.858362961097827"/>
			<inertia ixx="0.03" ixy="0" ixz="0" iyx="0" iyy="0.03" izz="0.03"/>
		</inertial>
	</link>
	<link name="11">
		<visual>
			<geometry>
				<cylinder length="1.011626046047713" radius="0.16489927627096637"/>
			</geometry>
		</visual>
		<collision>
			<geometry>
				<cylinder length="1.011626046047713" radius="0.16489927627096637"/>
			</geometry>
		</collision>
		<inertial>
			<mass value="0.08641862943656423"/>
			<inertia ixx="0.03" ixy="0" ixz="0" iyx="0" iyy="0.03" izz="0.03"/>
		</inertial>
	</link>
	<link name="12">
		<visual>
			<geometry>
				<cylinder length="1.011626046047713" radius="0.16489927627096637"/>
			</geometry>
		</visual>
		<collision>
			<geometry>
				<cylinder length="1.011626046047713" radius="0.16489927627096637"/>
			</geometry>
		</collision>
		<inertial>
			<mass value="0.08641862943656423"/>
			<inertia ixx="0.03" ixy="0" ixz="0" iyx="0" iyy="0.03" izz="0.03"/>
		</inertial>
	</link>
	<link name="13">
		<visual>
			<geometry>
				<cylinder length="1.011626046047713" radius="0.16489927627096637"/>
			</geometry>
		</visual>
		<collision>
			<geometry>
				<cylinder length="1.011626046047713" radius="0.16489927627096637"/>
			</geometry>
		</collision>
		<inertial>
			<mass value="0.08641862943656423"/>
			<inertia ixx="0.03" ixy="0" ixz="0" iyx="0" iyy="0.03" izz="0.03"/>
		</inertial>
	</link>
	<joint name="11_to_0" type="revolute">
		<parent link="0"/>
		<child link="11"/>
		<axis xyz="1 0 0"/>
		<limit effort="1" lower="3.1415" upper="-3.1415" velocity="1"/>
		<origin rpy="0.2683820677782725 6.282556988648868 2.405435909672221" xyz="0.11350850196545192 0.7084136149139768 0.5152222755851831"/>
	</joint>
	<joint name="12_to_0" type="revolute">
		<parent link="0"/>
		<child link="12"/>
		<axis xyz="1 0 0"/>
		<limit effort="1" lower="3.1415" upper="-3.1415" velocity="1"/>
		<origin rpy="0.4025731016674088 6.282556988648868 2.405435909672221" xyz="0.11350850196545192 0.7084136149139768 0.5152222755851831"/>
	</joint>
	<joint name="13_to_0" type="revolute">
		<parent link="0"/>
		<child link="13"/>
		<axis xyz="1 0 0"/>
		<limit effort="1" lower="3.1415" upper="-3.1415" velocity="1"/>
		<origin rpy="0.536764135556545 6.282556988648868 2.405435909672221" xyz="0.11350850196545192 0.7084136149139768 0.5152222755851831"/>
	</joint>
</robot>
