<?xml version="1.0"?><robot name="pepe">
	<link name="0">
		<visual>
			<geometry>
				<cylinder length="1.9998" radius="0.40608676477427597"/>
			</geometry>
		</visual>
		<collision>
			<geometry>
				<cylinder length="1.9998" radius="0.40608676477427597"/>
			</geometry>
		</collision>
		<inertial>
			<mass value="1.0360342360436707"/>
			<inertia ixx="0.03" ixy="0" ixz="0" iyx="0" iyy="0.03" izz="0.03"/>
		</inertial>
	</link>
	<link name="11">
		<visual>
			<geometry>
				<cylinder length="1.9168577574955858" radius="0.0008612969648227331"/>
			</geometry>
		</visual>
		<collision>
			<geometry>
				<cylinder length="1.9168577574955858" radius="0.0008612969648227331"/>
			</geometry>
		</collision>
		<inertial>
			<mass value="4.467304882838585e-06"/>
			<inertia ixx="0.03" ixy="0" ixz="0" iyx="0" iyy="0.03" izz="0.03"/>
		</inertial>
	</link>
	<link name="22">
		<visual>
			<geometry>
				<cylinder length="1.9168577574955858" radius="0.10086129696482274"/>
			</geometry>
		</visual>
		<collision>
			<geometry>
				<cylinder length="1.9168577574955858" radius="0.10086129696482274"/>
			</geometry>
		</collision>
		<inertial>
			<mass value="0.06126167348981085"/>
			<inertia ixx="0.03" ixy="0" ixz="0" iyx="0" iyy="0.03" izz="0.03"/>
		</inertial>
	</link>
	<link name="33">
		<visual>
			<geometry>
				<cylinder length="0.40488831582507845" radius="0.7512024075422402"/>
			</geometry>
		</visual>
		<collision>
			<geometry>
				<cylinder length="0.40488831582507845" radius="0.7512024075422402"/>
			</geometry>
		</collision>
		<inertial>
			<mass value="0.7177927362512388"/>
			<inertia ixx="0.03" ixy="0" ixz="0" iyx="0" iyy="0.03" izz="0.03"/>
		</inertial>
	</link>
	<link name="34">
		<visual>
			<geometry>
				<cylinder length="0.40488831582507845" radius="0.7512024075422402"/>
			</geometry>
		</visual>
		<collision>
			<geometry>
				<cylinder length="0.40488831582507845" radius="0.7512024075422402"/>
			</geometry>
		</collision>
		<inertial>
			<mass value="0.7177927362512388"/>
			<inertia ixx="0.03" ixy="0" ixz="0" iyx="0" iyy="0.03" izz="0.03"/>
		</inertial>
	</link>
	<link name="25">
		<visual>
			<geometry>
				<cylinder length="1.9168577574955858" radius="0.10086129696482274"/>
			</geometry>
		</visual>
		<collision>
			<geometry>
				<cylinder length="1.9168577574955858" radius="0.10086129696482274"/>
			</geometry>
		</collision>
		<inertial>
			<mass value="0.06126167348981085"/>
			<inertia ixx="0.03" ixy="0" ixz="0" iyx="0" iyy="0.03" izz="0.03"/>
		</inertial>
	</link>
	<link name="36">
		<visual>
			<geometry>
				<cylinder length="0.40488831582507845" radius="0.7512024075422402"/>
			</geometry>
		</visual>
		<collision>
			<geometry>
				<cylinder length="0.40488831582507845" radius="0.7512024075422402"/>
			</geometry>
		</collision>
		<inertial>
			<mass value="0.7177927362512388"/>
			<inertia ixx="0.03" ixy="0" ixz="0" iyx="0" iyy="0.03" izz="0.03"/>
		</inertial>
	</link>
	<link name="37">
		<visual>
			<geometry>
				<cylinder length="0.40488831582507845" radius="0.7512024075422402"/>
			</geometry>
		</visual>
		<collision>
			<geometry>
				<cylinder length="0.40488831582507845" radius="0.7512024075422402"/>
			</geometry>
		</collision>
		<inertial>
			<mass value="0.7177927362512388"/>
			<inertia ixx="0.03" ixy="0" ixz="0" iyx="0" iyy="0.03" izz="0.03"/>
		</inertial>
	</link>
	<link name="18">
		<visual>
			<geometry>
				<cylinder length="1.9168577574955858" radius="0.0008612969648227331"/>
			</geometry>
		</visual>
		<collision>
			<geometry>
				<cylinder length="1.9168577574955858" radius="0.0008612969648227331"/>
			</geometry>
		</collision>
		<inertial>
			<mass value="4.467304882838585e-06"/>
			<inertia ixx="0.03" ixy="0" ixz="0" iyx="0" iyy="0.03" izz="0.03"/>
		</inertial>
	</link>
	<link name="29">
		<visual>
			<geometry>
				<cylinder length="1.9168577574955858" radius="0.10086129696482274"/>
			</geometry>
		</visual>
		<collision>
			<geometry>
				<cylinder length="1.9168577574955858" radius="0.10086129696482274"/>
			</geometry>
		</collision>
		<inertial>
			<mass value="0.06126167348981085"/>
			<inertia ixx="0.03" ixy="0" ixz="0" iyx="0" iyy="0.03" izz="0.03"/>
		</inertial>
	</link>
	<link name="310">
		<visual>
			<geometry>
				<cylinder length="0.40488831582507845" radius="0.7512024075422402"/>
			</geometry>
		</visual>
		<collision>
			<geometry>
				<cylinder length="0.40488831582507845" radius="0.7512024075422402"/>
			</geometry>
		</collision>
		<inertial>
			<mass value="0.7177927362512388"/>
			<inertia ixx="0.03" ixy="0" ixz="0" iyx="0" iyy="0.03" izz="0.03"/>
		</inertial>
	</link>
	<link name="311">
		<visual>
			<geometry>
				<cylinder length="0.40488831582507845" radius="0.7512024075422402"/>
			</geometry>
		</visual>
		<collision>
			<geometry>
				<cylinder length="0.40488831582507845" radius="0.7512024075422402"/>
			</geometry>
		</collision>
		<inertial>
			<mass value="0.7177927362512388"/>
			<inertia ixx="0.03" ixy="0" ixz="0" iyx="0" iyy="0.03" izz="0.03"/>
		</inertial>
	</link>
	<link name="212">
		<visual>
			<geometry>
				<cylinder length="1.9168577574955858" radius="0.10086129696482274"/>
			</geometry>
		</visual>
		<collision>
			<geometry>
				<cylinder length="1.9168577574955858" radius="0.10086129696482274"/>
			</geometry>
		</collision>
		<inertial>
			<mass value="0.06126167348981085"/>
			<inertia ixx="0.03" ixy="0" ixz="0" iyx="0" iyy="0.03" izz="0.03"/>
		</inertial>
	</link>
	<link name="313">
		<visual>
			<geometry>
				<cylinder length="0.40488831582507845" radius="0.7512024075422402"/>
			</geometry>
		</visual>
		<collision>
			<geometry>
				<cylinder length="0.40488831582507845" radius="0.7512024075422402"/>
			</geometry>
		</collision>
		<inertial>
			<mass value="0.7177927362512388"/>
			<inertia ixx="0.03" ixy="0" ixz="0" iyx="0" iyy="0.03" izz="0.03"/>
		</inertial>
	</link>
	<link name="314">
		<visual>
			<geometry>
				<cylinder length="0.40488831582507845" radius="0.7512024075422402"/>
			</geometry>
		</visual>
		<collision>
			<geometry>
				<cylinder length="0.40488831582507845" radius="0.7512024075422402"/>
			</geometry>
		</collision>
		<inertial>
			<mass value="0.7177927362512388"/>
			<inertia ixx="0.03" ixy="0" ixz="0" iyx="0" iyy="0.03" izz="0.03"/>
		</inertial>
	</link>
	<joint name="11_to_0" type="revolute">
		<parent link="0"/>
		<child link="11"/>
		<axis xyz="0 1 0"/>
		<limit effort="1" lower="3.1415" upper="-3.1415" velocity="1"/>
		<origin rpy="3.596398612651434 6.262356433276231 4.280533725595206" xyz="0.7236069504422373 0.9999 0.4161850445130292"/>
	</joint>
	<joint name="22_to_11" type="revolute">
		<parent link="11"/>
		<child link="22"/>
		<axis xyz="0 1 0"/>
		<limit effort="1" lower="3.1415" upper="-3.1415" velocity="1"/>
		<origin rpy="4.853035674087351 6.262356433276231 4.280533725595206" xyz="0.7236069504422373 0.9885880704038275 0.4161850445130292"/>
	</joint>
	<joint name="33_to_22" type="revolute">
		<parent link="22"/>
		<child link="33"/>
		<axis xyz="0 1 0"/>
		<limit effort="1" lower="3.1415" upper="-3.1415" velocity="1"/>
		<origin rpy="12.246047227773008 5.611737068211983 2.338051877508089" xyz="0.661355122961424 0.5316209256558981 0.2962522858232731"/>
	</joint>
	<joint name="34_to_22" type="revolute">
		<parent link="22"/>
		<child link="34"/>
		<axis xyz="0 1 0"/>
		<limit effort="1" lower="3.1415" upper="-3.1415" velocity="1"/>
		<origin rpy="18.369070841659514 5.611737068211983 2.338051877508089" xyz="0.661355122961424 0.5316209256558981 0.2962522858232731"/>
	</joint>
	<joint name="25_to_11" type="revolute">
		<parent link="11"/>
		<child link="25"/>
		<axis xyz="0 1 0"/>
		<limit effort="1" lower="3.1415" upper="-3.1415" velocity="1"/>
		<origin rpy="7.2795535111310254 6.262356433276231 4.280533725595206" xyz="0.7236069504422373 0.9885880704038275 0.4161850445130292"/>
	</joint>
	<joint name="36_to_25" type="revolute">
		<parent link="25"/>
		<child link="36"/>
		<axis xyz="0 1 0"/>
		<limit effort="1" lower="3.1415" upper="-3.1415" velocity="1"/>
		<origin rpy="12.246047227773008 5.611737068211983 2.338051877508089" xyz="0.661355122961424 0.5316209256558981 0.2962522858232731"/>
	</joint>
	<joint name="37_to_25" type="revolute">
		<parent link="25"/>
		<child link="37"/>
		<axis xyz="0 1 0"/>
		<limit effort="1" lower="3.1415" upper="-3.1415" velocity="1"/>
		<origin rpy="18.369070841659514 5.611737068211983 2.338051877508089" xyz="0.661355122961424 0.5316209256558981 0.2962522858232731"/>
	</joint>
	<joint name="18_to_0" type="revolute">
		<parent link="0"/>
		<child link="18"/>
		<axis xyz="0 1 0"/>
		<limit effort="1" lower="3.1415" upper="-3.1415" velocity="1"/>
		<origin rpy="5.3945979189771505 6.262356433276231 4.280533725595206" xyz="0.7236069504422373 0.9999 0.4161850445130292"/>
	</joint>
	<joint name="29_to_18" type="revolute">
		<parent link="18"/>
		<child link="29"/>
		<axis xyz="0 1 0"/>
		<limit effort="1" lower="3.1415" upper="-3.1415" velocity="1"/>
		<origin rpy="4.853035674087351 6.262356433276231 4.280533725595206" xyz="0.7236069504422373 0.9885880704038275 0.4161850445130292"/>
	</joint>
	<joint name="310_to_29" type="revolute">
		<parent link="29"/>
		<child link="310"/>
		<axis xyz="0 1 0"/>
		<limit effort="1" lower="3.1415" upper="-3.1415" velocity="1"/>
		<origin rpy="12.246047227773008 5.611737068211983 2.338051877508089" xyz="0.661355122961424 0.5316209256558981 0.2962522858232731"/>
	</joint>
	<joint name="311_to_29" type="revolute">
		<parent link="29"/>
		<child link="311"/>
		<axis xyz="0 1 0"/>
		<limit effort="1" lower="3.1415" upper="-3.1415" velocity="1"/>
		<origin rpy="18.369070841659514 5.611737068211983 2.338051877508089" xyz="0.661355122961424 0.5316209256558981 0.2962522858232731"/>
	</joint>
	<joint name="212_to_18" type="revolute">
		<parent link="18"/>
		<child link="212"/>
		<axis xyz="0 1 0"/>
		<limit effort="1" lower="3.1415" upper="-3.1415" velocity="1"/>
		<origin rpy="7.2795535111310254 6.262356433276231 4.280533725595206" xyz="0.7236069504422373 0.9885880704038275 0.4161850445130292"/>
	</joint>
	<joint name="313_to_212" type="revolute">
		<parent link="212"/>
		<child link="313"/>
		<axis xyz="0 1 0"/>
		<limit effort="1" lower="3.1415" upper="-3.1415" velocity="1"/>
		<origin rpy="12.246047227773008 5.611737068211983 2.338051877508089" xyz="0.661355122961424 0.5316209256558981 0.2962522858232731"/>
	</joint>
	<joint name="314_to_212" type="revolute">
		<parent link="212"/>
		<child link="314"/>
		<axis xyz="0 1 0"/>
		<limit effort="1" lower="3.1415" upper="-3.1415" velocity="1"/>
		<origin rpy="18.369070841659514 5.611737068211983 2.338051877508089" xyz="0.661355122961424 0.5316209256558981 0.2962522858232731"/>
	</joint>
</robot>
