<?xml version="1.0"?><robot name="pepe">
	<link name="0">
		<visual>
			<geometry>
				<cylinder length="0.9590842794497736" radius="0.9999"/>
			</geometry>
		</visual>
		<collision>
			<geometry>
				<cylinder length="0.9590842794497736" radius="0.9999"/>
			</geometry>
		</collision>
		<inertial>
			<mass value="3.012449546198092"/>
			<inertia ixx="0.03" ixy="0" ixz="0" iyx="0" iyy="0.03" izz="0.03"/>
		</inertial>
	</link>
	<link name="11">
		<visual>
			<geometry>
				<cylinder length="0.1840588742756495" radius="0.7477842884599845"/>
			</geometry>
		</visual>
		<collision>
			<geometry>
				<cylinder length="0.1840588742756495" radius="0.7477842884599845"/>
			</geometry>
		</collision>
		<inertial>
			<mass value="0.32333990492988784"/>
			<inertia ixx="0.03" ixy="0" ixz="0" iyx="0" iyy="0.03" izz="0.03"/>
		</inertial>
	</link>
	<link name="22">
		<visual>
			<geometry>
				<cylinder length="1.848696671994538" radius="0.32291556970490987"/>
			</geometry>
		</visual>
		<collision>
			<geometry>
				<cylinder length="1.848696671994538" radius="0.32291556970490987"/>
			</geometry>
		</collision>
		<inertial>
			<mass value="0.605610648863151"/>
			<inertia ixx="0.03" ixy="0" ixz="0" iyx="0" iyy="0.03" izz="0.03"/>
		</inertial>
	</link>
	<link name="23">
		<visual>
			<geometry>
				<cylinder length="1.848696671994538" radius="0.32291556970490987"/>
			</geometry>
		</visual>
		<collision>
			<geometry>
				<cylinder length="1.848696671994538" radius="0.32291556970490987"/>
			</geometry>
		</collision>
		<inertial>
			<mass value="0.605610648863151"/>
			<inertia ixx="0.03" ixy="0" ixz="0" iyx="0" iyy="0.03" izz="0.03"/>
		</inertial>
	</link>
	<link name="24">
		<visual>
			<geometry>
				<cylinder length="1.848696671994538" radius="0.32291556970490987"/>
			</geometry>
		</visual>
		<collision>
			<geometry>
				<cylinder length="1.848696671994538" radius="0.32291556970490987"/>
			</geometry>
		</collision>
		<inertial>
			<mass value="0.605610648863151"/>
			<inertia ixx="0.03" ixy="0" ixz="0" iyx="0" iyy="0.03" izz="0.03"/>
		</inertial>
	</link>
	<link name="15">
		<visual>
			<geometry>
				<cylinder length="0.1840588742756495" radius="0.7477842884599845"/>
			</geometry>
		</visual>
		<collision>
			<geometry>
				<cylinder length="0.1840588742756495" radius="0.7477842884599845"/>
			</geometry>
		</collision>
		<inertial>
			<mass value="0.32333990492988784"/>
			<inertia ixx="0.03" ixy="0" ixz="0" iyx="0" iyy="0.03" izz="0.03"/>
		</inertial>
	</link>
	<link name="26">
		<visual>
			<geometry>
				<cylinder length="1.848696671994538" radius="0.32291556970490987"/>
			</geometry>
		</visual>
		<collision>
			<geometry>
				<cylinder length="1.848696671994538" radius="0.32291556970490987"/>
			</geometry>
		</collision>
		<inertial>
			<mass value="0.605610648863151"/>
			<inertia ixx="0.03" ixy="0" ixz="0" iyx="0" iyy="0.03" izz="0.03"/>
		</inertial>
	</link>
	<link name="27">
		<visual>
			<geometry>
				<cylinder length="1.848696671994538" radius="0.32291556970490987"/>
			</geometry>
		</visual>
		<collision>
			<geometry>
				<cylinder length="1.848696671994538" radius="0.32291556970490987"/>
			</geometry>
		</collision>
		<inertial>
			<mass value="0.605610648863151"/>
			<inertia ixx="0.03" ixy="0" ixz="0" iyx="0" iyy="0.03" izz="0.03"/>
		</inertial>
	</link>
	<link name="28">
		<visual>
			<geometry>
				<cylinder length="1.848696671994538" radius="0.32291556970490987"/>
			</geometry>
		</visual>
		<collision>
			<geometry>
				<cylinder length="1.848696671994538" radius="0.32291556970490987"/>
			</geometry>
		</collision>
		<inertial>
			<mass value="0.605610648863151"/>
			<inertia ixx="0.03" ixy="0" ixz="0" iyx="0" iyy="0.03" izz="0.03"/>
		</inertial>
	</link>
	<link name="19">
		<visual>
			<geometry>
				<cylinder length="0.1840588742756495" radius="0.7477842884599845"/>
			</geometry>
		</visual>
		<collision>
			<geometry>
				<cylinder length="0.1840588742756495" radius="0.7477842884599845"/>
			</geometry>
		</collision>
		<inertial>
			<mass value="0.32333990492988784"/>
			<inertia ixx="0.03" ixy="0" ixz="0" iyx="0" iyy="0.03" izz="0.03"/>
		</inertial>
	</link>
	<link name="210">
		<visual>
			<geometry>
				<cylinder length="1.848696671994538" radius="0.32291556970490987"/>
			</geometry>
		</visual>
		<collision>
			<geometry>
				<cylinder length="1.848696671994538" radius="0.32291556970490987"/>
			</geometry>
		</collision>
		<inertial>
			<mass value="0.605610648863151"/>
			<inertia ixx="0.03" ixy="0" ixz="0" iyx="0" iyy="0.03" izz="0.03"/>
		</inertial>
	</link>
	<link name="211">
		<visual>
			<geometry>
				<cylinder length="1.848696671994538" radius="0.32291556970490987"/>
			</geometry>
		</visual>
		<collision>
			<geometry>
				<cylinder length="1.848696671994538" radius="0.32291556970490987"/>
			</geometry>
		</collision>
		<inertial>
			<mass value="0.605610648863151"/>
			<inertia ixx="0.03" ixy="0" ixz="0" iyx="0" iyy="0.03" izz="0.03"/>
		</inertial>
	</link>
	<link name="212">
		<visual>
			<geometry>
				<cylinder length="1.848696671994538" radius="0.32291556970490987"/>
			</geometry>
		</visual>
		<collision>
			<geometry>
				<cylinder length="1.848696671994538" radius="0.32291556970490987"/>
			</geometry>
		</collision>
		<inertial>
			<mass value="0.605610648863151"/>
			<inertia ixx="0.03" ixy="0" ixz="0" iyx="0" iyy="0.03" izz="0.03"/>
		</inertial>
	</link>
	<joint name="11_to_0" type="revolute">
		<parent link="0"/>
		<child link="11"/>
		<axis xyz="1 0 0"/>
		<limit effort="1" lower="3.1415" upper="-3.1415" velocity="1"/>
		<origin rpy="5.347372163065932 5.018109845555575 0.8638038636710728" xyz="0.6468384730736209 0.3982034764994321 0.6535115948109418"/>
	</joint>
	<joint name="22_to_11" type="revolute">
		<parent link="11"/>
		<child link="22"/>
		<axis xyz="0 0 1"/>
		<limit effort="1" lower="3.1415" upper="-3.1415" velocity="1"/>
		<origin rpy="12.565113977297736 5.5907467448347274 4.105571388352411" xyz="0.8347096686071067 0.9999 0.7316106344170129"/>
	</joint>
	<joint name="23_to_11" type="revolute">
		<parent link="11"/>
		<child link="23"/>
		<axis xyz="0 0 1"/>
		<limit effort="1" lower="3.1415" upper="-3.1415" velocity="1"/>
		<origin rpy="18.847670965946605 5.5907467448347274 4.105571388352411" xyz="0.8347096686071067 0.9999 0.7316106344170129"/>
	</joint>
	<joint name="24_to_11" type="revolute">
		<parent link="11"/>
		<child link="24"/>
		<axis xyz="0 0 1"/>
		<limit effort="1" lower="3.1415" upper="-3.1415" velocity="1"/>
		<origin rpy="25.130227954595473 5.5907467448347274 4.105571388352411" xyz="0.8347096686071067 0.9999 0.7316106344170129"/>
	</joint>
	<joint name="15_to_0" type="revolute">
		<parent link="0"/>
		<child link="15"/>
		<axis xyz="1 0 0"/>
		<limit effort="1" lower="3.1415" upper="-3.1415" velocity="1"/>
		<origin rpy="8.021058244598898 5.018109845555575 0.8638038636710728" xyz="0.6468384730736209 0.3982034764994321 0.6535115948109418"/>
	</joint>
	<joint name="26_to_15" type="revolute">
		<parent link="15"/>
		<child link="26"/>
		<axis xyz="0 0 1"/>
		<limit effort="1" lower="3.1415" upper="-3.1415" velocity="1"/>
		<origin rpy="12.565113977297736 5.5907467448347274 4.105571388352411" xyz="0.8347096686071067 0.9999 0.7316106344170129"/>
	</joint>
	<joint name="27_to_15" type="revolute">
		<parent link="15"/>
		<child link="27"/>
		<axis xyz="0 0 1"/>
		<limit effort="1" lower="3.1415" upper="-3.1415" velocity="1"/>
		<origin rpy="18.847670965946605 5.5907467448347274 4.105571388352411" xyz="0.8347096686071067 0.9999 0.7316106344170129"/>
	</joint>
	<joint name="28_to_15" type="revolute">
		<parent link="15"/>
		<child link="28"/>
		<axis xyz="0 0 1"/>
		<limit effort="1" lower="3.1415" upper="-3.1415" velocity="1"/>
		<origin rpy="25.130227954595473 5.5907467448347274 4.105571388352411" xyz="0.8347096686071067 0.9999 0.7316106344170129"/>
	</joint>
	<joint name="19_to_0" type="revolute">
		<parent link="0"/>
		<child link="19"/>
		<axis xyz="1 0 0"/>
		<limit effort="1" lower="3.1415" upper="-3.1415" velocity="1"/>
		<origin rpy="10.694744326131865 5.018109845555575 0.8638038636710728" xyz="0.6468384730736209 0.3982034764994321 0.6535115948109418"/>
	</joint>
	<joint name="210_to_19" type="revolute">
		<parent link="19"/>
		<child link="210"/>
		<axis xyz="0 0 1"/>
		<limit effort="1" lower="3.1415" upper="-3.1415" velocity="1"/>
		<origin rpy="12.565113977297736 5.5907467448347274 4.105571388352411" xyz="0.8347096686071067 0.9999 0.7316106344170129"/>
	</joint>
	<joint name="211_to_19" type="revolute">
		<parent link="19"/>
		<child link="211"/>
		<axis xyz="0 0 1"/>
		<limit effort="1" lower="3.1415" upper="-3.1415" velocity="1"/>
		<origin rpy="18.847670965946605 5.5907467448347274 4.105571388352411" xyz="0.8347096686071067 0.9999 0.7316106344170129"/>
	</joint>
	<joint name="212_to_19" type="revolute">
		<parent link="19"/>
		<child link="212"/>
		<axis xyz="0 0 1"/>
		<limit effort="1" lower="3.1415" upper="-3.1415" velocity="1"/>
		<origin rpy="25.130227954595473 5.5907467448347274 4.105571388352411" xyz="0.8347096686071067 0.9999 0.7316106344170129"/>
	</joint>
</robot>
