<?xml version="1.0"?><robot name="pepe">
	<link name="0">
		<visual>
			<geometry>
				<cylinder length="1.5467743005789663" radius="0.9999"/>
			</geometry>
		</visual>
		<collision>
			<geometry>
				<cylinder length="1.5467743005789663" radius="0.9999"/>
			</geometry>
		</collision>
		<inertial>
			<mass value="4.858362961097827"/>
			<inertia ixx="0.03" ixy="0" ixz="0" iyx="0" iyy="0.03" izz="0.03"/>
		</inertial>
	</link>
	<link name="11">
		<visual>
			<geometry>
				<cylinder length="0.8600601898436186" radius="0.15664213484259137"/>
			</geometry>
		</visual>
		<collision>
			<geometry>
				<cylinder length="0.8600601898436186" radius="0.15664213484259137"/>
			</geometry>
		</collision>
		<inertial>
			<mass value="0.06629730966755146"/>
			<inertia ixx="0.03" ixy="0" ixz="0" iyx="0" iyy="0.03" izz="0.03"/>
		</inertial>
	</link>
	<link name="12">
		<visual>
			<geometry>
				<cylinder length="0.8600601898436186" radius="0.15664213484259137"/>
			</geometry>
		</visual>
		<collision>
			<geometry>
				<cylinder length="0.8600601898436186" radius="0.15664213484259137"/>
			</geometry>
		</collision>
		<inertial>
			<mass value="0.06629730966755146"/>
			<inertia ixx="0.03" ixy="0" ixz="0" iyx="0" iyy="0.03" izz="0.03"/>
		</inertial>
	</link>
	<link name="13">
		<visual>
			<geometry>
				<cylinder length="0.8600601898436186" radius="0.15664213484259137"/>
			</geometry>
		</visual>
		<collision>
			<geometry>
				<cylinder length="0.8600601898436186" radius="0.15664213484259137"/>
			</geometry>
		</collision>
		<inertial>
			<mass value="0.06629730966755146"/>
			<inertia ixx="0.03" ixy="0" ixz="0" iyx="0" iyy="0.03" izz="0.03"/>
		</inertial>
	</link>
	<link name="14">
		<visual>
			<geometry>
				<cylinder length="0.8600601898436186" radius="0.15664213484259137"/>
			</geometry>
		</visual>
		<collision>
			<geometry>
				<cylinder length="0.8600601898436186" radius="0.15664213484259137"/>
			</geometry>
		</collision>
		<inertial>
			<mass value="0.06629730966755146"/>
			<inertia ixx="0.03" ixy="0" ixz="0" iyx="0" iyy="0.03" izz="0.03"/>
		</inertial>
	</link>
	<link name="15">
		<visual>
			<geometry>
				<cylinder length="0.8600601898436186" radius="0.15664213484259137"/>
			</geometry>
		</visual>
		<collision>
			<geometry>
				<cylinder length="0.8600601898436186" radius="0.15664213484259137"/>
			</geometry>
		</collision>
		<inertial>
			<mass value="0.06629730966755146"/>
			<inertia ixx="0.03" ixy="0" ixz="0" iyx="0" iyy="0.03" izz="0.03"/>
		</inertial>
	</link>
	<joint name="11_to_0" type="revolute">
		<parent link="0"/>
		<child link="11"/>
		<axis xyz="1 0 0"/>
		<limit effort="1" lower="3.1415" upper="-3.1415" velocity="1"/>
		<origin rpy="10.69768734061693 4.953343961282325 5.190068367303865" xyz="0.8917763905858218 0.986858241253344 0.6929518411048576"/>
	</joint>
	<joint name="12_to_0" type="revolute">
		<parent link="0"/>
		<child link="12"/>
		<axis xyz="1 0 0"/>
		<limit effort="1" lower="3.1415" upper="-3.1415" velocity="1"/>
		<origin rpy="16.046531010925396 4.953343961282325 5.190068367303865" xyz="0.8917763905858218 0.986858241253344 0.6929518411048576"/>
	</joint>
	<joint name="13_to_0" type="revolute">
		<parent link="0"/>
		<child link="13"/>
		<axis xyz="1 0 0"/>
		<limit effort="1" lower="3.1415" upper="-3.1415" velocity="1"/>
		<origin rpy="21.39537468123386 4.953343961282325 5.190068367303865" xyz="0.8917763905858218 0.986858241253344 0.6929518411048576"/>
	</joint>
	<joint name="14_to_0" type="revolute">
		<parent link="0"/>
		<child link="14"/>
		<axis xyz="1 0 0"/>
		<limit effort="1" lower="3.1415" upper="-3.1415" velocity="1"/>
		<origin rpy="26.744218351542326 4.953343961282325 5.190068367303865" xyz="0.8917763905858218 0.986858241253344 0.6929518411048576"/>
	</joint>
	<joint name="15_to_0" type="revolute">
		<parent link="0"/>
		<child link="15"/>
		<axis xyz="1 0 0"/>
		<limit effort="1" lower="3.1415" upper="-3.1415" velocity="1"/>
		<origin rpy="32.09306202185079 4.953343961282325 5.190068367303865" xyz="0.8917763905858218 0.986858241253344 0.6929518411048576"/>
	</joint>
</robot>
