<?xml version="1.0"?><robot name="pepe">
	<link name="0">
		<visual>
			<geometry>
				<cylinder length="0.8233219586705103" radius="0.7519539931818936"/>
			</geometry>
		</visual>
		<collision>
			<geometry>
				<cylinder length="0.8233219586705103" radius="0.7519539931818936"/>
			</geometry>
		</collision>
		<inertial>
			<mass value="1.4625210014394228"/>
			<inertia ixx="0.03" ixy="0" ixz="0" iyx="0" iyy="0.03" izz="0.03"/>
		</inertial>
	</link>
	<link name="11">
		<visual>
			<geometry>
				<cylinder length="0.10430806287932759" radius="0.6293243395328799"/>
			</geometry>
		</visual>
		<collision>
			<geometry>
				<cylinder length="0.10430806287932759" radius="0.6293243395328799"/>
			</geometry>
		</collision>
		<inertial>
			<mass value="0.12978270156493504"/>
			<inertia ixx="0.03" ixy="0" ixz="0" iyx="0" iyy="0.03" izz="0.03"/>
		</inertial>
	</link>
	<link name="12">
		<visual>
			<geometry>
				<cylinder length="0.10430806287932759" radius="0.6293243395328799"/>
			</geometry>
		</visual>
		<collision>
			<geometry>
				<cylinder length="0.10430806287932759" radius="0.6293243395328799"/>
			</geometry>
		</collision>
		<inertial>
			<mass value="0.12978270156493504"/>
			<inertia ixx="0.03" ixy="0" ixz="0" iyx="0" iyy="0.03" izz="0.03"/>
		</inertial>
	</link>
	<link name="13">
		<visual>
			<geometry>
				<cylinder length="0.10430806287932759" radius="0.6293243395328799"/>
			</geometry>
		</visual>
		<collision>
			<geometry>
				<cylinder length="0.10430806287932759" radius="0.6293243395328799"/>
			</geometry>
		</collision>
		<inertial>
			<mass value="0.12978270156493504"/>
			<inertia ixx="0.03" ixy="0" ixz="0" iyx="0" iyy="0.03" izz="0.03"/>
		</inertial>
	</link>
	<joint name="11_to_0" type="revolute">
		<parent link="0"/>
		<child link="11"/>
		<axis xyz="1 0 0"/>
		<limit effort="1" lower="3.1415" upper="-3.1415" velocity="1"/>
		<origin rpy="6.524330174264022 4.717985807462383 2.359086977962126" xyz="0.18457565513068275 0.37313347329975777 0.8217667791091414"/>
	</joint>
	<joint name="12_to_0" type="revolute">
		<parent link="0"/>
		<child link="12"/>
		<axis xyz="1 0 0"/>
		<limit effort="1" lower="3.1415" upper="-3.1415" velocity="1"/>
		<origin rpy="9.786495261396032 4.717985807462383 2.359086977962126" xyz="0.18457565513068275 0.37313347329975777 0.8217667791091414"/>
	</joint>
	<joint name="13_to_0" type="revolute">
		<parent link="0"/>
		<child link="13"/>
		<axis xyz="1 0 0"/>
		<limit effort="1" lower="3.1415" upper="-3.1415" velocity="1"/>
		<origin rpy="13.048660348528044 4.717985807462383 2.359086977962126" xyz="0.18457565513068275 0.37313347329975777 0.8217667791091414"/>
	</joint>
</robot>
