<?xml version="1.0"?><robot name="pepe">
	<link name="0">
		<visual>
			<geometry>
				<cylinder length="0.40822760514093215" radius="0.7966574774006026"/>
			</geometry>
		</visual>
		<collision>
			<geometry>
				<cylinder length="0.40822760514093215" radius="0.7966574774006026"/>
			</geometry>
		</collision>
		<inertial>
			<mass value="0.8139458541752262"/>
			<inertia ixx="0.03" ixy="0" ixz="0" iyx="0" iyy="0.03" izz="0.03"/>
		</inertial>
	</link>
	<link name="11">
		<visual>
			<geometry>
				<cylinder length="1.0405702092825304" radius="0.7800194428038744"/>
			</geometry>
		</visual>
		<collision>
			<geometry>
				<cylinder length="1.0405702092825304" radius="0.7800194428038744"/>
			</geometry>
		</collision>
		<inertial>
			<mass value="1.9889877898897173"/>
			<inertia ixx="0.03" ixy="0" ixz="0" iyx="0" iyy="0.03" izz="0.03"/>
		</inertial>
	</link>
	<link name="22">
		<visual>
			<geometry>
				<cylinder length="0.849653953050868" radius="0.44209079357692094"/>
			</geometry>
		</visual>
		<collision>
			<geometry>
				<cylinder length="0.849653953050868" radius="0.44209079357692094"/>
			</geometry>
		</collision>
		<inertial>
			<mass value="0.5216928647685514"/>
			<inertia ixx="0.03" ixy="0" ixz="0" iyx="0" iyy="0.03" izz="0.03"/>
		</inertial>
	</link>
	<link name="43">
		<visual>
			<geometry>
				<cylinder length="1.1223021971240348" radius="0.16462157245364717"/>
			</geometry>
		</visual>
		<collision>
			<geometry>
				<cylinder length="1.1223021971240348" radius="0.16462157245364717"/>
			</geometry>
		</collision>
		<inertial>
			<mass value="0.09555054692555189"/>
			<inertia ixx="0.03" ixy="0" ixz="0" iyx="0" iyy="0.03" izz="0.03"/>
		</inertial>
	</link>
	<link name="64">
		<visual>
			<geometry>
				<cylinder length="1.0506945150317666" radius="0.8533924153043504"/>
			</geometry>
		</visual>
		<collision>
			<geometry>
				<cylinder length="1.0506945150317666" radius="0.8533924153043504"/>
			</geometry>
		</collision>
		<inertial>
			<mass value="2.4039415012928758"/>
			<inertia ixx="0.03" ixy="0" ixz="0" iyx="0" iyy="0.03" izz="0.03"/>
		</inertial>
	</link>
	<link name="85">
		<visual>
			<geometry>
				<cylinder length="0.19807085979372197" radius="0.707478838805014"/>
			</geometry>
		</visual>
		<collision>
			<geometry>
				<cylinder length="0.19807085979372197" radius="0.707478838805014"/>
			</geometry>
		</collision>
		<inertial>
			<mass value="0.31145647795027437"/>
			<inertia ixx="0.03" ixy="0" ixz="0" iyx="0" iyy="0.03" izz="0.03"/>
		</inertial>
	</link>
	<link name="66">
		<visual>
			<geometry>
				<cylinder length="1.0506945150317666" radius="0.8533924153043504"/>
			</geometry>
		</visual>
		<collision>
			<geometry>
				<cylinder length="1.0506945150317666" radius="0.8533924153043504"/>
			</geometry>
		</collision>
		<inertial>
			<mass value="2.4039415012928758"/>
			<inertia ixx="0.03" ixy="0" ixz="0" iyx="0" iyy="0.03" izz="0.03"/>
		</inertial>
	</link>
	<link name="87">
		<visual>
			<geometry>
				<cylinder length="0.19807085979372197" radius="0.707478838805014"/>
			</geometry>
		</visual>
		<collision>
			<geometry>
				<cylinder length="0.19807085979372197" radius="0.707478838805014"/>
			</geometry>
		</collision>
		<inertial>
			<mass value="0.31145647795027437"/>
			<inertia ixx="0.03" ixy="0" ixz="0" iyx="0" iyy="0.03" izz="0.03"/>
		</inertial>
	</link>
	<link name="68">
		<visual>
			<geometry>
				<cylinder length="1.0506945150317666" radius="0.8533924153043504"/>
			</geometry>
		</visual>
		<collision>
			<geometry>
				<cylinder length="1.0506945150317666" radius="0.8533924153043504"/>
			</geometry>
		</collision>
		<inertial>
			<mass value="2.4039415012928758"/>
			<inertia ixx="0.03" ixy="0" ixz="0" iyx="0" iyy="0.03" izz="0.03"/>
		</inertial>
	</link>
	<link name="89">
		<visual>
			<geometry>
				<cylinder length="0.19807085979372197" radius="0.707478838805014"/>
			</geometry>
		</visual>
		<collision>
			<geometry>
				<cylinder length="0.19807085979372197" radius="0.707478838805014"/>
			</geometry>
		</collision>
		<inertial>
			<mass value="0.31145647795027437"/>
			<inertia ixx="0.03" ixy="0" ixz="0" iyx="0" iyy="0.03" izz="0.03"/>
		</inertial>
	</link>
	<link name="410">
		<visual>
			<geometry>
				<cylinder length="1.1223021971240348" radius="0.16462157245364717"/>
			</geometry>
		</visual>
		<collision>
			<geometry>
				<cylinder length="1.1223021971240348" radius="0.16462157245364717"/>
			</geometry>
		</collision>
		<inertial>
			<mass value="0.09555054692555189"/>
			<inertia ixx="0.03" ixy="0" ixz="0" iyx="0" iyy="0.03" izz="0.03"/>
		</inertial>
	</link>
	<link name="611">
		<visual>
			<geometry>
				<cylinder length="1.0506945150317666" radius="0.8533924153043504"/>
			</geometry>
		</visual>
		<collision>
			<geometry>
				<cylinder length="1.0506945150317666" radius="0.8533924153043504"/>
			</geometry>
		</collision>
		<inertial>
			<mass value="2.4039415012928758"/>
			<inertia ixx="0.03" ixy="0" ixz="0" iyx="0" iyy="0.03" izz="0.03"/>
		</inertial>
	</link>
	<link name="812">
		<visual>
			<geometry>
				<cylinder length="0.19807085979372197" radius="0.707478838805014"/>
			</geometry>
		</visual>
		<collision>
			<geometry>
				<cylinder length="0.19807085979372197" radius="0.707478838805014"/>
			</geometry>
		</collision>
		<inertial>
			<mass value="0.31145647795027437"/>
			<inertia ixx="0.03" ixy="0" ixz="0" iyx="0" iyy="0.03" izz="0.03"/>
		</inertial>
	</link>
	<link name="613">
		<visual>
			<geometry>
				<cylinder length="1.0506945150317666" radius="0.8533924153043504"/>
			</geometry>
		</visual>
		<collision>
			<geometry>
				<cylinder length="1.0506945150317666" radius="0.8533924153043504"/>
			</geometry>
		</collision>
		<inertial>
			<mass value="2.4039415012928758"/>
			<inertia ixx="0.03" ixy="0" ixz="0" iyx="0" iyy="0.03" izz="0.03"/>
		</inertial>
	</link>
	<link name="814">
		<visual>
			<geometry>
				<cylinder length="0.19807085979372197" radius="0.707478838805014"/>
			</geometry>
		</visual>
		<collision>
			<geometry>
				<cylinder length="0.19807085979372197" radius="0.707478838805014"/>
			</geometry>
		</collision>
		<inertial>
			<mass value="0.31145647795027437"/>
			<inertia ixx="0.03" ixy="0" ixz="0" iyx="0" iyy="0.03" izz="0.03"/>
		</inertial>
	</link>
	<link name="615">
		<visual>
			<geometry>
				<cylinder length="1.0506945150317666" radius="0.8533924153043504"/>
			</geometry>
		</visual>
		<collision>
			<geometry>
				<cylinder length="1.0506945150317666" radius="0.8533924153043504"/>
			</geometry>
		</collision>
		<inertial>
			<mass value="2.4039415012928758"/>
			<inertia ixx="0.03" ixy="0" ixz="0" iyx="0" iyy="0.03" izz="0.03"/>
		</inertial>
	</link>
	<link name="816">
		<visual>
			<geometry>
				<cylinder length="0.19807085979372197" radius="0.707478838805014"/>
			</geometry>
		</visual>
		<collision>
			<geometry>
				<cylinder length="0.19807085979372197" radius="0.707478838805014"/>
			</geometry>
		</collision>
		<inertial>
			<mass value="0.31145647795027437"/>
			<inertia ixx="0.03" ixy="0" ixz="0" iyx="0" iyy="0.03" izz="0.03"/>
		</inertial>
	</link>
	<link name="417">
		<visual>
			<geometry>
				<cylinder length="1.1223021971240348" radius="0.16462157245364717"/>
			</geometry>
		</visual>
		<collision>
			<geometry>
				<cylinder length="1.1223021971240348" radius="0.16462157245364717"/>
			</geometry>
		</collision>
		<inertial>
			<mass value="0.09555054692555189"/>
			<inertia ixx="0.03" ixy="0" ixz="0" iyx="0" iyy="0.03" izz="0.03"/>
		</inertial>
	</link>
	<link name="618">
		<visual>
			<geometry>
				<cylinder length="1.0506945150317666" radius="0.8533924153043504"/>
			</geometry>
		</visual>
		<collision>
			<geometry>
				<cylinder length="1.0506945150317666" radius="0.8533924153043504"/>
			</geometry>
		</collision>
		<inertial>
			<mass value="2.4039415012928758"/>
			<inertia ixx="0.03" ixy="0" ixz="0" iyx="0" iyy="0.03" izz="0.03"/>
		</inertial>
	</link>
	<link name="819">
		<visual>
			<geometry>
				<cylinder length="0.19807085979372197" radius="0.707478838805014"/>
			</geometry>
		</visual>
		<collision>
			<geometry>
				<cylinder length="0.19807085979372197" radius="0.707478838805014"/>
			</geometry>
		</collision>
		<inertial>
			<mass value="0.31145647795027437"/>
			<inertia ixx="0.03" ixy="0" ixz="0" iyx="0" iyy="0.03" izz="0.03"/>
		</inertial>
	</link>
	<link name="620">
		<visual>
			<geometry>
				<cylinder length="1.0506945150317666" radius="0.8533924153043504"/>
			</geometry>
		</visual>
		<collision>
			<geometry>
				<cylinder length="1.0506945150317666" radius="0.8533924153043504"/>
			</geometry>
		</collision>
		<inertial>
			<mass value="2.4039415012928758"/>
			<inertia ixx="0.03" ixy="0" ixz="0" iyx="0" iyy="0.03" izz="0.03"/>
		</inertial>
	</link>
	<link name="821">
		<visual>
			<geometry>
				<cylinder length="0.19807085979372197" radius="0.707478838805014"/>
			</geometry>
		</visual>
		<collision>
			<geometry>
				<cylinder length="0.19807085979372197" radius="0.707478838805014"/>
			</geometry>
		</collision>
		<inertial>
			<mass value="0.31145647795027437"/>
			<inertia ixx="0.03" ixy="0" ixz="0" iyx="0" iyy="0.03" izz="0.03"/>
		</inertial>
	</link>
	<link name="622">
		<visual>
			<geometry>
				<cylinder length="1.0506945150317666" radius="0.8533924153043504"/>
			</geometry>
		</visual>
		<collision>
			<geometry>
				<cylinder length="1.0506945150317666" radius="0.8533924153043504"/>
			</geometry>
		</collision>
		<inertial>
			<mass value="2.4039415012928758"/>
			<inertia ixx="0.03" ixy="0" ixz="0" iyx="0" iyy="0.03" izz="0.03"/>
		</inertial>
	</link>
	<link name="823">
		<visual>
			<geometry>
				<cylinder length="0.19807085979372197" radius="0.707478838805014"/>
			</geometry>
		</visual>
		<collision>
			<geometry>
				<cylinder length="0.19807085979372197" radius="0.707478838805014"/>
			</geometry>
		</collision>
		<inertial>
			<mass value="0.31145647795027437"/>
			<inertia ixx="0.03" ixy="0" ixz="0" iyx="0" iyy="0.03" izz="0.03"/>
		</inertial>
	</link>
	<link name="224">
		<visual>
			<geometry>
				<cylinder length="0.849653953050868" radius="0.44209079357692094"/>
			</geometry>
		</visual>
		<collision>
			<geometry>
				<cylinder length="0.849653953050868" radius="0.44209079357692094"/>
			</geometry>
		</collision>
		<inertial>
			<mass value="0.5216928647685514"/>
			<inertia ixx="0.03" ixy="0" ixz="0" iyx="0" iyy="0.03" izz="0.03"/>
		</inertial>
	</link>
	<link name="425">
		<visual>
			<geometry>
				<cylinder length="1.1223021971240348" radius="0.16462157245364717"/>
			</geometry>
		</visual>
		<collision>
			<geometry>
				<cylinder length="1.1223021971240348" radius="0.16462157245364717"/>
			</geometry>
		</collision>
		<inertial>
			<mass value="0.09555054692555189"/>
			<inertia ixx="0.03" ixy="0" ixz="0" iyx="0" iyy="0.03" izz="0.03"/>
		</inertial>
	</link>
	<link name="626">
		<visual>
			<geometry>
				<cylinder length="1.0506945150317666" radius="0.8533924153043504"/>
			</geometry>
		</visual>
		<collision>
			<geometry>
				<cylinder length="1.0506945150317666" radius="0.8533924153043504"/>
			</geometry>
		</collision>
		<inertial>
			<mass value="2.4039415012928758"/>
			<inertia ixx="0.03" ixy="0" ixz="0" iyx="0" iyy="0.03" izz="0.03"/>
		</inertial>
	</link>
	<link name="827">
		<visual>
			<geometry>
				<cylinder length="0.19807085979372197" radius="0.707478838805014"/>
			</geometry>
		</visual>
		<collision>
			<geometry>
				<cylinder length="0.19807085979372197" radius="0.707478838805014"/>
			</geometry>
		</collision>
		<inertial>
			<mass value="0.31145647795027437"/>
			<inertia ixx="0.03" ixy="0" ixz="0" iyx="0" iyy="0.03" izz="0.03"/>
		</inertial>
	</link>
	<link name="628">
		<visual>
			<geometry>
				<cylinder length="1.0506945150317666" radius="0.8533924153043504"/>
			</geometry>
		</visual>
		<collision>
			<geometry>
				<cylinder length="1.0506945150317666" radius="0.8533924153043504"/>
			</geometry>
		</collision>
		<inertial>
			<mass value="2.4039415012928758"/>
			<inertia ixx="0.03" ixy="0" ixz="0" iyx="0" iyy="0.03" izz="0.03"/>
		</inertial>
	</link>
	<link name="829">
		<visual>
			<geometry>
				<cylinder length="0.19807085979372197" radius="0.707478838805014"/>
			</geometry>
		</visual>
		<collision>
			<geometry>
				<cylinder length="0.19807085979372197" radius="0.707478838805014"/>
			</geometry>
		</collision>
		<inertial>
			<mass value="0.31145647795027437"/>
			<inertia ixx="0.03" ixy="0" ixz="0" iyx="0" iyy="0.03" izz="0.03"/>
		</inertial>
	</link>
	<link name="630">
		<visual>
			<geometry>
				<cylinder length="1.0506945150317666" radius="0.8533924153043504"/>
			</geometry>
		</visual>
		<collision>
			<geometry>
				<cylinder length="1.0506945150317666" radius="0.8533924153043504"/>
			</geometry>
		</collision>
		<inertial>
			<mass value="2.4039415012928758"/>
			<inertia ixx="0.03" ixy="0" ixz="0" iyx="0" iyy="0.03" izz="0.03"/>
		</inertial>
	</link>
	<link name="831">
		<visual>
			<geometry>
				<cylinder length="0.19807085979372197" radius="0.707478838805014"/>
			</geometry>
		</visual>
		<collision>
			<geometry>
				<cylinder length="0.19807085979372197" radius="0.707478838805014"/>
			</geometry>
		</collision>
		<inertial>
			<mass value="0.31145647795027437"/>
			<inertia ixx="0.03" ixy="0" ixz="0" iyx="0" iyy="0.03" izz="0.03"/>
		</inertial>
	</link>
	<link name="432">
		<visual>
			<geometry>
				<cylinder length="1.1223021971240348" radius="0.16462157245364717"/>
			</geometry>
		</visual>
		<collision>
			<geometry>
				<cylinder length="1.1223021971240348" radius="0.16462157245364717"/>
			</geometry>
		</collision>
		<inertial>
			<mass value="0.09555054692555189"/>
			<inertia ixx="0.03" ixy="0" ixz="0" iyx="0" iyy="0.03" izz="0.03"/>
		</inertial>
	</link>
	<link name="633">
		<visual>
			<geometry>
				<cylinder length="1.0506945150317666" radius="0.8533924153043504"/>
			</geometry>
		</visual>
		<collision>
			<geometry>
				<cylinder length="1.0506945150317666" radius="0.8533924153043504"/>
			</geometry>
		</collision>
		<inertial>
			<mass value="2.4039415012928758"/>
			<inertia ixx="0.03" ixy="0" ixz="0" iyx="0" iyy="0.03" izz="0.03"/>
		</inertial>
	</link>
	<link name="834">
		<visual>
			<geometry>
				<cylinder length="0.19807085979372197" radius="0.707478838805014"/>
			</geometry>
		</visual>
		<collision>
			<geometry>
				<cylinder length="0.19807085979372197" radius="0.707478838805014"/>
			</geometry>
		</collision>
		<inertial>
			<mass value="0.31145647795027437"/>
			<inertia ixx="0.03" ixy="0" ixz="0" iyx="0" iyy="0.03" izz="0.03"/>
		</inertial>
	</link>
	<link name="635">
		<visual>
			<geometry>
				<cylinder length="1.0506945150317666" radius="0.8533924153043504"/>
			</geometry>
		</visual>
		<collision>
			<geometry>
				<cylinder length="1.0506945150317666" radius="0.8533924153043504"/>
			</geometry>
		</collision>
		<inertial>
			<mass value="2.4039415012928758"/>
			<inertia ixx="0.03" ixy="0" ixz="0" iyx="0" iyy="0.03" izz="0.03"/>
		</inertial>
	</link>
	<link name="836">
		<visual>
			<geometry>
				<cylinder length="0.19807085979372197" radius="0.707478838805014"/>
			</geometry>
		</visual>
		<collision>
			<geometry>
				<cylinder length="0.19807085979372197" radius="0.707478838805014"/>
			</geometry>
		</collision>
		<inertial>
			<mass value="0.31145647795027437"/>
			<inertia ixx="0.03" ixy="0" ixz="0" iyx="0" iyy="0.03" izz="0.03"/>
		</inertial>
	</link>
	<link name="637">
		<visual>
			<geometry>
				<cylinder length="1.0506945150317666" radius="0.8533924153043504"/>
			</geometry>
		</visual>
		<collision>
			<geometry>
				<cylinder length="1.0506945150317666" radius="0.8533924153043504"/>
			</geometry>
		</collision>
		<inertial>
			<mass value="2.4039415012928758"/>
			<inertia ixx="0.03" ixy="0" ixz="0" iyx="0" iyy="0.03" izz="0.03"/>
		</inertial>
	</link>
	<link name="838">
		<visual>
			<geometry>
				<cylinder length="0.19807085979372197" radius="0.707478838805014"/>
			</geometry>
		</visual>
		<collision>
			<geometry>
				<cylinder length="0.19807085979372197" radius="0.707478838805014"/>
			</geometry>
		</collision>
		<inertial>
			<mass value="0.31145647795027437"/>
			<inertia ixx="0.03" ixy="0" ixz="0" iyx="0" iyy="0.03" izz="0.03"/>
		</inertial>
	</link>
	<link name="439">
		<visual>
			<geometry>
				<cylinder length="1.1223021971240348" radius="0.16462157245364717"/>
			</geometry>
		</visual>
		<collision>
			<geometry>
				<cylinder length="1.1223021971240348" radius="0.16462157245364717"/>
			</geometry>
		</collision>
		<inertial>
			<mass value="0.09555054692555189"/>
			<inertia ixx="0.03" ixy="0" ixz="0" iyx="0" iyy="0.03" izz="0.03"/>
		</inertial>
	</link>
	<link name="640">
		<visual>
			<geometry>
				<cylinder length="1.0506945150317666" radius="0.8533924153043504"/>
			</geometry>
		</visual>
		<collision>
			<geometry>
				<cylinder length="1.0506945150317666" radius="0.8533924153043504"/>
			</geometry>
		</collision>
		<inertial>
			<mass value="2.4039415012928758"/>
			<inertia ixx="0.03" ixy="0" ixz="0" iyx="0" iyy="0.03" izz="0.03"/>
		</inertial>
	</link>
	<link name="841">
		<visual>
			<geometry>
				<cylinder length="0.19807085979372197" radius="0.707478838805014"/>
			</geometry>
		</visual>
		<collision>
			<geometry>
				<cylinder length="0.19807085979372197" radius="0.707478838805014"/>
			</geometry>
		</collision>
		<inertial>
			<mass value="0.31145647795027437"/>
			<inertia ixx="0.03" ixy="0" ixz="0" iyx="0" iyy="0.03" izz="0.03"/>
		</inertial>
	</link>
	<link name="642">
		<visual>
			<geometry>
				<cylinder length="1.0506945150317666" radius="0.8533924153043504"/>
			</geometry>
		</visual>
		<collision>
			<geometry>
				<cylinder length="1.0506945150317666" radius="0.8533924153043504"/>
			</geometry>
		</collision>
		<inertial>
			<mass value="2.4039415012928758"/>
			<inertia ixx="0.03" ixy="0" ixz="0" iyx="0" iyy="0.03" izz="0.03"/>
		</inertial>
	</link>
	<link name="843">
		<visual>
			<geometry>
				<cylinder length="0.19807085979372197" radius="0.707478838805014"/>
			</geometry>
		</visual>
		<collision>
			<geometry>
				<cylinder length="0.19807085979372197" radius="0.707478838805014"/>
			</geometry>
		</collision>
		<inertial>
			<mass value="0.31145647795027437"/>
			<inertia ixx="0.03" ixy="0" ixz="0" iyx="0" iyy="0.03" izz="0.03"/>
		</inertial>
	</link>
	<link name="644">
		<visual>
			<geometry>
				<cylinder length="1.0506945150317666" radius="0.8533924153043504"/>
			</geometry>
		</visual>
		<collision>
			<geometry>
				<cylinder length="1.0506945150317666" radius="0.8533924153043504"/>
			</geometry>
		</collision>
		<inertial>
			<mass value="2.4039415012928758"/>
			<inertia ixx="0.03" ixy="0" ixz="0" iyx="0" iyy="0.03" izz="0.03"/>
		</inertial>
	</link>
	<link name="845">
		<visual>
			<geometry>
				<cylinder length="0.19807085979372197" radius="0.707478838805014"/>
			</geometry>
		</visual>
		<collision>
			<geometry>
				<cylinder length="0.19807085979372197" radius="0.707478838805014"/>
			</geometry>
		</collision>
		<inertial>
			<mass value="0.31145647795027437"/>
			<inertia ixx="0.03" ixy="0" ixz="0" iyx="0" iyy="0.03" izz="0.03"/>
		</inertial>
	</link>
	<link name="1146">
		<visual>
			<geometry>
				<cylinder length="1.3969387081538238" radius="0.2797185829594738"/>
			</geometry>
		</visual>
		<collision>
			<geometry>
				<cylinder length="1.3969387081538238" radius="0.2797185829594738"/>
			</geometry>
		</collision>
		<inertial>
			<mass value="0.3433759414168353"/>
			<inertia ixx="0.03" ixy="0" ixz="0" iyx="0" iyy="0.03" izz="0.03"/>
		</inertial>
	</link>
	<link name="1147">
		<visual>
			<geometry>
				<cylinder length="1.3969387081538238" radius="0.2797185829594738"/>
			</geometry>
		</visual>
		<collision>
			<geometry>
				<cylinder length="1.3969387081538238" radius="0.2797185829594738"/>
			</geometry>
		</collision>
		<inertial>
			<mass value="0.3433759414168353"/>
			<inertia ixx="0.03" ixy="0" ixz="0" iyx="0" iyy="0.03" izz="0.03"/>
		</inertial>
	</link>
	<link name="348">
		<visual>
			<geometry>
				<cylinder length="0.27142930178008573" radius="0.16672744421248098"/>
			</geometry>
		</visual>
		<collision>
			<geometry>
				<cylinder length="0.27142930178008573" radius="0.16672744421248098"/>
			</geometry>
		</collision>
		<inertial>
			<mass value="0.023703953577840074"/>
			<inertia ixx="0.03" ixy="0" ixz="0" iyx="0" iyy="0.03" izz="0.03"/>
		</inertial>
	</link>
	<link name="1049">
		<visual>
			<geometry>
				<cylinder length="1.3695203358489894" radius="0.9793046814165782"/>
			</geometry>
		</visual>
		<collision>
			<geometry>
				<cylinder length="1.3695203358489894" radius="0.9793046814165782"/>
			</geometry>
		</collision>
		<inertial>
			<mass value="4.126235577075312"/>
			<inertia ixx="0.03" ixy="0" ixz="0" iyx="0" iyy="0.03" izz="0.03"/>
		</inertial>
	</link>
	<link name="1050">
		<visual>
			<geometry>
				<cylinder length="1.3695203358489894" radius="0.9793046814165782"/>
			</geometry>
		</visual>
		<collision>
			<geometry>
				<cylinder length="1.3695203358489894" radius="0.9793046814165782"/>
			</geometry>
		</collision>
		<inertial>
			<mass value="4.126235577075312"/>
			<inertia ixx="0.03" ixy="0" ixz="0" iyx="0" iyy="0.03" izz="0.03"/>
		</inertial>
	</link>
	<link name="1051">
		<visual>
			<geometry>
				<cylinder length="1.3695203358489894" radius="0.9793046814165782"/>
			</geometry>
		</visual>
		<collision>
			<geometry>
				<cylinder length="1.3695203358489894" radius="0.9793046814165782"/>
			</geometry>
		</collision>
		<inertial>
			<mass value="4.126235577075312"/>
			<inertia ixx="0.03" ixy="0" ixz="0" iyx="0" iyy="0.03" izz="0.03"/>
		</inertial>
	</link>
	<link name="352">
		<visual>
			<geometry>
				<cylinder length="0.27142930178008573" radius="0.16672744421248098"/>
			</geometry>
		</visual>
		<collision>
			<geometry>
				<cylinder length="0.27142930178008573" radius="0.16672744421248098"/>
			</geometry>
		</collision>
		<inertial>
			<mass value="0.023703953577840074"/>
			<inertia ixx="0.03" ixy="0" ixz="0" iyx="0" iyy="0.03" izz="0.03"/>
		</inertial>
	</link>
	<link name="1053">
		<visual>
			<geometry>
				<cylinder length="1.3695203358489894" radius="0.9793046814165782"/>
			</geometry>
		</visual>
		<collision>
			<geometry>
				<cylinder length="1.3695203358489894" radius="0.9793046814165782"/>
			</geometry>
		</collision>
		<inertial>
			<mass value="4.126235577075312"/>
			<inertia ixx="0.03" ixy="0" ixz="0" iyx="0" iyy="0.03" izz="0.03"/>
		</inertial>
	</link>
	<link name="1054">
		<visual>
			<geometry>
				<cylinder length="1.3695203358489894" radius="0.9793046814165782"/>
			</geometry>
		</visual>
		<collision>
			<geometry>
				<cylinder length="1.3695203358489894" radius="0.9793046814165782"/>
			</geometry>
		</collision>
		<inertial>
			<mass value="4.126235577075312"/>
			<inertia ixx="0.03" ixy="0" ixz="0" iyx="0" iyy="0.03" izz="0.03"/>
		</inertial>
	</link>
	<link name="1055">
		<visual>
			<geometry>
				<cylinder length="1.3695203358489894" radius="0.9793046814165782"/>
			</geometry>
		</visual>
		<collision>
			<geometry>
				<cylinder length="1.3695203358489894" radius="0.9793046814165782"/>
			</geometry>
		</collision>
		<inertial>
			<mass value="4.126235577075312"/>
			<inertia ixx="0.03" ixy="0" ixz="0" iyx="0" iyy="0.03" izz="0.03"/>
		</inertial>
	</link>
	<link name="556">
		<visual>
			<geometry>
				<cylinder length="0.2980986715695999" radius="0.8394130725775503"/>
			</geometry>
		</visual>
		<collision>
			<geometry>
				<cylinder length="0.2980986715695999" radius="0.8394130725775503"/>
			</geometry>
		</collision>
		<inertial>
			<mass value="0.6598745368206834"/>
			<inertia ixx="0.03" ixy="0" ixz="0" iyx="0" iyy="0.03" izz="0.03"/>
		</inertial>
	</link>
	<link name="957">
		<visual>
			<geometry>
				<cylinder length="1.319274594883958" radius="0.7016124186034169"/>
			</geometry>
		</visual>
		<collision>
			<geometry>
				<cylinder length="1.319274594883958" radius="0.7016124186034169"/>
			</geometry>
		</collision>
		<inertial>
			<mass value="2.040232244472827"/>
			<inertia ixx="0.03" ixy="0" ixz="0" iyx="0" iyy="0.03" izz="0.03"/>
		</inertial>
	</link>
	<link name="958">
		<visual>
			<geometry>
				<cylinder length="1.319274594883958" radius="0.7016124186034169"/>
			</geometry>
		</visual>
		<collision>
			<geometry>
				<cylinder length="1.319274594883958" radius="0.7016124186034169"/>
			</geometry>
		</collision>
		<inertial>
			<mass value="2.040232244472827"/>
			<inertia ixx="0.03" ixy="0" ixz="0" iyx="0" iyy="0.03" izz="0.03"/>
		</inertial>
	</link>
	<link name="959">
		<visual>
			<geometry>
				<cylinder length="1.319274594883958" radius="0.7016124186034169"/>
			</geometry>
		</visual>
		<collision>
			<geometry>
				<cylinder length="1.319274594883958" radius="0.7016124186034169"/>
			</geometry>
		</collision>
		<inertial>
			<mass value="2.040232244472827"/>
			<inertia ixx="0.03" ixy="0" ixz="0" iyx="0" iyy="0.03" izz="0.03"/>
		</inertial>
	</link>
	<link name="560">
		<visual>
			<geometry>
				<cylinder length="0.2980986715695999" radius="0.8394130725775503"/>
			</geometry>
		</visual>
		<collision>
			<geometry>
				<cylinder length="0.2980986715695999" radius="0.8394130725775503"/>
			</geometry>
		</collision>
		<inertial>
			<mass value="0.6598745368206834"/>
			<inertia ixx="0.03" ixy="0" ixz="0" iyx="0" iyy="0.03" izz="0.03"/>
		</inertial>
	</link>
	<link name="961">
		<visual>
			<geometry>
				<cylinder length="1.319274594883958" radius="0.7016124186034169"/>
			</geometry>
		</visual>
		<collision>
			<geometry>
				<cylinder length="1.319274594883958" radius="0.7016124186034169"/>
			</geometry>
		</collision>
		<inertial>
			<mass value="2.040232244472827"/>
			<inertia ixx="0.03" ixy="0" ixz="0" iyx="0" iyy="0.03" izz="0.03"/>
		</inertial>
	</link>
	<link name="962">
		<visual>
			<geometry>
				<cylinder length="1.319274594883958" radius="0.7016124186034169"/>
			</geometry>
		</visual>
		<collision>
			<geometry>
				<cylinder length="1.319274594883958" radius="0.7016124186034169"/>
			</geometry>
		</collision>
		<inertial>
			<mass value="2.040232244472827"/>
			<inertia ixx="0.03" ixy="0" ixz="0" iyx="0" iyy="0.03" izz="0.03"/>
		</inertial>
	</link>
	<link name="963">
		<visual>
			<geometry>
				<cylinder length="1.319274594883958" radius="0.7016124186034169"/>
			</geometry>
		</visual>
		<collision>
			<geometry>
				<cylinder length="1.319274594883958" radius="0.7016124186034169"/>
			</geometry>
		</collision>
		<inertial>
			<mass value="2.040232244472827"/>
			<inertia ixx="0.03" ixy="0" ixz="0" iyx="0" iyy="0.03" izz="0.03"/>
		</inertial>
	</link>
	<link name="764">
		<visual>
			<geometry>
				<cylinder length="0.7390831769888209" radius="0.7629603532872585"/>
			</geometry>
		</visual>
		<collision>
			<geometry>
				<cylinder length="0.7390831769888209" radius="0.7629603532872585"/>
			</geometry>
		</collision>
		<inertial>
			<mass value="1.3515967260672412"/>
			<inertia ixx="0.03" ixy="0" ixz="0" iyx="0" iyy="0.03" izz="0.03"/>
		</inertial>
	</link>
	<joint name="11_to_0" type="revolute">
		<parent link="0"/>
		<child link="11"/>
		<axis xyz="0 0 1"/>
		<limit effort="1" lower="3.1415" upper="-3.1415" velocity="1"/>
		<origin rpy="11.822094737011717 3.2344109917944204 6.2708300967620465" xyz="0.7828126461661352 0.7986140533382843 0.43640233465293987"/>
	</joint>
	<joint name="22_to_11" type="revolute">
		<parent link="11"/>
		<child link="22"/>
		<axis xyz="0 1 0"/>
		<limit effort="1" lower="3.1415" upper="-3.1415" velocity="1"/>
		<origin rpy="1.8616732608495665 2.309547221866396 2.5437504573615826" xyz="0.2898618834629527 0.12111020551829221 0.2987015808209723"/>
	</joint>
	<joint name="43_to_22" type="revolute">
		<parent link="22"/>
		<child link="43"/>
		<axis xyz="1 0 0"/>
		<limit effort="1" lower="3.1415" upper="-3.1415" velocity="1"/>
		<origin rpy="12.351760547302755 4.866146533503591 3.93600277992102" xyz="0.0795227714165776 0.07899819511160344 0.9403764140235277"/>
	</joint>
	<joint name="64_to_43" type="revolute">
		<parent link="43"/>
		<child link="64"/>
		<axis xyz="1 0 0"/>
		<limit effort="1" lower="3.1415" upper="-3.1415" velocity="1"/>
		<origin rpy="7.293624636999397 3.007103172227348 2.383112587734063" xyz="0.03500880458913069 0.9465450328437638 0.957432691851095"/>
	</joint>
	<joint name="85_to_64" type="revolute">
		<parent link="64"/>
		<child link="85"/>
		<axis xyz="0 0 1"/>
		<limit effort="1" lower="3.1415" upper="-3.1415" velocity="1"/>
		<origin rpy="0.690173890197422 3.0872900666689023 3.091815968624401" xyz="0.5897459048431841 0.9667936021174044 0.30451345024267074"/>
	</joint>
	<joint name="66_to_43" type="revolute">
		<parent link="43"/>
		<child link="66"/>
		<axis xyz="1 0 0"/>
		<limit effort="1" lower="3.1415" upper="-3.1415" velocity="1"/>
		<origin rpy="10.940436955499095 3.007103172227348 2.383112587734063" xyz="0.03500880458913069 0.9465450328437638 0.957432691851095"/>
	</joint>
	<joint name="87_to_66" type="revolute">
		<parent link="66"/>
		<child link="87"/>
		<axis xyz="0 0 1"/>
		<limit effort="1" lower="3.1415" upper="-3.1415" velocity="1"/>
		<origin rpy="0.690173890197422 3.0872900666689023 3.091815968624401" xyz="0.5897459048431841 0.9667936021174044 0.30451345024267074"/>
	</joint>
	<joint name="68_to_43" type="revolute">
		<parent link="43"/>
		<child link="68"/>
		<axis xyz="1 0 0"/>
		<limit effort="1" lower="3.1415" upper="-3.1415" velocity="1"/>
		<origin rpy="14.587249273998793 3.007103172227348 2.383112587734063" xyz="0.03500880458913069 0.9465450328437638 0.957432691851095"/>
	</joint>
	<joint name="89_to_68" type="revolute">
		<parent link="68"/>
		<child link="89"/>
		<axis xyz="0 0 1"/>
		<limit effort="1" lower="3.1415" upper="-3.1415" velocity="1"/>
		<origin rpy="0.690173890197422 3.0872900666689023 3.091815968624401" xyz="0.5897459048431841 0.9667936021174044 0.30451345024267074"/>
	</joint>
	<joint name="410_to_22" type="revolute">
		<parent link="22"/>
		<child link="410"/>
		<axis xyz="1 0 0"/>
		<limit effort="1" lower="3.1415" upper="-3.1415" velocity="1"/>
		<origin rpy="18.527640820954133 4.866146533503591 3.93600277992102" xyz="0.0795227714165776 0.07899819511160344 0.9403764140235277"/>
	</joint>
	<joint name="611_to_410" type="revolute">
		<parent link="410"/>
		<child link="611"/>
		<axis xyz="1 0 0"/>
		<limit effort="1" lower="3.1415" upper="-3.1415" velocity="1"/>
		<origin rpy="7.293624636999397 3.007103172227348 2.383112587734063" xyz="0.03500880458913069 0.9465450328437638 0.957432691851095"/>
	</joint>
	<joint name="812_to_611" type="revolute">
		<parent link="611"/>
		<child link="812"/>
		<axis xyz="0 0 1"/>
		<limit effort="1" lower="3.1415" upper="-3.1415" velocity="1"/>
		<origin rpy="0.690173890197422 3.0872900666689023 3.091815968624401" xyz="0.5897459048431841 0.9667936021174044 0.30451345024267074"/>
	</joint>
	<joint name="613_to_410" type="revolute">
		<parent link="410"/>
		<child link="613"/>
		<axis xyz="1 0 0"/>
		<limit effort="1" lower="3.1415" upper="-3.1415" velocity="1"/>
		<origin rpy="10.940436955499095 3.007103172227348 2.383112587734063" xyz="0.03500880458913069 0.9465450328437638 0.957432691851095"/>
	</joint>
	<joint name="814_to_613" type="revolute">
		<parent link="613"/>
		<child link="814"/>
		<axis xyz="0 0 1"/>
		<limit effort="1" lower="3.1415" upper="-3.1415" velocity="1"/>
		<origin rpy="0.690173890197422 3.0872900666689023 3.091815968624401" xyz="0.5897459048431841 0.9667936021174044 0.30451345024267074"/>
	</joint>
	<joint name="615_to_410" type="revolute">
		<parent link="410"/>
		<child link="615"/>
		<axis xyz="1 0 0"/>
		<limit effort="1" lower="3.1415" upper="-3.1415" velocity="1"/>
		<origin rpy="14.587249273998793 3.007103172227348 2.383112587734063" xyz="0.03500880458913069 0.9465450328437638 0.957432691851095"/>
	</joint>
	<joint name="816_to_615" type="revolute">
		<parent link="615"/>
		<child link="816"/>
		<axis xyz="0 0 1"/>
		<limit effort="1" lower="3.1415" upper="-3.1415" velocity="1"/>
		<origin rpy="0.690173890197422 3.0872900666689023 3.091815968624401" xyz="0.5897459048431841 0.9667936021174044 0.30451345024267074"/>
	</joint>
	<joint name="417_to_22" type="revolute">
		<parent link="22"/>
		<child link="417"/>
		<axis xyz="1 0 0"/>
		<limit effort="1" lower="3.1415" upper="-3.1415" velocity="1"/>
		<origin rpy="24.70352109460551 4.866146533503591 3.93600277992102" xyz="0.0795227714165776 0.07899819511160344 0.9403764140235277"/>
	</joint>
	<joint name="618_to_417" type="revolute">
		<parent link="417"/>
		<child link="618"/>
		<axis xyz="1 0 0"/>
		<limit effort="1" lower="3.1415" upper="-3.1415" velocity="1"/>
		<origin rpy="7.293624636999397 3.007103172227348 2.383112587734063" xyz="0.03500880458913069 0.9465450328437638 0.957432691851095"/>
	</joint>
	<joint name="819_to_618" type="revolute">
		<parent link="618"/>
		<child link="819"/>
		<axis xyz="0 0 1"/>
		<limit effort="1" lower="3.1415" upper="-3.1415" velocity="1"/>
		<origin rpy="0.690173890197422 3.0872900666689023 3.091815968624401" xyz="0.5897459048431841 0.9667936021174044 0.30451345024267074"/>
	</joint>
	<joint name="620_to_417" type="revolute">
		<parent link="417"/>
		<child link="620"/>
		<axis xyz="1 0 0"/>
		<limit effort="1" lower="3.1415" upper="-3.1415" velocity="1"/>
		<origin rpy="10.940436955499095 3.007103172227348 2.383112587734063" xyz="0.03500880458913069 0.9465450328437638 0.957432691851095"/>
	</joint>
	<joint name="821_to_620" type="revolute">
		<parent link="620"/>
		<child link="821"/>
		<axis xyz="0 0 1"/>
		<limit effort="1" lower="3.1415" upper="-3.1415" velocity="1"/>
		<origin rpy="0.690173890197422 3.0872900666689023 3.091815968624401" xyz="0.5897459048431841 0.9667936021174044 0.30451345024267074"/>
	</joint>
	<joint name="622_to_417" type="revolute">
		<parent link="417"/>
		<child link="622"/>
		<axis xyz="1 0 0"/>
		<limit effort="1" lower="3.1415" upper="-3.1415" velocity="1"/>
		<origin rpy="14.587249273998793 3.007103172227348 2.383112587734063" xyz="0.03500880458913069 0.9465450328437638 0.957432691851095"/>
	</joint>
	<joint name="823_to_622" type="revolute">
		<parent link="622"/>
		<child link="823"/>
		<axis xyz="0 0 1"/>
		<limit effort="1" lower="3.1415" upper="-3.1415" velocity="1"/>
		<origin rpy="0.690173890197422 3.0872900666689023 3.091815968624401" xyz="0.5897459048431841 0.9667936021174044 0.30451345024267074"/>
	</joint>
	<joint name="224_to_11" type="revolute">
		<parent link="11"/>
		<child link="224"/>
		<axis xyz="0 1 0"/>
		<limit effort="1" lower="3.1415" upper="-3.1415" velocity="1"/>
		<origin rpy="2.79250989127435 2.309547221866396 2.5437504573615826" xyz="0.2898618834629527 0.12111020551829221 0.2987015808209723"/>
	</joint>
	<joint name="425_to_224" type="revolute">
		<parent link="224"/>
		<child link="425"/>
		<axis xyz="1 0 0"/>
		<limit effort="1" lower="3.1415" upper="-3.1415" velocity="1"/>
		<origin rpy="12.351760547302755 4.866146533503591 3.93600277992102" xyz="0.0795227714165776 0.07899819511160344 0.9403764140235277"/>
	</joint>
	<joint name="626_to_425" type="revolute">
		<parent link="425"/>
		<child link="626"/>
		<axis xyz="1 0 0"/>
		<limit effort="1" lower="3.1415" upper="-3.1415" velocity="1"/>
		<origin rpy="7.293624636999397 3.007103172227348 2.383112587734063" xyz="0.03500880458913069 0.9465450328437638 0.957432691851095"/>
	</joint>
	<joint name="827_to_626" type="revolute">
		<parent link="626"/>
		<child link="827"/>
		<axis xyz="0 0 1"/>
		<limit effort="1" lower="3.1415" upper="-3.1415" velocity="1"/>
		<origin rpy="0.690173890197422 3.0872900666689023 3.091815968624401" xyz="0.5897459048431841 0.9667936021174044 0.30451345024267074"/>
	</joint>
	<joint name="628_to_425" type="revolute">
		<parent link="425"/>
		<child link="628"/>
		<axis xyz="1 0 0"/>
		<limit effort="1" lower="3.1415" upper="-3.1415" velocity="1"/>
		<origin rpy="10.940436955499095 3.007103172227348 2.383112587734063" xyz="0.03500880458913069 0.9465450328437638 0.957432691851095"/>
	</joint>
	<joint name="829_to_628" type="revolute">
		<parent link="628"/>
		<child link="829"/>
		<axis xyz="0 0 1"/>
		<limit effort="1" lower="3.1415" upper="-3.1415" velocity="1"/>
		<origin rpy="0.690173890197422 3.0872900666689023 3.091815968624401" xyz="0.5897459048431841 0.9667936021174044 0.30451345024267074"/>
	</joint>
	<joint name="630_to_425" type="revolute">
		<parent link="425"/>
		<child link="630"/>
		<axis xyz="1 0 0"/>
		<limit effort="1" lower="3.1415" upper="-3.1415" velocity="1"/>
		<origin rpy="14.587249273998793 3.007103172227348 2.383112587734063" xyz="0.03500880458913069 0.9465450328437638 0.957432691851095"/>
	</joint>
	<joint name="831_to_630" type="revolute">
		<parent link="630"/>
		<child link="831"/>
		<axis xyz="0 0 1"/>
		<limit effort="1" lower="3.1415" upper="-3.1415" velocity="1"/>
		<origin rpy="0.690173890197422 3.0872900666689023 3.091815968624401" xyz="0.5897459048431841 0.9667936021174044 0.30451345024267074"/>
	</joint>
	<joint name="432_to_224" type="revolute">
		<parent link="224"/>
		<child link="432"/>
		<axis xyz="1 0 0"/>
		<limit effort="1" lower="3.1415" upper="-3.1415" velocity="1"/>
		<origin rpy="18.527640820954133 4.866146533503591 3.93600277992102" xyz="0.0795227714165776 0.07899819511160344 0.9403764140235277"/>
	</joint>
	<joint name="633_to_432" type="revolute">
		<parent link="432"/>
		<child link="633"/>
		<axis xyz="1 0 0"/>
		<limit effort="1" lower="3.1415" upper="-3.1415" velocity="1"/>
		<origin rpy="7.293624636999397 3.007103172227348 2.383112587734063" xyz="0.03500880458913069 0.9465450328437638 0.957432691851095"/>
	</joint>
	<joint name="834_to_633" type="revolute">
		<parent link="633"/>
		<child link="834"/>
		<axis xyz="0 0 1"/>
		<limit effort="1" lower="3.1415" upper="-3.1415" velocity="1"/>
		<origin rpy="0.690173890197422 3.0872900666689023 3.091815968624401" xyz="0.5897459048431841 0.9667936021174044 0.30451345024267074"/>
	</joint>
	<joint name="635_to_432" type="revolute">
		<parent link="432"/>
		<child link="635"/>
		<axis xyz="1 0 0"/>
		<limit effort="1" lower="3.1415" upper="-3.1415" velocity="1"/>
		<origin rpy="10.940436955499095 3.007103172227348 2.383112587734063" xyz="0.03500880458913069 0.9465450328437638 0.957432691851095"/>
	</joint>
	<joint name="836_to_635" type="revolute">
		<parent link="635"/>
		<child link="836"/>
		<axis xyz="0 0 1"/>
		<limit effort="1" lower="3.1415" upper="-3.1415" velocity="1"/>
		<origin rpy="0.690173890197422 3.0872900666689023 3.091815968624401" xyz="0.5897459048431841 0.9667936021174044 0.30451345024267074"/>
	</joint>
	<joint name="637_to_432" type="revolute">
		<parent link="432"/>
		<child link="637"/>
		<axis xyz="1 0 0"/>
		<limit effort="1" lower="3.1415" upper="-3.1415" velocity="1"/>
		<origin rpy="14.587249273998793 3.007103172227348 2.383112587734063" xyz="0.03500880458913069 0.9465450328437638 0.957432691851095"/>
	</joint>
	<joint name="838_to_637" type="revolute">
		<parent link="637"/>
		<child link="838"/>
		<axis xyz="0 0 1"/>
		<limit effort="1" lower="3.1415" upper="-3.1415" velocity="1"/>
		<origin rpy="0.690173890197422 3.0872900666689023 3.091815968624401" xyz="0.5897459048431841 0.9667936021174044 0.30451345024267074"/>
	</joint>
	<joint name="439_to_224" type="revolute">
		<parent link="224"/>
		<child link="439"/>
		<axis xyz="1 0 0"/>
		<limit effort="1" lower="3.1415" upper="-3.1415" velocity="1"/>
		<origin rpy="24.70352109460551 4.866146533503591 3.93600277992102" xyz="0.0795227714165776 0.07899819511160344 0.9403764140235277"/>
	</joint>
	<joint name="640_to_439" type="revolute">
		<parent link="439"/>
		<child link="640"/>
		<axis xyz="1 0 0"/>
		<limit effort="1" lower="3.1415" upper="-3.1415" velocity="1"/>
		<origin rpy="7.293624636999397 3.007103172227348 2.383112587734063" xyz="0.03500880458913069 0.9465450328437638 0.957432691851095"/>
	</joint>
	<joint name="841_to_640" type="revolute">
		<parent link="640"/>
		<child link="841"/>
		<axis xyz="0 0 1"/>
		<limit effort="1" lower="3.1415" upper="-3.1415" velocity="1"/>
		<origin rpy="0.690173890197422 3.0872900666689023 3.091815968624401" xyz="0.5897459048431841 0.9667936021174044 0.30451345024267074"/>
	</joint>
	<joint name="642_to_439" type="revolute">
		<parent link="439"/>
		<child link="642"/>
		<axis xyz="1 0 0"/>
		<limit effort="1" lower="3.1415" upper="-3.1415" velocity="1"/>
		<origin rpy="10.940436955499095 3.007103172227348 2.383112587734063" xyz="0.03500880458913069 0.9465450328437638 0.957432691851095"/>
	</joint>
	<joint name="843_to_642" type="revolute">
		<parent link="642"/>
		<child link="843"/>
		<axis xyz="0 0 1"/>
		<limit effort="1" lower="3.1415" upper="-3.1415" velocity="1"/>
		<origin rpy="0.690173890197422 3.0872900666689023 3.091815968624401" xyz="0.5897459048431841 0.9667936021174044 0.30451345024267074"/>
	</joint>
	<joint name="644_to_439" type="revolute">
		<parent link="439"/>
		<child link="644"/>
		<axis xyz="1 0 0"/>
		<limit effort="1" lower="3.1415" upper="-3.1415" velocity="1"/>
		<origin rpy="14.587249273998793 3.007103172227348 2.383112587734063" xyz="0.03500880458913069 0.9465450328437638 0.957432691851095"/>
	</joint>
	<joint name="845_to_644" type="revolute">
		<parent link="644"/>
		<child link="845"/>
		<axis xyz="0 0 1"/>
		<limit effort="1" lower="3.1415" upper="-3.1415" velocity="1"/>
		<origin rpy="0.690173890197422 3.0872900666689023 3.091815968624401" xyz="0.5897459048431841 0.9667936021174044 0.30451345024267074"/>
	</joint>
	<joint name="1146_to_11" type="revolute">
		<parent link="11"/>
		<child link="1146"/>
		<axis xyz="1 0 0"/>
		<limit effort="1" lower="3.1415" upper="-3.1415" velocity="1"/>
		<origin rpy="19.01390187411934 0.8561090588488995 0.7694526617129129" xyz="0.3423828114444265 0.034751076140057235 0.6588360001906323"/>
	</joint>
	<joint name="1147_to_11" type="revolute">
		<parent link="11"/>
		<child link="1147"/>
		<axis xyz="1 0 0"/>
		<limit effort="1" lower="3.1415" upper="-3.1415" velocity="1"/>
		<origin rpy="23.767377342649176 0.8561090588488995 0.7694526617129129" xyz="0.3423828114444265 0.034751076140057235 0.6588360001906323"/>
	</joint>
	<joint name="348_to_0" type="revolute">
		<parent link="0"/>
		<child link="348"/>
		<axis xyz="0 1 0"/>
		<limit effort="1" lower="3.1415" upper="-3.1415" velocity="1"/>
		<origin rpy="6.443767287826526 1.541742815005916 4.333288145743621" xyz="0.5384865003818801 0.36810618671737816 0.9782339347613873"/>
	</joint>
	<joint name="1049_to_348" type="revolute">
		<parent link="348"/>
		<child link="1049"/>
		<axis xyz="0 0 1"/>
		<limit effort="1" lower="3.1415" upper="-3.1415" velocity="1"/>
		<origin rpy="3.4041331543050393 5.949841444419147 0.5858163661468186" xyz="0.1809368801136635 0.27070320647523094 0.7879792012950888"/>
	</joint>
	<joint name="1050_to_348" type="revolute">
		<parent link="348"/>
		<child link="1050"/>
		<axis xyz="0 0 1"/>
		<limit effort="1" lower="3.1415" upper="-3.1415" velocity="1"/>
		<origin rpy="5.106199731457559 5.949841444419147 0.5858163661468186" xyz="0.1809368801136635 0.27070320647523094 0.7879792012950888"/>
	</joint>
	<joint name="1051_to_348" type="revolute">
		<parent link="348"/>
		<child link="1051"/>
		<axis xyz="0 0 1"/>
		<limit effort="1" lower="3.1415" upper="-3.1415" velocity="1"/>
		<origin rpy="6.8082663086100785 5.949841444419147 0.5858163661468186" xyz="0.1809368801136635 0.27070320647523094 0.7879792012950888"/>
	</joint>
	<joint name="352_to_0" type="revolute">
		<parent link="0"/>
		<child link="352"/>
		<axis xyz="0 1 0"/>
		<limit effort="1" lower="3.1415" upper="-3.1415" velocity="1"/>
		<origin rpy="8.591689717102035 1.541742815005916 4.333288145743621" xyz="0.5384865003818801 0.36810618671737816 0.9782339347613873"/>
	</joint>
	<joint name="1053_to_352" type="revolute">
		<parent link="352"/>
		<child link="1053"/>
		<axis xyz="0 0 1"/>
		<limit effort="1" lower="3.1415" upper="-3.1415" velocity="1"/>
		<origin rpy="3.4041331543050393 5.949841444419147 0.5858163661468186" xyz="0.1809368801136635 0.27070320647523094 0.7879792012950888"/>
	</joint>
	<joint name="1054_to_352" type="revolute">
		<parent link="352"/>
		<child link="1054"/>
		<axis xyz="0 0 1"/>
		<limit effort="1" lower="3.1415" upper="-3.1415" velocity="1"/>
		<origin rpy="5.106199731457559 5.949841444419147 0.5858163661468186" xyz="0.1809368801136635 0.27070320647523094 0.7879792012950888"/>
	</joint>
	<joint name="1055_to_352" type="revolute">
		<parent link="352"/>
		<child link="1055"/>
		<axis xyz="0 0 1"/>
		<limit effort="1" lower="3.1415" upper="-3.1415" velocity="1"/>
		<origin rpy="6.8082663086100785 5.949841444419147 0.5858163661468186" xyz="0.1809368801136635 0.27070320647523094 0.7879792012950888"/>
	</joint>
	<joint name="556_to_0" type="revolute">
		<parent link="0"/>
		<child link="556"/>
		<axis xyz="0 1 0"/>
		<limit effort="1" lower="3.1415" upper="-3.1415" velocity="1"/>
		<origin rpy="17.841971329215976 1.5957991928453787 1.3425006001442445" xyz="0.41243871539538246 0.5121799284126735 0.27366759565566456"/>
	</joint>
	<joint name="957_to_556" type="revolute">
		<parent link="556"/>
		<child link="957"/>
		<axis xyz="1 0 0"/>
		<limit effort="1" lower="3.1415" upper="-3.1415" velocity="1"/>
		<origin rpy="5.566358203215809 4.699692982970437 4.560035112450073" xyz="0.5492848996184815 0.9585454484674019 0.04537651413796595"/>
	</joint>
	<joint name="958_to_556" type="revolute">
		<parent link="556"/>
		<child link="958"/>
		<axis xyz="1 0 0"/>
		<limit effort="1" lower="3.1415" upper="-3.1415" velocity="1"/>
		<origin rpy="8.349537304823713 4.699692982970437 4.560035112450073" xyz="0.5492848996184815 0.9585454484674019 0.04537651413796595"/>
	</joint>
	<joint name="959_to_556" type="revolute">
		<parent link="556"/>
		<child link="959"/>
		<axis xyz="1 0 0"/>
		<limit effort="1" lower="3.1415" upper="-3.1415" velocity="1"/>
		<origin rpy="11.132716406431618 4.699692982970437 4.560035112450073" xyz="0.5492848996184815 0.9585454484674019 0.04537651413796595"/>
	</joint>
	<joint name="560_to_0" type="revolute">
		<parent link="0"/>
		<child link="560"/>
		<axis xyz="0 1 0"/>
		<limit effort="1" lower="3.1415" upper="-3.1415" velocity="1"/>
		<origin rpy="21.41036559505917 1.5957991928453787 1.3425006001442445" xyz="0.41243871539538246 0.5121799284126735 0.27366759565566456"/>
	</joint>
	<joint name="961_to_560" type="revolute">
		<parent link="560"/>
		<child link="961"/>
		<axis xyz="1 0 0"/>
		<limit effort="1" lower="3.1415" upper="-3.1415" velocity="1"/>
		<origin rpy="5.566358203215809 4.699692982970437 4.560035112450073" xyz="0.5492848996184815 0.9585454484674019 0.04537651413796595"/>
	</joint>
	<joint name="962_to_560" type="revolute">
		<parent link="560"/>
		<child link="962"/>
		<axis xyz="1 0 0"/>
		<limit effort="1" lower="3.1415" upper="-3.1415" velocity="1"/>
		<origin rpy="8.349537304823713 4.699692982970437 4.560035112450073" xyz="0.5492848996184815 0.9585454484674019 0.04537651413796595"/>
	</joint>
	<joint name="963_to_560" type="revolute">
		<parent link="560"/>
		<child link="963"/>
		<axis xyz="1 0 0"/>
		<limit effort="1" lower="3.1415" upper="-3.1415" velocity="1"/>
		<origin rpy="11.132716406431618 4.699692982970437 4.560035112450073" xyz="0.5492848996184815 0.9585454484674019 0.04537651413796595"/>
	</joint>
	<joint name="764_to_0" type="revolute">
		<parent link="0"/>
		<child link="764"/>
		<axis xyz="0 1 0"/>
		<limit effort="1" lower="3.1415" upper="-3.1415" velocity="1"/>
		<origin rpy="35.701716692082144 1.1509652196123565 4.159956866208719" xyz="0.35109787791652247 0.6840231105680503 0.8323246229831529"/>
	</joint>
</robot>
