<?xml version="1.0"?><robot name="pepe">
	<link name="0">
		<visual>
			<geometry>
				<cylinder length="0.1840588742756495" radius="0.7477842884599845"/>
			</geometry>
		</visual>
		<collision>
			<geometry>
				<cylinder length="0.1840588742756495" radius="0.7477842884599845"/>
			</geometry>
		</collision>
		<inertial>
			<mass value="0.32333990492988784"/>
			<inertia ixx="0.03" ixy="0" ixz="0" iyx="0" iyy="0.03" izz="0.03"/>
		</inertial>
	</link>
	<link name="11">
		<visual>
			<geometry>
				<cylinder length="0.9590842794497736" radius="0.9999"/>
			</geometry>
		</visual>
		<collision>
			<geometry>
				<cylinder length="0.9590842794497736" radius="0.9999"/>
			</geometry>
		</collision>
		<inertial>
			<mass value="3.012449546198092"/>
			<inertia ixx="0.03" ixy="0" ixz="0" iyx="0" iyy="0.03" izz="0.03"/>
		</inertial>
	</link>
	<link name="22">
		<visual>
			<geometry>
				<cylinder length="0.1840588742756495" radius="0.7477842884599845"/>
			</geometry>
		</visual>
		<collision>
			<geometry>
				<cylinder length="0.1840588742756495" radius="0.7477842884599845"/>
			</geometry>
		</collision>
		<inertial>
			<mass value="0.32333990492988784"/>
			<inertia ixx="0.03" ixy="0" ixz="0" iyx="0" iyy="0.03" izz="0.03"/>
		</inertial>
	</link>
	<link name="23">
		<visual>
			<geometry>
				<cylinder length="0.1840588742756495" radius="0.7477842884599845"/>
			</geometry>
		</visual>
		<collision>
			<geometry>
				<cylinder length="0.1840588742756495" radius="0.7477842884599845"/>
			</geometry>
		</collision>
		<inertial>
			<mass value="0.32333990492988784"/>
			<inertia ixx="0.03" ixy="0" ixz="0" iyx="0" iyy="0.03" izz="0.03"/>
		</inertial>
	</link>
	<link name="14">
		<visual>
			<geometry>
				<cylinder length="0.9590842794497736" radius="0.9999"/>
			</geometry>
		</visual>
		<collision>
			<geometry>
				<cylinder length="0.9590842794497736" radius="0.9999"/>
			</geometry>
		</collision>
		<inertial>
			<mass value="3.012449546198092"/>
			<inertia ixx="0.03" ixy="0" ixz="0" iyx="0" iyy="0.03" izz="0.03"/>
		</inertial>
	</link>
	<link name="25">
		<visual>
			<geometry>
				<cylinder length="0.1840588742756495" radius="0.7477842884599845"/>
			</geometry>
		</visual>
		<collision>
			<geometry>
				<cylinder length="0.1840588742756495" radius="0.7477842884599845"/>
			</geometry>
		</collision>
		<inertial>
			<mass value="0.32333990492988784"/>
			<inertia ixx="0.03" ixy="0" ixz="0" iyx="0" iyy="0.03" izz="0.03"/>
		</inertial>
	</link>
	<link name="26">
		<visual>
			<geometry>
				<cylinder length="0.1840588742756495" radius="0.7477842884599845"/>
			</geometry>
		</visual>
		<collision>
			<geometry>
				<cylinder length="0.1840588742756495" radius="0.7477842884599845"/>
			</geometry>
		</collision>
		<inertial>
			<mass value="0.32333990492988784"/>
			<inertia ixx="0.03" ixy="0" ixz="0" iyx="0" iyy="0.03" izz="0.03"/>
		</inertial>
	</link>
	<joint name="11_to_0" type="revolute">
		<parent link="0"/>
		<child link="11"/>
		<axis xyz="1 0 0"/>
		<limit effort="1" lower="3.1415" upper="-3.1415" velocity="1"/>
		<origin rpy="1.6963969333852684 4.691213996647221 4.587332218059687" xyz="0.9999 0.9999 0.8113147983958526"/>
	</joint>
	<joint name="22_to_11" type="revolute">
		<parent link="11"/>
		<child link="22"/>
		<axis xyz="1 0 0"/>
		<limit effort="1" lower="3.1415" upper="-3.1415" velocity="1"/>
		<origin rpy="6.60400922450185 5.6464283762735334 0.8638038636710728" xyz="0.6468384730736209 0.3982034764994321 0.6535115948109418"/>
	</joint>
	<joint name="23_to_11" type="revolute">
		<parent link="11"/>
		<child link="23"/>
		<axis xyz="1 0 0"/>
		<limit effort="1" lower="3.1415" upper="-3.1415" velocity="1"/>
		<origin rpy="9.906013836752773 5.6464283762735334 0.8638038636710728" xyz="0.6468384730736209 0.3982034764994321 0.6535115948109418"/>
	</joint>
	<joint name="14_to_0" type="revolute">
		<parent link="0"/>
		<child link="14"/>
		<axis xyz="1 0 0"/>
		<limit effort="1" lower="3.1415" upper="-3.1415" velocity="1"/>
		<origin rpy="2.5445954000779025 4.691213996647221 4.587332218059687" xyz="0.9999 0.9999 0.8113147983958526"/>
	</joint>
	<joint name="25_to_14" type="revolute">
		<parent link="14"/>
		<child link="25"/>
		<axis xyz="1 0 0"/>
		<limit effort="1" lower="3.1415" upper="-3.1415" velocity="1"/>
		<origin rpy="6.60400922450185 5.6464283762735334 0.8638038636710728" xyz="0.6468384730736209 0.3982034764994321 0.6535115948109418"/>
	</joint>
	<joint name="26_to_14" type="revolute">
		<parent link="14"/>
		<child link="26"/>
		<axis xyz="1 0 0"/>
		<limit effort="1" lower="3.1415" upper="-3.1415" velocity="1"/>
		<origin rpy="9.906013836752773 5.6464283762735334 0.8638038636710728" xyz="0.6468384730736209 0.3982034764994321 0.6535115948109418"/>
	</joint>
</robot>
