<?xml version="1.0"?><robot name="pepe">
	<link name="0">
		<visual>
			<geometry>
				<cylinder length="0.10972258479473807" radius="0.8177725882595563"/>
			</geometry>
		</visual>
		<collision>
			<geometry>
				<cylinder length="0.10972258479473807" radius="0.8177725882595563"/>
			</geometry>
		</collision>
		<inertial>
			<mass value="0.23052126836723216"/>
			<inertia ixx="0.03" ixy="0" ixz="0" iyx="0" iyy="0.03" izz="0.03"/>
		</inertial>
	</link>
	<link name="11">
		<visual>
			<geometry>
				<cylinder length="0.7790799140414826" radius="0.9737004041083995"/>
			</geometry>
		</visual>
		<collision>
			<geometry>
				<cylinder length="0.7790799140414826" radius="0.9737004041083995"/>
			</geometry>
		</collision>
		<inertial>
			<mass value="2.320505386463417"/>
			<inertia ixx="0.03" ixy="0" ixz="0" iyx="0" iyy="0.03" izz="0.03"/>
		</inertial>
	</link>
	<link name="22">
		<visual>
			<geometry>
				<cylinder length="0.6171897003218518" radius="0.6603024381020903"/>
			</geometry>
		</visual>
		<collision>
			<geometry>
				<cylinder length="0.6171897003218518" radius="0.6603024381020903"/>
			</geometry>
		</collision>
		<inertial>
			<mass value="0.8453846236435617"/>
			<inertia ixx="0.03" ixy="0" ixz="0" iyx="0" iyy="0.03" izz="0.03"/>
		</inertial>
	</link>
	<link name="43">
		<visual>
			<geometry>
				<cylinder length="0.5962720823711678" radius="0.8857549578567819"/>
			</geometry>
		</visual>
		<collision>
			<geometry>
				<cylinder length="0.5962720823711678" radius="0.8857549578567819"/>
			</geometry>
		</collision>
		<inertial>
			<mass value="1.4696757643787193"/>
			<inertia ixx="0.03" ixy="0" ixz="0" iyx="0" iyy="0.03" izz="0.03"/>
		</inertial>
	</link>
	<link name="74">
		<visual>
			<geometry>
				<cylinder length="1.3282000554461173" radius="0.3250339807916235"/>
			</geometry>
		</visual>
		<collision>
			<geometry>
				<cylinder length="1.3282000554461173" radius="0.3250339807916235"/>
			</geometry>
		</collision>
		<inertial>
			<mass value="0.4408297546473238"/>
			<inertia ixx="0.03" ixy="0" ixz="0" iyx="0" iyy="0.03" izz="0.03"/>
		</inertial>
	</link>
	<link name="75">
		<visual>
			<geometry>
				<cylinder length="1.3282000554461173" radius="0.3250339807916235"/>
			</geometry>
		</visual>
		<collision>
			<geometry>
				<cylinder length="1.3282000554461173" radius="0.3250339807916235"/>
			</geometry>
		</collision>
		<inertial>
			<mass value="0.4408297546473238"/>
			<inertia ixx="0.03" ixy="0" ixz="0" iyx="0" iyy="0.03" izz="0.03"/>
		</inertial>
	</link>
	<link name="106">
		<visual>
			<geometry>
				<cylinder length="1.2158762526652545" radius="0.8572332267231851"/>
			</geometry>
		</visual>
		<collision>
			<geometry>
				<cylinder length="1.2158762526652545" radius="0.8572332267231851"/>
			</geometry>
		</collision>
		<inertial>
			<mass value="2.806966575901167"/>
			<inertia ixx="0.03" ixy="0" ixz="0" iyx="0" iyy="0.03" izz="0.03"/>
		</inertial>
	</link>
	<link name="107">
		<visual>
			<geometry>
				<cylinder length="1.2158762526652545" radius="0.8572332267231851"/>
			</geometry>
		</visual>
		<collision>
			<geometry>
				<cylinder length="1.2158762526652545" radius="0.8572332267231851"/>
			</geometry>
		</collision>
		<inertial>
			<mass value="2.806966575901167"/>
			<inertia ixx="0.03" ixy="0" ixz="0" iyx="0" iyy="0.03" izz="0.03"/>
		</inertial>
	</link>
	<link name="108">
		<visual>
			<geometry>
				<cylinder length="1.2158762526652545" radius="0.8572332267231851"/>
			</geometry>
		</visual>
		<collision>
			<geometry>
				<cylinder length="1.2158762526652545" radius="0.8572332267231851"/>
			</geometry>
		</collision>
		<inertial>
			<mass value="2.806966575901167"/>
			<inertia ixx="0.03" ixy="0" ixz="0" iyx="0" iyy="0.03" izz="0.03"/>
		</inertial>
	</link>
	<link name="49">
		<visual>
			<geometry>
				<cylinder length="0.5962720823711678" radius="0.8857549578567819"/>
			</geometry>
		</visual>
		<collision>
			<geometry>
				<cylinder length="0.5962720823711678" radius="0.8857549578567819"/>
			</geometry>
		</collision>
		<inertial>
			<mass value="1.4696757643787193"/>
			<inertia ixx="0.03" ixy="0" ixz="0" iyx="0" iyy="0.03" izz="0.03"/>
		</inertial>
	</link>
	<link name="710">
		<visual>
			<geometry>
				<cylinder length="1.3282000554461173" radius="0.3250339807916235"/>
			</geometry>
		</visual>
		<collision>
			<geometry>
				<cylinder length="1.3282000554461173" radius="0.3250339807916235"/>
			</geometry>
		</collision>
		<inertial>
			<mass value="0.4408297546473238"/>
			<inertia ixx="0.03" ixy="0" ixz="0" iyx="0" iyy="0.03" izz="0.03"/>
		</inertial>
	</link>
	<link name="711">
		<visual>
			<geometry>
				<cylinder length="1.3282000554461173" radius="0.3250339807916235"/>
			</geometry>
		</visual>
		<collision>
			<geometry>
				<cylinder length="1.3282000554461173" radius="0.3250339807916235"/>
			</geometry>
		</collision>
		<inertial>
			<mass value="0.4408297546473238"/>
			<inertia ixx="0.03" ixy="0" ixz="0" iyx="0" iyy="0.03" izz="0.03"/>
		</inertial>
	</link>
	<link name="1012">
		<visual>
			<geometry>
				<cylinder length="1.2158762526652545" radius="0.8572332267231851"/>
			</geometry>
		</visual>
		<collision>
			<geometry>
				<cylinder length="1.2158762526652545" radius="0.8572332267231851"/>
			</geometry>
		</collision>
		<inertial>
			<mass value="2.806966575901167"/>
			<inertia ixx="0.03" ixy="0" ixz="0" iyx="0" iyy="0.03" izz="0.03"/>
		</inertial>
	</link>
	<link name="1013">
		<visual>
			<geometry>
				<cylinder length="1.2158762526652545" radius="0.8572332267231851"/>
			</geometry>
		</visual>
		<collision>
			<geometry>
				<cylinder length="1.2158762526652545" radius="0.8572332267231851"/>
			</geometry>
		</collision>
		<inertial>
			<mass value="2.806966575901167"/>
			<inertia ixx="0.03" ixy="0" ixz="0" iyx="0" iyy="0.03" izz="0.03"/>
		</inertial>
	</link>
	<link name="1014">
		<visual>
			<geometry>
				<cylinder length="1.2158762526652545" radius="0.8572332267231851"/>
			</geometry>
		</visual>
		<collision>
			<geometry>
				<cylinder length="1.2158762526652545" radius="0.8572332267231851"/>
			</geometry>
		</collision>
		<inertial>
			<mass value="2.806966575901167"/>
			<inertia ixx="0.03" ixy="0" ixz="0" iyx="0" iyy="0.03" izz="0.03"/>
		</inertial>
	</link>
	<link name="415">
		<visual>
			<geometry>
				<cylinder length="0.5962720823711678" radius="0.8857549578567819"/>
			</geometry>
		</visual>
		<collision>
			<geometry>
				<cylinder length="0.5962720823711678" radius="0.8857549578567819"/>
			</geometry>
		</collision>
		<inertial>
			<mass value="1.4696757643787193"/>
			<inertia ixx="0.03" ixy="0" ixz="0" iyx="0" iyy="0.03" izz="0.03"/>
		</inertial>
	</link>
	<link name="716">
		<visual>
			<geometry>
				<cylinder length="1.3282000554461173" radius="0.3250339807916235"/>
			</geometry>
		</visual>
		<collision>
			<geometry>
				<cylinder length="1.3282000554461173" radius="0.3250339807916235"/>
			</geometry>
		</collision>
		<inertial>
			<mass value="0.4408297546473238"/>
			<inertia ixx="0.03" ixy="0" ixz="0" iyx="0" iyy="0.03" izz="0.03"/>
		</inertial>
	</link>
	<link name="717">
		<visual>
			<geometry>
				<cylinder length="1.3282000554461173" radius="0.3250339807916235"/>
			</geometry>
		</visual>
		<collision>
			<geometry>
				<cylinder length="1.3282000554461173" radius="0.3250339807916235"/>
			</geometry>
		</collision>
		<inertial>
			<mass value="0.4408297546473238"/>
			<inertia ixx="0.03" ixy="0" ixz="0" iyx="0" iyy="0.03" izz="0.03"/>
		</inertial>
	</link>
	<link name="1018">
		<visual>
			<geometry>
				<cylinder length="1.2158762526652545" radius="0.8572332267231851"/>
			</geometry>
		</visual>
		<collision>
			<geometry>
				<cylinder length="1.2158762526652545" radius="0.8572332267231851"/>
			</geometry>
		</collision>
		<inertial>
			<mass value="2.806966575901167"/>
			<inertia ixx="0.03" ixy="0" ixz="0" iyx="0" iyy="0.03" izz="0.03"/>
		</inertial>
	</link>
	<link name="1019">
		<visual>
			<geometry>
				<cylinder length="1.2158762526652545" radius="0.8572332267231851"/>
			</geometry>
		</visual>
		<collision>
			<geometry>
				<cylinder length="1.2158762526652545" radius="0.8572332267231851"/>
			</geometry>
		</collision>
		<inertial>
			<mass value="2.806966575901167"/>
			<inertia ixx="0.03" ixy="0" ixz="0" iyx="0" iyy="0.03" izz="0.03"/>
		</inertial>
	</link>
	<link name="1020">
		<visual>
			<geometry>
				<cylinder length="1.2158762526652545" radius="0.8572332267231851"/>
			</geometry>
		</visual>
		<collision>
			<geometry>
				<cylinder length="1.2158762526652545" radius="0.8572332267231851"/>
			</geometry>
		</collision>
		<inertial>
			<mass value="2.806966575901167"/>
			<inertia ixx="0.03" ixy="0" ixz="0" iyx="0" iyy="0.03" izz="0.03"/>
		</inertial>
	</link>
	<link name="621">
		<visual>
			<geometry>
				<cylinder length="1.4005043964146984" radius="0.771221915570814"/>
			</geometry>
		</visual>
		<collision>
			<geometry>
				<cylinder length="1.4005043964146984" radius="0.771221915570814"/>
			</geometry>
		</collision>
		<inertial>
			<mass value="2.6169358319387985"/>
			<inertia ixx="0.03" ixy="0" ixz="0" iyx="0" iyy="0.03" izz="0.03"/>
		</inertial>
	</link>
	<link name="822">
		<visual>
			<geometry>
				<cylinder length="1.0345992792024636" radius="0.06466256185382258"/>
			</geometry>
		</visual>
		<collision>
			<geometry>
				<cylinder length="1.0345992792024636" radius="0.06466256185382258"/>
			</geometry>
		</collision>
		<inertial>
			<mass value="0.013590262892744332"/>
			<inertia ixx="0.03" ixy="0" ixz="0" iyx="0" iyy="0.03" izz="0.03"/>
		</inertial>
	</link>
	<link name="623">
		<visual>
			<geometry>
				<cylinder length="1.4005043964146984" radius="0.771221915570814"/>
			</geometry>
		</visual>
		<collision>
			<geometry>
				<cylinder length="1.4005043964146984" radius="0.771221915570814"/>
			</geometry>
		</collision>
		<inertial>
			<mass value="2.6169358319387985"/>
			<inertia ixx="0.03" ixy="0" ixz="0" iyx="0" iyy="0.03" izz="0.03"/>
		</inertial>
	</link>
	<link name="824">
		<visual>
			<geometry>
				<cylinder length="1.0345992792024636" radius="0.06466256185382258"/>
			</geometry>
		</visual>
		<collision>
			<geometry>
				<cylinder length="1.0345992792024636" radius="0.06466256185382258"/>
			</geometry>
		</collision>
		<inertial>
			<mass value="0.013590262892744332"/>
			<inertia ixx="0.03" ixy="0" ixz="0" iyx="0" iyy="0.03" izz="0.03"/>
		</inertial>
	</link>
	<link name="625">
		<visual>
			<geometry>
				<cylinder length="1.4005043964146984" radius="0.771221915570814"/>
			</geometry>
		</visual>
		<collision>
			<geometry>
				<cylinder length="1.4005043964146984" radius="0.771221915570814"/>
			</geometry>
		</collision>
		<inertial>
			<mass value="2.6169358319387985"/>
			<inertia ixx="0.03" ixy="0" ixz="0" iyx="0" iyy="0.03" izz="0.03"/>
		</inertial>
	</link>
	<link name="826">
		<visual>
			<geometry>
				<cylinder length="1.0345992792024636" radius="0.06466256185382258"/>
			</geometry>
		</visual>
		<collision>
			<geometry>
				<cylinder length="1.0345992792024636" radius="0.06466256185382258"/>
			</geometry>
		</collision>
		<inertial>
			<mass value="0.013590262892744332"/>
			<inertia ixx="0.03" ixy="0" ixz="0" iyx="0" iyy="0.03" izz="0.03"/>
		</inertial>
	</link>
	<link name="327">
		<visual>
			<geometry>
				<cylinder length="1.4894472867661672" radius="0.534166585047344"/>
			</geometry>
		</visual>
		<collision>
			<geometry>
				<cylinder length="1.4894472867661672" radius="0.534166585047344"/>
			</geometry>
		</collision>
		<inertial>
			<mass value="1.3351450334014843"/>
			<inertia ixx="0.03" ixy="0" ixz="0" iyx="0" iyy="0.03" izz="0.03"/>
		</inertial>
	</link>
	<link name="928">
		<visual>
			<geometry>
				<cylinder length="1.178941283373043" radius="0.7160254496198138"/>
			</geometry>
		</visual>
		<collision>
			<geometry>
				<cylinder length="1.178941283373043" radius="0.7160254496198138"/>
			</geometry>
		</collision>
		<inertial>
			<mass value="1.8988863203241333"/>
			<inertia ixx="0.03" ixy="0" ixz="0" iyx="0" iyy="0.03" izz="0.03"/>
		</inertial>
	</link>
	<link name="929">
		<visual>
			<geometry>
				<cylinder length="1.178941283373043" radius="0.7160254496198138"/>
			</geometry>
		</visual>
		<collision>
			<geometry>
				<cylinder length="1.178941283373043" radius="0.7160254496198138"/>
			</geometry>
		</collision>
		<inertial>
			<mass value="1.8988863203241333"/>
			<inertia ixx="0.03" ixy="0" ixz="0" iyx="0" iyy="0.03" izz="0.03"/>
		</inertial>
	</link>
	<link name="930">
		<visual>
			<geometry>
				<cylinder length="1.178941283373043" radius="0.7160254496198138"/>
			</geometry>
		</visual>
		<collision>
			<geometry>
				<cylinder length="1.178941283373043" radius="0.7160254496198138"/>
			</geometry>
		</collision>
		<inertial>
			<mass value="1.8988863203241333"/>
			<inertia ixx="0.03" ixy="0" ixz="0" iyx="0" iyy="0.03" izz="0.03"/>
		</inertial>
	</link>
	<link name="331">
		<visual>
			<geometry>
				<cylinder length="1.4894472867661672" radius="0.534166585047344"/>
			</geometry>
		</visual>
		<collision>
			<geometry>
				<cylinder length="1.4894472867661672" radius="0.534166585047344"/>
			</geometry>
		</collision>
		<inertial>
			<mass value="1.3351450334014843"/>
			<inertia ixx="0.03" ixy="0" ixz="0" iyx="0" iyy="0.03" izz="0.03"/>
		</inertial>
	</link>
	<link name="932">
		<visual>
			<geometry>
				<cylinder length="1.178941283373043" radius="0.7160254496198138"/>
			</geometry>
		</visual>
		<collision>
			<geometry>
				<cylinder length="1.178941283373043" radius="0.7160254496198138"/>
			</geometry>
		</collision>
		<inertial>
			<mass value="1.8988863203241333"/>
			<inertia ixx="0.03" ixy="0" ixz="0" iyx="0" iyy="0.03" izz="0.03"/>
		</inertial>
	</link>
	<link name="933">
		<visual>
			<geometry>
				<cylinder length="1.178941283373043" radius="0.7160254496198138"/>
			</geometry>
		</visual>
		<collision>
			<geometry>
				<cylinder length="1.178941283373043" radius="0.7160254496198138"/>
			</geometry>
		</collision>
		<inertial>
			<mass value="1.8988863203241333"/>
			<inertia ixx="0.03" ixy="0" ixz="0" iyx="0" iyy="0.03" izz="0.03"/>
		</inertial>
	</link>
	<link name="934">
		<visual>
			<geometry>
				<cylinder length="1.178941283373043" radius="0.7160254496198138"/>
			</geometry>
		</visual>
		<collision>
			<geometry>
				<cylinder length="1.178941283373043" radius="0.7160254496198138"/>
			</geometry>
		</collision>
		<inertial>
			<mass value="1.8988863203241333"/>
			<inertia ixx="0.03" ixy="0" ixz="0" iyx="0" iyy="0.03" izz="0.03"/>
		</inertial>
	</link>
	<link name="535">
		<visual>
			<geometry>
				<cylinder length="1.8179222192250082" radius="0.14849749961737102"/>
			</geometry>
		</visual>
		<collision>
			<geometry>
				<cylinder length="1.8179222192250082" radius="0.14849749961737102"/>
			</geometry>
		</collision>
		<inertial>
			<mass value="0.1259399314832643"/>
			<inertia ixx="0.03" ixy="0" ixz="0" iyx="0" iyy="0.03" izz="0.03"/>
		</inertial>
	</link>
	<link name="536">
		<visual>
			<geometry>
				<cylinder length="1.8179222192250082" radius="0.14849749961737102"/>
			</geometry>
		</visual>
		<collision>
			<geometry>
				<cylinder length="1.8179222192250082" radius="0.14849749961737102"/>
			</geometry>
		</collision>
		<inertial>
			<mass value="0.1259399314832643"/>
			<inertia ixx="0.03" ixy="0" ixz="0" iyx="0" iyy="0.03" izz="0.03"/>
		</inertial>
	</link>
	<link name="1137">
		<visual>
			<geometry>
				<cylinder length="0.11957728452206506" radius="0.6993258746079154"/>
			</geometry>
		</visual>
		<collision>
			<geometry>
				<cylinder length="0.11957728452206506" radius="0.6993258746079154"/>
			</geometry>
		</collision>
		<inertial>
			<mass value="0.18372055716174684"/>
			<inertia ixx="0.03" ixy="0" ixz="0" iyx="0" iyy="0.03" izz="0.03"/>
		</inertial>
	</link>
	<link name="1138">
		<visual>
			<geometry>
				<cylinder length="0.11957728452206506" radius="0.6993258746079154"/>
			</geometry>
		</visual>
		<collision>
			<geometry>
				<cylinder length="0.11957728452206506" radius="0.6993258746079154"/>
			</geometry>
		</collision>
		<inertial>
			<mass value="0.18372055716174684"/>
			<inertia ixx="0.03" ixy="0" ixz="0" iyx="0" iyy="0.03" izz="0.03"/>
		</inertial>
	</link>
	<link name="1139">
		<visual>
			<geometry>
				<cylinder length="0.11957728452206506" radius="0.6993258746079154"/>
			</geometry>
		</visual>
		<collision>
			<geometry>
				<cylinder length="0.11957728452206506" radius="0.6993258746079154"/>
			</geometry>
		</collision>
		<inertial>
			<mass value="0.18372055716174684"/>
			<inertia ixx="0.03" ixy="0" ixz="0" iyx="0" iyy="0.03" izz="0.03"/>
		</inertial>
	</link>
	<link name="140">
		<visual>
			<geometry>
				<cylinder length="0.7790799140414826" radius="0.9737004041083995"/>
			</geometry>
		</visual>
		<collision>
			<geometry>
				<cylinder length="0.7790799140414826" radius="0.9737004041083995"/>
			</geometry>
		</collision>
		<inertial>
			<mass value="2.320505386463417"/>
			<inertia ixx="0.03" ixy="0" ixz="0" iyx="0" iyy="0.03" izz="0.03"/>
		</inertial>
	</link>
	<link name="241">
		<visual>
			<geometry>
				<cylinder length="0.6171897003218518" radius="0.6603024381020903"/>
			</geometry>
		</visual>
		<collision>
			<geometry>
				<cylinder length="0.6171897003218518" radius="0.6603024381020903"/>
			</geometry>
		</collision>
		<inertial>
			<mass value="0.8453846236435617"/>
			<inertia ixx="0.03" ixy="0" ixz="0" iyx="0" iyy="0.03" izz="0.03"/>
		</inertial>
	</link>
	<link name="442">
		<visual>
			<geometry>
				<cylinder length="0.5962720823711678" radius="0.8857549578567819"/>
			</geometry>
		</visual>
		<collision>
			<geometry>
				<cylinder length="0.5962720823711678" radius="0.8857549578567819"/>
			</geometry>
		</collision>
		<inertial>
			<mass value="1.4696757643787193"/>
			<inertia ixx="0.03" ixy="0" ixz="0" iyx="0" iyy="0.03" izz="0.03"/>
		</inertial>
	</link>
	<link name="743">
		<visual>
			<geometry>
				<cylinder length="1.3282000554461173" radius="0.3250339807916235"/>
			</geometry>
		</visual>
		<collision>
			<geometry>
				<cylinder length="1.3282000554461173" radius="0.3250339807916235"/>
			</geometry>
		</collision>
		<inertial>
			<mass value="0.4408297546473238"/>
			<inertia ixx="0.03" ixy="0" ixz="0" iyx="0" iyy="0.03" izz="0.03"/>
		</inertial>
	</link>
	<link name="744">
		<visual>
			<geometry>
				<cylinder length="1.3282000554461173" radius="0.3250339807916235"/>
			</geometry>
		</visual>
		<collision>
			<geometry>
				<cylinder length="1.3282000554461173" radius="0.3250339807916235"/>
			</geometry>
		</collision>
		<inertial>
			<mass value="0.4408297546473238"/>
			<inertia ixx="0.03" ixy="0" ixz="0" iyx="0" iyy="0.03" izz="0.03"/>
		</inertial>
	</link>
	<link name="1045">
		<visual>
			<geometry>
				<cylinder length="1.2158762526652545" radius="0.8572332267231851"/>
			</geometry>
		</visual>
		<collision>
			<geometry>
				<cylinder length="1.2158762526652545" radius="0.8572332267231851"/>
			</geometry>
		</collision>
		<inertial>
			<mass value="2.806966575901167"/>
			<inertia ixx="0.03" ixy="0" ixz="0" iyx="0" iyy="0.03" izz="0.03"/>
		</inertial>
	</link>
	<link name="1046">
		<visual>
			<geometry>
				<cylinder length="1.2158762526652545" radius="0.8572332267231851"/>
			</geometry>
		</visual>
		<collision>
			<geometry>
				<cylinder length="1.2158762526652545" radius="0.8572332267231851"/>
			</geometry>
		</collision>
		<inertial>
			<mass value="2.806966575901167"/>
			<inertia ixx="0.03" ixy="0" ixz="0" iyx="0" iyy="0.03" izz="0.03"/>
		</inertial>
	</link>
	<link name="1047">
		<visual>
			<geometry>
				<cylinder length="1.2158762526652545" radius="0.8572332267231851"/>
			</geometry>
		</visual>
		<collision>
			<geometry>
				<cylinder length="1.2158762526652545" radius="0.8572332267231851"/>
			</geometry>
		</collision>
		<inertial>
			<mass value="2.806966575901167"/>
			<inertia ixx="0.03" ixy="0" ixz="0" iyx="0" iyy="0.03" izz="0.03"/>
		</inertial>
	</link>
	<link name="448">
		<visual>
			<geometry>
				<cylinder length="0.5962720823711678" radius="0.8857549578567819"/>
			</geometry>
		</visual>
		<collision>
			<geometry>
				<cylinder length="0.5962720823711678" radius="0.8857549578567819"/>
			</geometry>
		</collision>
		<inertial>
			<mass value="1.4696757643787193"/>
			<inertia ixx="0.03" ixy="0" ixz="0" iyx="0" iyy="0.03" izz="0.03"/>
		</inertial>
	</link>
	<link name="749">
		<visual>
			<geometry>
				<cylinder length="1.3282000554461173" radius="0.3250339807916235"/>
			</geometry>
		</visual>
		<collision>
			<geometry>
				<cylinder length="1.3282000554461173" radius="0.3250339807916235"/>
			</geometry>
		</collision>
		<inertial>
			<mass value="0.4408297546473238"/>
			<inertia ixx="0.03" ixy="0" ixz="0" iyx="0" iyy="0.03" izz="0.03"/>
		</inertial>
	</link>
	<link name="750">
		<visual>
			<geometry>
				<cylinder length="1.3282000554461173" radius="0.3250339807916235"/>
			</geometry>
		</visual>
		<collision>
			<geometry>
				<cylinder length="1.3282000554461173" radius="0.3250339807916235"/>
			</geometry>
		</collision>
		<inertial>
			<mass value="0.4408297546473238"/>
			<inertia ixx="0.03" ixy="0" ixz="0" iyx="0" iyy="0.03" izz="0.03"/>
		</inertial>
	</link>
	<link name="1051">
		<visual>
			<geometry>
				<cylinder length="1.2158762526652545" radius="0.8572332267231851"/>
			</geometry>
		</visual>
		<collision>
			<geometry>
				<cylinder length="1.2158762526652545" radius="0.8572332267231851"/>
			</geometry>
		</collision>
		<inertial>
			<mass value="2.806966575901167"/>
			<inertia ixx="0.03" ixy="0" ixz="0" iyx="0" iyy="0.03" izz="0.03"/>
		</inertial>
	</link>
	<link name="1052">
		<visual>
			<geometry>
				<cylinder length="1.2158762526652545" radius="0.8572332267231851"/>
			</geometry>
		</visual>
		<collision>
			<geometry>
				<cylinder length="1.2158762526652545" radius="0.8572332267231851"/>
			</geometry>
		</collision>
		<inertial>
			<mass value="2.806966575901167"/>
			<inertia ixx="0.03" ixy="0" ixz="0" iyx="0" iyy="0.03" izz="0.03"/>
		</inertial>
	</link>
	<link name="1053">
		<visual>
			<geometry>
				<cylinder length="1.2158762526652545" radius="0.8572332267231851"/>
			</geometry>
		</visual>
		<collision>
			<geometry>
				<cylinder length="1.2158762526652545" radius="0.8572332267231851"/>
			</geometry>
		</collision>
		<inertial>
			<mass value="2.806966575901167"/>
			<inertia ixx="0.03" ixy="0" ixz="0" iyx="0" iyy="0.03" izz="0.03"/>
		</inertial>
	</link>
	<link name="454">
		<visual>
			<geometry>
				<cylinder length="0.5962720823711678" radius="0.8857549578567819"/>
			</geometry>
		</visual>
		<collision>
			<geometry>
				<cylinder length="0.5962720823711678" radius="0.8857549578567819"/>
			</geometry>
		</collision>
		<inertial>
			<mass value="1.4696757643787193"/>
			<inertia ixx="0.03" ixy="0" ixz="0" iyx="0" iyy="0.03" izz="0.03"/>
		</inertial>
	</link>
	<link name="755">
		<visual>
			<geometry>
				<cylinder length="1.3282000554461173" radius="0.3250339807916235"/>
			</geometry>
		</visual>
		<collision>
			<geometry>
				<cylinder length="1.3282000554461173" radius="0.3250339807916235"/>
			</geometry>
		</collision>
		<inertial>
			<mass value="0.4408297546473238"/>
			<inertia ixx="0.03" ixy="0" ixz="0" iyx="0" iyy="0.03" izz="0.03"/>
		</inertial>
	</link>
	<link name="756">
		<visual>
			<geometry>
				<cylinder length="1.3282000554461173" radius="0.3250339807916235"/>
			</geometry>
		</visual>
		<collision>
			<geometry>
				<cylinder length="1.3282000554461173" radius="0.3250339807916235"/>
			</geometry>
		</collision>
		<inertial>
			<mass value="0.4408297546473238"/>
			<inertia ixx="0.03" ixy="0" ixz="0" iyx="0" iyy="0.03" izz="0.03"/>
		</inertial>
	</link>
	<link name="1057">
		<visual>
			<geometry>
				<cylinder length="1.2158762526652545" radius="0.8572332267231851"/>
			</geometry>
		</visual>
		<collision>
			<geometry>
				<cylinder length="1.2158762526652545" radius="0.8572332267231851"/>
			</geometry>
		</collision>
		<inertial>
			<mass value="2.806966575901167"/>
			<inertia ixx="0.03" ixy="0" ixz="0" iyx="0" iyy="0.03" izz="0.03"/>
		</inertial>
	</link>
	<link name="1058">
		<visual>
			<geometry>
				<cylinder length="1.2158762526652545" radius="0.8572332267231851"/>
			</geometry>
		</visual>
		<collision>
			<geometry>
				<cylinder length="1.2158762526652545" radius="0.8572332267231851"/>
			</geometry>
		</collision>
		<inertial>
			<mass value="2.806966575901167"/>
			<inertia ixx="0.03" ixy="0" ixz="0" iyx="0" iyy="0.03" izz="0.03"/>
		</inertial>
	</link>
	<link name="1059">
		<visual>
			<geometry>
				<cylinder length="1.2158762526652545" radius="0.8572332267231851"/>
			</geometry>
		</visual>
		<collision>
			<geometry>
				<cylinder length="1.2158762526652545" radius="0.8572332267231851"/>
			</geometry>
		</collision>
		<inertial>
			<mass value="2.806966575901167"/>
			<inertia ixx="0.03" ixy="0" ixz="0" iyx="0" iyy="0.03" izz="0.03"/>
		</inertial>
	</link>
	<link name="660">
		<visual>
			<geometry>
				<cylinder length="1.4005043964146984" radius="0.771221915570814"/>
			</geometry>
		</visual>
		<collision>
			<geometry>
				<cylinder length="1.4005043964146984" radius="0.771221915570814"/>
			</geometry>
		</collision>
		<inertial>
			<mass value="2.6169358319387985"/>
			<inertia ixx="0.03" ixy="0" ixz="0" iyx="0" iyy="0.03" izz="0.03"/>
		</inertial>
	</link>
	<link name="861">
		<visual>
			<geometry>
				<cylinder length="1.0345992792024636" radius="0.06466256185382258"/>
			</geometry>
		</visual>
		<collision>
			<geometry>
				<cylinder length="1.0345992792024636" radius="0.06466256185382258"/>
			</geometry>
		</collision>
		<inertial>
			<mass value="0.013590262892744332"/>
			<inertia ixx="0.03" ixy="0" ixz="0" iyx="0" iyy="0.03" izz="0.03"/>
		</inertial>
	</link>
	<link name="662">
		<visual>
			<geometry>
				<cylinder length="1.4005043964146984" radius="0.771221915570814"/>
			</geometry>
		</visual>
		<collision>
			<geometry>
				<cylinder length="1.4005043964146984" radius="0.771221915570814"/>
			</geometry>
		</collision>
		<inertial>
			<mass value="2.6169358319387985"/>
			<inertia ixx="0.03" ixy="0" ixz="0" iyx="0" iyy="0.03" izz="0.03"/>
		</inertial>
	</link>
	<link name="863">
		<visual>
			<geometry>
				<cylinder length="1.0345992792024636" radius="0.06466256185382258"/>
			</geometry>
		</visual>
		<collision>
			<geometry>
				<cylinder length="1.0345992792024636" radius="0.06466256185382258"/>
			</geometry>
		</collision>
		<inertial>
			<mass value="0.013590262892744332"/>
			<inertia ixx="0.03" ixy="0" ixz="0" iyx="0" iyy="0.03" izz="0.03"/>
		</inertial>
	</link>
	<link name="664">
		<visual>
			<geometry>
				<cylinder length="1.4005043964146984" radius="0.771221915570814"/>
			</geometry>
		</visual>
		<collision>
			<geometry>
				<cylinder length="1.4005043964146984" radius="0.771221915570814"/>
			</geometry>
		</collision>
		<inertial>
			<mass value="2.6169358319387985"/>
			<inertia ixx="0.03" ixy="0" ixz="0" iyx="0" iyy="0.03" izz="0.03"/>
		</inertial>
	</link>
	<link name="865">
		<visual>
			<geometry>
				<cylinder length="1.0345992792024636" radius="0.06466256185382258"/>
			</geometry>
		</visual>
		<collision>
			<geometry>
				<cylinder length="1.0345992792024636" radius="0.06466256185382258"/>
			</geometry>
		</collision>
		<inertial>
			<mass value="0.013590262892744332"/>
			<inertia ixx="0.03" ixy="0" ixz="0" iyx="0" iyy="0.03" izz="0.03"/>
		</inertial>
	</link>
	<link name="366">
		<visual>
			<geometry>
				<cylinder length="1.4894472867661672" radius="0.534166585047344"/>
			</geometry>
		</visual>
		<collision>
			<geometry>
				<cylinder length="1.4894472867661672" radius="0.534166585047344"/>
			</geometry>
		</collision>
		<inertial>
			<mass value="1.3351450334014843"/>
			<inertia ixx="0.03" ixy="0" ixz="0" iyx="0" iyy="0.03" izz="0.03"/>
		</inertial>
	</link>
	<link name="967">
		<visual>
			<geometry>
				<cylinder length="1.178941283373043" radius="0.7160254496198138"/>
			</geometry>
		</visual>
		<collision>
			<geometry>
				<cylinder length="1.178941283373043" radius="0.7160254496198138"/>
			</geometry>
		</collision>
		<inertial>
			<mass value="1.8988863203241333"/>
			<inertia ixx="0.03" ixy="0" ixz="0" iyx="0" iyy="0.03" izz="0.03"/>
		</inertial>
	</link>
	<link name="968">
		<visual>
			<geometry>
				<cylinder length="1.178941283373043" radius="0.7160254496198138"/>
			</geometry>
		</visual>
		<collision>
			<geometry>
				<cylinder length="1.178941283373043" radius="0.7160254496198138"/>
			</geometry>
		</collision>
		<inertial>
			<mass value="1.8988863203241333"/>
			<inertia ixx="0.03" ixy="0" ixz="0" iyx="0" iyy="0.03" izz="0.03"/>
		</inertial>
	</link>
	<link name="969">
		<visual>
			<geometry>
				<cylinder length="1.178941283373043" radius="0.7160254496198138"/>
			</geometry>
		</visual>
		<collision>
			<geometry>
				<cylinder length="1.178941283373043" radius="0.7160254496198138"/>
			</geometry>
		</collision>
		<inertial>
			<mass value="1.8988863203241333"/>
			<inertia ixx="0.03" ixy="0" ixz="0" iyx="0" iyy="0.03" izz="0.03"/>
		</inertial>
	</link>
	<link name="370">
		<visual>
			<geometry>
				<cylinder length="1.4894472867661672" radius="0.534166585047344"/>
			</geometry>
		</visual>
		<collision>
			<geometry>
				<cylinder length="1.4894472867661672" radius="0.534166585047344"/>
			</geometry>
		</collision>
		<inertial>
			<mass value="1.3351450334014843"/>
			<inertia ixx="0.03" ixy="0" ixz="0" iyx="0" iyy="0.03" izz="0.03"/>
		</inertial>
	</link>
	<link name="971">
		<visual>
			<geometry>
				<cylinder length="1.178941283373043" radius="0.7160254496198138"/>
			</geometry>
		</visual>
		<collision>
			<geometry>
				<cylinder length="1.178941283373043" radius="0.7160254496198138"/>
			</geometry>
		</collision>
		<inertial>
			<mass value="1.8988863203241333"/>
			<inertia ixx="0.03" ixy="0" ixz="0" iyx="0" iyy="0.03" izz="0.03"/>
		</inertial>
	</link>
	<link name="972">
		<visual>
			<geometry>
				<cylinder length="1.178941283373043" radius="0.7160254496198138"/>
			</geometry>
		</visual>
		<collision>
			<geometry>
				<cylinder length="1.178941283373043" radius="0.7160254496198138"/>
			</geometry>
		</collision>
		<inertial>
			<mass value="1.8988863203241333"/>
			<inertia ixx="0.03" ixy="0" ixz="0" iyx="0" iyy="0.03" izz="0.03"/>
		</inertial>
	</link>
	<link name="973">
		<visual>
			<geometry>
				<cylinder length="1.178941283373043" radius="0.7160254496198138"/>
			</geometry>
		</visual>
		<collision>
			<geometry>
				<cylinder length="1.178941283373043" radius="0.7160254496198138"/>
			</geometry>
		</collision>
		<inertial>
			<mass value="1.8988863203241333"/>
			<inertia ixx="0.03" ixy="0" ixz="0" iyx="0" iyy="0.03" izz="0.03"/>
		</inertial>
	</link>
	<link name="574">
		<visual>
			<geometry>
				<cylinder length="1.8179222192250082" radius="0.14849749961737102"/>
			</geometry>
		</visual>
		<collision>
			<geometry>
				<cylinder length="1.8179222192250082" radius="0.14849749961737102"/>
			</geometry>
		</collision>
		<inertial>
			<mass value="0.1259399314832643"/>
			<inertia ixx="0.03" ixy="0" ixz="0" iyx="0" iyy="0.03" izz="0.03"/>
		</inertial>
	</link>
	<link name="575">
		<visual>
			<geometry>
				<cylinder length="1.8179222192250082" radius="0.14849749961737102"/>
			</geometry>
		</visual>
		<collision>
			<geometry>
				<cylinder length="1.8179222192250082" radius="0.14849749961737102"/>
			</geometry>
		</collision>
		<inertial>
			<mass value="0.1259399314832643"/>
			<inertia ixx="0.03" ixy="0" ixz="0" iyx="0" iyy="0.03" izz="0.03"/>
		</inertial>
	</link>
	<link name="1176">
		<visual>
			<geometry>
				<cylinder length="0.11957728452206506" radius="0.6993258746079154"/>
			</geometry>
		</visual>
		<collision>
			<geometry>
				<cylinder length="0.11957728452206506" radius="0.6993258746079154"/>
			</geometry>
		</collision>
		<inertial>
			<mass value="0.18372055716174684"/>
			<inertia ixx="0.03" ixy="0" ixz="0" iyx="0" iyy="0.03" izz="0.03"/>
		</inertial>
	</link>
	<link name="1177">
		<visual>
			<geometry>
				<cylinder length="0.11957728452206506" radius="0.6993258746079154"/>
			</geometry>
		</visual>
		<collision>
			<geometry>
				<cylinder length="0.11957728452206506" radius="0.6993258746079154"/>
			</geometry>
		</collision>
		<inertial>
			<mass value="0.18372055716174684"/>
			<inertia ixx="0.03" ixy="0" ixz="0" iyx="0" iyy="0.03" izz="0.03"/>
		</inertial>
	</link>
	<link name="1178">
		<visual>
			<geometry>
				<cylinder length="0.11957728452206506" radius="0.6993258746079154"/>
			</geometry>
		</visual>
		<collision>
			<geometry>
				<cylinder length="0.11957728452206506" radius="0.6993258746079154"/>
			</geometry>
		</collision>
		<inertial>
			<mass value="0.18372055716174684"/>
			<inertia ixx="0.03" ixy="0" ixz="0" iyx="0" iyy="0.03" izz="0.03"/>
		</inertial>
	</link>
	<joint name="11_to_0" type="revolute">
		<parent link="0"/>
		<child link="11"/>
		<axis xyz="1 0 0"/>
		<limit effort="1" lower="3.1415" upper="-3.1415" velocity="1"/>
		<origin rpy="0.4549805967947394 2.9586189339625926 1.6838704116656529" xyz="0.5413006718965738 0.7365466788366941 0.21370201835359925"/>
	</joint>
	<joint name="22_to_11" type="revolute">
		<parent link="11"/>
		<child link="22"/>
		<axis xyz="0 0 1"/>
		<limit effort="1" lower="3.1415" upper="-3.1415" velocity="1"/>
		<origin rpy="11.3660897094889 3.0428706290340473 2.0589992593609847" xyz="0.5000315411784426 0.20529255884376718 0.1713161441039227"/>
	</joint>
	<joint name="43_to_22" type="revolute">
		<parent link="22"/>
		<child link="43"/>
		<axis xyz="0 1 0"/>
		<limit effort="1" lower="3.1415" upper="-3.1415" velocity="1"/>
		<origin rpy="1.597477916238717 3.3128001126324267 3.0193954515937693" xyz="0.10911108138419778 0.545118737809867 0.30977664146782835"/>
	</joint>
	<joint name="74_to_43" type="revolute">
		<parent link="43"/>
		<child link="74"/>
		<axis xyz="0 0 1"/>
		<limit effort="1" lower="3.1415" upper="-3.1415" velocity="1"/>
		<origin rpy="2.424590078205876 3.433968707250544 3.9153310195599498" xyz="0.513449609166835 0.17256258145547576 0.10747627175183372"/>
	</joint>
	<joint name="75_to_43" type="revolute">
		<parent link="43"/>
		<child link="75"/>
		<axis xyz="0 0 1"/>
		<limit effort="1" lower="3.1415" upper="-3.1415" velocity="1"/>
		<origin rpy="3.6368851173088137 3.433968707250544 3.9153310195599498" xyz="0.513449609166835 0.17256258145547576 0.10747627175183372"/>
	</joint>
	<joint name="106_to_43" type="revolute">
		<parent link="43"/>
		<child link="106"/>
		<axis xyz="0 0 1"/>
		<limit effort="1" lower="3.1415" upper="-3.1415" velocity="1"/>
		<origin rpy="6.34638956423286 4.6057762313231 4.116066467158098" xyz="0.9441648623242971 0.03575603795805771 0.6777622285871637"/>
	</joint>
	<joint name="107_to_43" type="revolute">
		<parent link="43"/>
		<child link="107"/>
		<axis xyz="0 0 1"/>
		<limit effort="1" lower="3.1415" upper="-3.1415" velocity="1"/>
		<origin rpy="7.932986955291074 4.6057762313231 4.116066467158098" xyz="0.9441648623242971 0.03575603795805771 0.6777622285871637"/>
	</joint>
	<joint name="108_to_43" type="revolute">
		<parent link="43"/>
		<child link="108"/>
		<axis xyz="0 0 1"/>
		<limit effort="1" lower="3.1415" upper="-3.1415" velocity="1"/>
		<origin rpy="9.51958434634929 4.6057762313231 4.116066467158098" xyz="0.9441648623242971 0.03575603795805771 0.6777622285871637"/>
	</joint>
	<joint name="49_to_22" type="revolute">
		<parent link="22"/>
		<child link="49"/>
		<axis xyz="0 1 0"/>
		<limit effort="1" lower="3.1415" upper="-3.1415" velocity="1"/>
		<origin rpy="2.3962168743580756 3.3128001126324267 3.0193954515937693" xyz="0.10911108138419778 0.545118737809867 0.30977664146782835"/>
	</joint>
	<joint name="710_to_49" type="revolute">
		<parent link="49"/>
		<child link="710"/>
		<axis xyz="0 0 1"/>
		<limit effort="1" lower="3.1415" upper="-3.1415" velocity="1"/>
		<origin rpy="2.424590078205876 3.433968707250544 3.9153310195599498" xyz="0.513449609166835 0.17256258145547576 0.10747627175183372"/>
	</joint>
	<joint name="711_to_49" type="revolute">
		<parent link="49"/>
		<child link="711"/>
		<axis xyz="0 0 1"/>
		<limit effort="1" lower="3.1415" upper="-3.1415" velocity="1"/>
		<origin rpy="3.6368851173088137 3.433968707250544 3.9153310195599498" xyz="0.513449609166835 0.17256258145547576 0.10747627175183372"/>
	</joint>
	<joint name="1012_to_49" type="revolute">
		<parent link="49"/>
		<child link="1012"/>
		<axis xyz="0 0 1"/>
		<limit effort="1" lower="3.1415" upper="-3.1415" velocity="1"/>
		<origin rpy="6.34638956423286 4.6057762313231 4.116066467158098" xyz="0.9441648623242971 0.03575603795805771 0.6777622285871637"/>
	</joint>
	<joint name="1013_to_49" type="revolute">
		<parent link="49"/>
		<child link="1013"/>
		<axis xyz="0 0 1"/>
		<limit effort="1" lower="3.1415" upper="-3.1415" velocity="1"/>
		<origin rpy="7.932986955291074 4.6057762313231 4.116066467158098" xyz="0.9441648623242971 0.03575603795805771 0.6777622285871637"/>
	</joint>
	<joint name="1014_to_49" type="revolute">
		<parent link="49"/>
		<child link="1014"/>
		<axis xyz="0 0 1"/>
		<limit effort="1" lower="3.1415" upper="-3.1415" velocity="1"/>
		<origin rpy="9.51958434634929 4.6057762313231 4.116066467158098" xyz="0.9441648623242971 0.03575603795805771 0.6777622285871637"/>
	</joint>
	<joint name="415_to_22" type="revolute">
		<parent link="22"/>
		<child link="415"/>
		<axis xyz="0 1 0"/>
		<limit effort="1" lower="3.1415" upper="-3.1415" velocity="1"/>
		<origin rpy="3.194955832477434 3.3128001126324267 3.0193954515937693" xyz="0.10911108138419778 0.545118737809867 0.30977664146782835"/>
	</joint>
	<joint name="716_to_415" type="revolute">
		<parent link="415"/>
		<child link="716"/>
		<axis xyz="0 0 1"/>
		<limit effort="1" lower="3.1415" upper="-3.1415" velocity="1"/>
		<origin rpy="2.424590078205876 3.433968707250544 3.9153310195599498" xyz="0.513449609166835 0.17256258145547576 0.10747627175183372"/>
	</joint>
	<joint name="717_to_415" type="revolute">
		<parent link="415"/>
		<child link="717"/>
		<axis xyz="0 0 1"/>
		<limit effort="1" lower="3.1415" upper="-3.1415" velocity="1"/>
		<origin rpy="3.6368851173088137 3.433968707250544 3.9153310195599498" xyz="0.513449609166835 0.17256258145547576 0.10747627175183372"/>
	</joint>
	<joint name="1018_to_415" type="revolute">
		<parent link="415"/>
		<child link="1018"/>
		<axis xyz="0 0 1"/>
		<limit effort="1" lower="3.1415" upper="-3.1415" velocity="1"/>
		<origin rpy="6.34638956423286 4.6057762313231 4.116066467158098" xyz="0.9441648623242971 0.03575603795805771 0.6777622285871637"/>
	</joint>
	<joint name="1019_to_415" type="revolute">
		<parent link="415"/>
		<child link="1019"/>
		<axis xyz="0 0 1"/>
		<limit effort="1" lower="3.1415" upper="-3.1415" velocity="1"/>
		<origin rpy="7.932986955291074 4.6057762313231 4.116066467158098" xyz="0.9441648623242971 0.03575603795805771 0.6777622285871637"/>
	</joint>
	<joint name="1020_to_415" type="revolute">
		<parent link="415"/>
		<child link="1020"/>
		<axis xyz="0 0 1"/>
		<limit effort="1" lower="3.1415" upper="-3.1415" velocity="1"/>
		<origin rpy="9.51958434634929 4.6057762313231 4.116066467158098" xyz="0.9441648623242971 0.03575603795805771 0.6777622285871637"/>
	</joint>
	<joint name="621_to_22" type="revolute">
		<parent link="22"/>
		<child link="621"/>
		<axis xyz="0 1 0"/>
		<limit effort="1" lower="3.1415" upper="-3.1415" velocity="1"/>
		<origin rpy="3.8420239360981268 3.6945942238276532 3.7656443446822414" xyz="0.48904692493117463 0.3616103010396594 0.2748141126507512"/>
	</joint>
	<joint name="822_to_621" type="revolute">
		<parent link="621"/>
		<child link="822"/>
		<axis xyz="1 0 0"/>
		<limit effort="1" lower="3.1415" upper="-3.1415" velocity="1"/>
		<origin rpy="5.173357940100616 3.2733982649686078 1.3738119842501992" xyz="0.8397619150174855 0.4198149852115245 0.7316587060861907"/>
	</joint>
	<joint name="623_to_22" type="revolute">
		<parent link="22"/>
		<child link="623"/>
		<axis xyz="0 1 0"/>
		<limit effort="1" lower="3.1415" upper="-3.1415" velocity="1"/>
		<origin rpy="4.610428723317752 3.6945942238276532 3.7656443446822414" xyz="0.48904692493117463 0.3616103010396594 0.2748141126507512"/>
	</joint>
	<joint name="824_to_623" type="revolute">
		<parent link="623"/>
		<child link="824"/>
		<axis xyz="1 0 0"/>
		<limit effort="1" lower="3.1415" upper="-3.1415" velocity="1"/>
		<origin rpy="5.173357940100616 3.2733982649686078 1.3738119842501992" xyz="0.8397619150174855 0.4198149852115245 0.7316587060861907"/>
	</joint>
	<joint name="625_to_22" type="revolute">
		<parent link="22"/>
		<child link="625"/>
		<axis xyz="0 1 0"/>
		<limit effort="1" lower="3.1415" upper="-3.1415" velocity="1"/>
		<origin rpy="5.378833510537378 3.6945942238276532 3.7656443446822414" xyz="0.48904692493117463 0.3616103010396594 0.2748141126507512"/>
	</joint>
	<joint name="826_to_625" type="revolute">
		<parent link="625"/>
		<child link="826"/>
		<axis xyz="1 0 0"/>
		<limit effort="1" lower="3.1415" upper="-3.1415" velocity="1"/>
		<origin rpy="5.173357940100616 3.2733982649686078 1.3738119842501992" xyz="0.8397619150174855 0.4198149852115245 0.7316587060861907"/>
	</joint>
	<joint name="327_to_11" type="revolute">
		<parent link="11"/>
		<child link="327"/>
		<axis xyz="1 0 0"/>
		<limit effort="1" lower="3.1415" upper="-3.1415" velocity="1"/>
		<origin rpy="10.491170289653072 3.9344879327490054 1.7864063596710278" xyz="0.4610179755996069 0.08805756137348231 0.26320984231011235"/>
	</joint>
	<joint name="928_to_327" type="revolute">
		<parent link="327"/>
		<child link="928"/>
		<axis xyz="0 0 1"/>
		<limit effort="1" lower="3.1415" upper="-3.1415" velocity="1"/>
		<origin rpy="1.6376957940216532 5.944922854943341 0.016570953960627847" xyz="0.42946886327154843 0.9470078419747924 0.4308568350125678"/>
	</joint>
	<joint name="929_to_327" type="revolute">
		<parent link="327"/>
		<child link="929"/>
		<axis xyz="0 0 1"/>
		<limit effort="1" lower="3.1415" upper="-3.1415" velocity="1"/>
		<origin rpy="2.45654369103248 5.944922854943341 0.016570953960627847" xyz="0.42946886327154843 0.9470078419747924 0.4308568350125678"/>
	</joint>
	<joint name="930_to_327" type="revolute">
		<parent link="327"/>
		<child link="930"/>
		<axis xyz="0 0 1"/>
		<limit effort="1" lower="3.1415" upper="-3.1415" velocity="1"/>
		<origin rpy="3.2753915880433064 5.944922854943341 0.016570953960627847" xyz="0.42946886327154843 0.9470078419747924 0.4308568350125678"/>
	</joint>
	<joint name="331_to_11" type="revolute">
		<parent link="11"/>
		<child link="331"/>
		<axis xyz="1 0 0"/>
		<limit effort="1" lower="3.1415" upper="-3.1415" velocity="1"/>
		<origin rpy="13.988227052870762 3.9344879327490054 1.7864063596710278" xyz="0.4610179755996069 0.08805756137348231 0.26320984231011235"/>
	</joint>
	<joint name="932_to_331" type="revolute">
		<parent link="331"/>
		<child link="932"/>
		<axis xyz="0 0 1"/>
		<limit effort="1" lower="3.1415" upper="-3.1415" velocity="1"/>
		<origin rpy="1.6376957940216532 5.944922854943341 0.016570953960627847" xyz="0.42946886327154843 0.9470078419747924 0.4308568350125678"/>
	</joint>
	<joint name="933_to_331" type="revolute">
		<parent link="331"/>
		<child link="933"/>
		<axis xyz="0 0 1"/>
		<limit effort="1" lower="3.1415" upper="-3.1415" velocity="1"/>
		<origin rpy="2.45654369103248 5.944922854943341 0.016570953960627847" xyz="0.42946886327154843 0.9470078419747924 0.4308568350125678"/>
	</joint>
	<joint name="934_to_331" type="revolute">
		<parent link="331"/>
		<child link="934"/>
		<axis xyz="0 0 1"/>
		<limit effort="1" lower="3.1415" upper="-3.1415" velocity="1"/>
		<origin rpy="3.2753915880433064 5.944922854943341 0.016570953960627847" xyz="0.42946886327154843 0.9470078419747924 0.4308568350125678"/>
	</joint>
	<joint name="535_to_11" type="revolute">
		<parent link="11"/>
		<child link="535"/>
		<axis xyz="1 0 0"/>
		<limit effort="1" lower="3.1415" upper="-3.1415" velocity="1"/>
		<origin rpy="6.170917235056622 4.8517640051467215 4.364670579203324" xyz="0.005683955250957662 0.09737229592884222 0.5408591155595072"/>
	</joint>
	<joint name="536_to_11" type="revolute">
		<parent link="11"/>
		<child link="536"/>
		<axis xyz="1 0 0"/>
		<limit effort="1" lower="3.1415" upper="-3.1415" velocity="1"/>
		<origin rpy="7.405100682067946 4.8517640051467215 4.364670579203324" xyz="0.005683955250957662 0.09737229592884222 0.5408591155595072"/>
	</joint>
	<joint name="1137_to_11" type="revolute">
		<parent link="11"/>
		<child link="1137"/>
		<axis xyz="0 1 0"/>
		<limit effort="1" lower="3.1415" upper="-3.1415" velocity="1"/>
		<origin rpy="4.4846267049499025 2.6745928977140294 4.237730073756579" xyz="0.05696756686212334 0.13814507211450522 0.8244958323783818"/>
	</joint>
	<joint name="1138_to_11" type="revolute">
		<parent link="11"/>
		<child link="1138"/>
		<axis xyz="0 1 0"/>
		<limit effort="1" lower="3.1415" upper="-3.1415" velocity="1"/>
		<origin rpy="5.125287662799889 2.6745928977140294 4.237730073756579" xyz="0.05696756686212334 0.13814507211450522 0.8244958323783818"/>
	</joint>
	<joint name="1139_to_11" type="revolute">
		<parent link="11"/>
		<child link="1139"/>
		<axis xyz="0 1 0"/>
		<limit effort="1" lower="3.1415" upper="-3.1415" velocity="1"/>
		<origin rpy="5.765948620649875 2.6745928977140294 4.237730073756579" xyz="0.05696756686212334 0.13814507211450522 0.8244958323783818"/>
	</joint>
	<joint name="140_to_0" type="revolute">
		<parent link="0"/>
		<child link="140"/>
		<axis xyz="1 0 0"/>
		<limit effort="1" lower="3.1415" upper="-3.1415" velocity="1"/>
		<origin rpy="0.6824708951921091 2.9586189339625926 1.6838704116656529" xyz="0.5413006718965738 0.7365466788366941 0.21370201835359925"/>
	</joint>
	<joint name="241_to_140" type="revolute">
		<parent link="140"/>
		<child link="241"/>
		<axis xyz="0 0 1"/>
		<limit effort="1" lower="3.1415" upper="-3.1415" velocity="1"/>
		<origin rpy="11.3660897094889 3.0428706290340473 2.0589992593609847" xyz="0.5000315411784426 0.20529255884376718 0.1713161441039227"/>
	</joint>
	<joint name="442_to_241" type="revolute">
		<parent link="241"/>
		<child link="442"/>
		<axis xyz="0 1 0"/>
		<limit effort="1" lower="3.1415" upper="-3.1415" velocity="1"/>
		<origin rpy="1.597477916238717 3.3128001126324267 3.0193954515937693" xyz="0.10911108138419778 0.545118737809867 0.30977664146782835"/>
	</joint>
	<joint name="743_to_442" type="revolute">
		<parent link="442"/>
		<child link="743"/>
		<axis xyz="0 0 1"/>
		<limit effort="1" lower="3.1415" upper="-3.1415" velocity="1"/>
		<origin rpy="2.424590078205876 3.433968707250544 3.9153310195599498" xyz="0.513449609166835 0.17256258145547576 0.10747627175183372"/>
	</joint>
	<joint name="744_to_442" type="revolute">
		<parent link="442"/>
		<child link="744"/>
		<axis xyz="0 0 1"/>
		<limit effort="1" lower="3.1415" upper="-3.1415" velocity="1"/>
		<origin rpy="3.6368851173088137 3.433968707250544 3.9153310195599498" xyz="0.513449609166835 0.17256258145547576 0.10747627175183372"/>
	</joint>
	<joint name="1045_to_442" type="revolute">
		<parent link="442"/>
		<child link="1045"/>
		<axis xyz="0 0 1"/>
		<limit effort="1" lower="3.1415" upper="-3.1415" velocity="1"/>
		<origin rpy="6.34638956423286 4.6057762313231 4.116066467158098" xyz="0.9441648623242971 0.03575603795805771 0.6777622285871637"/>
	</joint>
	<joint name="1046_to_442" type="revolute">
		<parent link="442"/>
		<child link="1046"/>
		<axis xyz="0 0 1"/>
		<limit effort="1" lower="3.1415" upper="-3.1415" velocity="1"/>
		<origin rpy="7.932986955291074 4.6057762313231 4.116066467158098" xyz="0.9441648623242971 0.03575603795805771 0.6777622285871637"/>
	</joint>
	<joint name="1047_to_442" type="revolute">
		<parent link="442"/>
		<child link="1047"/>
		<axis xyz="0 0 1"/>
		<limit effort="1" lower="3.1415" upper="-3.1415" velocity="1"/>
		<origin rpy="9.51958434634929 4.6057762313231 4.116066467158098" xyz="0.9441648623242971 0.03575603795805771 0.6777622285871637"/>
	</joint>
	<joint name="448_to_241" type="revolute">
		<parent link="241"/>
		<child link="448"/>
		<axis xyz="0 1 0"/>
		<limit effort="1" lower="3.1415" upper="-3.1415" velocity="1"/>
		<origin rpy="2.3962168743580756 3.3128001126324267 3.0193954515937693" xyz="0.10911108138419778 0.545118737809867 0.30977664146782835"/>
	</joint>
	<joint name="749_to_448" type="revolute">
		<parent link="448"/>
		<child link="749"/>
		<axis xyz="0 0 1"/>
		<limit effort="1" lower="3.1415" upper="-3.1415" velocity="1"/>
		<origin rpy="2.424590078205876 3.433968707250544 3.9153310195599498" xyz="0.513449609166835 0.17256258145547576 0.10747627175183372"/>
	</joint>
	<joint name="750_to_448" type="revolute">
		<parent link="448"/>
		<child link="750"/>
		<axis xyz="0 0 1"/>
		<limit effort="1" lower="3.1415" upper="-3.1415" velocity="1"/>
		<origin rpy="3.6368851173088137 3.433968707250544 3.9153310195599498" xyz="0.513449609166835 0.17256258145547576 0.10747627175183372"/>
	</joint>
	<joint name="1051_to_448" type="revolute">
		<parent link="448"/>
		<child link="1051"/>
		<axis xyz="0 0 1"/>
		<limit effort="1" lower="3.1415" upper="-3.1415" velocity="1"/>
		<origin rpy="6.34638956423286 4.6057762313231 4.116066467158098" xyz="0.9441648623242971 0.03575603795805771 0.6777622285871637"/>
	</joint>
	<joint name="1052_to_448" type="revolute">
		<parent link="448"/>
		<child link="1052"/>
		<axis xyz="0 0 1"/>
		<limit effort="1" lower="3.1415" upper="-3.1415" velocity="1"/>
		<origin rpy="7.932986955291074 4.6057762313231 4.116066467158098" xyz="0.9441648623242971 0.03575603795805771 0.6777622285871637"/>
	</joint>
	<joint name="1053_to_448" type="revolute">
		<parent link="448"/>
		<child link="1053"/>
		<axis xyz="0 0 1"/>
		<limit effort="1" lower="3.1415" upper="-3.1415" velocity="1"/>
		<origin rpy="9.51958434634929 4.6057762313231 4.116066467158098" xyz="0.9441648623242971 0.03575603795805771 0.6777622285871637"/>
	</joint>
	<joint name="454_to_241" type="revolute">
		<parent link="241"/>
		<child link="454"/>
		<axis xyz="0 1 0"/>
		<limit effort="1" lower="3.1415" upper="-3.1415" velocity="1"/>
		<origin rpy="3.194955832477434 3.3128001126324267 3.0193954515937693" xyz="0.10911108138419778 0.545118737809867 0.30977664146782835"/>
	</joint>
	<joint name="755_to_454" type="revolute">
		<parent link="454"/>
		<child link="755"/>
		<axis xyz="0 0 1"/>
		<limit effort="1" lower="3.1415" upper="-3.1415" velocity="1"/>
		<origin rpy="2.424590078205876 3.433968707250544 3.9153310195599498" xyz="0.513449609166835 0.17256258145547576 0.10747627175183372"/>
	</joint>
	<joint name="756_to_454" type="revolute">
		<parent link="454"/>
		<child link="756"/>
		<axis xyz="0 0 1"/>
		<limit effort="1" lower="3.1415" upper="-3.1415" velocity="1"/>
		<origin rpy="3.6368851173088137 3.433968707250544 3.9153310195599498" xyz="0.513449609166835 0.17256258145547576 0.10747627175183372"/>
	</joint>
	<joint name="1057_to_454" type="revolute">
		<parent link="454"/>
		<child link="1057"/>
		<axis xyz="0 0 1"/>
		<limit effort="1" lower="3.1415" upper="-3.1415" velocity="1"/>
		<origin rpy="6.34638956423286 4.6057762313231 4.116066467158098" xyz="0.9441648623242971 0.03575603795805771 0.6777622285871637"/>
	</joint>
	<joint name="1058_to_454" type="revolute">
		<parent link="454"/>
		<child link="1058"/>
		<axis xyz="0 0 1"/>
		<limit effort="1" lower="3.1415" upper="-3.1415" velocity="1"/>
		<origin rpy="7.932986955291074 4.6057762313231 4.116066467158098" xyz="0.9441648623242971 0.03575603795805771 0.6777622285871637"/>
	</joint>
	<joint name="1059_to_454" type="revolute">
		<parent link="454"/>
		<child link="1059"/>
		<axis xyz="0 0 1"/>
		<limit effort="1" lower="3.1415" upper="-3.1415" velocity="1"/>
		<origin rpy="9.51958434634929 4.6057762313231 4.116066467158098" xyz="0.9441648623242971 0.03575603795805771 0.6777622285871637"/>
	</joint>
	<joint name="660_to_241" type="revolute">
		<parent link="241"/>
		<child link="660"/>
		<axis xyz="0 1 0"/>
		<limit effort="1" lower="3.1415" upper="-3.1415" velocity="1"/>
		<origin rpy="3.8420239360981268 3.6945942238276532 3.7656443446822414" xyz="0.48904692493117463 0.3616103010396594 0.2748141126507512"/>
	</joint>
	<joint name="861_to_660" type="revolute">
		<parent link="660"/>
		<child link="861"/>
		<axis xyz="1 0 0"/>
		<limit effort="1" lower="3.1415" upper="-3.1415" velocity="1"/>
		<origin rpy="5.173357940100616 3.2733982649686078 1.3738119842501992" xyz="0.8397619150174855 0.4198149852115245 0.7316587060861907"/>
	</joint>
	<joint name="662_to_241" type="revolute">
		<parent link="241"/>
		<child link="662"/>
		<axis xyz="0 1 0"/>
		<limit effort="1" lower="3.1415" upper="-3.1415" velocity="1"/>
		<origin rpy="4.610428723317752 3.6945942238276532 3.7656443446822414" xyz="0.48904692493117463 0.3616103010396594 0.2748141126507512"/>
	</joint>
	<joint name="863_to_662" type="revolute">
		<parent link="662"/>
		<child link="863"/>
		<axis xyz="1 0 0"/>
		<limit effort="1" lower="3.1415" upper="-3.1415" velocity="1"/>
		<origin rpy="5.173357940100616 3.2733982649686078 1.3738119842501992" xyz="0.8397619150174855 0.4198149852115245 0.7316587060861907"/>
	</joint>
	<joint name="664_to_241" type="revolute">
		<parent link="241"/>
		<child link="664"/>
		<axis xyz="0 1 0"/>
		<limit effort="1" lower="3.1415" upper="-3.1415" velocity="1"/>
		<origin rpy="5.378833510537378 3.6945942238276532 3.7656443446822414" xyz="0.48904692493117463 0.3616103010396594 0.2748141126507512"/>
	</joint>
	<joint name="865_to_664" type="revolute">
		<parent link="664"/>
		<child link="865"/>
		<axis xyz="1 0 0"/>
		<limit effort="1" lower="3.1415" upper="-3.1415" velocity="1"/>
		<origin rpy="5.173357940100616 3.2733982649686078 1.3738119842501992" xyz="0.8397619150174855 0.4198149852115245 0.7316587060861907"/>
	</joint>
	<joint name="366_to_140" type="revolute">
		<parent link="140"/>
		<child link="366"/>
		<axis xyz="1 0 0"/>
		<limit effort="1" lower="3.1415" upper="-3.1415" velocity="1"/>
		<origin rpy="10.491170289653072 3.9344879327490054 1.7864063596710278" xyz="0.4610179755996069 0.08805756137348231 0.26320984231011235"/>
	</joint>
	<joint name="967_to_366" type="revolute">
		<parent link="366"/>
		<child link="967"/>
		<axis xyz="0 0 1"/>
		<limit effort="1" lower="3.1415" upper="-3.1415" velocity="1"/>
		<origin rpy="1.6376957940216532 5.944922854943341 0.016570953960627847" xyz="0.42946886327154843 0.9470078419747924 0.4308568350125678"/>
	</joint>
	<joint name="968_to_366" type="revolute">
		<parent link="366"/>
		<child link="968"/>
		<axis xyz="0 0 1"/>
		<limit effort="1" lower="3.1415" upper="-3.1415" velocity="1"/>
		<origin rpy="2.45654369103248 5.944922854943341 0.016570953960627847" xyz="0.42946886327154843 0.9470078419747924 0.4308568350125678"/>
	</joint>
	<joint name="969_to_366" type="revolute">
		<parent link="366"/>
		<child link="969"/>
		<axis xyz="0 0 1"/>
		<limit effort="1" lower="3.1415" upper="-3.1415" velocity="1"/>
		<origin rpy="3.2753915880433064 5.944922854943341 0.016570953960627847" xyz="0.42946886327154843 0.9470078419747924 0.4308568350125678"/>
	</joint>
	<joint name="370_to_140" type="revolute">
		<parent link="140"/>
		<child link="370"/>
		<axis xyz="1 0 0"/>
		<limit effort="1" lower="3.1415" upper="-3.1415" velocity="1"/>
		<origin rpy="13.988227052870762 3.9344879327490054 1.7864063596710278" xyz="0.4610179755996069 0.08805756137348231 0.26320984231011235"/>
	</joint>
	<joint name="971_to_370" type="revolute">
		<parent link="370"/>
		<child link="971"/>
		<axis xyz="0 0 1"/>
		<limit effort="1" lower="3.1415" upper="-3.1415" velocity="1"/>
		<origin rpy="1.6376957940216532 5.944922854943341 0.016570953960627847" xyz="0.42946886327154843 0.9470078419747924 0.4308568350125678"/>
	</joint>
	<joint name="972_to_370" type="revolute">
		<parent link="370"/>
		<child link="972"/>
		<axis xyz="0 0 1"/>
		<limit effort="1" lower="3.1415" upper="-3.1415" velocity="1"/>
		<origin rpy="2.45654369103248 5.944922854943341 0.016570953960627847" xyz="0.42946886327154843 0.9470078419747924 0.4308568350125678"/>
	</joint>
	<joint name="973_to_370" type="revolute">
		<parent link="370"/>
		<child link="973"/>
		<axis xyz="0 0 1"/>
		<limit effort="1" lower="3.1415" upper="-3.1415" velocity="1"/>
		<origin rpy="3.2753915880433064 5.944922854943341 0.016570953960627847" xyz="0.42946886327154843 0.9470078419747924 0.4308568350125678"/>
	</joint>
	<joint name="574_to_140" type="revolute">
		<parent link="140"/>
		<child link="574"/>
		<axis xyz="1 0 0"/>
		<limit effort="1" lower="3.1415" upper="-3.1415" velocity="1"/>
		<origin rpy="6.170917235056622 4.8517640051467215 4.364670579203324" xyz="0.005683955250957662 0.09737229592884222 0.5408591155595072"/>
	</joint>
	<joint name="575_to_140" type="revolute">
		<parent link="140"/>
		<child link="575"/>
		<axis xyz="1 0 0"/>
		<limit effort="1" lower="3.1415" upper="-3.1415" velocity="1"/>
		<origin rpy="7.405100682067946 4.8517640051467215 4.364670579203324" xyz="0.005683955250957662 0.09737229592884222 0.5408591155595072"/>
	</joint>
	<joint name="1176_to_140" type="revolute">
		<parent link="140"/>
		<child link="1176"/>
		<axis xyz="0 1 0"/>
		<limit effort="1" lower="3.1415" upper="-3.1415" velocity="1"/>
		<origin rpy="4.4846267049499025 2.6745928977140294 4.237730073756579" xyz="0.05696756686212334 0.13814507211450522 0.8244958323783818"/>
	</joint>
	<joint name="1177_to_140" type="revolute">
		<parent link="140"/>
		<child link="1177"/>
		<axis xyz="0 1 0"/>
		<limit effort="1" lower="3.1415" upper="-3.1415" velocity="1"/>
		<origin rpy="5.125287662799889 2.6745928977140294 4.237730073756579" xyz="0.05696756686212334 0.13814507211450522 0.8244958323783818"/>
	</joint>
	<joint name="1178_to_140" type="revolute">
		<parent link="140"/>
		<child link="1178"/>
		<axis xyz="0 1 0"/>
		<limit effort="1" lower="3.1415" upper="-3.1415" velocity="1"/>
		<origin rpy="5.765948620649875 2.6745928977140294 4.237730073756579" xyz="0.05696756686212334 0.13814507211450522 0.8244958323783818"/>
	</joint>
</robot>
