<?xml version="1.0"?><robot name="pepe">
	<link name="0">
		<visual>
			<geometry>
				<cylinder length="1.349073549002775" radius="0.8003669461604143"/>
			</geometry>
		</visual>
		<collision>
			<geometry>
				<cylinder length="1.349073549002775" radius="0.8003669461604143"/>
			</geometry>
		</collision>
		<inertial>
			<mass value="2.714962212292477"/>
			<inertia ixx="0.03" ixy="0" ixz="0" iyx="0" iyy="0.03" izz="0.03"/>
		</inertial>
	</link>
	<link name="11">
		<visual>
			<geometry>
				<cylinder length="0.7967607353490778" radius="0.43004798710737613"/>
			</geometry>
		</visual>
		<collision>
			<geometry>
				<cylinder length="0.7967607353490778" radius="0.43004798710737613"/>
			</geometry>
		</collision>
		<inertial>
			<mass value="0.4629260655908738"/>
			<inertia ixx="0.03" ixy="0" ixz="0" iyx="0" iyy="0.03" izz="0.03"/>
		</inertial>
	</link>
	<link name="22">
		<visual>
			<geometry>
				<cylinder length="1.856737948346875" radius="0.9999"/>
			</geometry>
		</visual>
		<collision>
			<geometry>
				<cylinder length="1.856737948346875" radius="0.9999"/>
			</geometry>
		</collision>
		<inertial>
			<mass value="5.831947733639437"/>
			<inertia ixx="0.03" ixy="0" ixz="0" iyx="0" iyy="0.03" izz="0.03"/>
		</inertial>
	</link>
	<link name="33">
		<visual>
			<geometry>
				<cylinder length="1.2924712818558965" radius="0.17741869393731358"/>
			</geometry>
		</visual>
		<collision>
			<geometry>
				<cylinder length="1.2924712818558965" radius="0.17741869393731358"/>
			</geometry>
		</collision>
		<inertial>
			<mass value="0.12781138190273833"/>
			<inertia ixx="0.03" ixy="0" ixz="0" iyx="0" iyy="0.03" izz="0.03"/>
		</inertial>
	</link>
	<link name="34">
		<visual>
			<geometry>
				<cylinder length="1.2924712818558965" radius="0.17741869393731358"/>
			</geometry>
		</visual>
		<collision>
			<geometry>
				<cylinder length="1.2924712818558965" radius="0.17741869393731358"/>
			</geometry>
		</collision>
		<inertial>
			<mass value="0.12781138190273833"/>
			<inertia ixx="0.03" ixy="0" ixz="0" iyx="0" iyy="0.03" izz="0.03"/>
		</inertial>
	</link>
	<link name="25">
		<visual>
			<geometry>
				<cylinder length="1.856737948346875" radius="0.9999"/>
			</geometry>
		</visual>
		<collision>
			<geometry>
				<cylinder length="1.856737948346875" radius="0.9999"/>
			</geometry>
		</collision>
		<inertial>
			<mass value="5.831947733639437"/>
			<inertia ixx="0.03" ixy="0" ixz="0" iyx="0" iyy="0.03" izz="0.03"/>
		</inertial>
	</link>
	<link name="36">
		<visual>
			<geometry>
				<cylinder length="1.2924712818558965" radius="0.17741869393731358"/>
			</geometry>
		</visual>
		<collision>
			<geometry>
				<cylinder length="1.2924712818558965" radius="0.17741869393731358"/>
			</geometry>
		</collision>
		<inertial>
			<mass value="0.12781138190273833"/>
			<inertia ixx="0.03" ixy="0" ixz="0" iyx="0" iyy="0.03" izz="0.03"/>
		</inertial>
	</link>
	<link name="37">
		<visual>
			<geometry>
				<cylinder length="1.2924712818558965" radius="0.17741869393731358"/>
			</geometry>
		</visual>
		<collision>
			<geometry>
				<cylinder length="1.2924712818558965" radius="0.17741869393731358"/>
			</geometry>
		</collision>
		<inertial>
			<mass value="0.12781138190273833"/>
			<inertia ixx="0.03" ixy="0" ixz="0" iyx="0" iyy="0.03" izz="0.03"/>
		</inertial>
	</link>
	<joint name="11_to_0" type="revolute">
		<parent link="0"/>
		<child link="11"/>
		<axis xyz="0 0 1"/>
		<limit effort="1" lower="3.1415" upper="-3.1415" velocity="1"/>
		<origin rpy="6.997964998096057 4.674758863147256 1.4498086777749795" xyz="0.9563592729508589 0.6524380266579504 0.6067726166371412"/>
	</joint>
	<joint name="22_to_11" type="revolute">
		<parent link="11"/>
		<child link="22"/>
		<axis xyz="1 0 0"/>
		<limit effort="1" lower="3.1415" upper="-3.1415" velocity="1"/>
		<origin rpy="12.565113977297736 5.358322996685524 1.1143862440410601" xyz="0.9921446809327699 0.9999 0.7039010056764574"/>
	</joint>
	<joint name="33_to_22" type="revolute">
		<parent link="22"/>
		<child link="33"/>
		<axis xyz="0 0 1"/>
		<limit effort="1" lower="3.1415" upper="-3.1415" velocity="1"/>
		<origin rpy="2.0556543177386426 4.786743107309758 1.4581030541810585" xyz="0.7677225202684853 0.7526722238192851 0.8568453700284847"/>
	</joint>
	<joint name="34_to_22" type="revolute">
		<parent link="22"/>
		<child link="34"/>
		<axis xyz="0 0 1"/>
		<limit effort="1" lower="3.1415" upper="-3.1415" velocity="1"/>
		<origin rpy="3.0834814766079637 4.786743107309758 1.4581030541810585" xyz="0.7677225202684853 0.7526722238192851 0.8568453700284847"/>
	</joint>
	<joint name="25_to_11" type="revolute">
		<parent link="11"/>
		<child link="25"/>
		<axis xyz="1 0 0"/>
		<limit effort="1" lower="3.1415" upper="-3.1415" velocity="1"/>
		<origin rpy="18.847670965946605 5.358322996685524 1.1143862440410601" xyz="0.9921446809327699 0.9999 0.7039010056764574"/>
	</joint>
	<joint name="36_to_25" type="revolute">
		<parent link="25"/>
		<child link="36"/>
		<axis xyz="0 0 1"/>
		<limit effort="1" lower="3.1415" upper="-3.1415" velocity="1"/>
		<origin rpy="2.0556543177386426 4.786743107309758 1.4581030541810585" xyz="0.7677225202684853 0.7526722238192851 0.8568453700284847"/>
	</joint>
	<joint name="37_to_25" type="revolute">
		<parent link="25"/>
		<child link="37"/>
		<axis xyz="0 0 1"/>
		<limit effort="1" lower="3.1415" upper="-3.1415" velocity="1"/>
		<origin rpy="3.0834814766079637 4.786743107309758 1.4581030541810585" xyz="0.7677225202684853 0.7526722238192851 0.8568453700284847"/>
	</joint>
</robot>
