<?xml version="1.0"?><robot name="pepe">
	<link name="0">
		<visual>
			<geometry>
				<cylinder length="1.149073549002775" radius="0.8003669461604143"/>
			</geometry>
		</visual>
		<collision>
			<geometry>
				<cylinder length="1.149073549002775" radius="0.8003669461604143"/>
			</geometry>
		</collision>
		<inertial>
			<mass value="2.3124693735144346"/>
			<inertia ixx="0.03" ixy="0" ixz="0" iyx="0" iyy="0.03" izz="0.03"/>
		</inertial>
	</link>
	<link name="11">
		<visual>
			<geometry>
				<cylinder length="0.9967607353490777" radius="0.5300479871073761"/>
			</geometry>
		</visual>
		<collision>
			<geometry>
				<cylinder length="0.9967607353490777" radius="0.5300479871073761"/>
			</geometry>
		</collision>
		<inertial>
			<mass value="0.879774102452685"/>
			<inertia ixx="0.03" ixy="0" ixz="0" iyx="0" iyy="0.03" izz="0.03"/>
		</inertial>
	</link>
	<joint name="11_to_0" type="revolute">
		<parent link="0"/>
		<child link="11"/>
		<axis xyz="0 0 1"/>
		<limit effort="1" lower="3.1415" upper="-3.1415" velocity="1"/>
		<origin rpy="8.254602059531974 4.674758863147256 1.4498086777749795" xyz="0.9999 0.6524380266579504 0.6067726166371412"/>
	</joint>
</robot>
