<?xml version="1.0"?><robot name="pepe">
	<link name="0">
		<visual>
			<geometry>
				<cylinder length="1.2481208226524536" radius="0.3765850662787882"/>
			</geometry>
		</visual>
		<collision>
			<geometry>
				<cylinder length="1.2481208226524536" radius="0.3765850662787882"/>
			</geometry>
		</collision>
		<inertial>
			<mass value="0.5560741273262054"/>
			<inertia ixx="0.03" ixy="0" ixz="0" iyx="0" iyy="0.03" izz="0.03"/>
		</inertial>
	</link>
	<link name="11">
		<visual>
			<geometry>
				<cylinder length="0.7853454403519184" radius="0.35254160807820756"/>
			</geometry>
		</visual>
		<collision>
			<geometry>
				<cylinder length="0.7853454403519184" radius="0.35254160807820756"/>
			</geometry>
		</collision>
		<inertial>
			<mass value="0.3066418042690306"/>
			<inertia ixx="0.03" ixy="0" ixz="0" iyx="0" iyy="0.03" izz="0.03"/>
		</inertial>
	</link>
	<joint name="11_to_0" type="revolute">
		<parent link="0"/>
		<child link="11"/>
		<axis xyz="0 0 1"/>
		<limit effort="1" lower="3.1415" upper="-3.1415" velocity="1"/>
		<origin rpy="12.316564959942818 2.536670462446014 2.250080051231806" xyz="0.33638400265132096 0.035632360108815986 0.41232581489814224"/>
	</joint>
</robot>
