<?xml version="1.0"?><robot name="pepe">
	<link name="0">
		<visual>
			<geometry>
				<cylinder length="0.7853454403519184" radius="0.2525416080782076"/>
			</geometry>
		</visual>
		<collision>
			<geometry>
				<cylinder length="0.7853454403519184" radius="0.2525416080782076"/>
			</geometry>
		</collision>
		<inertial>
			<mass value="0.15735352719442636"/>
			<inertia ixx="0.03" ixy="0" ixz="0" iyx="0" iyy="0.03" izz="0.03"/>
		</inertial>
	</link>
	<link name="11">
		<visual>
			<geometry>
				<cylinder length="1.9168577574955858" radius="0.0008612969648227331"/>
			</geometry>
		</visual>
		<collision>
			<geometry>
				<cylinder length="1.9168577574955858" radius="0.0008612969648227331"/>
			</geometry>
		</collision>
		<inertial>
			<mass value="4.467304882838585e-06"/>
			<inertia ixx="0.03" ixy="0" ixz="0" iyx="0" iyy="0.03" izz="0.03"/>
		</inertial>
	</link>
	<link name="22">
		<visual>
			<geometry>
				<cylinder length="1.8305118696539509" radius="0.40608676477427597"/>
			</geometry>
		</visual>
		<collision>
			<geometry>
				<cylinder length="1.8305118696539509" radius="0.40608676477427597"/>
			</geometry>
		</collision>
		<inertial>
			<mass value="0.9483313163545366"/>
			<inertia ixx="0.03" ixy="0" ixz="0" iyx="0" iyy="0.03" izz="0.03"/>
		</inertial>
	</link>
	<link name="23">
		<visual>
			<geometry>
				<cylinder length="1.8305118696539509" radius="0.40608676477427597"/>
			</geometry>
		</visual>
		<collision>
			<geometry>
				<cylinder length="1.8305118696539509" radius="0.40608676477427597"/>
			</geometry>
		</collision>
		<inertial>
			<mass value="0.9483313163545366"/>
			<inertia ixx="0.03" ixy="0" ixz="0" iyx="0" iyy="0.03" izz="0.03"/>
		</inertial>
	</link>
	<link name="24">
		<visual>
			<geometry>
				<cylinder length="1.8305118696539509" radius="0.40608676477427597"/>
			</geometry>
		</visual>
		<collision>
			<geometry>
				<cylinder length="1.8305118696539509" radius="0.40608676477427597"/>
			</geometry>
		</collision>
		<inertial>
			<mass value="0.9483313163545366"/>
			<inertia ixx="0.03" ixy="0" ixz="0" iyx="0" iyy="0.03" izz="0.03"/>
		</inertial>
	</link>
	<link name="15">
		<visual>
			<geometry>
				<cylinder length="1.9168577574955858" radius="0.0008612969648227331"/>
			</geometry>
		</visual>
		<collision>
			<geometry>
				<cylinder length="1.9168577574955858" radius="0.0008612969648227331"/>
			</geometry>
		</collision>
		<inertial>
			<mass value="4.467304882838585e-06"/>
			<inertia ixx="0.03" ixy="0" ixz="0" iyx="0" iyy="0.03" izz="0.03"/>
		</inertial>
	</link>
	<link name="26">
		<visual>
			<geometry>
				<cylinder length="1.8305118696539509" radius="0.40608676477427597"/>
			</geometry>
		</visual>
		<collision>
			<geometry>
				<cylinder length="1.8305118696539509" radius="0.40608676477427597"/>
			</geometry>
		</collision>
		<inertial>
			<mass value="0.9483313163545366"/>
			<inertia ixx="0.03" ixy="0" ixz="0" iyx="0" iyy="0.03" izz="0.03"/>
		</inertial>
	</link>
	<link name="27">
		<visual>
			<geometry>
				<cylinder length="1.8305118696539509" radius="0.40608676477427597"/>
			</geometry>
		</visual>
		<collision>
			<geometry>
				<cylinder length="1.8305118696539509" radius="0.40608676477427597"/>
			</geometry>
		</collision>
		<inertial>
			<mass value="0.9483313163545366"/>
			<inertia ixx="0.03" ixy="0" ixz="0" iyx="0" iyy="0.03" izz="0.03"/>
		</inertial>
	</link>
	<link name="28">
		<visual>
			<geometry>
				<cylinder length="1.8305118696539509" radius="0.40608676477427597"/>
			</geometry>
		</visual>
		<collision>
			<geometry>
				<cylinder length="1.8305118696539509" radius="0.40608676477427597"/>
			</geometry>
		</collision>
		<inertial>
			<mass value="0.9483313163545366"/>
			<inertia ixx="0.03" ixy="0" ixz="0" iyx="0" iyy="0.03" izz="0.03"/>
		</inertial>
	</link>
	<link name="39">
		<visual>
			<geometry>
				<cylinder length="0.8778408121753121" radius="0.6810602327278827"/>
			</geometry>
		</visual>
		<collision>
			<geometry>
				<cylinder length="0.8778408121753121" radius="0.6810602327278827"/>
			</geometry>
		</collision>
		<inertial>
			<mass value="1.279194800911756"/>
			<inertia ixx="0.03" ixy="0" ixz="0" iyx="0" iyy="0.03" izz="0.03"/>
		</inertial>
	</link>
	<link name="310">
		<visual>
			<geometry>
				<cylinder length="0.8778408121753121" radius="0.6810602327278827"/>
			</geometry>
		</visual>
		<collision>
			<geometry>
				<cylinder length="0.8778408121753121" radius="0.6810602327278827"/>
			</geometry>
		</collision>
		<inertial>
			<mass value="1.279194800911756"/>
			<inertia ixx="0.03" ixy="0" ixz="0" iyx="0" iyy="0.03" izz="0.03"/>
		</inertial>
	</link>
	<link name="311">
		<visual>
			<geometry>
				<cylinder length="0.8778408121753121" radius="0.6810602327278827"/>
			</geometry>
		</visual>
		<collision>
			<geometry>
				<cylinder length="0.8778408121753121" radius="0.6810602327278827"/>
			</geometry>
		</collision>
		<inertial>
			<mass value="1.279194800911756"/>
			<inertia ixx="0.03" ixy="0" ixz="0" iyx="0" iyy="0.03" izz="0.03"/>
		</inertial>
	</link>
	<joint name="11_to_0" type="revolute">
		<parent link="0"/>
		<child link="11"/>
		<axis xyz="0 1 0"/>
		<limit effort="1" lower="3.1415" upper="-3.1415" velocity="1"/>
		<origin rpy="4.853035674087351 6.262356433276231 4.280533725595206" xyz="0.7236069504422373 0.9885880704038275 0.4161850445130292"/>
	</joint>
	<joint name="22_to_11" type="revolute">
		<parent link="11"/>
		<child link="22"/>
		<axis xyz="0 1 0"/>
		<limit effort="1" lower="3.1415" upper="-3.1415" velocity="1"/>
		<origin rpy="0.12511119359624798 5.869302657479386 3.7471401696628437" xyz="0.9665428940687371 0.9896372884871573 0.8568418066111094"/>
	</joint>
	<joint name="23_to_11" type="revolute">
		<parent link="11"/>
		<child link="23"/>
		<axis xyz="0 1 0"/>
		<limit effort="1" lower="3.1415" upper="-3.1415" velocity="1"/>
		<origin rpy="0.18766679039437195 5.869302657479386 3.7471401696628437" xyz="0.9665428940687371 0.9896372884871573 0.8568418066111094"/>
	</joint>
	<joint name="24_to_11" type="revolute">
		<parent link="11"/>
		<child link="24"/>
		<axis xyz="0 1 0"/>
		<limit effort="1" lower="3.1415" upper="-3.1415" velocity="1"/>
		<origin rpy="0.25022238719249595 5.869302657479386 3.7471401696628437" xyz="0.9665428940687371 0.9896372884871573 0.8568418066111094"/>
	</joint>
	<joint name="15_to_0" type="revolute">
		<parent link="0"/>
		<child link="15"/>
		<axis xyz="0 1 0"/>
		<limit effort="1" lower="3.1415" upper="-3.1415" velocity="1"/>
		<origin rpy="7.2795535111310254 6.262356433276231 4.280533725595206" xyz="0.7236069504422373 0.9885880704038275 0.4161850445130292"/>
	</joint>
	<joint name="26_to_15" type="revolute">
		<parent link="15"/>
		<child link="26"/>
		<axis xyz="0 1 0"/>
		<limit effort="1" lower="3.1415" upper="-3.1415" velocity="1"/>
		<origin rpy="0.12511119359624798 5.869302657479386 3.7471401696628437" xyz="0.9665428940687371 0.9896372884871573 0.8568418066111094"/>
	</joint>
	<joint name="27_to_15" type="revolute">
		<parent link="15"/>
		<child link="27"/>
		<axis xyz="0 1 0"/>
		<limit effort="1" lower="3.1415" upper="-3.1415" velocity="1"/>
		<origin rpy="0.18766679039437195 5.869302657479386 3.7471401696628437" xyz="0.9665428940687371 0.9896372884871573 0.8568418066111094"/>
	</joint>
	<joint name="28_to_15" type="revolute">
		<parent link="15"/>
		<child link="28"/>
		<axis xyz="0 1 0"/>
		<limit effort="1" lower="3.1415" upper="-3.1415" velocity="1"/>
		<origin rpy="0.25022238719249595 5.869302657479386 3.7471401696628437" xyz="0.9665428940687371 0.9896372884871573 0.8568418066111094"/>
	</joint>
	<joint name="39_to_0" type="revolute">
		<parent link="0"/>
		<child link="39"/>
		<axis xyz="1 0 0"/>
		<limit effort="1" lower="3.1415" upper="-3.1415" velocity="1"/>
		<origin rpy="5.013880434378061 6.0545731271296654 1.7865608202423602" xyz="0.912872583023103 0.511143821914881 0.06417149582715598"/>
	</joint>
	<joint name="310_to_0" type="revolute">
		<parent link="0"/>
		<child link="310"/>
		<axis xyz="1 0 0"/>
		<limit effort="1" lower="3.1415" upper="-3.1415" velocity="1"/>
		<origin rpy="6.267350542972576 6.0545731271296654 1.7865608202423602" xyz="0.912872583023103 0.511143821914881 0.06417149582715598"/>
	</joint>
	<joint name="311_to_0" type="revolute">
		<parent link="0"/>
		<child link="311"/>
		<axis xyz="1 0 0"/>
		<limit effort="1" lower="3.1415" upper="-3.1415" velocity="1"/>
		<origin rpy="7.5208206515670915 6.0545731271296654 1.7865608202423602" xyz="0.912872583023103 0.511143821914881 0.06417149582715598"/>
	</joint>
</robot>
