<?xml version="1.0"?><robot name="pepe">
	<link name="0">
		<visual>
			<geometry>
				<cylinder length="1.7112919320549032" radius="0.5135074818764842"/>
			</geometry>
		</visual>
		<collision>
			<geometry>
				<cylinder length="1.7112919320549032" radius="0.5135074818764842"/>
			</geometry>
		</collision>
		<inertial>
			<mass value="1.4176451191353034"/>
			<inertia ixx="0.03" ixy="0" ixz="0" iyx="0" iyy="0.03" izz="0.03"/>
		</inertial>
	</link>
	<link name="11">
		<visual>
			<geometry>
				<cylinder length="1.9998" radius="0.11852262176713524"/>
			</geometry>
		</visual>
		<collision>
			<geometry>
				<cylinder length="1.9998" radius="0.11852262176713524"/>
			</geometry>
		</collision>
		<inertial>
			<mass value="0.08825492213118463"/>
			<inertia ixx="0.03" ixy="0" ixz="0" iyx="0" iyy="0.03" izz="0.03"/>
		</inertial>
	</link>
	<link name="22">
		<visual>
			<geometry>
				<cylinder length="1.7112919320549032" radius="0.5135074818764842"/>
			</geometry>
		</visual>
		<collision>
			<geometry>
				<cylinder length="1.7112919320549032" radius="0.5135074818764842"/>
			</geometry>
		</collision>
		<inertial>
			<mass value="1.4176451191353034"/>
			<inertia ixx="0.03" ixy="0" ixz="0" iyx="0" iyy="0.03" izz="0.03"/>
		</inertial>
	</link>
	<link name="23">
		<visual>
			<geometry>
				<cylinder length="1.7112919320549032" radius="0.5135074818764842"/>
			</geometry>
		</visual>
		<collision>
			<geometry>
				<cylinder length="1.7112919320549032" radius="0.5135074818764842"/>
			</geometry>
		</collision>
		<inertial>
			<mass value="1.4176451191353034"/>
			<inertia ixx="0.03" ixy="0" ixz="0" iyx="0" iyy="0.03" izz="0.03"/>
		</inertial>
	</link>
	<link name="24">
		<visual>
			<geometry>
				<cylinder length="1.7112919320549032" radius="0.5135074818764842"/>
			</geometry>
		</visual>
		<collision>
			<geometry>
				<cylinder length="1.7112919320549032" radius="0.5135074818764842"/>
			</geometry>
		</collision>
		<inertial>
			<mass value="1.4176451191353034"/>
			<inertia ixx="0.03" ixy="0" ixz="0" iyx="0" iyy="0.03" izz="0.03"/>
		</inertial>
	</link>
	<joint name="11_to_0" type="revolute">
		<parent link="0"/>
		<child link="11"/>
		<axis xyz="0 0 1"/>
		<limit effort="1" lower="3.1415" upper="-3.1415" velocity="1"/>
		<origin rpy="0.9411766697284422 6.282556988648868 4.669752477075483" xyz="0.20275605527502139 0.9999 0.2447046369169771"/>
	</joint>
	<joint name="22_to_0" type="revolute">
		<parent link="0"/>
		<child link="22"/>
		<axis xyz="1 0 0"/>
		<limit effort="1" lower="3.1415" upper="-3.1415" velocity="1"/>
		<origin rpy="8.866774735883505 1.0907596646813935 6.282556988648868" xyz="0.10903610664661101 0.3415547623359111 0.310074180084253"/>
	</joint>
	<joint name="23_to_0" type="revolute">
		<parent link="0"/>
		<child link="23"/>
		<axis xyz="1 0 0"/>
		<limit effort="1" lower="3.1415" upper="-3.1415" velocity="1"/>
		<origin rpy="11.82236631451134 1.0907596646813935 6.282556988648868" xyz="0.10903610664661101 0.3415547623359111 0.310074180084253"/>
	</joint>
	<joint name="24_to_0" type="revolute">
		<parent link="0"/>
		<child link="24"/>
		<axis xyz="1 0 0"/>
		<limit effort="1" lower="3.1415" upper="-3.1415" velocity="1"/>
		<origin rpy="14.777957893139176 1.0907596646813935 6.282556988648868" xyz="0.10903610664661101 0.3415547623359111 0.310074180084253"/>
	</joint>
</robot>
