<?xml version="1.0"?><robot name="pepe">
	<link name="0">
		<visual>
			<geometry>
				<cylinder length="1.848696671994538" radius="0.42291556970490984"/>
			</geometry>
		</visual>
		<collision>
			<geometry>
				<cylinder length="1.848696671994538" radius="0.42291556970490984"/>
			</geometry>
		</collision>
		<inertial>
			<mass value="1.038778327639143"/>
			<inertia ixx="0.03" ixy="0" ixz="0" iyx="0" iyy="0.03" izz="0.03"/>
		</inertial>
	</link>
	<link name="11">
		<visual>
			<geometry>
				<cylinder length="0.05255946890700525" radius="0.5398177036498966"/>
			</geometry>
		</visual>
		<collision>
			<geometry>
				<cylinder length="0.05255946890700525" radius="0.5398177036498966"/>
			</geometry>
		</collision>
		<inertial>
			<mass value="0.048116617275910635"/>
			<inertia ixx="0.03" ixy="0" ixz="0" iyx="0" iyy="0.03" izz="0.03"/>
		</inertial>
	</link>
	<link name="12">
		<visual>
			<geometry>
				<cylinder length="0.05255946890700525" radius="0.5398177036498966"/>
			</geometry>
		</visual>
		<collision>
			<geometry>
				<cylinder length="0.05255946890700525" radius="0.5398177036498966"/>
			</geometry>
		</collision>
		<inertial>
			<mass value="0.048116617275910635"/>
			<inertia ixx="0.03" ixy="0" ixz="0" iyx="0" iyy="0.03" izz="0.03"/>
		</inertial>
	</link>
	<link name="13">
		<visual>
			<geometry>
				<cylinder length="0.05255946890700525" radius="0.5398177036498966"/>
			</geometry>
		</visual>
		<collision>
			<geometry>
				<cylinder length="0.05255946890700525" radius="0.5398177036498966"/>
			</geometry>
		</collision>
		<inertial>
			<mass value="0.048116617275910635"/>
			<inertia ixx="0.03" ixy="0" ixz="0" iyx="0" iyy="0.03" izz="0.03"/>
		</inertial>
	</link>
	<joint name="11_to_0" type="revolute">
		<parent link="0"/>
		<child link="11"/>
		<axis xyz="0 0 1"/>
		<limit effort="1" lower="3.1415" upper="-3.1415" velocity="1"/>
		<origin rpy="5.6612653984215715 3.1699043910322446 0.44175665736072767" xyz="0.5346921704194656 0.7675536365303309 0.03727917973075667"/>
	</joint>
	<joint name="12_to_0" type="revolute">
		<parent link="0"/>
		<child link="12"/>
		<axis xyz="0 0 1"/>
		<limit effort="1" lower="3.1415" upper="-3.1415" velocity="1"/>
		<origin rpy="8.491898097632358 3.1699043910322446 0.44175665736072767" xyz="0.5346921704194656 0.7675536365303309 0.03727917973075667"/>
	</joint>
	<joint name="13_to_0" type="revolute">
		<parent link="0"/>
		<child link="13"/>
		<axis xyz="0 0 1"/>
		<limit effort="1" lower="3.1415" upper="-3.1415" velocity="1"/>
		<origin rpy="11.322530796843143 3.1699043910322446 0.44175665736072767" xyz="0.5346921704194656 0.7675536365303309 0.03727917973075667"/>
	</joint>
</robot>
