<?xml version="1.0"?><robot name="pepe">
	<link name="0">
		<visual>
			<geometry>
				<cylinder length="1.9998" radius="0.9999"/>
			</geometry>
		</visual>
		<collision>
			<geometry>
				<cylinder length="1.9998" radius="0.9999"/>
			</geometry>
		</collision>
		<inertial>
			<mass value="6.281300540076709"/>
			<inertia ixx="0.03" ixy="0" ixz="0" iyx="0" iyy="0.03" izz="0.03"/>
		</inertial>
	</link>
	<link name="11">
		<visual>
			<geometry>
				<cylinder length="0.9274469940070369" radius="0.24450679369046097"/>
			</geometry>
		</visual>
		<collision>
			<geometry>
				<cylinder length="0.9274469940070369" radius="0.24450679369046097"/>
			</geometry>
		</collision>
		<inertial>
			<mass value="0.1741890424965086"/>
			<inertia ixx="0.03" ixy="0" ixz="0" iyx="0" iyy="0.03" izz="0.03"/>
		</inertial>
	</link>
	<link name="12">
		<visual>
			<geometry>
				<cylinder length="0.9274469940070369" radius="0.24450679369046097"/>
			</geometry>
		</visual>
		<collision>
			<geometry>
				<cylinder length="0.9274469940070369" radius="0.24450679369046097"/>
			</geometry>
		</collision>
		<inertial>
			<mass value="0.1741890424965086"/>
			<inertia ixx="0.03" ixy="0" ixz="0" iyx="0" iyy="0.03" izz="0.03"/>
		</inertial>
	</link>
	<link name="13">
		<visual>
			<geometry>
				<cylinder length="0.9274469940070369" radius="0.24450679369046097"/>
			</geometry>
		</visual>
		<collision>
			<geometry>
				<cylinder length="0.9274469940070369" radius="0.24450679369046097"/>
			</geometry>
		</collision>
		<inertial>
			<mass value="0.1741890424965086"/>
			<inertia ixx="0.03" ixy="0" ixz="0" iyx="0" iyy="0.03" izz="0.03"/>
		</inertial>
	</link>
	<joint name="11_to_0" type="revolute">
		<parent link="0"/>
		<child link="11"/>
		<axis xyz="0 0 1"/>
		<limit effort="1" lower="3.1415" upper="-3.1415" velocity="1"/>
		<origin rpy="12.501403369026615 6.282556988648868 4.095839754883953" xyz="0.5507040907358064 0.3018865040146698 0.2808948815863546"/>
	</joint>
	<joint name="12_to_0" type="revolute">
		<parent link="0"/>
		<child link="12"/>
		<axis xyz="0 0 1"/>
		<limit effort="1" lower="3.1415" upper="-3.1415" velocity="1"/>
		<origin rpy="18.75210505353992 6.282556988648868 4.095839754883953" xyz="0.5507040907358064 0.3018865040146698 0.2808948815863546"/>
	</joint>
	<joint name="13_to_0" type="revolute">
		<parent link="0"/>
		<child link="13"/>
		<axis xyz="0 0 1"/>
		<limit effort="1" lower="3.1415" upper="-3.1415" velocity="1"/>
		<origin rpy="25.00280673805323 6.282556988648868 4.095839754883953" xyz="0.5507040907358064 0.3018865040146698 0.2808948815863546"/>
	</joint>
</robot>
