<?xml version="1.0"?><robot name="pepe">
	<link name="0">
		<visual>
			<geometry>
				<cylinder length="1.9998" radius="0.11026936717753458"/>
			</geometry>
		</visual>
		<collision>
			<geometry>
				<cylinder length="1.9998" radius="0.11026936717753458"/>
			</geometry>
		</collision>
		<inertial>
			<mass value="0.07639170463829152"/>
			<inertia ixx="0.03" ixy="0" ixz="0" iyx="0" iyy="0.03" izz="0.03"/>
		</inertial>
	</link>
	<link name="11">
		<visual>
			<geometry>
				<cylinder length="1.9998" radius="0.9999"/>
			</geometry>
		</visual>
		<collision>
			<geometry>
				<cylinder length="1.9998" radius="0.9999"/>
			</geometry>
		</collision>
		<inertial>
			<mass value="6.281300540076709"/>
			<inertia ixx="0.03" ixy="0" ixz="0" iyx="0" iyy="0.03" izz="0.03"/>
		</inertial>
	</link>
	<link name="22">
		<visual>
			<geometry>
				<cylinder length="0.46564214033996487" radius="0.5289516258890312"/>
			</geometry>
		</visual>
		<collision>
			<geometry>
				<cylinder length="0.46564214033996487" radius="0.5289516258890312"/>
			</geometry>
		</collision>
		<inertial>
			<mass value="0.4092927598651034"/>
			<inertia ixx="0.03" ixy="0" ixz="0" iyx="0" iyy="0.03" izz="0.03"/>
		</inertial>
	</link>
	<link name="23">
		<visual>
			<geometry>
				<cylinder length="0.46564214033996487" radius="0.5289516258890312"/>
			</geometry>
		</visual>
		<collision>
			<geometry>
				<cylinder length="0.46564214033996487" radius="0.5289516258890312"/>
			</geometry>
		</collision>
		<inertial>
			<mass value="0.4092927598651034"/>
			<inertia ixx="0.03" ixy="0" ixz="0" iyx="0" iyy="0.03" izz="0.03"/>
		</inertial>
	</link>
	<link name="14">
		<visual>
			<geometry>
				<cylinder length="1.9998" radius="0.9999"/>
			</geometry>
		</visual>
		<collision>
			<geometry>
				<cylinder length="1.9998" radius="0.9999"/>
			</geometry>
		</collision>
		<inertial>
			<mass value="6.281300540076709"/>
			<inertia ixx="0.03" ixy="0" ixz="0" iyx="0" iyy="0.03" izz="0.03"/>
		</inertial>
	</link>
	<link name="25">
		<visual>
			<geometry>
				<cylinder length="0.46564214033996487" radius="0.5289516258890312"/>
			</geometry>
		</visual>
		<collision>
			<geometry>
				<cylinder length="0.46564214033996487" radius="0.5289516258890312"/>
			</geometry>
		</collision>
		<inertial>
			<mass value="0.4092927598651034"/>
			<inertia ixx="0.03" ixy="0" ixz="0" iyx="0" iyy="0.03" izz="0.03"/>
		</inertial>
	</link>
	<link name="26">
		<visual>
			<geometry>
				<cylinder length="0.46564214033996487" radius="0.5289516258890312"/>
			</geometry>
		</visual>
		<collision>
			<geometry>
				<cylinder length="0.46564214033996487" radius="0.5289516258890312"/>
			</geometry>
		</collision>
		<inertial>
			<mass value="0.4092927598651034"/>
			<inertia ixx="0.03" ixy="0" ixz="0" iyx="0" iyy="0.03" izz="0.03"/>
		</inertial>
	</link>
	<link name="17">
		<visual>
			<geometry>
				<cylinder length="1.9998" radius="0.9999"/>
			</geometry>
		</visual>
		<collision>
			<geometry>
				<cylinder length="1.9998" radius="0.9999"/>
			</geometry>
		</collision>
		<inertial>
			<mass value="6.281300540076709"/>
			<inertia ixx="0.03" ixy="0" ixz="0" iyx="0" iyy="0.03" izz="0.03"/>
		</inertial>
	</link>
	<link name="28">
		<visual>
			<geometry>
				<cylinder length="0.46564214033996487" radius="0.5289516258890312"/>
			</geometry>
		</visual>
		<collision>
			<geometry>
				<cylinder length="0.46564214033996487" radius="0.5289516258890312"/>
			</geometry>
		</collision>
		<inertial>
			<mass value="0.4092927598651034"/>
			<inertia ixx="0.03" ixy="0" ixz="0" iyx="0" iyy="0.03" izz="0.03"/>
		</inertial>
	</link>
	<link name="29">
		<visual>
			<geometry>
				<cylinder length="0.46564214033996487" radius="0.5289516258890312"/>
			</geometry>
		</visual>
		<collision>
			<geometry>
				<cylinder length="0.46564214033996487" radius="0.5289516258890312"/>
			</geometry>
		</collision>
		<inertial>
			<mass value="0.4092927598651034"/>
			<inertia ixx="0.03" ixy="0" ixz="0" iyx="0" iyy="0.03" izz="0.03"/>
		</inertial>
	</link>
	<joint name="11_to_0" type="revolute">
		<parent link="0"/>
		<child link="11"/>
		<axis xyz="1 0 0"/>
		<limit effort="1" lower="3.1415" upper="-3.1415" velocity="1"/>
		<origin rpy="10.00547663531266 4.992877849106409 3.6585971237677777" xyz="0.6849810317268884 0.32622935137280745 0.9999"/>
	</joint>
	<joint name="22_to_11" type="revolute">
		<parent link="11"/>
		<child link="22"/>
		<axis xyz="0 0 1"/>
		<limit effort="1" lower="3.1415" upper="-3.1415" velocity="1"/>
		<origin rpy="5.449753385454596 1.8085062525917641 2.305270979714643" xyz="0.6994641821454983 0.9096325912542799 0.9175651804489386"/>
	</joint>
	<joint name="23_to_11" type="revolute">
		<parent link="11"/>
		<child link="23"/>
		<axis xyz="0 0 1"/>
		<limit effort="1" lower="3.1415" upper="-3.1415" velocity="1"/>
		<origin rpy="8.174630078181893 1.8085062525917641 2.305270979714643" xyz="0.6994641821454983 0.9096325912542799 0.9175651804489386"/>
	</joint>
	<joint name="14_to_0" type="revolute">
		<parent link="0"/>
		<child link="14"/>
		<axis xyz="1 0 0"/>
		<limit effort="1" lower="3.1415" upper="-3.1415" velocity="1"/>
		<origin rpy="15.008214952968988 4.992877849106409 3.6585971237677777" xyz="0.6849810317268884 0.32622935137280745 0.9999"/>
	</joint>
	<joint name="25_to_14" type="revolute">
		<parent link="14"/>
		<child link="25"/>
		<axis xyz="0 0 1"/>
		<limit effort="1" lower="3.1415" upper="-3.1415" velocity="1"/>
		<origin rpy="5.449753385454596 1.8085062525917641 2.305270979714643" xyz="0.6994641821454983 0.9096325912542799 0.9175651804489386"/>
	</joint>
	<joint name="26_to_14" type="revolute">
		<parent link="14"/>
		<child link="26"/>
		<axis xyz="0 0 1"/>
		<limit effort="1" lower="3.1415" upper="-3.1415" velocity="1"/>
		<origin rpy="8.174630078181893 1.8085062525917641 2.305270979714643" xyz="0.6994641821454983 0.9096325912542799 0.9175651804489386"/>
	</joint>
	<joint name="17_to_0" type="revolute">
		<parent link="0"/>
		<child link="17"/>
		<axis xyz="1 0 0"/>
		<limit effort="1" lower="3.1415" upper="-3.1415" velocity="1"/>
		<origin rpy="20.01095327062532 4.992877849106409 3.6585971237677777" xyz="0.6849810317268884 0.32622935137280745 0.9999"/>
	</joint>
	<joint name="28_to_17" type="revolute">
		<parent link="17"/>
		<child link="28"/>
		<axis xyz="0 0 1"/>
		<limit effort="1" lower="3.1415" upper="-3.1415" velocity="1"/>
		<origin rpy="5.449753385454596 1.8085062525917641 2.305270979714643" xyz="0.6994641821454983 0.9096325912542799 0.9175651804489386"/>
	</joint>
	<joint name="29_to_17" type="revolute">
		<parent link="17"/>
		<child link="29"/>
		<axis xyz="0 0 1"/>
		<limit effort="1" lower="3.1415" upper="-3.1415" velocity="1"/>
		<origin rpy="8.174630078181893 1.8085062525917641 2.305270979714643" xyz="0.6994641821454983 0.9096325912542799 0.9175651804489386"/>
	</joint>
</robot>
