<?xml version="1.0"?><robot name="pepe">
	<link name="0">
		<visual>
			<geometry>
				<cylinder length="0.20469765564289283" radius="0.01737578657019445"/>
			</geometry>
		</visual>
		<collision>
			<geometry>
				<cylinder length="0.20469765564289283" radius="0.01737578657019445"/>
			</geometry>
		</collision>
		<inertial>
			<mass value="0.00019415638996012175"/>
			<inertia ixx="0.03" ixy="0" ixz="0" iyx="0" iyy="0.03" izz="0.03"/>
		</inertial>
	</link>
	<link name="11">
		<visual>
			<geometry>
				<cylinder length="1.8650633825301641" radius="0.10428888937644346"/>
			</geometry>
		</visual>
		<collision>
			<geometry>
				<cylinder length="1.8650633825301641" radius="0.10428888937644346"/>
			</geometry>
		</collision>
		<inertial>
			<mass value="0.0637264246388024"/>
			<inertia ixx="0.03" ixy="0" ixz="0" iyx="0" iyy="0.03" izz="0.03"/>
		</inertial>
	</link>
	<link name="12">
		<visual>
			<geometry>
				<cylinder length="1.8650633825301641" radius="0.10428888937644346"/>
			</geometry>
		</visual>
		<collision>
			<geometry>
				<cylinder length="1.8650633825301641" radius="0.10428888937644346"/>
			</geometry>
		</collision>
		<inertial>
			<mass value="0.0637264246388024"/>
			<inertia ixx="0.03" ixy="0" ixz="0" iyx="0" iyy="0.03" izz="0.03"/>
		</inertial>
	</link>
	<link name="13">
		<visual>
			<geometry>
				<cylinder length="1.8650633825301641" radius="0.10428888937644346"/>
			</geometry>
		</visual>
		<collision>
			<geometry>
				<cylinder length="1.8650633825301641" radius="0.10428888937644346"/>
			</geometry>
		</collision>
		<inertial>
			<mass value="0.0637264246388024"/>
			<inertia ixx="0.03" ixy="0" ixz="0" iyx="0" iyy="0.03" izz="0.03"/>
		</inertial>
	</link>
	<joint name="11_to_0" type="revolute">
		<parent link="0"/>
		<child link="11"/>
		<axis xyz="0 0 1"/>
		<limit effort="1" lower="3.1415" upper="-3.1415" velocity="1"/>
		<origin rpy="12.565113977297736 6.282556988648868 6.282556988648868" xyz="0.9963054758440083 0.9999 0.9999"/>
	</joint>
	<joint name="12_to_0" type="revolute">
		<parent link="0"/>
		<child link="12"/>
		<axis xyz="0 0 1"/>
		<limit effort="1" lower="3.1415" upper="-3.1415" velocity="1"/>
		<origin rpy="18.847670965946605 6.282556988648868 6.282556988648868" xyz="0.9963054758440083 0.9999 0.9999"/>
	</joint>
	<joint name="13_to_0" type="revolute">
		<parent link="0"/>
		<child link="13"/>
		<axis xyz="0 0 1"/>
		<limit effort="1" lower="3.1415" upper="-3.1415" velocity="1"/>
		<origin rpy="25.130227954595473 6.282556988648868 6.282556988648868" xyz="0.9963054758440083 0.9999 0.9999"/>
	</joint>
</robot>
