<?xml version="1.0"?><robot name="pepe">
	<link name="0">
		<visual>
			<geometry>
				<cylinder length="0.8154769926966201" radius="0.9999"/>
			</geometry>
		</visual>
		<collision>
			<geometry>
				<cylinder length="0.8154769926966201" radius="0.9999"/>
			</geometry>
		</collision>
		<inertial>
			<mass value="2.561384175740279"/>
			<inertia ixx="0.03" ixy="0" ixz="0" iyx="0" iyy="0.03" izz="0.03"/>
		</inertial>
	</link>
	<link name="11">
		<visual>
			<geometry>
				<cylinder length="1.2050055825401313" radius="0.18290773275572914"/>
			</geometry>
		</visual>
		<collision>
			<geometry>
				<cylinder length="1.2050055825401313" radius="0.18290773275572914"/>
			</geometry>
		</collision>
		<inertial>
			<mass value="0.1266493789566258"/>
			<inertia ixx="0.03" ixy="0" ixz="0" iyx="0" iyy="0.03" izz="0.03"/>
		</inertial>
	</link>
	<link name="12">
		<visual>
			<geometry>
				<cylinder length="1.2050055825401313" radius="0.18290773275572914"/>
			</geometry>
		</visual>
		<collision>
			<geometry>
				<cylinder length="1.2050055825401313" radius="0.18290773275572914"/>
			</geometry>
		</collision>
		<inertial>
			<mass value="0.1266493789566258"/>
			<inertia ixx="0.03" ixy="0" ixz="0" iyx="0" iyy="0.03" izz="0.03"/>
		</inertial>
	</link>
	<link name="13">
		<visual>
			<geometry>
				<cylinder length="1.2050055825401313" radius="0.18290773275572914"/>
			</geometry>
		</visual>
		<collision>
			<geometry>
				<cylinder length="1.2050055825401313" radius="0.18290773275572914"/>
			</geometry>
		</collision>
		<inertial>
			<mass value="0.1266493789566258"/>
			<inertia ixx="0.03" ixy="0" ixz="0" iyx="0" iyy="0.03" izz="0.03"/>
		</inertial>
	</link>
	<joint name="11_to_0" type="revolute">
		<parent link="0"/>
		<child link="11"/>
		<axis xyz="0 1 0"/>
		<limit effort="1" lower="3.1415" upper="-3.1415" velocity="1"/>
		<origin rpy="4.9167587414661424 4.924491704359826 3.0762963088839346" xyz="0.29548778666124453 0.12065575549339036 0.5154713031273903"/>
	</joint>
	<joint name="12_to_0" type="revolute">
		<parent link="0"/>
		<child link="12"/>
		<axis xyz="0 1 0"/>
		<limit effort="1" lower="3.1415" upper="-3.1415" velocity="1"/>
		<origin rpy="7.375138112199213 4.924491704359826 3.0762963088839346" xyz="0.29548778666124453 0.12065575549339036 0.5154713031273903"/>
	</joint>
	<joint name="13_to_0" type="revolute">
		<parent link="0"/>
		<child link="13"/>
		<axis xyz="0 1 0"/>
		<limit effort="1" lower="3.1415" upper="-3.1415" velocity="1"/>
		<origin rpy="9.833517482932285 4.924491704359826 3.0762963088839346" xyz="0.29548778666124453 0.12065575549339036 0.5154713031273903"/>
	</joint>
</robot>
