<?xml version="1.0"?><robot name="pepe">
	<link name="0">
		<visual>
			<geometry>
				<cylinder length="0.1840588742756495" radius="0.7477842884599845"/>
			</geometry>
		</visual>
		<collision>
			<geometry>
				<cylinder length="0.1840588742756495" radius="0.7477842884599845"/>
			</geometry>
		</collision>
		<inertial>
			<mass value="0.32333990492988784"/>
			<inertia ixx="0.03" ixy="0" ixz="0" iyx="0" iyy="0.03" izz="0.03"/>
		</inertial>
	</link>
	<link name="11">
		<visual>
			<geometry>
				<cylinder length="1.848696671994538" radius="0.32291556970490987"/>
			</geometry>
		</visual>
		<collision>
			<geometry>
				<cylinder length="1.848696671994538" radius="0.32291556970490987"/>
			</geometry>
		</collision>
		<inertial>
			<mass value="0.605610648863151"/>
			<inertia ixx="0.03" ixy="0" ixz="0" iyx="0" iyy="0.03" izz="0.03"/>
		</inertial>
	</link>
	<link name="12">
		<visual>
			<geometry>
				<cylinder length="1.848696671994538" radius="0.32291556970490987"/>
			</geometry>
		</visual>
		<collision>
			<geometry>
				<cylinder length="1.848696671994538" radius="0.32291556970490987"/>
			</geometry>
		</collision>
		<inertial>
			<mass value="0.605610648863151"/>
			<inertia ixx="0.03" ixy="0" ixz="0" iyx="0" iyy="0.03" izz="0.03"/>
		</inertial>
	</link>
	<link name="13">
		<visual>
			<geometry>
				<cylinder length="1.848696671994538" radius="0.32291556970490987"/>
			</geometry>
		</visual>
		<collision>
			<geometry>
				<cylinder length="1.848696671994538" radius="0.32291556970490987"/>
			</geometry>
		</collision>
		<inertial>
			<mass value="0.605610648863151"/>
			<inertia ixx="0.03" ixy="0" ixz="0" iyx="0" iyy="0.03" izz="0.03"/>
		</inertial>
	</link>
	<joint name="11_to_0" type="revolute">
		<parent link="0"/>
		<child link="11"/>
		<axis xyz="0 0 1"/>
		<limit effort="1" lower="3.1415" upper="-3.1415" velocity="1"/>
		<origin rpy="12.565113977297736 6.282556988648868 4.105571388352411" xyz="0.9347096686071067 0.9999 0.6316106344170129"/>
	</joint>
	<joint name="12_to_0" type="revolute">
		<parent link="0"/>
		<child link="12"/>
		<axis xyz="0 0 1"/>
		<limit effort="1" lower="3.1415" upper="-3.1415" velocity="1"/>
		<origin rpy="18.847670965946605 6.282556988648868 4.105571388352411" xyz="0.9347096686071067 0.9999 0.6316106344170129"/>
	</joint>
	<joint name="13_to_0" type="revolute">
		<parent link="0"/>
		<child link="13"/>
		<axis xyz="0 0 1"/>
		<limit effort="1" lower="3.1415" upper="-3.1415" velocity="1"/>
		<origin rpy="25.130227954595473 6.282556988648868 4.105571388352411" xyz="0.9347096686071067 0.9999 0.6316106344170129"/>
	</joint>
</robot>
