<?xml version="1.0"?><robot name="pepe">
	<link name="0">
		<visual>
			<geometry>
				<cylinder length="1.0481208226524537" radius="0.3765850662787882"/>
			</geometry>
		</visual>
		<collision>
			<geometry>
				<cylinder length="1.0481208226524537" radius="0.3765850662787882"/>
			</geometry>
		</collision>
		<inertial>
			<mass value="0.46696831044792275"/>
			<inertia ixx="0.03" ixy="0" ixz="0" iyx="0" iyy="0.03" izz="0.03"/>
		</inertial>
	</link>
	<link name="11">
		<visual>
			<geometry>
				<cylinder length="0.9853454403519184" radius="0.2525416080782076"/>
			</geometry>
		</visual>
		<collision>
			<geometry>
				<cylinder length="0.9853454403519184" radius="0.2525416080782076"/>
			</geometry>
		</collision>
		<inertial>
			<mass value="0.19742596388519396"/>
			<inertia ixx="0.03" ixy="0" ixz="0" iyx="0" iyy="0.03" izz="0.03"/>
		</inertial>
	</link>
	<joint name="11_to_0" type="revolute">
		<parent link="0"/>
		<child link="11"/>
		<axis xyz="0 0 1"/>
		<limit effort="1" lower="3.1415" upper="-3.1415" velocity="1"/>
		<origin rpy="11.059927898506901 2.536670462446014 1.6217615205138476" xyz="0.33638400265132096 0.035632360108815986 0.41232581489814224"/>
	</joint>
</robot>
