<?xml version="1.0"?><robot name="pepe">
	<link name="0">
		<visual>
			<geometry>
				<cylinder length="0.8901920514966477" radius="0.5064472825512059"/>
			</geometry>
		</visual>
		<collision>
			<geometry>
				<cylinder length="0.8901920514966477" radius="0.5064472825512059"/>
			</geometry>
		</collision>
		<inertial>
			<mass value="0.7173020552644698"/>
			<inertia ixx="0.03" ixy="0" ixz="0" iyx="0" iyy="0.03" izz="0.03"/>
		</inertial>
	</link>
	<link name="11">
		<visual>
			<geometry>
				<cylinder length="1.70395249428705" radius="0.7651485416739926"/>
			</geometry>
		</visual>
		<collision>
			<geometry>
				<cylinder length="1.70395249428705" radius="0.7651485416739926"/>
			</geometry>
		</collision>
		<inertial>
			<mass value="3.1339990824625334"/>
			<inertia ixx="0.03" ixy="0" ixz="0" iyx="0" iyy="0.03" izz="0.03"/>
		</inertial>
	</link>
	<link name="42">
		<visual>
			<geometry>
				<cylinder length="0.7999796851661325" radius="0.01937483564958875"/>
			</geometry>
		</visual>
		<collision>
			<geometry>
				<cylinder length="0.7999796851661325" radius="0.01937483564958875"/>
			</geometry>
		</collision>
		<inertial>
			<mass value="0.0009434195804922696"/>
			<inertia ixx="0.03" ixy="0" ixz="0" iyx="0" iyy="0.03" izz="0.03"/>
		</inertial>
	</link>
	<link name="43">
		<visual>
			<geometry>
				<cylinder length="0.7999796851661325" radius="0.01937483564958875"/>
			</geometry>
		</visual>
		<collision>
			<geometry>
				<cylinder length="0.7999796851661325" radius="0.01937483564958875"/>
			</geometry>
		</collision>
		<inertial>
			<mass value="0.0009434195804922696"/>
			<inertia ixx="0.03" ixy="0" ixz="0" iyx="0" iyy="0.03" izz="0.03"/>
		</inertial>
	</link>
	<link name="44">
		<visual>
			<geometry>
				<cylinder length="0.7999796851661325" radius="0.01937483564958875"/>
			</geometry>
		</visual>
		<collision>
			<geometry>
				<cylinder length="0.7999796851661325" radius="0.01937483564958875"/>
			</geometry>
		</collision>
		<inertial>
			<mass value="0.0009434195804922696"/>
			<inertia ixx="0.03" ixy="0" ixz="0" iyx="0" iyy="0.03" izz="0.03"/>
		</inertial>
	</link>
	<link name="15">
		<visual>
			<geometry>
				<cylinder length="1.70395249428705" radius="0.7651485416739926"/>
			</geometry>
		</visual>
		<collision>
			<geometry>
				<cylinder length="1.70395249428705" radius="0.7651485416739926"/>
			</geometry>
		</collision>
		<inertial>
			<mass value="3.1339990824625334"/>
			<inertia ixx="0.03" ixy="0" ixz="0" iyx="0" iyy="0.03" izz="0.03"/>
		</inertial>
	</link>
	<link name="46">
		<visual>
			<geometry>
				<cylinder length="0.7999796851661325" radius="0.01937483564958875"/>
			</geometry>
		</visual>
		<collision>
			<geometry>
				<cylinder length="0.7999796851661325" radius="0.01937483564958875"/>
			</geometry>
		</collision>
		<inertial>
			<mass value="0.0009434195804922696"/>
			<inertia ixx="0.03" ixy="0" ixz="0" iyx="0" iyy="0.03" izz="0.03"/>
		</inertial>
	</link>
	<link name="47">
		<visual>
			<geometry>
				<cylinder length="0.7999796851661325" radius="0.01937483564958875"/>
			</geometry>
		</visual>
		<collision>
			<geometry>
				<cylinder length="0.7999796851661325" radius="0.01937483564958875"/>
			</geometry>
		</collision>
		<inertial>
			<mass value="0.0009434195804922696"/>
			<inertia ixx="0.03" ixy="0" ixz="0" iyx="0" iyy="0.03" izz="0.03"/>
		</inertial>
	</link>
	<link name="48">
		<visual>
			<geometry>
				<cylinder length="0.7999796851661325" radius="0.01937483564958875"/>
			</geometry>
		</visual>
		<collision>
			<geometry>
				<cylinder length="0.7999796851661325" radius="0.01937483564958875"/>
			</geometry>
		</collision>
		<inertial>
			<mass value="0.0009434195804922696"/>
			<inertia ixx="0.03" ixy="0" ixz="0" iyx="0" iyy="0.03" izz="0.03"/>
		</inertial>
	</link>
	<link name="19">
		<visual>
			<geometry>
				<cylinder length="1.70395249428705" radius="0.7651485416739926"/>
			</geometry>
		</visual>
		<collision>
			<geometry>
				<cylinder length="1.70395249428705" radius="0.7651485416739926"/>
			</geometry>
		</collision>
		<inertial>
			<mass value="3.1339990824625334"/>
			<inertia ixx="0.03" ixy="0" ixz="0" iyx="0" iyy="0.03" izz="0.03"/>
		</inertial>
	</link>
	<link name="410">
		<visual>
			<geometry>
				<cylinder length="0.7999796851661325" radius="0.01937483564958875"/>
			</geometry>
		</visual>
		<collision>
			<geometry>
				<cylinder length="0.7999796851661325" radius="0.01937483564958875"/>
			</geometry>
		</collision>
		<inertial>
			<mass value="0.0009434195804922696"/>
			<inertia ixx="0.03" ixy="0" ixz="0" iyx="0" iyy="0.03" izz="0.03"/>
		</inertial>
	</link>
	<link name="411">
		<visual>
			<geometry>
				<cylinder length="0.7999796851661325" radius="0.01937483564958875"/>
			</geometry>
		</visual>
		<collision>
			<geometry>
				<cylinder length="0.7999796851661325" radius="0.01937483564958875"/>
			</geometry>
		</collision>
		<inertial>
			<mass value="0.0009434195804922696"/>
			<inertia ixx="0.03" ixy="0" ixz="0" iyx="0" iyy="0.03" izz="0.03"/>
		</inertial>
	</link>
	<link name="412">
		<visual>
			<geometry>
				<cylinder length="0.7999796851661325" radius="0.01937483564958875"/>
			</geometry>
		</visual>
		<collision>
			<geometry>
				<cylinder length="0.7999796851661325" radius="0.01937483564958875"/>
			</geometry>
		</collision>
		<inertial>
			<mass value="0.0009434195804922696"/>
			<inertia ixx="0.03" ixy="0" ixz="0" iyx="0" iyy="0.03" izz="0.03"/>
		</inertial>
	</link>
	<link name="213">
		<visual>
			<geometry>
				<cylinder length="1.2064577379601262" radius="0.2627926120981494"/>
			</geometry>
		</visual>
		<collision>
			<geometry>
				<cylinder length="1.2064577379601262" radius="0.2627926120981494"/>
			</geometry>
		</collision>
		<inertial>
			<mass value="0.261750963731005"/>
			<inertia ixx="0.03" ixy="0" ixz="0" iyx="0" iyy="0.03" izz="0.03"/>
		</inertial>
	</link>
	<link name="614">
		<visual>
			<geometry>
				<cylinder length="1.6809551169049792" radius="0.4075818163612328"/>
			</geometry>
		</visual>
		<collision>
			<geometry>
				<cylinder length="1.6809551169049792" radius="0.4075818163612328"/>
			</geometry>
		</collision>
		<inertial>
			<mass value="0.8772746721156066"/>
			<inertia ixx="0.03" ixy="0" ixz="0" iyx="0" iyy="0.03" izz="0.03"/>
		</inertial>
	</link>
	<link name="615">
		<visual>
			<geometry>
				<cylinder length="1.6809551169049792" radius="0.4075818163612328"/>
			</geometry>
		</visual>
		<collision>
			<geometry>
				<cylinder length="1.6809551169049792" radius="0.4075818163612328"/>
			</geometry>
		</collision>
		<inertial>
			<mass value="0.8772746721156066"/>
			<inertia ixx="0.03" ixy="0" ixz="0" iyx="0" iyy="0.03" izz="0.03"/>
		</inertial>
	</link>
	<link name="616">
		<visual>
			<geometry>
				<cylinder length="1.6809551169049792" radius="0.4075818163612328"/>
			</geometry>
		</visual>
		<collision>
			<geometry>
				<cylinder length="1.6809551169049792" radius="0.4075818163612328"/>
			</geometry>
		</collision>
		<inertial>
			<mass value="0.8772746721156066"/>
			<inertia ixx="0.03" ixy="0" ixz="0" iyx="0" iyy="0.03" izz="0.03"/>
		</inertial>
	</link>
	<link name="1017">
		<visual>
			<geometry>
				<cylinder length="0.028577785341288298" radius="0.7447936491645138"/>
			</geometry>
		</visual>
		<collision>
			<geometry>
				<cylinder length="0.028577785341288298" radius="0.7447936491645138"/>
			</geometry>
		</collision>
		<inertial>
			<mass value="0.04980241145395348"/>
			<inertia ixx="0.03" ixy="0" ixz="0" iyx="0" iyy="0.03" izz="0.03"/>
		</inertial>
	</link>
	<link name="218">
		<visual>
			<geometry>
				<cylinder length="1.2064577379601262" radius="0.2627926120981494"/>
			</geometry>
		</visual>
		<collision>
			<geometry>
				<cylinder length="1.2064577379601262" radius="0.2627926120981494"/>
			</geometry>
		</collision>
		<inertial>
			<mass value="0.261750963731005"/>
			<inertia ixx="0.03" ixy="0" ixz="0" iyx="0" iyy="0.03" izz="0.03"/>
		</inertial>
	</link>
	<link name="619">
		<visual>
			<geometry>
				<cylinder length="1.6809551169049792" radius="0.4075818163612328"/>
			</geometry>
		</visual>
		<collision>
			<geometry>
				<cylinder length="1.6809551169049792" radius="0.4075818163612328"/>
			</geometry>
		</collision>
		<inertial>
			<mass value="0.8772746721156066"/>
			<inertia ixx="0.03" ixy="0" ixz="0" iyx="0" iyy="0.03" izz="0.03"/>
		</inertial>
	</link>
	<link name="620">
		<visual>
			<geometry>
				<cylinder length="1.6809551169049792" radius="0.4075818163612328"/>
			</geometry>
		</visual>
		<collision>
			<geometry>
				<cylinder length="1.6809551169049792" radius="0.4075818163612328"/>
			</geometry>
		</collision>
		<inertial>
			<mass value="0.8772746721156066"/>
			<inertia ixx="0.03" ixy="0" ixz="0" iyx="0" iyy="0.03" izz="0.03"/>
		</inertial>
	</link>
	<link name="621">
		<visual>
			<geometry>
				<cylinder length="1.6809551169049792" radius="0.4075818163612328"/>
			</geometry>
		</visual>
		<collision>
			<geometry>
				<cylinder length="1.6809551169049792" radius="0.4075818163612328"/>
			</geometry>
		</collision>
		<inertial>
			<mass value="0.8772746721156066"/>
			<inertia ixx="0.03" ixy="0" ixz="0" iyx="0" iyy="0.03" izz="0.03"/>
		</inertial>
	</link>
	<link name="1022">
		<visual>
			<geometry>
				<cylinder length="0.028577785341288298" radius="0.7447936491645138"/>
			</geometry>
		</visual>
		<collision>
			<geometry>
				<cylinder length="0.028577785341288298" radius="0.7447936491645138"/>
			</geometry>
		</collision>
		<inertial>
			<mass value="0.04980241145395348"/>
			<inertia ixx="0.03" ixy="0" ixz="0" iyx="0" iyy="0.03" izz="0.03"/>
		</inertial>
	</link>
	<link name="223">
		<visual>
			<geometry>
				<cylinder length="1.2064577379601262" radius="0.2627926120981494"/>
			</geometry>
		</visual>
		<collision>
			<geometry>
				<cylinder length="1.2064577379601262" radius="0.2627926120981494"/>
			</geometry>
		</collision>
		<inertial>
			<mass value="0.261750963731005"/>
			<inertia ixx="0.03" ixy="0" ixz="0" iyx="0" iyy="0.03" izz="0.03"/>
		</inertial>
	</link>
	<link name="624">
		<visual>
			<geometry>
				<cylinder length="1.6809551169049792" radius="0.4075818163612328"/>
			</geometry>
		</visual>
		<collision>
			<geometry>
				<cylinder length="1.6809551169049792" radius="0.4075818163612328"/>
			</geometry>
		</collision>
		<inertial>
			<mass value="0.8772746721156066"/>
			<inertia ixx="0.03" ixy="0" ixz="0" iyx="0" iyy="0.03" izz="0.03"/>
		</inertial>
	</link>
	<link name="625">
		<visual>
			<geometry>
				<cylinder length="1.6809551169049792" radius="0.4075818163612328"/>
			</geometry>
		</visual>
		<collision>
			<geometry>
				<cylinder length="1.6809551169049792" radius="0.4075818163612328"/>
			</geometry>
		</collision>
		<inertial>
			<mass value="0.8772746721156066"/>
			<inertia ixx="0.03" ixy="0" ixz="0" iyx="0" iyy="0.03" izz="0.03"/>
		</inertial>
	</link>
	<link name="626">
		<visual>
			<geometry>
				<cylinder length="1.6809551169049792" radius="0.4075818163612328"/>
			</geometry>
		</visual>
		<collision>
			<geometry>
				<cylinder length="1.6809551169049792" radius="0.4075818163612328"/>
			</geometry>
		</collision>
		<inertial>
			<mass value="0.8772746721156066"/>
			<inertia ixx="0.03" ixy="0" ixz="0" iyx="0" iyy="0.03" izz="0.03"/>
		</inertial>
	</link>
	<link name="1027">
		<visual>
			<geometry>
				<cylinder length="0.028577785341288298" radius="0.7447936491645138"/>
			</geometry>
		</visual>
		<collision>
			<geometry>
				<cylinder length="0.028577785341288298" radius="0.7447936491645138"/>
			</geometry>
		</collision>
		<inertial>
			<mass value="0.04980241145395348"/>
			<inertia ixx="0.03" ixy="0" ixz="0" iyx="0" iyy="0.03" izz="0.03"/>
		</inertial>
	</link>
	<link name="328">
		<visual>
			<geometry>
				<cylinder length="1.6092216545349383" radius="0.48012630367590414"/>
			</geometry>
		</visual>
		<collision>
			<geometry>
				<cylinder length="1.6092216545349383" radius="0.48012630367590414"/>
			</geometry>
		</collision>
		<inertial>
			<mass value="1.1654046310325978"/>
			<inertia ixx="0.03" ixy="0" ixz="0" iyx="0" iyy="0.03" izz="0.03"/>
		</inertial>
	</link>
	<link name="929">
		<visual>
			<geometry>
				<cylinder length="0.20136715535178928" radius="0.9924780481241718"/>
			</geometry>
		</visual>
		<collision>
			<geometry>
				<cylinder length="0.20136715535178928" radius="0.9924780481241718"/>
			</geometry>
		</collision>
		<inertial>
			<mass value="0.6231323913035248"/>
			<inertia ixx="0.03" ixy="0" ixz="0" iyx="0" iyy="0.03" izz="0.03"/>
		</inertial>
	</link>
	<link name="330">
		<visual>
			<geometry>
				<cylinder length="1.6092216545349383" radius="0.48012630367590414"/>
			</geometry>
		</visual>
		<collision>
			<geometry>
				<cylinder length="1.6092216545349383" radius="0.48012630367590414"/>
			</geometry>
		</collision>
		<inertial>
			<mass value="1.1654046310325978"/>
			<inertia ixx="0.03" ixy="0" ixz="0" iyx="0" iyy="0.03" izz="0.03"/>
		</inertial>
	</link>
	<link name="931">
		<visual>
			<geometry>
				<cylinder length="0.20136715535178928" radius="0.9924780481241718"/>
			</geometry>
		</visual>
		<collision>
			<geometry>
				<cylinder length="0.20136715535178928" radius="0.9924780481241718"/>
			</geometry>
		</collision>
		<inertial>
			<mass value="0.6231323913035248"/>
			<inertia ixx="0.03" ixy="0" ixz="0" iyx="0" iyy="0.03" izz="0.03"/>
		</inertial>
	</link>
	<link name="532">
		<visual>
			<geometry>
				<cylinder length="1.0406269822043908" radius="0.520911832069013"/>
			</geometry>
		</visual>
		<collision>
			<geometry>
				<cylinder length="1.0406269822043908" radius="0.520911832069013"/>
			</geometry>
		</collision>
		<inertial>
			<mass value="0.8871016754345425"/>
			<inertia ixx="0.03" ixy="0" ixz="0" iyx="0" iyy="0.03" izz="0.03"/>
		</inertial>
	</link>
	<link name="833">
		<visual>
			<geometry>
				<cylinder length="1.8282608727290366" radius="0.5238322988696953"/>
			</geometry>
		</visual>
		<collision>
			<geometry>
				<cylinder length="1.8282608727290366" radius="0.5238322988696953"/>
			</geometry>
		</collision>
		<inertial>
			<mass value="1.5760594072011493"/>
			<inertia ixx="0.03" ixy="0" ixz="0" iyx="0" iyy="0.03" izz="0.03"/>
		</inertial>
	</link>
	<link name="1134">
		<visual>
			<geometry>
				<cylinder length="1.3413208221722763" radius="0.23622438679956503"/>
			</geometry>
		</visual>
		<collision>
			<geometry>
				<cylinder length="1.3413208221722763" radius="0.23622438679956503"/>
			</geometry>
		</collision>
		<inertial>
			<mass value="0.23514297025400552"/>
			<inertia ixx="0.03" ixy="0" ixz="0" iyx="0" iyy="0.03" izz="0.03"/>
		</inertial>
	</link>
	<link name="735">
		<visual>
			<geometry>
				<cylinder length="0.38292365083524227" radius="0.8735914438047099"/>
			</geometry>
		</visual>
		<collision>
			<geometry>
				<cylinder length="0.38292365083524227" radius="0.8735914438047099"/>
			</geometry>
		</collision>
		<inertial>
			<mass value="0.9180763651901928"/>
			<inertia ixx="0.03" ixy="0" ixz="0" iyx="0" iyy="0.03" izz="0.03"/>
		</inertial>
	</link>
	<link name="736">
		<visual>
			<geometry>
				<cylinder length="0.38292365083524227" radius="0.8735914438047099"/>
			</geometry>
		</visual>
		<collision>
			<geometry>
				<cylinder length="0.38292365083524227" radius="0.8735914438047099"/>
			</geometry>
		</collision>
		<inertial>
			<mass value="0.9180763651901928"/>
			<inertia ixx="0.03" ixy="0" ixz="0" iyx="0" iyy="0.03" izz="0.03"/>
		</inertial>
	</link>
	<joint name="11_to_0" type="revolute">
		<parent link="0"/>
		<child link="11"/>
		<axis xyz="1 0 0"/>
		<limit effort="1" lower="3.1415" upper="-3.1415" velocity="1"/>
		<origin rpy="9.032049515710266 2.55451078082068 3.1761236737343506" xyz="0.68566985513273 0.5064215327422712 0.4388266654996933"/>
	</joint>
	<joint name="42_to_11" type="revolute">
		<parent link="11"/>
		<child link="42"/>
		<axis xyz="0 1 0"/>
		<limit effort="1" lower="3.1415" upper="-3.1415" velocity="1"/>
		<origin rpy="6.626474784837578 1.2643631658433683 0.5610217053788114" xyz="0.7279412650846612 0.660848220537147 0.3340370481463345"/>
	</joint>
	<joint name="43_to_11" type="revolute">
		<parent link="11"/>
		<child link="43"/>
		<axis xyz="0 1 0"/>
		<limit effort="1" lower="3.1415" upper="-3.1415" velocity="1"/>
		<origin rpy="9.939712177256368 1.2643631658433683 0.5610217053788114" xyz="0.7279412650846612 0.660848220537147 0.3340370481463345"/>
	</joint>
	<joint name="44_to_11" type="revolute">
		<parent link="11"/>
		<child link="44"/>
		<axis xyz="0 1 0"/>
		<limit effort="1" lower="3.1415" upper="-3.1415" velocity="1"/>
		<origin rpy="13.252949569675156 1.2643631658433683 0.5610217053788114" xyz="0.7279412650846612 0.660848220537147 0.3340370481463345"/>
	</joint>
	<joint name="15_to_0" type="revolute">
		<parent link="0"/>
		<child link="15"/>
		<axis xyz="1 0 0"/>
		<limit effort="1" lower="3.1415" upper="-3.1415" velocity="1"/>
		<origin rpy="13.5480742735654 2.55451078082068 3.1761236737343506" xyz="0.68566985513273 0.5064215327422712 0.4388266654996933"/>
	</joint>
	<joint name="46_to_15" type="revolute">
		<parent link="15"/>
		<child link="46"/>
		<axis xyz="0 1 0"/>
		<limit effort="1" lower="3.1415" upper="-3.1415" velocity="1"/>
		<origin rpy="6.626474784837578 1.2643631658433683 0.5610217053788114" xyz="0.7279412650846612 0.660848220537147 0.3340370481463345"/>
	</joint>
	<joint name="47_to_15" type="revolute">
		<parent link="15"/>
		<child link="47"/>
		<axis xyz="0 1 0"/>
		<limit effort="1" lower="3.1415" upper="-3.1415" velocity="1"/>
		<origin rpy="9.939712177256368 1.2643631658433683 0.5610217053788114" xyz="0.7279412650846612 0.660848220537147 0.3340370481463345"/>
	</joint>
	<joint name="48_to_15" type="revolute">
		<parent link="15"/>
		<child link="48"/>
		<axis xyz="0 1 0"/>
		<limit effort="1" lower="3.1415" upper="-3.1415" velocity="1"/>
		<origin rpy="13.252949569675156 1.2643631658433683 0.5610217053788114" xyz="0.7279412650846612 0.660848220537147 0.3340370481463345"/>
	</joint>
	<joint name="19_to_0" type="revolute">
		<parent link="0"/>
		<child link="19"/>
		<axis xyz="1 0 0"/>
		<limit effort="1" lower="3.1415" upper="-3.1415" velocity="1"/>
		<origin rpy="18.064099031420533 2.55451078082068 3.1761236737343506" xyz="0.68566985513273 0.5064215327422712 0.4388266654996933"/>
	</joint>
	<joint name="410_to_19" type="revolute">
		<parent link="19"/>
		<child link="410"/>
		<axis xyz="0 1 0"/>
		<limit effort="1" lower="3.1415" upper="-3.1415" velocity="1"/>
		<origin rpy="6.626474784837578 1.2643631658433683 0.5610217053788114" xyz="0.7279412650846612 0.660848220537147 0.3340370481463345"/>
	</joint>
	<joint name="411_to_19" type="revolute">
		<parent link="19"/>
		<child link="411"/>
		<axis xyz="0 1 0"/>
		<limit effort="1" lower="3.1415" upper="-3.1415" velocity="1"/>
		<origin rpy="9.939712177256368 1.2643631658433683 0.5610217053788114" xyz="0.7279412650846612 0.660848220537147 0.3340370481463345"/>
	</joint>
	<joint name="412_to_19" type="revolute">
		<parent link="19"/>
		<child link="412"/>
		<axis xyz="0 1 0"/>
		<limit effort="1" lower="3.1415" upper="-3.1415" velocity="1"/>
		<origin rpy="13.252949569675156 1.2643631658433683 0.5610217053788114" xyz="0.7279412650846612 0.660848220537147 0.3340370481463345"/>
	</joint>
	<joint name="213_to_0" type="revolute">
		<parent link="0"/>
		<child link="213"/>
		<axis xyz="0 1 0"/>
		<limit effort="1" lower="3.1415" upper="-3.1415" velocity="1"/>
		<origin rpy="28.171939074159358 0.8793802002745661 3.7692474170316608" xyz="0.3098044227317448 0.025479588017144672 0.33241017639811965"/>
	</joint>
	<joint name="614_to_213" type="revolute">
		<parent link="213"/>
		<child link="614"/>
		<axis xyz="0 1 0"/>
		<limit effort="1" lower="3.1415" upper="-3.1415" velocity="1"/>
		<origin rpy="10.087498024251 4.491488243147064 0.46713990964497015" xyz="0.6643551668921392 0.057871213077229866 0.0897885952109625"/>
	</joint>
	<joint name="615_to_213" type="revolute">
		<parent link="213"/>
		<child link="615"/>
		<axis xyz="0 1 0"/>
		<limit effort="1" lower="3.1415" upper="-3.1415" velocity="1"/>
		<origin rpy="15.1312470363765 4.491488243147064 0.46713990964497015" xyz="0.6643551668921392 0.057871213077229866 0.0897885952109625"/>
	</joint>
	<joint name="616_to_213" type="revolute">
		<parent link="213"/>
		<child link="616"/>
		<axis xyz="0 1 0"/>
		<limit effort="1" lower="3.1415" upper="-3.1415" velocity="1"/>
		<origin rpy="20.174996048502 4.491488243147064 0.46713990964497015" xyz="0.6643551668921392 0.057871213077229866 0.0897885952109625"/>
	</joint>
	<joint name="1017_to_213" type="revolute">
		<parent link="213"/>
		<child link="1017"/>
		<axis xyz="1 0 0"/>
		<limit effort="1" lower="3.1415" upper="-3.1415" velocity="1"/>
		<origin rpy="8.677071237850072 3.618958195114275 2.748632317477414" xyz="0.92498770577277 0.05855291418934361 0.41834577379170323"/>
	</joint>
	<joint name="218_to_0" type="revolute">
		<parent link="0"/>
		<child link="218"/>
		<axis xyz="0 1 0"/>
		<limit effort="1" lower="3.1415" upper="-3.1415" velocity="1"/>
		<origin rpy="33.80632688899123 0.8793802002745661 3.7692474170316608" xyz="0.3098044227317448 0.025479588017144672 0.33241017639811965"/>
	</joint>
	<joint name="619_to_218" type="revolute">
		<parent link="218"/>
		<child link="619"/>
		<axis xyz="0 1 0"/>
		<limit effort="1" lower="3.1415" upper="-3.1415" velocity="1"/>
		<origin rpy="10.087498024251 4.491488243147064 0.46713990964497015" xyz="0.6643551668921392 0.057871213077229866 0.0897885952109625"/>
	</joint>
	<joint name="620_to_218" type="revolute">
		<parent link="218"/>
		<child link="620"/>
		<axis xyz="0 1 0"/>
		<limit effort="1" lower="3.1415" upper="-3.1415" velocity="1"/>
		<origin rpy="15.1312470363765 4.491488243147064 0.46713990964497015" xyz="0.6643551668921392 0.057871213077229866 0.0897885952109625"/>
	</joint>
	<joint name="621_to_218" type="revolute">
		<parent link="218"/>
		<child link="621"/>
		<axis xyz="0 1 0"/>
		<limit effort="1" lower="3.1415" upper="-3.1415" velocity="1"/>
		<origin rpy="20.174996048502 4.491488243147064 0.46713990964497015" xyz="0.6643551668921392 0.057871213077229866 0.0897885952109625"/>
	</joint>
	<joint name="1022_to_218" type="revolute">
		<parent link="218"/>
		<child link="1022"/>
		<axis xyz="1 0 0"/>
		<limit effort="1" lower="3.1415" upper="-3.1415" velocity="1"/>
		<origin rpy="8.677071237850072 3.618958195114275 2.748632317477414" xyz="0.92498770577277 0.05855291418934361 0.41834577379170323"/>
	</joint>
	<joint name="223_to_0" type="revolute">
		<parent link="0"/>
		<child link="223"/>
		<axis xyz="0 1 0"/>
		<limit effort="1" lower="3.1415" upper="-3.1415" velocity="1"/>
		<origin rpy="39.440714703823105 0.8793802002745661 3.7692474170316608" xyz="0.3098044227317448 0.025479588017144672 0.33241017639811965"/>
	</joint>
	<joint name="624_to_223" type="revolute">
		<parent link="223"/>
		<child link="624"/>
		<axis xyz="0 1 0"/>
		<limit effort="1" lower="3.1415" upper="-3.1415" velocity="1"/>
		<origin rpy="10.087498024251 4.491488243147064 0.46713990964497015" xyz="0.6643551668921392 0.057871213077229866 0.0897885952109625"/>
	</joint>
	<joint name="625_to_223" type="revolute">
		<parent link="223"/>
		<child link="625"/>
		<axis xyz="0 1 0"/>
		<limit effort="1" lower="3.1415" upper="-3.1415" velocity="1"/>
		<origin rpy="15.1312470363765 4.491488243147064 0.46713990964497015" xyz="0.6643551668921392 0.057871213077229866 0.0897885952109625"/>
	</joint>
	<joint name="626_to_223" type="revolute">
		<parent link="223"/>
		<child link="626"/>
		<axis xyz="0 1 0"/>
		<limit effort="1" lower="3.1415" upper="-3.1415" velocity="1"/>
		<origin rpy="20.174996048502 4.491488243147064 0.46713990964497015" xyz="0.6643551668921392 0.057871213077229866 0.0897885952109625"/>
	</joint>
	<joint name="1027_to_223" type="revolute">
		<parent link="223"/>
		<child link="1027"/>
		<axis xyz="1 0 0"/>
		<limit effort="1" lower="3.1415" upper="-3.1415" velocity="1"/>
		<origin rpy="8.677071237850072 3.618958195114275 2.748632317477414" xyz="0.92498770577277 0.05855291418934361 0.41834577379170323"/>
	</joint>
	<joint name="328_to_0" type="revolute">
		<parent link="0"/>
		<child link="328"/>
		<axis xyz="1 0 0"/>
		<limit effort="1" lower="3.1415" upper="-3.1415" velocity="1"/>
		<origin rpy="28.83982731647279 2.869972002944927 4.817300266565993" xyz="0.6697313751728675 0.7912288769389556 0.13765386662496326"/>
	</joint>
	<joint name="929_to_328" type="revolute">
		<parent link="328"/>
		<child link="929"/>
		<axis xyz="1 0 0"/>
		<limit effort="1" lower="3.1415" upper="-3.1415" velocity="1"/>
		<origin rpy="9.560429822679476 2.1307635358824233 5.11997545788624" xyz="0.023220178926395052 0.7508712035405971 0.3593218542290584"/>
	</joint>
	<joint name="330_to_0" type="revolute">
		<parent link="0"/>
		<child link="330"/>
		<axis xyz="1 0 0"/>
		<limit effort="1" lower="3.1415" upper="-3.1415" velocity="1"/>
		<origin rpy="32.444805731031884 2.869972002944927 4.817300266565993" xyz="0.6697313751728675 0.7912288769389556 0.13765386662496326"/>
	</joint>
	<joint name="931_to_330" type="revolute">
		<parent link="330"/>
		<child link="931"/>
		<axis xyz="1 0 0"/>
		<limit effort="1" lower="3.1415" upper="-3.1415" velocity="1"/>
		<origin rpy="9.560429822679476 2.1307635358824233 5.11997545788624" xyz="0.023220178926395052 0.7508712035405971 0.3593218542290584"/>
	</joint>
	<joint name="532_to_0" type="revolute">
		<parent link="0"/>
		<child link="532"/>
		<axis xyz="0 0 1"/>
		<limit effort="1" lower="3.1415" upper="-3.1415" velocity="1"/>
		<origin rpy="23.313157531502018 2.921742854645346 5.417100368229721" xyz="0.6311731668571811 0.5488892795999986 0.6587657313720761"/>
	</joint>
	<joint name="833_to_532" type="revolute">
		<parent link="532"/>
		<child link="833"/>
		<axis xyz="0 0 1"/>
		<limit effort="1" lower="3.1415" upper="-3.1415" velocity="1"/>
		<origin rpy="4.243949125648589 3.4876402535323656 2.67529066228197" xyz="0.7815786058354325 0.07844805318990133 0.48759290902017616"/>
	</joint>
	<joint name="1134_to_833" type="revolute">
		<parent link="833"/>
		<child link="1134"/>
		<axis xyz="0 1 0"/>
		<limit effort="1" lower="3.1415" upper="-3.1415" velocity="1"/>
		<origin rpy="11.463662242295957 4.017093750120236 3.7249955736455207" xyz="0.6121503695421647 0.9977790525935057 0.5548802267482097"/>
	</joint>
	<joint name="735_to_0" type="revolute">
		<parent link="0"/>
		<child link="735"/>
		<axis xyz="0 0 1"/>
		<limit effort="1" lower="3.1415" upper="-3.1415" velocity="1"/>
		<origin rpy="64.0580606115269 2.7989390601761093 0.12886566206073458" xyz="0.848363801600674 0.7740647791391594 0.44155881610197"/>
	</joint>
	<joint name="736_to_0" type="revolute">
		<parent link="0"/>
		<child link="736"/>
		<axis xyz="0 0 1"/>
		<limit effort="1" lower="3.1415" upper="-3.1415" velocity="1"/>
		<origin rpy="69.88152066712024 2.7989390601761093 0.12886566206073458" xyz="0.848363801600674 0.7740647791391594 0.44155881610197"/>
	</joint>
</robot>
